Workbook

Sheet Overblik_26211425
A1: Westpack A/S (CVR 26211425) — Regnskabsanalyse – Resultatopgørelse & Balance (t.kr.) · Klasse C-mellem · Revision · Regnskabsår 1/5–30/4 (forskudt)
H2: Indekstal (2022=100)
A3: Resultatopgørelse t.kr. | B3: 2022 | C3: 2023 | D3: 2024 | E3: 2025 | F3: 2026 | H3: 2022 | I3: 2023 | J3: 2024 | K3: 2025 | L3: 2026
A4: Nettoomsætning | B4: ='res_raw_26211425'!$B$2 | C4: ='res_raw_26211425'!$C$2 | D4: ='res_raw_26211425'!$D$2 | E4: ='res_raw_26211425'!$E$2 | F4: ='res_raw_26211425'!$F$2 | H4: =IFERROR(B4/$B$4*100,"") | I4: =IFERROR(C4/$B$4*100,"") | J4: =IFERROR(D4/$B$4*100,"") | K4: =IFERROR(E4/$B$4*100,"") | L4: =IFERROR(F4/$B$4*100,"")
A5: Andre driftsindtægter | B5: ='res_raw_26211425'!$B$3 | C5: ='res_raw_26211425'!$C$3 | D5: ='res_raw_26211425'!$D$3 | E5: ='res_raw_26211425'!$E$3 | F5: ='res_raw_26211425'!$F$3 | H5: =IFERROR(B5/$B$5*100,"") | I5: =IFERROR(C5/$B$5*100,"") | J5: =IFERROR(D5/$B$5*100,"") | K5: =IFERROR(E5/$B$5*100,"") | L5: =IFERROR(F5/$B$5*100,"")
A6: Vareforbrug | B6: ='res_raw_26211425'!$B$4 | C6: ='res_raw_26211425'!$C$4 | D6: ='res_raw_26211425'!$D$4 | E6: ='res_raw_26211425'!$E$4 | F6: ='res_raw_26211425'!$F$4 | H6: =IFERROR(B6/$B$6*100,"") | I6: =IFERROR(C6/$B$6*100,"") | J6: =IFERROR(D6/$B$6*100,"") | K6: =IFERROR(E6/$B$6*100,"") | L6: =IFERROR(F6/$B$6*100,"")
A7: Andre eksterne omkostninger | B7: ='res_raw_26211425'!$B$5 | C7: ='res_raw_26211425'!$C$5 | D7: ='res_raw_26211425'!$D$5 | E7: ='res_raw_26211425'!$E$5 | F7: ='res_raw_26211425'!$F$5 | H7: =IFERROR(B7/$B$7*100,"") | I7: =IFERROR(C7/$B$7*100,"") | J7: =IFERROR(D7/$B$7*100,"") | K7: =IFERROR(E7/$B$7*100,"") | L7: =IFERROR(F7/$B$7*100,"")
A8: Bruttoresultat | B8: ='res_raw_26211425'!$B$6 | C8: ='res_raw_26211425'!$C$6 | D8: ='res_raw_26211425'!$D$6 | E8: ='res_raw_26211425'!$E$6 | F8: ='res_raw_26211425'!$F$6 | H8: =IFERROR(B8/$B$8*100,"") | I8: =IFERROR(C8/$B$8*100,"") | J8: =IFERROR(D8/$B$8*100,"") | K8: =IFERROR(E8/$B$8*100,"") | L8: =IFERROR(F8/$B$8*100,"")
A9: Personaleomkostninger | B9: ='res_raw_26211425'!$B$7 | C9: ='res_raw_26211425'!$C$7 | D9: ='res_raw_26211425'!$D$7 | E9: ='res_raw_26211425'!$E$7 | F9: ='res_raw_26211425'!$F$7 | H9: =IFERROR(B9/$B$9*100,"") | I9: =IFERROR(C9/$B$9*100,"") | J9: =IFERROR(D9/$B$9*100,"") | K9: =IFERROR(E9/$B$9*100,"") | L9: =IFERROR(F9/$B$9*100,"")
A10: Resultat før afskrivninger | B10: =IFERROR($B$8-ABS($B$9),"") | C10: =IFERROR($C$8-ABS($C$9),"") | D10: =IFERROR($D$8-ABS($D$9),"") | E10: =IFERROR($E$8-ABS($E$9),"") | F10: =IFERROR($F$8-ABS($F$9),"") | H10: =IFERROR(B10/$B$10*100,"") | I10: =IFERROR(C10/$B$10*100,"") | J10: =IFERROR(D10/$B$10*100,"") | K10: =IFERROR(E10/$B$10*100,"") | L10: =IFERROR(F10/$B$10*100,"")
A11: Af- og nedskrivninger | B11: ='res_raw_26211425'!$B$9 | C11: ='res_raw_26211425'!$C$9 | D11: ='res_raw_26211425'!$D$9 | E11: ='res_raw_26211425'!$E$9 | F11: ='res_raw_26211425'!$F$9 | H11: =IFERROR(B11/$B$11*100,"") | I11: =IFERROR(C11/$B$11*100,"") | J11: =IFERROR(D11/$B$11*100,"") | K11: =IFERROR(E11/$B$11*100,"") | L11: =IFERROR(F11/$B$11*100,"")
A12: Andre driftsomkostninger | B12: ='res_raw_26211425'!$B$10 | C12: ='res_raw_26211425'!$C$10 | D12: ='res_raw_26211425'!$D$10 | E12: ='res_raw_26211425'!$E$10 | F12: ='res_raw_26211425'!$F$10 | H12: =IFERROR(B12/$B$12*100,"") | I12: =IFERROR(C12/$B$12*100,"") | J12: =IFERROR(D12/$B$12*100,"") | K12: =IFERROR(E12/$B$12*100,"") | L12: =IFERROR(F12/$B$12*100,"")
A13: Resultat af primær drift | B13: ='res_raw_26211425'!$B$11 | C13: ='res_raw_26211425'!$C$11 | D13: ='res_raw_26211425'!$D$11 | E13: ='res_raw_26211425'!$E$11 | F13: ='res_raw_26211425'!$F$11 | H13: =IFERROR(B13/$B$13*100,"") | I13: =IFERROR(C13/$B$13*100,"") | J13: =IFERROR(D13/$B$13*100,"") | K13: =IFERROR(E13/$B$13*100,"") | L13: =IFERROR(F13/$B$13*100,"")
A14: Indtægter af kapitalandele, dattervirksomheder | B14: ='res_raw_26211425'!$B$12 | C14: ='res_raw_26211425'!$C$12 | D14: ='res_raw_26211425'!$D$12 | E14: ='res_raw_26211425'!$E$12 | F14: ='res_raw_26211425'!$F$12 | H14: =IFERROR(B14/$B$14*100,"") | I14: =IFERROR(C14/$B$14*100,"") | J14: =IFERROR(D14/$B$14*100,"") | K14: =IFERROR(E14/$B$14*100,"") | L14: =IFERROR(F14/$B$14*100,"")
A15: Finansielle indtægter | B15: ='res_raw_26211425'!$B$13 | C15: ='res_raw_26211425'!$C$13 | D15: ='res_raw_26211425'!$D$13 | E15: ='res_raw_26211425'!$E$13 | F15: ='res_raw_26211425'!$F$13 | H15: =IFERROR(B15/$B$15*100,"") | I15: =IFERROR(C15/$B$15*100,"") | J15: =IFERROR(D15/$B$15*100,"") | K15: =IFERROR(E15/$B$15*100,"") | L15: =IFERROR(F15/$B$15*100,"")
A16: Finansielle omkostninger | B16: ='res_raw_26211425'!$B$14 | C16: ='res_raw_26211425'!$C$14 | D16: ='res_raw_26211425'!$D$14 | E16: ='res_raw_26211425'!$E$14 | F16: ='res_raw_26211425'!$F$14 | H16: =IFERROR(B16/$B$16*100,"") | I16: =IFERROR(C16/$B$16*100,"") | J16: =IFERROR(D16/$B$16*100,"") | K16: =IFERROR(E16/$B$16*100,"") | L16: =IFERROR(F16/$B$16*100,"")
A17: Finansielle poster, netto | B17: ='res_raw_26211425'!$B$15 | C17: ='res_raw_26211425'!$C$15 | D17: ='res_raw_26211425'!$D$15 | E17: ='res_raw_26211425'!$E$15 | F17: ='res_raw_26211425'!$F$15 | H17: =IFERROR(B17/$B$17*100,"") | I17: =IFERROR(C17/$B$17*100,"") | J17: =IFERROR(D17/$B$17*100,"") | K17: =IFERROR(E17/$B$17*100,"") | L17: =IFERROR(F17/$B$17*100,"")
A18: Resultat før skat | B18: ='res_raw_26211425'!$B$16 | C18: ='res_raw_26211425'!$C$16 | D18: ='res_raw_26211425'!$D$16 | E18: ='res_raw_26211425'!$E$16 | F18: ='res_raw_26211425'!$F$16 | H18: =IFERROR(B18/$B$18*100,"") | I18: =IFERROR(C18/$B$18*100,"") | J18: =IFERROR(D18/$B$18*100,"") | K18: =IFERROR(E18/$B$18*100,"") | L18: =IFERROR(F18/$B$18*100,"")
A19: Skat af årets resultat | B19: ='res_raw_26211425'!$B$17 | C19: ='res_raw_26211425'!$C$17 | D19: ='res_raw_26211425'!$D$17 | E19: ='res_raw_26211425'!$E$17 | F19: ='res_raw_26211425'!$F$17 | H19: =IFERROR(B19/$B$19*100,"") | I19: =IFERROR(C19/$B$19*100,"") | J19: =IFERROR(D19/$B$19*100,"") | K19: =IFERROR(E19/$B$19*100,"") | L19: =IFERROR(F19/$B$19*100,"")
A20: Årets resultat | B20: ='res_raw_26211425'!$B$18 | C20: ='res_raw_26211425'!$C$18 | D20: ='res_raw_26211425'!$D$18 | E20: ='res_raw_26211425'!$E$18 | F20: ='res_raw_26211425'!$F$18 | H20: =IFERROR(B20/$B$20*100,"") | I20: =IFERROR(C20/$B$20*100,"") | J20: =IFERROR(D20/$B$20*100,"") | K20: =IFERROR(E20/$B$20*100,"") | L20: =IFERROR(F20/$B$20*100,"")
A22: AKTIVER t.kr. | B22: 2022 | C22: 2023 | D22: 2024 | E22: 2025 | F22: 2026 | H22: 2022 | I22: 2023 | J22: 2024 | K22: 2025 | L22: 2026
A23: Udviklingsprojekter | B23: ='balance_raw_26211425'!$B$2 | C23: ='balance_raw_26211425'!$C$2 | D23: ='balance_raw_26211425'!$D$2 | E23: ='balance_raw_26211425'!$E$2 | F23: ='balance_raw_26211425'!$F$2 | H23: =IFERROR(B23/$B$23*100,"") | I23: =IFERROR(C23/$B$23*100,"") | J23: =IFERROR(D23/$B$23*100,"") | K23: =IFERROR(E23/$B$23*100,"") | L23: =IFERROR(F23/$B$23*100,"")
A24: Patenter, varemærker mv. | B24: ='balance_raw_26211425'!$B$3 | C24: ='balance_raw_26211425'!$C$3 | D24: ='balance_raw_26211425'!$D$3 | E24: ='balance_raw_26211425'!$E$3 | F24: ='balance_raw_26211425'!$F$3 | H24: =IFERROR(B24/$B$24*100,"") | I24: =IFERROR(C24/$B$24*100,"") | J24: =IFERROR(D24/$B$24*100,"") | K24: =IFERROR(E24/$B$24*100,"") | L24: =IFERROR(F24/$B$24*100,"")
A25: Goodwill | B25: ='balance_raw_26211425'!$B$4 | C25: ='balance_raw_26211425'!$C$4 | D25: ='balance_raw_26211425'!$D$4 | E25: ='balance_raw_26211425'!$E$4 | F25: ='balance_raw_26211425'!$F$4 | H25: =IFERROR(B25/$B$25*100,"") | I25: =IFERROR(C25/$B$25*100,"") | J25: =IFERROR(D25/$B$25*100,"") | K25: =IFERROR(E25/$B$25*100,"") | L25: =IFERROR(F25/$B$25*100,"")
A26: Immaterielle anlægsaktiver | B26: ='balance_raw_26211425'!$B$5 | C26: ='balance_raw_26211425'!$C$5 | D26: ='balance_raw_26211425'!$D$5 | E26: ='balance_raw_26211425'!$E$5 | F26: ='balance_raw_26211425'!$F$5 | H26: =IFERROR(B26/$B$26*100,"") | I26: =IFERROR(C26/$B$26*100,"") | J26: =IFERROR(D26/$B$26*100,"") | K26: =IFERROR(E26/$B$26*100,"") | L26: =IFERROR(F26/$B$26*100,"")
A27: Grunde og bygninger | B27: ='balance_raw_26211425'!$B$6 | C27: ='balance_raw_26211425'!$C$6 | D27: ='balance_raw_26211425'!$D$6 | E27: ='balance_raw_26211425'!$E$6 | F27: ='balance_raw_26211425'!$F$6 | H27: =IFERROR(B27/$B$27*100,"") | I27: =IFERROR(C27/$B$27*100,"") | J27: =IFERROR(D27/$B$27*100,"") | K27: =IFERROR(E27/$B$27*100,"") | L27: =IFERROR(F27/$B$27*100,"")
A28: Produktionsanlæg og maskiner | B28: ='balance_raw_26211425'!$B$7 | C28: ='balance_raw_26211425'!$C$7 | D28: ='balance_raw_26211425'!$D$7 | E28: ='balance_raw_26211425'!$E$7 | F28: ='balance_raw_26211425'!$F$7 | H28: =IFERROR(B28/$B$28*100,"") | I28: =IFERROR(C28/$B$28*100,"") | J28: =IFERROR(D28/$B$28*100,"") | K28: =IFERROR(E28/$B$28*100,"") | L28: =IFERROR(F28/$B$28*100,"")
A29: Driftsmateriel og inventar | B29: ='balance_raw_26211425'!$B$8 | C29: ='balance_raw_26211425'!$C$8 | D29: ='balance_raw_26211425'!$D$8 | E29: ='balance_raw_26211425'!$E$8 | F29: ='balance_raw_26211425'!$F$8 | H29: =IFERROR(B29/$B$29*100,"") | I29: =IFERROR(C29/$B$29*100,"") | J29: =IFERROR(D29/$B$29*100,"") | K29: =IFERROR(E29/$B$29*100,"") | L29: =IFERROR(F29/$B$29*100,"")
A30: Indretning af lejede lokaler | B30: ='balance_raw_26211425'!$B$9 | C30: ='balance_raw_26211425'!$C$9 | D30: ='balance_raw_26211425'!$D$9 | E30: ='balance_raw_26211425'!$E$9 | F30: ='balance_raw_26211425'!$F$9 | H30: =IFERROR(B30/$B$30*100,"") | I30: =IFERROR(C30/$B$30*100,"") | J30: =IFERROR(D30/$B$30*100,"") | K30: =IFERROR(E30/$B$30*100,"") | L30: =IFERROR(F30/$B$30*100,"")
A31: Forudbetaling og anlægsaktiver under opførelse | B31: ='balance_raw_26211425'!$B$10 | C31: ='balance_raw_26211425'!$C$10 | D31: ='balance_raw_26211425'!$D$10 | E31: ='balance_raw_26211425'!$E$10 | F31: ='balance_raw_26211425'!$F$10 | H31: =IFERROR(B31/$B$31*100,"") | I31: =IFERROR(C31/$B$31*100,"") | J31: =IFERROR(D31/$B$31*100,"") | K31: =IFERROR(E31/$B$31*100,"") | L31: =IFERROR(F31/$B$31*100,"")
A32: Materielle anlægsaktiver | B32: ='balance_raw_26211425'!$B$11 | C32: ='balance_raw_26211425'!$C$11 | D32: ='balance_raw_26211425'!$D$11 | E32: ='balance_raw_26211425'!$E$11 | F32: ='balance_raw_26211425'!$F$11 | H32: =IFERROR(B32/$B$32*100,"") | I32: =IFERROR(C32/$B$32*100,"") | J32: =IFERROR(D32/$B$32*100,"") | K32: =IFERROR(E32/$B$32*100,"") | L32: =IFERROR(F32/$B$32*100,"")
A33: Kapitalandele, dattervirksomheder | B33: ='balance_raw_26211425'!$B$12 | C33: ='balance_raw_26211425'!$C$12 | D33: ='balance_raw_26211425'!$D$12 | E33: ='balance_raw_26211425'!$E$12 | F33: ='balance_raw_26211425'!$F$12 | H33: =IFERROR(B33/$B$33*100,"") | I33: =IFERROR(C33/$B$33*100,"") | J33: =IFERROR(D33/$B$33*100,"") | K33: =IFERROR(E33/$B$33*100,"") | L33: =IFERROR(F33/$B$33*100,"")
A34: Deposita | B34: ='balance_raw_26211425'!$B$13 | C34: ='balance_raw_26211425'!$C$13 | D34: ='balance_raw_26211425'!$D$13 | E34: ='balance_raw_26211425'!$E$13 | F34: ='balance_raw_26211425'!$F$13 | H34: =IFERROR(B34/$B$34*100,"") | I34: =IFERROR(C34/$B$34*100,"") | J34: =IFERROR(D34/$B$34*100,"") | K34: =IFERROR(E34/$B$34*100,"") | L34: =IFERROR(F34/$B$34*100,"")
A35: Finansielle anlægsaktiver | B35: ='balance_raw_26211425'!$B$14 | C35: ='balance_raw_26211425'!$C$14 | D35: ='balance_raw_26211425'!$D$14 | E35: ='balance_raw_26211425'!$E$14 | F35: ='balance_raw_26211425'!$F$14 | H35: =IFERROR(B35/$B$35*100,"") | I35: =IFERROR(C35/$B$35*100,"") | J35: =IFERROR(D35/$B$35*100,"") | K35: =IFERROR(E35/$B$35*100,"") | L35: =IFERROR(F35/$B$35*100,"")
A36: Anlægsaktiver | B36: ='balance_raw_26211425'!$B$15 | C36: ='balance_raw_26211425'!$C$15 | D36: ='balance_raw_26211425'!$D$15 | E36: ='balance_raw_26211425'!$E$15 | F36: ='balance_raw_26211425'!$F$15 | H36: =IFERROR(B36/$B$36*100,"") | I36: =IFERROR(C36/$B$36*100,"") | J36: =IFERROR(D36/$B$36*100,"") | K36: =IFERROR(E36/$B$36*100,"") | L36: =IFERROR(F36/$B$36*100,"")
A37: Råvarer og hjælpematerialer | B37: ='balance_raw_26211425'!$B$16 | C37: ='balance_raw_26211425'!$C$16 | D37: ='balance_raw_26211425'!$D$16 | E37: ='balance_raw_26211425'!$E$16 | F37: ='balance_raw_26211425'!$F$16 | H37: =IFERROR(B37/$B$37*100,"") | I37: =IFERROR(C37/$B$37*100,"") | J37: =IFERROR(D37/$B$37*100,"") | K37: =IFERROR(E37/$B$37*100,"") | L37: =IFERROR(F37/$B$37*100,"")
A38: Varer under fremstilling | B38: ='balance_raw_26211425'!$B$17 | C38: ='balance_raw_26211425'!$C$17 | D38: ='balance_raw_26211425'!$D$17 | E38: ='balance_raw_26211425'!$E$17 | F38: ='balance_raw_26211425'!$F$17 | H38: =IFERROR(B38/$B$38*100,"") | I38: =IFERROR(C38/$B$38*100,"") | J38: =IFERROR(D38/$B$38*100,"") | K38: =IFERROR(E38/$B$38*100,"") | L38: =IFERROR(F38/$B$38*100,"")
A39: Færdigvarer og handelsvarer | B39: ='balance_raw_26211425'!$B$18 | C39: ='balance_raw_26211425'!$C$18 | D39: ='balance_raw_26211425'!$D$18 | E39: ='balance_raw_26211425'!$E$18 | F39: ='balance_raw_26211425'!$F$18 | H39: =IFERROR(B39/$B$39*100,"") | I39: =IFERROR(C39/$B$39*100,"") | J39: =IFERROR(D39/$B$39*100,"") | K39: =IFERROR(E39/$B$39*100,"") | L39: =IFERROR(F39/$B$39*100,"")
A40: Varebeholdninger | B40: ='balance_raw_26211425'!$B$19 | C40: ='balance_raw_26211425'!$C$19 | D40: ='balance_raw_26211425'!$D$19 | E40: ='balance_raw_26211425'!$E$19 | F40: ='balance_raw_26211425'!$F$19 | H40: =IFERROR(B40/$B$40*100,"") | I40: =IFERROR(C40/$B$40*100,"") | J40: =IFERROR(D40/$B$40*100,"") | K40: =IFERROR(E40/$B$40*100,"") | L40: =IFERROR(F40/$B$40*100,"")
A41: Tilgodehavender fra salg og tjenesteydelser | B41: ='balance_raw_26211425'!$B$20 | C41: ='balance_raw_26211425'!$C$20 | D41: ='balance_raw_26211425'!$D$20 | E41: ='balance_raw_26211425'!$E$20 | F41: ='balance_raw_26211425'!$F$20 | H41: =IFERROR(B41/$B$41*100,"") | I41: =IFERROR(C41/$B$41*100,"") | J41: =IFERROR(D41/$B$41*100,"") | K41: =IFERROR(E41/$B$41*100,"") | L41: =IFERROR(F41/$B$41*100,"")
...

Sheet res_raw_26211425
A1: Westpack A/S (CVR 26211425) — Resultatopgørelse & nøgleoplysninger (t.kr.) | B1: 2022 | C1: 2023 | D1: 2024 | E1: 2025 | F1: 2026
A2: Nettoomsætning
A3: Andre driftsindtægter | B3: 239 | C3: 0
A4: Vareforbrug
A5: Andre eksterne omkostninger
A6: Bruttoresultat | B6: 96413 | C6: 85539 | D6: 90590 | E6: 104580 | F6: 111457
A7: Personaleomkostninger | B7: 69741 | C7: 70534 | D7: 80988 | E7: 79983 | F7: 82824
A8: Resultat før afskrivninger
A9: Af- og nedskrivninger
A10: Andre driftsomkostninger | B10: 11648 | C10: 0
A11: Resultat af primær drift | B11: 56724 | C11: 47314 | D11: 47697 | E11: 58387 | F11: 60519
A12: Indtægter af kapitalandele, dattervirksomheder | B12: 479 | C12: 678 | D12: 179 | E12: 105 | F12: -202
A13: Finansielle indtægter | B13: 294 | C13: 427 | D13: 471 | E13: 278 | F13: 245
A14: Finansielle omkostninger | B14: 2188 | C14: 5259 | D14: 3244 | E14: 4525 | F14: 4807
A15: Finansielle poster, netto | B15: -1415 | C15: -4154 | D15: -2773 | E15: -4247 | F15: -4562
A16: Resultat før skat | B16: 43900 | C16: 43160 | D16: 45103 | E16: 54245 | F16: 55755
A17: Skat af årets resultat | B17: 12095 | C17: 9215 | D17: 10092 | E17: 11915 | F17: 11929
A18: Årets resultat | B18: 31805 | C18: 33945 | D18: 35011 | E18: 42330 | F18: 43826
A19: Gns. antal medarbejdere | B19: 142 | C19: 148 | D19: 160 | E19: 157 | F19: 159
A20: Investering i materielle anlægsaktiver | B20: 3813 | C20: 9126 | D20: 3570 | E20: 1153 | F20: 7090

Sheet balance_raw_26211425
A1: Westpack A/S (CVR 26211425) — Balance (t.kr.) | B1: 2022 | C1: 2023 | D1: 2024 | E1: 2025 | F1: 2026
A2: Udviklingsprojekter | C2: 322 | D2: 605 | E2: 715 | F2: 1040
A3: Patenter, varemærker mv. | B3: 1338 | C3: 631
A4: Goodwill
A5: Immaterielle anlægsaktiver | B5: 1338 | C5: 953 | D5: 858 | E5: 948 | F5: 1040
A6: Grunde og bygninger
A7: Produktionsanlæg og maskiner | B7: 10565 | C7: 14619 | D7: 12718 | E7: 8923 | F7: 4918
A8: Driftsmateriel og inventar | B8: 3966 | C8: 3109 | D8: 2049 | E8: 1557 | F8: 1530
A9: Indretning af lejede lokaler | D9: 34 | E9: 26 | F9: 18
A10: Forudbetaling og anlægsaktiver under opførelse | B10: 2030 | C10: 1580 | D10: 755 | E10: 0 | F10: 6307
A11: Materielle anlægsaktiver | B11: 16561 | C11: 19308 | D11: 15556 | E11: 10506 | F11: 12773
A12: Kapitalandele, dattervirksomheder | B12: 5174 | C12: 5375 | D12: 5442 | E12: 5218 | F12: 5194
A13: Deposita
A14: Finansielle anlægsaktiver | B14: 5174 | C14: 5375 | D14: 5442 | E14: 5218 | F14: 5194
A15: Anlægsaktiver | B15: 23073 | C15: 25636 | D15: 21856 | E15: 16672 | F15: 19007
A16: Råvarer og hjælpematerialer | B16: 9932 | C16: 10724 | D16: 10848 | E16: 9875 | F16: 9001
A17: Varer under fremstilling | B17: 4734 | C17: 4910 | D17: 3892 | E17: 2735 | F17: 1915
A18: Færdigvarer og handelsvarer | B18: 82752 | C18: 68663 | D18: 67202 | E18: 80785 | F18: 77356
A19: Varebeholdninger | B19: 99184 | C19: 84823 | D19: 82159 | E19: 93725 | F19: 90037
A20: Tilgodehavender fra salg og tjenesteydelser | B20: 37314 | C20: 30349 | D20: 32196 | E20: 30034 | F20: 32085
A21: Tilgodehavender hos tilknyttede virksomheder | B21: 0
A22: Andre tilgodehavender | B22: 903 | C22: 112 | D22: 387 | E22: 368 | F22: 592
A23: Periodeafgrænsningsposter (aktiver) | B23: 2027 | C23: 2003 | D23: 2254 | E23: 2637 | F23: 2512
A24: Udskudt skatteaktiv
A25: Tilgodehavende skat hos tilknyttede virksomheder
A26: Kortfristede skattetilgodehavender | E26: 4596 | F26: 4366
A27: Tilgodehavender | B27: 40244 | C27: 32464 | D27: 34837 | E27: 37635 | F27: 39555
A28: Værdipapirer
A29: Likvide beholdninger | B29: 3059 | C29: 7563 | D29: 5023 | E29: 696 | F29: 21825
A30: Omsætningsaktiver | B30: 142487 | C30: 124850 | D30: 122019 | E30: 132056 | F30: 151417
A31: Aktiver | B31: 165560 | C31: 150486 | D31: 143875 | E31: 148728 | F31: 170424
A32: Selskabskapital | B32: 1000 | C32: 1000 | D32: 1000 | E32: 1000 | F32: 1000
A33: Reserve for nettoopskrivning (indre værdis metode) | B33: 4078 | C33: 4279 | D33: 4346 | E33: 4122 | F33: 4098
A34: Reserve for udviklingsomkostninger | D34: 472 | E34: 182 | F34: 0
A35: Reserve for sikringstransaktioner | D35: 62 | E35: -780 | F35: -18
A36: Andre reserver
A37: Overført resultat | B37: 56435 | C37: 54183 | D37: 55625 | E37: 58140 | F37: 102350
A38: Egenkapital i alt | B38: 61513 | C38: 95462 | D38: 84505 | E38: 87664 | F38: 107430
A39: Hensættelse til udskudt skat | B39: 2578 | C39: 2159 | D39: 1706 | E39: 1668 | F39: 1288
A40: Hensatte forpligtelser | B40: 2578 | C40: 2159 | D40: 1706 | E40: 1668 | F40: 1288
...

Sheet pengestrom_raw_26211425
A1: Westpack A/S (CVR 26211425) — Pengestrømsopgørelse (t.kr.) | B1: 2022 | C1: 2023 | D1: 2024 | E1: 2025 | F1: 2026
A2: Pengestrømme fra driftsaktivitet | B2: 1892 | C2: 61980 | D2: 59829 | E2: 51318 | F2: 64613
A3: Pengestrømme fra investeringsaktivitet | B3: -4278 | C3: -9538 | D3: -4020 | E3: -1601 | F3: -7675
A4: Pengestrømme fra finansieringsaktivitet | B4: 1833 | C4: -22605 | D4: -45423 | E4: -36448 | F4: -17974
A5: Årets pengestrøm

Sheet Simpel_arts
A1: Westpack A/S (CVR 26211425) — Regnskabs- og nøgletal (CVR: 26211425) — artsopdelt
A3: Beløb i 1.000 kr. | B3: 2026 | C3: 2025 | D3: 2024 | F3: Note / XBRL-felt
A4: Uddrag af resultatopgørelse
A5: Nettoomsætning | B5: ='res_raw_26211425'!$F$2 | C5: ='res_raw_26211425'!$E$2 | D5: ='res_raw_26211425'!$D$2 | F5: fsa:Revenue
A6: Andre driftsindtægter | B6: ='res_raw_26211425'!$F$3 | C6: ='res_raw_26211425'!$E$3 | D6: ='res_raw_26211425'!$D$3 | F6: fsa:OtherOperatingIncome. Indtægter fra sekundære aktiviteter (huslejeindtægter, avance ved salg af anlæg mv.).
A7: Vareforbrug | B7: =-'res_raw_26211425'!$F$4 | C7: =-'res_raw_26211425'!$E$4 | D7: =-'res_raw_26211425'!$D$4 | F7: fsa:CostOfSales (vises negativt for korrekt SUM-formel).
A8: Andre eksterne omk. mv. | B8: =-'res_raw_26211425'!$F$5 | C8: =-'res_raw_26211425'!$E$5 | D8: =-'res_raw_26211425'!$D$5 | F8: fsa:OtherExternalExpenses (vises negativt). Husleje, energi, kontorhold mv.
A9: Bruttofortjeneste | B9: =IF(ABS((SUM(B5:B8))-'res_raw_26211425'!$F$6)<=2,SUM(B5:B8),'res_raw_26211425'!$F$6) | C9: =IF(ABS((SUM(C5:C8))-'res_raw_26211425'!$E$6)<=2,SUM(C5:C8),'res_raw_26211425'!$E$6) | D9: =IF(ABS((SUM(D5:D8))-'res_raw_26211425'!$D$6)<=2,SUM(D5:D8),'res_raw_26211425'!$D$6) | F9: Beregnet: Nettoomsætning + Andre driftsindt. − Vareforbrug − Andre ext. omk. Er komponenterne ikke indberettet, vises rapporteret bruttoresultat (fsa:GrossResult) direkte.
A10: Personaleomkostninger | B10: =-'res_raw_26211425'!$F$7 | C10: =-'res_raw_26211425'!$E$7 | D10: =-'res_raw_26211425'!$D$7 | F10: fsa:EmployeeBenefitsExpense (vises negativt). Lønninger, pension, sociale ydelser.
A11: Af- og nedskrivninger | B11: =-'res_raw_26211425'!$F$9 | C11: =-'res_raw_26211425'!$E$9 | D11: =-'res_raw_26211425'!$D$9 | F11: fsa:Depreciation (vises negativt). Af- og nedskrivninger på materielle og immaterielle anlægsaktiver.
A12: Andre driftsomkostninger | B12: =-'res_raw_26211425'!$F$10 | C12: =-'res_raw_26211425'!$E$10 | D12: =-'res_raw_26211425'!$D$10 | F12: fsa:OtherOperatingExpenses (vises negativt). Typisk 0 eller meget lille post.
A13: Resultat af primær drift | B13: =IF(ABS((SUM(B9:B12))-'res_raw_26211425'!$F$11)<=2,SUM(B9:B12),'res_raw_26211425'!$F$11) | C13: =IF(ABS((SUM(C9:C12))-'res_raw_26211425'!$E$11)<=2,SUM(C9:C12),'res_raw_26211425'!$E$11) | D13: =IF(ABS((SUM(D9:D12))-'res_raw_26211425'!$D$11)<=2,SUM(D9:D12),'res_raw_26211425'!$D$11) | F13: Beregnet: Bruttofortjeneste − Personaleomk. − Af- og nedskrivninger − Andre driftsomk. EBIT.
A14: Finansielle indtægter mv. | B14: =N('res_raw_26211425'!$F$12)+N('res_raw_26211425'!$F$13) | C14: =N('res_raw_26211425'!$E$12)+N('res_raw_26211425'!$E$13) | D14: =N('res_raw_26211425'!$D$12)+N('res_raw_26211425'!$D$13) | F14: fsa:IncomeFromSubsidiaries + fsa:OtherFinanceIncome.
A15: Finansielle omkostninger mv. | B15: =-'res_raw_26211425'!$F$14 | C15: =-'res_raw_26211425'!$E$14 | D15: =-'res_raw_26211425'!$D$14 | F15: fsa:OtherFinanceExpenses (vises negativt). Renteomkostninger, kurstab mv.
A16: Resultat før skat | B16: =IF(ABS((SUM(B13:B15))-'res_raw_26211425'!$F$16)<=2,SUM(B13:B15),'res_raw_26211425'!$F$16) | C16: =IF(ABS((SUM(C13:C15))-'res_raw_26211425'!$E$16)<=2,SUM(C13:C15),'res_raw_26211425'!$E$16) | D16: =IF(ABS((SUM(D13:D15))-'res_raw_26211425'!$D$16)<=2,SUM(D13:D15),'res_raw_26211425'!$D$16) | F16: Beregnet: EBIT + Fin. indtægter + Fin. omk. EBT.
A18: Uddrag af balance
A19: Anlægsaktiver | B19: ='balance_raw_26211425'!$F$15 | C19: ='balance_raw_26211425'!$E$15 | D19: ='balance_raw_26211425'!$D$15 | F19: fsa:NoncurrentAssets. Materielle, immaterielle og finansielle anlægsaktiver.
A20: Omsætningsaktiver | B20: ='balance_raw_26211425'!$F$30 | C20: ='balance_raw_26211425'!$E$30 | D20: ='balance_raw_26211425'!$D$30 | F20: fsa:CurrentAssets. Varebeholdninger, tilgodehavender, likvider.
A21: Aktiver i alt | B21: =SUM(B19:B20) | C21: =SUM(C19:C20) | D21: =SUM(D19:D20) | F21: Beregnet: Anlægsaktiver + Omsætningsaktiver. Bør matche fsa:Assets.
A23: Egenkapital | B23: ='balance_raw_26211425'!$F$38 | C23: ='balance_raw_26211425'!$E$38 | D23: ='balance_raw_26211425'!$D$38 | F23: fsa:Equity. Selskabskapital, overført resultat, reserver.
A24: Forpligtelser | B24: ='balance_raw_26211425'!$F$59-'balance_raw_26211425'!$F$38 | C24: ='balance_raw_26211425'!$E$59-'balance_raw_26211425'!$E$38 | D24: ='balance_raw_26211425'!$D$59-'balance_raw_26211425'!$D$38 | F24: Beregnet: Passiver (fsa:LiabilitiesAndEquity) − Egenkapital. Hensættelser + kort- og langfristet gæld.
A25: Passiver i alt | B25: =SUM(B23:B24) | C25: =SUM(C23:C24) | D25: =SUM(D23:D24) | F25: Beregnet: Egenkapital + Forpligtelser. Bør matche Aktiver i alt.
A27: Udvalgte balanceposter
A28: Varebeholdninger | B28: ='balance_raw_26211425'!$F$19 | C28: ='balance_raw_26211425'!$E$19 | D28: ='balance_raw_26211425'!$D$19 | F28: fsa:Inventories (eller fsa:ManufacturedGoodsAndGoodsForResale hvis total mangler).
A29: Tilgodehavender fra salg | B29: ='balance_raw_26211425'!$F$20 | C29: ='balance_raw_26211425'!$E$20 | D29: ='balance_raw_26211425'!$D$20 | F29: fsa:ShorttermTradeReceivables. Kortfristede tilgodehavender fra kunder.
A30: Kortfristede gældsforpligtelser | B30: ='balance_raw_26211425'!$F$57 | C30: ='balance_raw_26211425'!$E$57 | D30: ='balance_raw_26211425'!$D$57 | F30: fsa:ShorttermLiabilitiesOtherThanProvisions. Gæld der forfalder inden for 1 år.
A32: Rentabilitet
A33: Afkastningsgrad, % | B33: =IFERROR((B13+B14)/B21*100,"") | C33: =IFERROR((C13+C14)/C21*100,"") | D33: =IFERROR((D13+D14)/D21*100,"")
A34: Overskudsgrad (af bruttofortjeneste), % | B34: =IFERROR((B13+B14)/B9*100,"") | C34: =IFERROR((C13+C14)/C9*100,"") | D34: =IFERROR((D13+D14)/D9*100,"")
A35: Aktivernes omsætningshastighed (af bruttofortjeneste), gange | B35: =IFERROR(B9/B21,"") | C35: =IFERROR(C9/C21,"") | D35: =IFERROR(D9/D21,"")
A36: Gældsrente, % | B36: =IFERROR(-B15*100/B24,"") | C36: =IFERROR(-C15*100/C24,"") | D36: =IFERROR(-D15*100/D24,"")
A37: Egenkapitalens forrentning, % | B37: =IFERROR(B16/B23*100,"") | C37: =IFERROR(C16/C23*100,"") | D37: =IFERROR(D16/D23*100,"")
A38: Gearing, gange | B38: =IFERROR(B24/B23,"") | C38: =IFERROR(C24/C23,"") | D38: =IFERROR(D24/D23,"")
A40: Indekstal for indtjeningsevne (2024=100)
A41: Bruttofortjeneste | B41: =IFERROR(B9/$D9*100,"") | C41: =IFERROR(C9/$D9*100,"") | D41: =IFERROR(D9/$D9*100,"")
A42: Vareforbrug | B42: =IFERROR(B7/$D7*100,"") | C42: =IFERROR(C7/$D7*100,"") | D42: =IFERROR(D7/$D7*100,"")
A43: Andre eksterne omk. | B43: =IFERROR(B8/$D8*100,"") | C43: =IFERROR(C8/$D8*100,"") | D43: =IFERROR(D8/$D8*100,"")
A44: Personaleomkostninger | B44: =IFERROR(B10/$D10*100,"") | C44: =IFERROR(C10/$D10*100,"") | D44: =IFERROR(D10/$D10*100,"")
A45: Af- og nedskrivninger | B45: =IFERROR(B11/$D11*100,"") | C45: =IFERROR(C11/$D11*100,"") | D45: =IFERROR(D11/$D11*100,"")
A47: Indekstal for kapitaltilpasningsevne (2024=100)
...

Sheet Noter_info
A1: Westpack A/S (CVR 26211425) — Ukendte XBRL-felter — disse er noter og ikke en del af hoved-regnskabet
A2: Kategori | B2: Dansk navn | C2: XBRL feltnavn | D2: 2022 t.kr. | E2: 2023 t.kr. | F2: 2024 t.kr. | G2: 2025 t.kr. | H2: 2026 t.kr. | I2: Forklaring
A3: Øvrige (ukendt) | B3: fsa:ReductionOfLeaseCommitments | C3: fsa:ReductionOfLeaseCommitments | D3: 236 | E3: 239 | F3: -244 | G3: 498 | H3: 0 | I3: Ingen forklaring tilgængelig.
