Workbook

Sheet Overblik_33034474
A1: Danske Licens Spil A/S (CVR 33034474) — Regnskabsanalyse – Resultatopgørelse & Balance (t.kr.) · Revision
H2: Indekstal (2021=100)
A3: Resultatopgørelse t.kr. | B3: 2021 | C3: 2022 | D3: 2023 | E3: 2024 | F3: 2025 | H3: 2021 | I3: 2022 | J3: 2023 | K3: 2024 | L3: 2025
A4: Nettoomsætning | B4: ='res_raw_33034474'!$B$2 | C4: ='res_raw_33034474'!$C$2 | D4: ='res_raw_33034474'!$D$2 | E4: ='res_raw_33034474'!$E$2 | F4: ='res_raw_33034474'!$F$2 | H4: =IFERROR(B4/$B$4*100,"") | I4: =IFERROR(C4/$B$4*100,"") | J4: =IFERROR(D4/$B$4*100,"") | K4: =IFERROR(E4/$B$4*100,"") | L4: =IFERROR(F4/$B$4*100,"")
A5: Andre driftsindtægter | B5: ='res_raw_33034474'!$B$3 | C5: ='res_raw_33034474'!$C$3 | D5: ='res_raw_33034474'!$D$3 | E5: ='res_raw_33034474'!$E$3 | F5: ='res_raw_33034474'!$F$3 | H5: =IFERROR(B5/$B$5*100,"") | I5: =IFERROR(C5/$B$5*100,"") | J5: =IFERROR(D5/$B$5*100,"") | K5: =IFERROR(E5/$B$5*100,"") | L5: =IFERROR(F5/$B$5*100,"")
A6: Vareforbrug | B6: ='res_raw_33034474'!$B$4 | C6: ='res_raw_33034474'!$C$4 | D6: ='res_raw_33034474'!$D$4 | E6: ='res_raw_33034474'!$E$4 | F6: ='res_raw_33034474'!$F$4 | H6: =IFERROR(B6/$B$6*100,"") | I6: =IFERROR(C6/$B$6*100,"") | J6: =IFERROR(D6/$B$6*100,"") | K6: =IFERROR(E6/$B$6*100,"") | L6: =IFERROR(F6/$B$6*100,"")
A7: Andre eksterne omkostninger | B7: ='res_raw_33034474'!$B$5 | C7: ='res_raw_33034474'!$C$5 | D7: ='res_raw_33034474'!$D$5 | E7: ='res_raw_33034474'!$E$5 | F7: ='res_raw_33034474'!$F$5 | H7: =IFERROR(B7/$B$7*100,"") | I7: =IFERROR(C7/$B$7*100,"") | J7: =IFERROR(D7/$B$7*100,"") | K7: =IFERROR(E7/$B$7*100,"") | L7: =IFERROR(F7/$B$7*100,"")
A8: Bruttoresultat | B8: ='res_raw_33034474'!$B$6 | C8: ='res_raw_33034474'!$C$6 | D8: ='res_raw_33034474'!$D$6 | E8: ='res_raw_33034474'!$E$6 | F8: ='res_raw_33034474'!$F$6 | H8: =IFERROR(B8/$B$8*100,"") | I8: =IFERROR(C8/$B$8*100,"") | J8: =IFERROR(D8/$B$8*100,"") | K8: =IFERROR(E8/$B$8*100,"") | L8: =IFERROR(F8/$B$8*100,"")
A9: Personaleomkostninger | B9: ='res_raw_33034474'!$B$7 | C9: ='res_raw_33034474'!$C$7 | D9: ='res_raw_33034474'!$D$7 | E9: ='res_raw_33034474'!$E$7 | F9: ='res_raw_33034474'!$F$7 | H9: =IFERROR(B9/$B$9*100,"") | I9: =IFERROR(C9/$B$9*100,"") | J9: =IFERROR(D9/$B$9*100,"") | K9: =IFERROR(E9/$B$9*100,"") | L9: =IFERROR(F9/$B$9*100,"")
A10: Resultat før afskrivninger | B10: =IFERROR($B$8-ABS($B$9),"") | C10: =IFERROR($C$8-ABS($C$9),"") | D10: =IFERROR($D$8-ABS($D$9),"") | E10: =IFERROR($E$8-ABS($E$9),"") | F10: =IFERROR($F$8-ABS($F$9),"") | H10: =IFERROR(B10/$B$10*100,"") | I10: =IFERROR(C10/$B$10*100,"") | J10: =IFERROR(D10/$B$10*100,"") | K10: =IFERROR(E10/$B$10*100,"") | L10: =IFERROR(F10/$B$10*100,"")
A11: Af- og nedskrivninger | B11: ='res_raw_33034474'!$B$9 | C11: ='res_raw_33034474'!$C$9 | D11: ='res_raw_33034474'!$D$9 | E11: ='res_raw_33034474'!$E$9 | F11: ='res_raw_33034474'!$F$9 | H11: =IFERROR(B11/$B$11*100,"") | I11: =IFERROR(C11/$B$11*100,"") | J11: =IFERROR(D11/$B$11*100,"") | K11: =IFERROR(E11/$B$11*100,"") | L11: =IFERROR(F11/$B$11*100,"")
A12: Andre driftsomkostninger | B12: ='res_raw_33034474'!$B$10 | C12: ='res_raw_33034474'!$C$10 | D12: ='res_raw_33034474'!$D$10 | E12: ='res_raw_33034474'!$E$10 | F12: ='res_raw_33034474'!$F$10 | H12: =IFERROR(B12/$B$12*100,"") | I12: =IFERROR(C12/$B$12*100,"") | J12: =IFERROR(D12/$B$12*100,"") | K12: =IFERROR(E12/$B$12*100,"") | L12: =IFERROR(F12/$B$12*100,"")
A13: Resultat af primær drift | B13: ='res_raw_33034474'!$B$11 | C13: ='res_raw_33034474'!$C$11 | D13: ='res_raw_33034474'!$D$11 | E13: ='res_raw_33034474'!$E$11 | F13: ='res_raw_33034474'!$F$11 | H13: =IFERROR(B13/$B$13*100,"") | I13: =IFERROR(C13/$B$13*100,"") | J13: =IFERROR(D13/$B$13*100,"") | K13: =IFERROR(E13/$B$13*100,"") | L13: =IFERROR(F13/$B$13*100,"")
A14: Indtægter af kapitalandele, dattervirksomheder | B14: ='res_raw_33034474'!$B$12 | C14: ='res_raw_33034474'!$C$12 | D14: ='res_raw_33034474'!$D$12 | E14: ='res_raw_33034474'!$E$12 | F14: ='res_raw_33034474'!$F$12 | H14: =IFERROR(B14/$B$14*100,"") | I14: =IFERROR(C14/$B$14*100,"") | J14: =IFERROR(D14/$B$14*100,"") | K14: =IFERROR(E14/$B$14*100,"") | L14: =IFERROR(F14/$B$14*100,"")
A15: Finansielle indtægter | B15: ='res_raw_33034474'!$B$13 | C15: ='res_raw_33034474'!$C$13 | D15: ='res_raw_33034474'!$D$13 | E15: ='res_raw_33034474'!$E$13 | F15: ='res_raw_33034474'!$F$13 | H15: =IFERROR(B15/$B$15*100,"") | I15: =IFERROR(C15/$B$15*100,"") | J15: =IFERROR(D15/$B$15*100,"") | K15: =IFERROR(E15/$B$15*100,"") | L15: =IFERROR(F15/$B$15*100,"")
A16: Finansielle omkostninger | B16: ='res_raw_33034474'!$B$14 | C16: ='res_raw_33034474'!$C$14 | D16: ='res_raw_33034474'!$D$14 | E16: ='res_raw_33034474'!$E$14 | F16: ='res_raw_33034474'!$F$14 | H16: =IFERROR(B16/$B$16*100,"") | I16: =IFERROR(C16/$B$16*100,"") | J16: =IFERROR(D16/$B$16*100,"") | K16: =IFERROR(E16/$B$16*100,"") | L16: =IFERROR(F16/$B$16*100,"")
A17: Finansielle poster, netto | B17: ='res_raw_33034474'!$B$15 | C17: ='res_raw_33034474'!$C$15 | D17: ='res_raw_33034474'!$D$15 | E17: ='res_raw_33034474'!$E$15 | F17: ='res_raw_33034474'!$F$15 | H17: =IFERROR(B17/$B$17*100,"") | I17: =IFERROR(C17/$B$17*100,"") | J17: =IFERROR(D17/$B$17*100,"") | K17: =IFERROR(E17/$B$17*100,"") | L17: =IFERROR(F17/$B$17*100,"")
A18: Resultat før skat | B18: ='res_raw_33034474'!$B$16 | C18: ='res_raw_33034474'!$C$16 | D18: ='res_raw_33034474'!$D$16 | E18: ='res_raw_33034474'!$E$16 | F18: ='res_raw_33034474'!$F$16 | H18: =IFERROR(B18/$B$18*100,"") | I18: =IFERROR(C18/$B$18*100,"") | J18: =IFERROR(D18/$B$18*100,"") | K18: =IFERROR(E18/$B$18*100,"") | L18: =IFERROR(F18/$B$18*100,"")
A19: Skat af årets resultat | B19: ='res_raw_33034474'!$B$17 | C19: ='res_raw_33034474'!$C$17 | D19: ='res_raw_33034474'!$D$17 | E19: ='res_raw_33034474'!$E$17 | F19: ='res_raw_33034474'!$F$17 | H19: =IFERROR(B19/$B$19*100,"") | I19: =IFERROR(C19/$B$19*100,"") | J19: =IFERROR(D19/$B$19*100,"") | K19: =IFERROR(E19/$B$19*100,"") | L19: =IFERROR(F19/$B$19*100,"")
A20: Årets resultat | B20: ='res_raw_33034474'!$B$18 | C20: ='res_raw_33034474'!$C$18 | D20: ='res_raw_33034474'!$D$18 | E20: ='res_raw_33034474'!$E$18 | F20: ='res_raw_33034474'!$F$18 | H20: =IFERROR(B20/$B$20*100,"") | I20: =IFERROR(C20/$B$20*100,"") | J20: =IFERROR(D20/$B$20*100,"") | K20: =IFERROR(E20/$B$20*100,"") | L20: =IFERROR(F20/$B$20*100,"")
A22: AKTIVER t.kr. | B22: 2021 | C22: 2022 | D22: 2023 | E22: 2024 | F22: 2025 | H22: 2021 | I22: 2022 | J22: 2023 | K22: 2024 | L22: 2025
A23: Udviklingsprojekter | B23: ='balance_raw_33034474'!$B$2 | C23: ='balance_raw_33034474'!$C$2 | D23: ='balance_raw_33034474'!$D$2 | E23: ='balance_raw_33034474'!$E$2 | F23: ='balance_raw_33034474'!$F$2 | H23: =IFERROR(B23/$B$23*100,"") | I23: =IFERROR(C23/$B$23*100,"") | J23: =IFERROR(D23/$B$23*100,"") | K23: =IFERROR(E23/$B$23*100,"") | L23: =IFERROR(F23/$B$23*100,"")
A24: Patenter, varemærker mv. | B24: ='balance_raw_33034474'!$B$3 | C24: ='balance_raw_33034474'!$C$3 | D24: ='balance_raw_33034474'!$D$3 | E24: ='balance_raw_33034474'!$E$3 | F24: ='balance_raw_33034474'!$F$3 | H24: =IFERROR(B24/$B$24*100,"") | I24: =IFERROR(C24/$B$24*100,"") | J24: =IFERROR(D24/$B$24*100,"") | K24: =IFERROR(E24/$B$24*100,"") | L24: =IFERROR(F24/$B$24*100,"")
A25: Goodwill | B25: ='balance_raw_33034474'!$B$4 | C25: ='balance_raw_33034474'!$C$4 | D25: ='balance_raw_33034474'!$D$4 | E25: ='balance_raw_33034474'!$E$4 | F25: ='balance_raw_33034474'!$F$4 | H25: =IFERROR(B25/$B$25*100,"") | I25: =IFERROR(C25/$B$25*100,"") | J25: =IFERROR(D25/$B$25*100,"") | K25: =IFERROR(E25/$B$25*100,"") | L25: =IFERROR(F25/$B$25*100,"")
A26: Immaterielle anlægsaktiver | B26: ='balance_raw_33034474'!$B$5 | C26: ='balance_raw_33034474'!$C$5 | D26: ='balance_raw_33034474'!$D$5 | E26: ='balance_raw_33034474'!$E$5 | F26: ='balance_raw_33034474'!$F$5 | H26: =IFERROR(B26/$B$26*100,"") | I26: =IFERROR(C26/$B$26*100,"") | J26: =IFERROR(D26/$B$26*100,"") | K26: =IFERROR(E26/$B$26*100,"") | L26: =IFERROR(F26/$B$26*100,"")
A27: Materielle anlægsaktiver | B27: ='balance_raw_33034474'!$B$6 | C27: ='balance_raw_33034474'!$C$6 | D27: ='balance_raw_33034474'!$D$6 | E27: ='balance_raw_33034474'!$E$6 | F27: ='balance_raw_33034474'!$F$6 | H27: =IFERROR(B27/$B$27*100,"") | I27: =IFERROR(C27/$B$27*100,"") | J27: =IFERROR(D27/$B$27*100,"") | K27: =IFERROR(E27/$B$27*100,"") | L27: =IFERROR(F27/$B$27*100,"")
A28: Anlægsaktiver | B28: ='balance_raw_33034474'!$B$7 | C28: ='balance_raw_33034474'!$C$7 | D28: ='balance_raw_33034474'!$D$7 | E28: ='balance_raw_33034474'!$E$7 | F28: ='balance_raw_33034474'!$F$7 | H28: =IFERROR(B28/$B$28*100,"") | I28: =IFERROR(C28/$B$28*100,"") | J28: =IFERROR(D28/$B$28*100,"") | K28: =IFERROR(E28/$B$28*100,"") | L28: =IFERROR(F28/$B$28*100,"")
A29: Tilgodehavender fra salg og tjenesteydelser | B29: ='balance_raw_33034474'!$B$8 | C29: ='balance_raw_33034474'!$C$8 | D29: ='balance_raw_33034474'!$D$8 | E29: ='balance_raw_33034474'!$E$8 | F29: ='balance_raw_33034474'!$F$8 | H29: =IFERROR(B29/$B$29*100,"") | I29: =IFERROR(C29/$B$29*100,"") | J29: =IFERROR(D29/$B$29*100,"") | K29: =IFERROR(E29/$B$29*100,"") | L29: =IFERROR(F29/$B$29*100,"")
A30: Tilgodehavender hos tilknyttede virksomheder | B30: ='balance_raw_33034474'!$B$9 | C30: ='balance_raw_33034474'!$C$9 | D30: ='balance_raw_33034474'!$D$9 | E30: ='balance_raw_33034474'!$E$9 | F30: ='balance_raw_33034474'!$F$9 | H30: =IFERROR(B30/$B$30*100,"") | I30: =IFERROR(C30/$B$30*100,"") | J30: =IFERROR(D30/$B$30*100,"") | K30: =IFERROR(E30/$B$30*100,"") | L30: =IFERROR(F30/$B$30*100,"")
A31: Andre tilgodehavender | B31: ='balance_raw_33034474'!$B$10 | C31: ='balance_raw_33034474'!$C$10 | D31: ='balance_raw_33034474'!$D$10 | E31: ='balance_raw_33034474'!$E$10 | F31: ='balance_raw_33034474'!$F$10 | H31: =IFERROR(B31/$B$31*100,"") | I31: =IFERROR(C31/$B$31*100,"") | J31: =IFERROR(D31/$B$31*100,"") | K31: =IFERROR(E31/$B$31*100,"") | L31: =IFERROR(F31/$B$31*100,"")
A32: Periodeafgrænsningsposter (aktiver) | B32: ='balance_raw_33034474'!$B$11 | C32: ='balance_raw_33034474'!$C$11 | D32: ='balance_raw_33034474'!$D$11 | E32: ='balance_raw_33034474'!$E$11 | F32: ='balance_raw_33034474'!$F$11 | H32: =IFERROR(B32/$B$32*100,"") | I32: =IFERROR(C32/$B$32*100,"") | J32: =IFERROR(D32/$B$32*100,"") | K32: =IFERROR(E32/$B$32*100,"") | L32: =IFERROR(F32/$B$32*100,"")
A33: Udskudt skatteaktiv | B33: ='balance_raw_33034474'!$B$12 | C33: ='balance_raw_33034474'!$C$12 | D33: ='balance_raw_33034474'!$D$12 | E33: ='balance_raw_33034474'!$E$12 | F33: ='balance_raw_33034474'!$F$12 | H33: =IFERROR(B33/$B$33*100,"") | I33: =IFERROR(C33/$B$33*100,"") | J33: =IFERROR(D33/$B$33*100,"") | K33: =IFERROR(E33/$B$33*100,"") | L33: =IFERROR(F33/$B$33*100,"")
A34: Tilgodehavende skat hos tilknyttede virksomheder | B34: ='balance_raw_33034474'!$B$13 | C34: ='balance_raw_33034474'!$C$13 | D34: ='balance_raw_33034474'!$D$13 | E34: ='balance_raw_33034474'!$E$13 | F34: ='balance_raw_33034474'!$F$13 | H34: =IFERROR(B34/$B$34*100,"") | I34: =IFERROR(C34/$B$34*100,"") | J34: =IFERROR(D34/$B$34*100,"") | K34: =IFERROR(E34/$B$34*100,"") | L34: =IFERROR(F34/$B$34*100,"")
A35: Kortfristede skattetilgodehavender | B35: ='balance_raw_33034474'!$B$14 | C35: ='balance_raw_33034474'!$C$14 | D35: ='balance_raw_33034474'!$D$14 | E35: ='balance_raw_33034474'!$E$14 | F35: ='balance_raw_33034474'!$F$14 | H35: =IFERROR(B35/$B$35*100,"") | I35: =IFERROR(C35/$B$35*100,"") | J35: =IFERROR(D35/$B$35*100,"") | K35: =IFERROR(E35/$B$35*100,"") | L35: =IFERROR(F35/$B$35*100,"")
A36: Tilgodehavender | B36: ='balance_raw_33034474'!$B$15 | C36: ='balance_raw_33034474'!$C$15 | D36: ='balance_raw_33034474'!$D$15 | E36: ='balance_raw_33034474'!$E$15 | F36: ='balance_raw_33034474'!$F$15 | H36: =IFERROR(B36/$B$36*100,"") | I36: =IFERROR(C36/$B$36*100,"") | J36: =IFERROR(D36/$B$36*100,"") | K36: =IFERROR(E36/$B$36*100,"") | L36: =IFERROR(F36/$B$36*100,"")
A37: Værdipapirer | B37: ='balance_raw_33034474'!$B$16 | C37: ='balance_raw_33034474'!$C$16 | D37: ='balance_raw_33034474'!$D$16 | E37: ='balance_raw_33034474'!$E$16 | F37: ='balance_raw_33034474'!$F$16 | H37: =IFERROR(B37/$B$37*100,"") | I37: =IFERROR(C37/$B$37*100,"") | J37: =IFERROR(D37/$B$37*100,"") | K37: =IFERROR(E37/$B$37*100,"") | L37: =IFERROR(F37/$B$37*100,"")
A38: Likvide beholdninger | B38: ='balance_raw_33034474'!$B$17 | C38: ='balance_raw_33034474'!$C$17 | D38: ='balance_raw_33034474'!$D$17 | E38: ='balance_raw_33034474'!$E$17 | F38: ='balance_raw_33034474'!$F$17 | H38: =IFERROR(B38/$B$38*100,"") | I38: =IFERROR(C38/$B$38*100,"") | J38: =IFERROR(D38/$B$38*100,"") | K38: =IFERROR(E38/$B$38*100,"") | L38: =IFERROR(F38/$B$38*100,"")
A39: Omsætningsaktiver | B39: ='balance_raw_33034474'!$B$18 | C39: ='balance_raw_33034474'!$C$18 | D39: ='balance_raw_33034474'!$D$18 | E39: ='balance_raw_33034474'!$E$18 | F39: ='balance_raw_33034474'!$F$18 | H39: =IFERROR(B39/$B$39*100,"") | I39: =IFERROR(C39/$B$39*100,"") | J39: =IFERROR(D39/$B$39*100,"") | K39: =IFERROR(E39/$B$39*100,"") | L39: =IFERROR(F39/$B$39*100,"")
A40: Aktiver | B40: ='balance_raw_33034474'!$B$19 | C40: ='balance_raw_33034474'!$C$19 | D40: ='balance_raw_33034474'!$D$19 | E40: ='balance_raw_33034474'!$E$19 | F40: ='balance_raw_33034474'!$F$19 | H40: =IFERROR(B40/$B$40*100,"") | I40: =IFERROR(C40/$B$40*100,"") | J40: =IFERROR(D40/$B$40*100,"") | K40: =IFERROR(E40/$B$40*100,"") | L40: =IFERROR(F40/$B$40*100,"")
A42: PASSIVER t.kr. | B42: 2021 | C42: 2022 | D42: 2023 | E42: 2024 | F42: 2025 | H42: 2021 | I42: 2022 | J42: 2023 | K42: 2024 | L42: 2025
...

Sheet res_raw_33034474
A1: Danske Licens Spil A/S (CVR 33034474) — Resultatopgørelse & nøgleoplysninger (t.kr.) | B1: 2021 | C1: 2022 | D1: 2023 | E1: 2024 | F1: 2025
A2: Nettoomsætning | B2: 1819679 | C2: 1661743 | D2: 1613015 | E2: 1631692 | F2: 1584199
A3: Andre driftsindtægter | B3: 1759 | C3: 1286 | D3: 1325 | E3: 2182 | F3: 3287
A4: Vareforbrug
A5: Andre eksterne omkostninger | B5: 478810 | C5: 450044 | D5: 479777 | E5: 475311 | F5: 461234
A6: Bruttoresultat | B6: 952955 | C6: 896248 | D6: 887375 | E6: 915715 | F6: 896244
A7: Personaleomkostninger | B7: 88174 | C7: 95574 | D7: 105338 | E7: 104250 | F7: 102133
A8: Resultat før afskrivninger
A9: Af- og nedskrivninger | B9: 146823 | C9: 91597 | D9: 95595 | E9: 130005 | F9: 88977
A10: Andre driftsomkostninger
A11: Resultat af primær drift | B11: 241941 | C11: 263518 | D11: 211627 | E11: 237618 | F11: 247187
A12: Indtægter af kapitalandele, dattervirksomheder
A13: Finansielle indtægter | B13: 0 | C13: 1837 | D13: 19273 | E13: 23559 | F13: 13053
A14: Finansielle omkostninger | B14: 41435 | C14: 45878 | D14: 43140 | E14: 45308 | F14: 42165
A15: Finansielle poster, netto | B15: -41435 | C15: -44041 | D15: -23867 | E15: -21749 | F15: -29112
A16: Resultat før skat | B16: 200507 | C16: 219477 | D16: 187759 | E16: 215869 | F16: 218075
A17: Skat af årets resultat | B17: 37208 | C17: 48521 | D17: 40993 | E17: 40488 | F17: 47426
A18: Årets resultat | B18: 163299 | C18: 170956 | D18: 146766 | E18: 175381 | F18: 170649
A19: Gns. antal medarbejdere
A20: Investering i materielle anlægsaktiver | B20: 0 | C20: 0

Sheet balance_raw_33034474
A1: Danske Licens Spil A/S (CVR 33034474) — Balance (t.kr.) | B1: 2021 | C1: 2022 | D1: 2023 | E1: 2024 | F1: 2025
A2: Udviklingsprojekter | B2: 209037 | C2: 177842 | D2: 137084 | E2: 118491 | F2: 91734
A3: Patenter, varemærker mv.
A4: Goodwill | B4: 71253 | C4: 71253 | D4: 71253 | E4: 71253 | F4: 71253
A5: Immaterielle anlægsaktiver | B5: 369182 | C5: 338547 | D5: 314912 | E5: 244619 | F5: 199128
A6: Materielle anlægsaktiver | B6: 7988 | C6: 3637 | D6: 4267 | E6: 655 | F6: 48
A7: Anlægsaktiver | B7: 389731 | C7: 354746 | D7: 331741 | E7: 245274 | F7: 199576
A8: Tilgodehavender fra salg og tjenesteydelser | B8: 113981 | C8: 151632 | D8: 50648 | E8: 65190 | F8: 70429
A9: Tilgodehavender hos tilknyttede virksomheder
A10: Andre tilgodehavender | B10: 1776 | C10: 2369 | D10: 5892 | E10: 5031 | F10: 5187
A11: Periodeafgrænsningsposter (aktiver) | B11: 3343 | C11: 7317 | D11: 5564 | E11: 9486 | F11: 7971
A12: Udskudt skatteaktiv
A13: Tilgodehavende skat hos tilknyttede virksomheder
A14: Kortfristede skattetilgodehavender | B14: 0 | C14: 15909 | D14: 14307 | E14: 22259 | F14: 354
A15: Tilgodehavender | B15: 544 | C15: 5071 | D15: 5517 | E15: 6240 | F15: 4268
A16: Værdipapirer
A17: Likvide beholdninger | B17: 462488 | C17: 461072 | D17: 310052 | E17: 412020 | F17: 421887
A18: Omsætningsaktiver | B18: 702851 | C18: 801545 | D18: 739811 | E18: 867114 | F18: 787889
A19: Aktiver | B19: 1092583 | C19: 1156291 | D19: 1071552 | E19: 1112387 | F19: 987465
A20: Selskabskapital | B20: 10000 | C20: 10000 | D20: 10000 | E20: 10000 | F20: 10000
A21: Reserve for nettoopskrivning (indre værdis metode)
A22: Reserve for udviklingsomkostninger
A23: Reserve for sikringstransaktioner
A24: Andre reserver
A25: Overført resultat | B25: 314582 | C25: 334066 | D25: 351302 | E25: 340726 | F25: 385684
A26: Egenkapital i alt | B26: 771677 | C26: 783701 | D26: 764424 | E26: 800373 | F26: 725548
A27: Hensættelse til udskudt skat | B27: 42962 | C27: 40732 | D27: 36619 | E27: 37777 | F27: 27870
A28: Hensatte forpligtelser | B28: 0 | C28: 0 | D28: 36619 | E28: 37777 | F28: 27870
A29: Langfristede gældsforpligtelser | B29: 51842 | C29: 47289 | D29: 39224 | E29: 37777 | F29: 27870
A30: Ansvarlig lånekapital (kortfristet)
A31: Kortfristet del af langfristede gældsforpligtelser
A32: Kreditinstitutter
A33: Leasingforpligtelser (kortfristet)
A34: Leverandører af varer og tjenesteydelser | B34: 29601 | C34: 48473 | D34: 30514 | E34: 38688 | F34: 31687
A35: Gæld til tilknyttede virksomheder
A36: Gæld til selskabsdeltagere og ledelse
A37: Selskabsskat
A38: Gæld til tilknyttede virksomheder vedr. selskabsskat
A39: Anden gæld (kortfristet) | B39: 175863 | C39: 171753 | D39: 185734 | E39: 184368 | F39: 175560
A40: Periodeafgrænsningsposter (passiver)
...

Sheet pengestrom_raw_33034474
A1: Danske Licens Spil A/S (CVR 33034474) — Pengestrømsopgørelse (t.kr.) | B1: 2021 | C1: 2022 | D1: 2023 | E1: 2024 | F1: 2025
A2: Pengestrømme fra driftsaktivitet | B2: 234464 | C2: 214592 | D2: 87091 | E2: 254314 | F2: 298131
A3: Pengestrømme fra investeringsaktivitet | B3: -30817 | C3: -56609 | D3: -71944 | E3: -14469 | F3: -43280
A4: Pengestrømme fra finansieringsaktivitet | B4: -123518 | C4: -159399 | D4: -166167 | E4: -137877 | F4: -244984
A5: Årets pengestrøm | B5: 80129 | C5: -1416 | D5: -151020 | E5: 101968 | F5: 9867

Sheet Simpel_arts
A1: Danske Licens Spil A/S (CVR 33034474) — Regnskabs- og nøgletal (CVR: 33034474) — artsopdelt
A3: Beløb i 1.000 kr. | B3: 2025 | C3: 2024 | D3: 2023 | F3: Note / XBRL-felt
A4: Uddrag af resultatopgørelse
A5: Nettoomsætning | B5: ='res_raw_33034474'!$F$2 | C5: ='res_raw_33034474'!$E$2 | D5: ='res_raw_33034474'!$D$2 | F5: fsa:Revenue
A6: Andre driftsindtægter | B6: ='res_raw_33034474'!$F$3 | C6: ='res_raw_33034474'!$E$3 | D6: ='res_raw_33034474'!$D$3 | F6: fsa:OtherOperatingIncome. Indtægter fra sekundære aktiviteter (huslejeindtægter, avance ved salg af anlæg mv.).
A7: Vareforbrug | B7: =-'res_raw_33034474'!$F$4 | C7: =-'res_raw_33034474'!$E$4 | D7: =-'res_raw_33034474'!$D$4 | F7: fsa:CostOfSales (vises negativt for korrekt SUM-formel).
A8: Andre eksterne omk. mv. | B8: =-'res_raw_33034474'!$F$5 | C8: =-'res_raw_33034474'!$E$5 | D8: =-'res_raw_33034474'!$D$5 | F8: fsa:OtherExternalExpenses (vises negativt). Husleje, energi, kontorhold mv.
A9: Bruttofortjeneste | B9: =IF(ABS((SUM(B5:B8))-'res_raw_33034474'!$F$6)<=2,SUM(B5:B8),'res_raw_33034474'!$F$6) | C9: =IF(ABS((SUM(C5:C8))-'res_raw_33034474'!$E$6)<=2,SUM(C5:C8),'res_raw_33034474'!$E$6) | D9: =IF(ABS((SUM(D5:D8))-'res_raw_33034474'!$D$6)<=2,SUM(D5:D8),'res_raw_33034474'!$D$6) | F9: Beregnet: Nettoomsætning + Andre driftsindt. − Vareforbrug − Andre ext. omk. Er komponenterne ikke indberettet, vises rapporteret bruttoresultat (fsa:GrossResult) direkte.
A10: Personaleomkostninger | B10: =-'res_raw_33034474'!$F$7 | C10: =-'res_raw_33034474'!$E$7 | D10: =-'res_raw_33034474'!$D$7 | F10: fsa:EmployeeBenefitsExpense (vises negativt). Lønninger, pension, sociale ydelser.
A11: Af- og nedskrivninger | B11: =-'res_raw_33034474'!$F$9 | C11: =-'res_raw_33034474'!$E$9 | D11: =-'res_raw_33034474'!$D$9 | F11: fsa:Depreciation (vises negativt). Af- og nedskrivninger på materielle og immaterielle anlægsaktiver.
A12: Andre driftsomkostninger | B12: =-'res_raw_33034474'!$F$10 | C12: =-'res_raw_33034474'!$E$10 | D12: =-'res_raw_33034474'!$D$10 | F12: fsa:OtherOperatingExpenses (vises negativt). Typisk 0 eller meget lille post.
A13: Resultat af primær drift | B13: =IF(ABS((SUM(B9:B12))-'res_raw_33034474'!$F$11)<=2,SUM(B9:B12),'res_raw_33034474'!$F$11) | C13: =IF(ABS((SUM(C9:C12))-'res_raw_33034474'!$E$11)<=2,SUM(C9:C12),'res_raw_33034474'!$E$11) | D13: =IF(ABS((SUM(D9:D12))-'res_raw_33034474'!$D$11)<=2,SUM(D9:D12),'res_raw_33034474'!$D$11) | F13: Beregnet: Bruttofortjeneste − Personaleomk. − Af- og nedskrivninger − Andre driftsomk. EBIT.
A14: Finansielle indtægter mv. | B14: =N('res_raw_33034474'!$F$12)+N('res_raw_33034474'!$F$13) | C14: =N('res_raw_33034474'!$E$12)+N('res_raw_33034474'!$E$13) | D14: =N('res_raw_33034474'!$D$12)+N('res_raw_33034474'!$D$13) | F14: fsa:IncomeFromSubsidiaries + fsa:OtherFinanceIncome.
A15: Finansielle omkostninger mv. | B15: =-'res_raw_33034474'!$F$14 | C15: =-'res_raw_33034474'!$E$14 | D15: =-'res_raw_33034474'!$D$14 | F15: fsa:OtherFinanceExpenses (vises negativt). Renteomkostninger, kurstab mv.
A16: Resultat før skat | B16: =IF(ABS((SUM(B13:B15))-'res_raw_33034474'!$F$16)<=2,SUM(B13:B15),'res_raw_33034474'!$F$16) | C16: =IF(ABS((SUM(C13:C15))-'res_raw_33034474'!$E$16)<=2,SUM(C13:C15),'res_raw_33034474'!$E$16) | D16: =IF(ABS((SUM(D13:D15))-'res_raw_33034474'!$D$16)<=2,SUM(D13:D15),'res_raw_33034474'!$D$16) | F16: Beregnet: EBIT + Fin. indtægter + Fin. omk. EBT.
A18: Uddrag af balance
A19: Anlægsaktiver | B19: ='balance_raw_33034474'!$F$7 | C19: ='balance_raw_33034474'!$E$7 | D19: ='balance_raw_33034474'!$D$7 | F19: fsa:NoncurrentAssets. Materielle, immaterielle og finansielle anlægsaktiver.
A20: Omsætningsaktiver | B20: ='balance_raw_33034474'!$F$18 | C20: ='balance_raw_33034474'!$E$18 | D20: ='balance_raw_33034474'!$D$18 | F20: fsa:CurrentAssets. Varebeholdninger, tilgodehavender, likvider.
A21: Aktiver i alt | B21: =SUM(B19:B20) | C21: =SUM(C19:C20) | D21: =SUM(D19:D20) | F21: Beregnet: Anlægsaktiver + Omsætningsaktiver. Bør matche fsa:Assets.
A23: Egenkapital | B23: ='balance_raw_33034474'!$F$26 | C23: ='balance_raw_33034474'!$E$26 | D23: ='balance_raw_33034474'!$D$26 | F23: fsa:Equity. Selskabskapital, overført resultat, reserver.
A24: Forpligtelser | B24: ='balance_raw_33034474'!$F$43-'balance_raw_33034474'!$F$26 | C24: ='balance_raw_33034474'!$E$43-'balance_raw_33034474'!$E$26 | D24: ='balance_raw_33034474'!$D$43-'balance_raw_33034474'!$D$26 | F24: Beregnet: Passiver (fsa:LiabilitiesAndEquity) − Egenkapital. Hensættelser + kort- og langfristet gæld.
A25: Passiver i alt | B25: =SUM(B23:B24) | C25: =SUM(C23:C24) | D25: =SUM(D23:D24) | F25: Beregnet: Egenkapital + Forpligtelser. Bør matche Aktiver i alt.
A27: Udvalgte balanceposter
A28: Varebeholdninger | F28: fsa:Inventories (eller fsa:ManufacturedGoodsAndGoodsForResale hvis total mangler).
A29: Tilgodehavender fra salg | B29: ='balance_raw_33034474'!$F$8 | C29: ='balance_raw_33034474'!$E$8 | D29: ='balance_raw_33034474'!$D$8 | F29: fsa:ShorttermTradeReceivables. Kortfristede tilgodehavender fra kunder.
A30: Kortfristede gældsforpligtelser | B30: ='balance_raw_33034474'!$F$41 | C30: ='balance_raw_33034474'!$E$41 | D30: ='balance_raw_33034474'!$D$41 | F30: fsa:ShorttermLiabilitiesOtherThanProvisions. Gæld der forfalder inden for 1 år.
A32: Rentabilitet
A33: Afkastningsgrad, % | B33: =IFERROR((B13+B14)/B21*100,"") | C33: =IFERROR((C13+C14)/C21*100,"") | D33: =IFERROR((D13+D14)/D21*100,"")
A34: Overskudsgrad, % | B34: =IFERROR((B13+B14)/B5*100,"") | C34: =IFERROR((C13+C14)/C5*100,"") | D34: =IFERROR((D13+D14)/D5*100,"")
A35: Aktivernes omsætningshastighed, gange | B35: =IFERROR(B5/B21,"") | C35: =IFERROR(C5/C21,"") | D35: =IFERROR(D5/D21,"")
A36: Gældsrente, % | B36: =IFERROR(-B15*100/B24,"") | C36: =IFERROR(-C15*100/C24,"") | D36: =IFERROR(-D15*100/D24,"")
A37: Egenkapitalens forrentning, % | B37: =IFERROR(B16/B23*100,"") | C37: =IFERROR(C16/C23*100,"") | D37: =IFERROR(D16/D23*100,"")
A38: Gearing, gange | B38: =IFERROR(B24/B23,"") | C38: =IFERROR(C24/C23,"") | D38: =IFERROR(D24/D23,"")
A40: Indekstal for indtjeningsevne (2023=100)
A41: Nettoomsætning | B41: =IFERROR(B5/$D5*100,"") | C41: =IFERROR(C5/$D5*100,"") | D41: =IFERROR(D5/$D5*100,"")
A42: Vareforbrug | B42: =IFERROR(B7/$D7*100,"") | C42: =IFERROR(C7/$D7*100,"") | D42: =IFERROR(D7/$D7*100,"")
A43: Andre eksterne omk. | B43: =IFERROR(B8/$D8*100,"") | C43: =IFERROR(C8/$D8*100,"") | D43: =IFERROR(D8/$D8*100,"")
A44: Personaleomkostninger | B44: =IFERROR(B10/$D10*100,"") | C44: =IFERROR(C10/$D10*100,"") | D44: =IFERROR(D10/$D10*100,"")
A45: Af- og nedskrivninger | B45: =IFERROR(B11/$D11*100,"") | C45: =IFERROR(C11/$D11*100,"") | D45: =IFERROR(D11/$D11*100,"")
A47: Indekstal for kapitaltilpasningsevne (2023=100)
...

Sheet Noter_info
A1: Danske Licens Spil A/S (CVR 33034474) — Ukendte XBRL-felter — disse er noter og ikke en del af hoved-regnskabet
A2: Kategori | B2: Dansk navn | C2: XBRL feltnavn | D2: 2021 t.kr. | E2: 2022 t.kr. | F2: 2023 t.kr. | G2: 2024 t.kr. | H2: 2025 t.kr. | I2: Forklaring
A3: Øvrige (ukendt) | B3: ifrs-full:AdjustmentsForFinanceCosts | C3: ifrs-full:AdjustmentsForFinanceCosts | I3: Ingen forklaring tilgængelig.
A4: Øvrige (ukendt) | B4: ifrs-full:AdjustmentsForFinanceIncome | C4: ifrs-full:AdjustmentsForFinanceIncome | I4: Ingen forklaring tilgængelig.
A5: Øvrige (ukendt) | B5: ifrs-full:AdjustmentsForGainLossOnDisposalOfInvestmentsInSubsidiariesJointVenturesAndAssociates | C5: ifrs-full:AdjustmentsForGainLossOnDisposalOfInvestmentsInSubsidiariesJointVenturesAndAssociates | F5: 0 | G5: 29287 | H5: 0 | I5: Ingen forklaring tilgængelig.
A6: Øvrige (ukendt) | B6: ifrs-full:AdjustmentsForIncomeTaxExpense | C6: ifrs-full:AdjustmentsForIncomeTaxExpense | D6: 37208 | E6: 48521 | F6: 40993 | G6: 40488 | H6: 47426 | I6: Ingen forklaring tilgængelig.
A7: Øvrige (ukendt) | B7: ifrs-full:AdjustmentsForInterestExpense | C7: ifrs-full:AdjustmentsForInterestExpense | D7: 41435 | E7: 45878 | F7: 43140 | G7: 45308 | H7: 42165 | I7: Ingen forklaring tilgængelig.
A8: Øvrige (ukendt) | B8: ifrs-full:AdjustmentsForInterestIncome | C8: ifrs-full:AdjustmentsForInterestIncome | D8: 0 | E8: 1837 | F8: 19273 | G8: 23559 | H8: 13053 | I8: Ingen forklaring tilgængelig.
A9: Øvrige (ukendt) | B9: ifrs-full:ComputerSoftware | C9: ifrs-full:ComputerSoftware | D9: 24669 | E9: 21489 | F9: 18309 | G9: 15128 | H9: 11948 | I9: Ingen forklaring tilgængelig.
A10: Øvrige (ukendt) | B10: ifrs-full:CurrentDividendPayables | C10: ifrs-full:CurrentDividendPayables | D10: 2436 | E10: 1969 | F10: 1845 | G10: 3398 | H10: 3890 | I10: Ingen forklaring tilgængelig.
A11: Øvrige (ukendt) | B11: ifrs-full:CurrentFinancialLiabilitiesAtFairValueThroughProfitOrLoss | C11: ifrs-full:CurrentFinancialLiabilitiesAtFairValueThroughProfitOrLoss | D11: 1776 | E11: 2369 | F11: 5892 | G11: 5031 | H11: 5187 | I11: Ingen forklaring tilgængelig.
A12: Øvrige (ukendt) | B12: ifrs-full:CustomerrelatedIntangibleAssetsRecognisedAsOfAcquisitionDate | C12: ifrs-full:CustomerrelatedIntangibleAssetsRecognisedAsOfAcquisitionDate | D12: 8004 | E12: 5090 | F12: 2176 | G12: 0 | H12: 0 | I12: Ingen forklaring tilgængelig.
A13: Øvrige (ukendt) | B13: ifrs-full:FeeAndCommissionExpense | C13: ifrs-full:FeeAndCommissionExpense | D13: 125671 | E13: 94867 | F13: 81860 | G13: 56607 | H13: 45362 | I13: Ingen forklaring tilgængelig.
A14: Øvrige (ukendt) | B14: ifrs-full:GainsLossesOnDisposalsOfInvestments | C14: ifrs-full:GainsLossesOnDisposalsOfInvestments | F14: 0 | G14: 29287 | H14: 0 | I14: Ingen forklaring tilgængelig.
A15: Øvrige (ukendt) | B15: ifrs-full:InvestmentsInSubsidiariesJointVenturesAndAssociates | C15: ifrs-full:InvestmentsInSubsidiariesJointVenturesAndAssociates | D15: 12562 | E15: 12562 | F15: 12562 | G15: 0 | H15: 400 | I15: Ingen forklaring tilgængelig.
A16: Øvrige (ukendt) | B16: ifrs-full:OtherIncomeExpenseFromSubsidiariesJointlyControlledEntitiesAndAssociates | C16: ifrs-full:OtherIncomeExpenseFromSubsidiariesJointlyControlledEntitiesAndAssociates | D16: 1034 | E16: 3199 | F16: 3637 | G16: 0 | I16: Ingen forklaring tilgængelig.
A17: Øvrige (ukendt) | B17: ifrs-full:OtherLiabilities | C17: ifrs-full:OtherLiabilities | H17: 0 | I17: Ingen forklaring tilgængelig.
A18: Øvrige (ukendt) | B18: ifrs-full:TaxExpenseOtherThanIncomeTaxExpense | C18: ifrs-full:TaxExpenseOtherThanIncomeTaxExpense | D18: 513868 | E18: 471559 | F18: 456874 | G18: 466806 | H18: 450699 | I18: Ingen forklaring tilgængelig.
A19: Øvrige (ukendt) | B19: ifrs-full:TradeAndOtherCurrentReceivablesDueFromRelatedParties | C19: ifrs-full:TradeAndOtherCurrentReceivablesDueFromRelatedParties | D19: 122495 | E19: 160543 | H19: 282980 | I19: Ingen forklaring tilgængelig.
