Workbook

Sheet Overblik
A1: ørsted — Regnskabsanalyse – Resultatopgørelse & Balance (t.kr.)
H2: Indekstal (2021=100)
A3: Resultatopgørelse t.kr. | B3: 2021 | C3: 2022 | D3: 2023 | E3: 2024 | F3: 2025 | H3: 2021 | I3: 2022 | J3: 2023 | K3: 2024 | L3: 2025
A4: Nettoomsætning | B4: ='res_raw'!$B$2 | C4: ='res_raw'!$C$2 | D4: ='res_raw'!$D$2 | E4: ='res_raw'!$E$2 | F4: ='res_raw'!$F$2 | H4: =IFERROR(B4/$B$4*100,"") | I4: =IFERROR(C4/$B$4*100,"") | J4: =IFERROR(D4/$B$4*100,"") | K4: =IFERROR(E4/$B$4*100,"") | L4: =IFERROR(F4/$B$4*100,"")
A5: Andre driftsindtægter | B5: ='res_raw'!$B$3 | C5: ='res_raw'!$C$3 | D5: ='res_raw'!$D$3 | E5: ='res_raw'!$E$3 | F5: ='res_raw'!$F$3 | H5: =IFERROR(B5/$B$5*100,"") | I5: =IFERROR(C5/$B$5*100,"") | J5: =IFERROR(D5/$B$5*100,"") | K5: =IFERROR(E5/$B$5*100,"") | L5: =IFERROR(F5/$B$5*100,"")
A6: Vareforbrug | B6: ='res_raw'!$B$4 | C6: ='res_raw'!$C$4 | D6: ='res_raw'!$D$4 | E6: ='res_raw'!$E$4 | F6: ='res_raw'!$F$4 | H6: =IFERROR(B6/$B$6*100,"") | I6: =IFERROR(C6/$B$6*100,"") | J6: =IFERROR(D6/$B$6*100,"") | K6: =IFERROR(E6/$B$6*100,"") | L6: =IFERROR(F6/$B$6*100,"")
A7: Andre eksterne omkostninger | B7: ='res_raw'!$B$5 | C7: ='res_raw'!$C$5 | D7: ='res_raw'!$D$5 | E7: ='res_raw'!$E$5 | F7: ='res_raw'!$F$5 | H7: =IFERROR(B7/$B$7*100,"") | I7: =IFERROR(C7/$B$7*100,"") | J7: =IFERROR(D7/$B$7*100,"") | K7: =IFERROR(E7/$B$7*100,"") | L7: =IFERROR(F7/$B$7*100,"")
A8: Bruttoresultat | B8: ='res_raw'!$B$6 | C8: ='res_raw'!$C$6 | D8: ='res_raw'!$D$6 | E8: ='res_raw'!$E$6 | F8: ='res_raw'!$F$6 | H8: =IFERROR(B8/$B$8*100,"") | I8: =IFERROR(C8/$B$8*100,"") | J8: =IFERROR(D8/$B$8*100,"") | K8: =IFERROR(E8/$B$8*100,"") | L8: =IFERROR(F8/$B$8*100,"")
A9: Personaleomkostninger | B9: ='res_raw'!$B$7 | C9: ='res_raw'!$C$7 | D9: ='res_raw'!$D$7 | E9: ='res_raw'!$E$7 | F9: ='res_raw'!$F$7 | H9: =IFERROR(B9/$B$9*100,"") | I9: =IFERROR(C9/$B$9*100,"") | J9: =IFERROR(D9/$B$9*100,"") | K9: =IFERROR(E9/$B$9*100,"") | L9: =IFERROR(F9/$B$9*100,"")
A10: Resultat før afskrivninger | B10: =IFERROR($B$8-ABS($B$9),"") | C10: =IFERROR($C$8-ABS($C$9),"") | D10: =IFERROR($D$8-ABS($D$9),"") | E10: =IFERROR($E$8-ABS($E$9),"") | F10: =IFERROR($F$8-ABS($F$9),"") | H10: =IFERROR(B10/$B$10*100,"") | I10: =IFERROR(C10/$B$10*100,"") | J10: =IFERROR(D10/$B$10*100,"") | K10: =IFERROR(E10/$B$10*100,"") | L10: =IFERROR(F10/$B$10*100,"")
A11: Af- og nedskrivninger | B11: ='res_raw'!$B$9 | C11: ='res_raw'!$C$9 | D11: ='res_raw'!$D$9 | E11: ='res_raw'!$E$9 | F11: ='res_raw'!$F$9 | H11: =IFERROR(B11/$B$11*100,"") | I11: =IFERROR(C11/$B$11*100,"") | J11: =IFERROR(D11/$B$11*100,"") | K11: =IFERROR(E11/$B$11*100,"") | L11: =IFERROR(F11/$B$11*100,"")
A12: Andre driftsomkostninger | B12: ='res_raw'!$B$10 | C12: ='res_raw'!$C$10 | D12: ='res_raw'!$D$10 | E12: ='res_raw'!$E$10 | F12: ='res_raw'!$F$10 | H12: =IFERROR(B12/$B$12*100,"") | I12: =IFERROR(C12/$B$12*100,"") | J12: =IFERROR(D12/$B$12*100,"") | K12: =IFERROR(E12/$B$12*100,"") | L12: =IFERROR(F12/$B$12*100,"")
A13: Resultat af primær drift | B13: ='res_raw'!$B$11 | C13: ='res_raw'!$C$11 | D13: ='res_raw'!$D$11 | E13: ='res_raw'!$E$11 | F13: ='res_raw'!$F$11 | H13: =IFERROR(B13/$B$13*100,"") | I13: =IFERROR(C13/$B$13*100,"") | J13: =IFERROR(D13/$B$13*100,"") | K13: =IFERROR(E13/$B$13*100,"") | L13: =IFERROR(F13/$B$13*100,"")
A14: Indtægter af kapitalandele, dattervirksomheder | B14: ='res_raw'!$B$12 | C14: ='res_raw'!$C$12 | D14: ='res_raw'!$D$12 | E14: ='res_raw'!$E$12 | F14: ='res_raw'!$F$12 | H14: =IFERROR(B14/$B$14*100,"") | I14: =IFERROR(C14/$B$14*100,"") | J14: =IFERROR(D14/$B$14*100,"") | K14: =IFERROR(E14/$B$14*100,"") | L14: =IFERROR(F14/$B$14*100,"")
A15: Finansielle indtægter | B15: ='res_raw'!$B$13 | C15: ='res_raw'!$C$13 | D15: ='res_raw'!$D$13 | E15: ='res_raw'!$E$13 | F15: ='res_raw'!$F$13 | H15: =IFERROR(B15/$B$15*100,"") | I15: =IFERROR(C15/$B$15*100,"") | J15: =IFERROR(D15/$B$15*100,"") | K15: =IFERROR(E15/$B$15*100,"") | L15: =IFERROR(F15/$B$15*100,"")
A16: Finansielle omkostninger | B16: ='res_raw'!$B$14 | C16: ='res_raw'!$C$14 | D16: ='res_raw'!$D$14 | E16: ='res_raw'!$E$14 | F16: ='res_raw'!$F$14 | H16: =IFERROR(B16/$B$16*100,"") | I16: =IFERROR(C16/$B$16*100,"") | J16: =IFERROR(D16/$B$16*100,"") | K16: =IFERROR(E16/$B$16*100,"") | L16: =IFERROR(F16/$B$16*100,"")
A17: Finansielle poster, netto | B17: ='res_raw'!$B$15 | C17: ='res_raw'!$C$15 | D17: ='res_raw'!$D$15 | E17: ='res_raw'!$E$15 | F17: ='res_raw'!$F$15 | H17: =IFERROR(B17/$B$17*100,"") | I17: =IFERROR(C17/$B$17*100,"") | J17: =IFERROR(D17/$B$17*100,"") | K17: =IFERROR(E17/$B$17*100,"") | L17: =IFERROR(F17/$B$17*100,"")
A18: Resultat før skat | B18: ='res_raw'!$B$16 | C18: ='res_raw'!$C$16 | D18: ='res_raw'!$D$16 | E18: ='res_raw'!$E$16 | F18: ='res_raw'!$F$16 | H18: =IFERROR(B18/$B$18*100,"") | I18: =IFERROR(C18/$B$18*100,"") | J18: =IFERROR(D18/$B$18*100,"") | K18: =IFERROR(E18/$B$18*100,"") | L18: =IFERROR(F18/$B$18*100,"")
A19: Skat af årets resultat | B19: ='res_raw'!$B$17 | C19: ='res_raw'!$C$17 | D19: ='res_raw'!$D$17 | E19: ='res_raw'!$E$17 | F19: ='res_raw'!$F$17 | H19: =IFERROR(B19/$B$19*100,"") | I19: =IFERROR(C19/$B$19*100,"") | J19: =IFERROR(D19/$B$19*100,"") | K19: =IFERROR(E19/$B$19*100,"") | L19: =IFERROR(F19/$B$19*100,"")
A20: Årets resultat | B20: ='res_raw'!$B$18 | C20: ='res_raw'!$C$18 | D20: ='res_raw'!$D$18 | E20: ='res_raw'!$E$18 | F20: ='res_raw'!$F$18 | H20: =IFERROR(B20/$B$20*100,"") | I20: =IFERROR(C20/$B$20*100,"") | J20: =IFERROR(D20/$B$20*100,"") | K20: =IFERROR(E20/$B$20*100,"") | L20: =IFERROR(F20/$B$20*100,"")
A22: AKTIVER t.kr. | B22: 2021 | C22: 2022 | D22: 2023 | E22: 2024 | F22: 2025 | H22: 2021 | I22: 2022 | J22: 2023 | K22: 2024 | L22: 2025
A23: Immaterielle anlægsaktiver | B23: ='balance_raw'!$B$2 | C23: ='balance_raw'!$C$2 | D23: ='balance_raw'!$D$2 | E23: ='balance_raw'!$E$2 | F23: ='balance_raw'!$F$2 | H23: =IFERROR(B23/$B$23*100,"") | I23: =IFERROR(C23/$B$23*100,"") | J23: =IFERROR(D23/$B$23*100,"") | K23: =IFERROR(E23/$B$23*100,"") | L23: =IFERROR(F23/$B$23*100,"")
A24: Grunde og bygninger | B24: ='balance_raw'!$B$3 | C24: ='balance_raw'!$C$3 | D24: ='balance_raw'!$D$3 | E24: ='balance_raw'!$E$3 | F24: ='balance_raw'!$F$3 | H24: =IFERROR(B24/$B$24*100,"") | I24: =IFERROR(C24/$B$24*100,"") | J24: =IFERROR(D24/$B$24*100,"") | K24: =IFERROR(E24/$B$24*100,"") | L24: =IFERROR(F24/$B$24*100,"")
A25: Produktionsanlæg og maskiner | B25: ='balance_raw'!$B$4 | C25: ='balance_raw'!$C$4 | D25: ='balance_raw'!$D$4 | E25: ='balance_raw'!$E$4 | F25: ='balance_raw'!$F$4 | H25: =IFERROR(B25/$B$25*100,"") | I25: =IFERROR(C25/$B$25*100,"") | J25: =IFERROR(D25/$B$25*100,"") | K25: =IFERROR(E25/$B$25*100,"") | L25: =IFERROR(F25/$B$25*100,"")
A26: Driftsmateriel og inventar | B26: ='balance_raw'!$B$5 | C26: ='balance_raw'!$C$5 | D26: ='balance_raw'!$D$5 | E26: ='balance_raw'!$E$5 | F26: ='balance_raw'!$F$5 | H26: =IFERROR(B26/$B$26*100,"") | I26: =IFERROR(C26/$B$26*100,"") | J26: =IFERROR(D26/$B$26*100,"") | K26: =IFERROR(E26/$B$26*100,"") | L26: =IFERROR(F26/$B$26*100,"")
A27: Indretning af lejede lokaler | B27: ='balance_raw'!$B$6 | C27: ='balance_raw'!$C$6 | D27: ='balance_raw'!$D$6 | E27: ='balance_raw'!$E$6 | F27: ='balance_raw'!$F$6 | H27: =IFERROR(B27/$B$27*100,"") | I27: =IFERROR(C27/$B$27*100,"") | J27: =IFERROR(D27/$B$27*100,"") | K27: =IFERROR(E27/$B$27*100,"") | L27: =IFERROR(F27/$B$27*100,"")
A28: Forudbetaling og anlægsaktiver under opførelse | B28: ='balance_raw'!$B$7 | C28: ='balance_raw'!$C$7 | D28: ='balance_raw'!$D$7 | E28: ='balance_raw'!$E$7 | F28: ='balance_raw'!$F$7 | H28: =IFERROR(B28/$B$28*100,"") | I28: =IFERROR(C28/$B$28*100,"") | J28: =IFERROR(D28/$B$28*100,"") | K28: =IFERROR(E28/$B$28*100,"") | L28: =IFERROR(F28/$B$28*100,"")
A29: Materielle anlægsaktiver | B29: ='balance_raw'!$B$8 | C29: ='balance_raw'!$C$8 | D29: ='balance_raw'!$D$8 | E29: ='balance_raw'!$E$8 | F29: ='balance_raw'!$F$8 | H29: =IFERROR(B29/$B$29*100,"") | I29: =IFERROR(C29/$B$29*100,"") | J29: =IFERROR(D29/$B$29*100,"") | K29: =IFERROR(E29/$B$29*100,"") | L29: =IFERROR(F29/$B$29*100,"")
A30: Kapitalandele, dattervirksomheder | B30: ='balance_raw'!$B$9 | C30: ='balance_raw'!$C$9 | D30: ='balance_raw'!$D$9 | E30: ='balance_raw'!$E$9 | F30: ='balance_raw'!$F$9 | H30: =IFERROR(B30/$B$30*100,"") | I30: =IFERROR(C30/$B$30*100,"") | J30: =IFERROR(D30/$B$30*100,"") | K30: =IFERROR(E30/$B$30*100,"") | L30: =IFERROR(F30/$B$30*100,"")
A31: Deposita | B31: ='balance_raw'!$B$10 | C31: ='balance_raw'!$C$10 | D31: ='balance_raw'!$D$10 | E31: ='balance_raw'!$E$10 | F31: ='balance_raw'!$F$10 | H31: =IFERROR(B31/$B$31*100,"") | I31: =IFERROR(C31/$B$31*100,"") | J31: =IFERROR(D31/$B$31*100,"") | K31: =IFERROR(E31/$B$31*100,"") | L31: =IFERROR(F31/$B$31*100,"")
A32: Finansielle anlægsaktiver | B32: ='balance_raw'!$B$11 | C32: ='balance_raw'!$C$11 | D32: ='balance_raw'!$D$11 | E32: ='balance_raw'!$E$11 | F32: ='balance_raw'!$F$11 | H32: =IFERROR(B32/$B$32*100,"") | I32: =IFERROR(C32/$B$32*100,"") | J32: =IFERROR(D32/$B$32*100,"") | K32: =IFERROR(E32/$B$32*100,"") | L32: =IFERROR(F32/$B$32*100,"")
A33: Anlægsaktiver | B33: ='balance_raw'!$B$12 | C33: ='balance_raw'!$C$12 | D33: ='balance_raw'!$D$12 | E33: ='balance_raw'!$E$12 | F33: ='balance_raw'!$F$12 | H33: =IFERROR(B33/$B$33*100,"") | I33: =IFERROR(C33/$B$33*100,"") | J33: =IFERROR(D33/$B$33*100,"") | K33: =IFERROR(E33/$B$33*100,"") | L33: =IFERROR(F33/$B$33*100,"")
A34: Varebeholdninger | B34: ='balance_raw'!$B$13 | C34: ='balance_raw'!$C$13 | D34: ='balance_raw'!$D$13 | E34: ='balance_raw'!$E$13 | F34: ='balance_raw'!$F$13 | H34: =IFERROR(B34/$B$34*100,"") | I34: =IFERROR(C34/$B$34*100,"") | J34: =IFERROR(D34/$B$34*100,"") | K34: =IFERROR(E34/$B$34*100,"") | L34: =IFERROR(F34/$B$34*100,"")
A35: Tilgodehavender fra salg og tjenesteydelser | B35: ='balance_raw'!$B$14 | C35: ='balance_raw'!$C$14 | D35: ='balance_raw'!$D$14 | E35: ='balance_raw'!$E$14 | F35: ='balance_raw'!$F$14 | H35: =IFERROR(B35/$B$35*100,"") | I35: =IFERROR(C35/$B$35*100,"") | J35: =IFERROR(D35/$B$35*100,"") | K35: =IFERROR(E35/$B$35*100,"") | L35: =IFERROR(F35/$B$35*100,"")
A36: Tilgodehavender hos tilknyttede virksomheder | B36: ='balance_raw'!$B$15 | C36: ='balance_raw'!$C$15 | D36: ='balance_raw'!$D$15 | E36: ='balance_raw'!$E$15 | F36: ='balance_raw'!$F$15 | H36: =IFERROR(B36/$B$36*100,"") | I36: =IFERROR(C36/$B$36*100,"") | J36: =IFERROR(D36/$B$36*100,"") | K36: =IFERROR(E36/$B$36*100,"") | L36: =IFERROR(F36/$B$36*100,"")
A37: Andre tilgodehavender | B37: ='balance_raw'!$B$16 | C37: ='balance_raw'!$C$16 | D37: ='balance_raw'!$D$16 | E37: ='balance_raw'!$E$16 | F37: ='balance_raw'!$F$16 | H37: =IFERROR(B37/$B$37*100,"") | I37: =IFERROR(C37/$B$37*100,"") | J37: =IFERROR(D37/$B$37*100,"") | K37: =IFERROR(E37/$B$37*100,"") | L37: =IFERROR(F37/$B$37*100,"")
A38: Periodeafgrænsningsposter (aktiver) | B38: ='balance_raw'!$B$17 | C38: ='balance_raw'!$C$17 | D38: ='balance_raw'!$D$17 | E38: ='balance_raw'!$E$17 | F38: ='balance_raw'!$F$17 | H38: =IFERROR(B38/$B$38*100,"") | I38: =IFERROR(C38/$B$38*100,"") | J38: =IFERROR(D38/$B$38*100,"") | K38: =IFERROR(E38/$B$38*100,"") | L38: =IFERROR(F38/$B$38*100,"")
A39: Udskudt skatteaktiv | B39: ='balance_raw'!$B$18 | C39: ='balance_raw'!$C$18 | D39: ='balance_raw'!$D$18 | E39: ='balance_raw'!$E$18 | F39: ='balance_raw'!$F$18 | H39: =IFERROR(B39/$B$39*100,"") | I39: =IFERROR(C39/$B$39*100,"") | J39: =IFERROR(D39/$B$39*100,"") | K39: =IFERROR(E39/$B$39*100,"") | L39: =IFERROR(F39/$B$39*100,"")
A40: Tilgodehavende skat hos tilknyttede virksomheder | B40: ='balance_raw'!$B$19 | C40: ='balance_raw'!$C$19 | D40: ='balance_raw'!$D$19 | E40: ='balance_raw'!$E$19 | F40: ='balance_raw'!$F$19 | H40: =IFERROR(B40/$B$40*100,"") | I40: =IFERROR(C40/$B$40*100,"") | J40: =IFERROR(D40/$B$40*100,"") | K40: =IFERROR(E40/$B$40*100,"") | L40: =IFERROR(F40/$B$40*100,"")
A41: Kortfristede skattetilgodehavender | B41: ='balance_raw'!$B$20 | C41: ='balance_raw'!$C$20 | D41: ='balance_raw'!$D$20 | E41: ='balance_raw'!$E$20 | F41: ='balance_raw'!$F$20 | H41: =IFERROR(B41/$B$41*100,"") | I41: =IFERROR(C41/$B$41*100,"") | J41: =IFERROR(D41/$B$41*100,"") | K41: =IFERROR(E41/$B$41*100,"") | L41: =IFERROR(F41/$B$41*100,"")
...

Sheet res_raw
A1: ørsted — Resultatopgørelse & nøgleoplysninger (t.kr.) | B1: 2021 | C1: 2022 | D1: 2023 | E1: 2024 | F1: 2025
A2: Nettoomsætning | B2: 77673000 | C2: 114417000 | D2: 79255000 | E2: 71034000 | F2: 73244000
A3: Andre driftsindtægter | B3: 10185000 | C3: 14119000 | D3: 10329000 | E3: 5298000 | F3: 9312000
A4: Vareforbrug
A5: Andre eksterne omkostninger | B5: 5760000 | C5: 7049000 | D5: 7406000 | E5: 8697000 | F5: 9063000
A6: Bruttoresultat
A7: Personaleomkostninger | B7: 4289000 | C7: 5278000 | D7: 6374000 | E7: 6532000 | F7: 7080000
A8: Resultat før afskrivninger
A9: Af- og nedskrivninger | B9: 8101000 | C9: 9754000 | D9: 9795000 | E9: 10225000 | F9: 10195000
A10: Andre driftsomkostninger
A11: Resultat af primær drift | B11: 16195000 | C11: 19774000 | D11: -17853000 | E11: 6171000 | F11: 8620000
A12: Indtægter af kapitalandele, dattervirksomheder
A13: Finansielle indtægter | B13: 4380000 | C13: 15514000 | D13: 12379000 | E13: 8590000 | F13: 11797000
A14: Finansielle omkostninger | B14: 6546000 | C14: 18050000 | D14: 13822000 | E14: 12181000 | F14: 14678000
A15: Finansielle poster, netto | B15: -2166000 | C15: -2536000 | D15: -1443000 | E15: -3591000 | F15: -2881000
A16: Resultat før skat | B16: 13277000 | C16: 17609000 | D16: -19026000 | E16: 2606000 | F16: 5988000
A17: Skat af årets resultat | B17: 2390000 | C17: 2613000 | D17: 1156000 | E17: 2590000 | F17: 2823000
A18: Årets resultat | B18: 10887000 | C18: 14996000 | D18: -20182000 | E18: 16000 | F18: 3165000
A19: Gns. antal medarbejdere
A20: Investering i materielle anlægsaktiver

Sheet balance_raw
A1: ørsted — Balance (t.kr.) | B1: 2021 | C1: 2022 | D1: 2023 | E1: 2024 | F1: 2025
A2: Immaterielle anlægsaktiver | B2: 1543000 | C2: 4029000 | D2: 3426000 | E2: 2611000 | F2: 755000
A3: Grunde og bygninger | B3: 8066000 | C3: 7980000 | D3: 7777000 | E3: 7977000 | F3: 7790000
A4: Produktionsanlæg og maskiner
A5: Driftsmateriel og inventar | B5: 604000 | C5: 1543000 | D5: 2042000 | E5: 2122000 | F5: 2179000
A6: Indretning af lejede lokaler
A7: Forudbetaling og anlægsaktiver under opførelse | B7: 57108000 | C7: 48931000 | D7: 48307000 | E7: 53118000 | F7: 77352000
A8: Materielle anlægsaktiver | B8: 161396000 | C8: 177665000 | D8: 179769000 | E8: 201694000 | F8: 210866000
A9: Kapitalandele, dattervirksomheder | B9: 572000 | C9: 772000 | D9: 960000 | E9: 870000 | F9: 434000
A10: Deposita | B10: 2937000 | C10: 1986000 | D10: 1523000 | E10: 1304000 | F10: 1571000
A11: Finansielle anlægsaktiver
A12: Anlægsaktiver | B12: 182221000 | C12: 201414000 | D12: 197081000 | E12: 219147000 | F12: 230412000
A13: Varebeholdninger | B13: 15998000 | C13: 14103000 | D13: 10539000 | E13: 17448000 | F13: 9938000
A14: Tilgodehavender fra salg og tjenesteydelser | B14: 9565000 | C14: 12701000 | D14: 11107000 | E14: 9045000 | F14: 9848000
A15: Tilgodehavender hos tilknyttede virksomheder
A16: Andre tilgodehavender | B16: 14078000 | C16: 23433000 | D16: 10473000 | E16: 4617000 | F16: 3539000
A17: Periodeafgrænsningsposter (aktiver) | B17: 2000 | C17: 408000 | D17: 802000 | E17: 324000 | F17: 0
A18: Udskudt skatteaktiv | B18: 13281000 | C18: 13719000 | D18: 8192000 | E18: 9250000 | F18: 9547000
A19: Tilgodehavende skat hos tilknyttede virksomheder
A20: Kortfristede skattetilgodehavender | B20: 1200000 | C20: 419000 | D20: 483000 | E20: 570000 | F20: 768000
A21: Tilgodehavender | B21: 14815000 | C21: 20289000 | D21: 10530000 | E21: 9936000 | F21: 10937000
A22: Værdipapirer
A23: Likvide beholdninger | B23: 18557000 | C23: 32353000 | D23: 20289000 | E23: 46250000 | F23: 53448000
A24: Omsætningsaktiver | B24: 86829000 | C24: 112728000 | D24: 84055000 | E24: 79639000 | F24: 126901000
A25: Aktiver | B25: 270385000 | C25: 314142000 | D25: 281136000 | E25: 298786000 | F25: 367922000
A26: Selskabskapital | B26: 4204000 | C26: 4204000 | D26: 4204000 | E26: 4204000 | F26: 13212000
A27: Reserve for nettoopskrivning (indre værdis metode)
A28: Reserve for udviklingsomkostninger
A29: Reserve for sikringstransaktioner
A30: Andre reserver | B30: -24778000 | C30: -26467000 | D30: -10251000 | E30: -5164000 | F30: -9164000
A31: Overført resultat | B31: 79391000 | C31: 88331000 | D31: 62829000 | E31: 63098000 | F31: 115670000
A32: Egenkapital i alt | B32: 67153000 | C32: 75739000 | D32: 58688000 | E32: 72529000 | F32: 127986000
A33: Hensættelse til udskudt skat | B33: 5616000 | C33: 7414000 | D33: 3439000 | E33: 2433000 | F33: 1969000
A34: Hensatte forpligtelser | B34: 15124000 | C34: 19121000 | D34: 16908000 | E34: 17735000 | F34: 18252000
A35: Ansvarlig lånekapital (langfristet)
A36: Langfristede lån
A37: Leasingforpligtelser (langfristet) | B37: 6812000 | C37: 7697000 | D37: 7618000 | E37: 8076000 | F37: 8120000
A38: Anden gæld (langfristet) | B38: 22146000 | C38: 31484000 | D38: 20036000 | E38: 14707000 | F38: 11264000
A39: Langfristede gældsforpligtelser | B39: 31502000 | C39: 60451000 | D39: 79236000 | E39: 83607000 | F39: 87204000
A40: Ansvarlig lånekapital (kortfristet)
...

Sheet pengestrom_raw
A1: ørsted — Pengestrømsopgørelse (t.kr.) | B1: 2021 | C1: 2022 | D1: 2023 | E1: 2024 | F1: 2025
A2: Pengestrømme fra driftsaktivitet | B2: 12148000 | C2: 11924000 | D2: 28532000 | E2: 18356000 | F2: 23741000
A3: Pengestrømme fra investeringsaktivitet | B3: -12591000 | C3: -17912000 | D3: -34732000 | E3: -21759000 | F3: -66471000
A4: Pengestrømme fra finansieringsaktivitet | B4: 3392000 | C4: 13785000 | D4: 265000 | E4: 15843000 | F4: 73809000
A5: Årets pengestrøm

Sheet Simpel_arts
A1: ørsted — Regnskabs- og nøgletal — artsopdelt
A3: Beløb i 1.000 kr. | B3: 2025 | C3: 2024 | D3: 2023 | F3: Note / XBRL-felt
A4: Uddrag af resultatopgørelse
A5: Nettoomsætning | B5: ='res_raw'!$F$2 | C5: ='res_raw'!$E$2 | D5: ='res_raw'!$D$2 | F5: fsa:Revenue
A6: Andre driftsindtægter | B6: ='res_raw'!$F$3 | C6: ='res_raw'!$E$3 | D6: ='res_raw'!$D$3 | F6: fsa:OtherOperatingIncome. Indtægter fra sekundære aktiviteter (huslejeindtægter, avance ved salg af anlæg mv.).
A7: Vareforbrug | B7: =-'res_raw'!$F$4 | C7: =-'res_raw'!$E$4 | D7: =-'res_raw'!$D$4 | F7: fsa:CostOfSales (vises negativt for korrekt SUM-formel).
A8: Andre eksterne omk. mv. | B8: =-'res_raw'!$F$5 | C8: =-'res_raw'!$E$5 | D8: =-'res_raw'!$D$5 | F8: fsa:OtherExternalExpenses (vises negativt). Husleje, energi, kontorhold mv.
A9: Bruttofortjeneste | B9: =IF(ABS((SUM(B5:B8))-'res_raw'!$F$6)<=2,SUM(B5:B8),'res_raw'!$F$6) | C9: =IF(ABS((SUM(C5:C8))-'res_raw'!$E$6)<=2,SUM(C5:C8),'res_raw'!$E$6) | D9: =IF(ABS((SUM(D5:D8))-'res_raw'!$D$6)<=2,SUM(D5:D8),'res_raw'!$D$6) | F9: Beregnet: Nettoomsætning + Andre driftsindt. − Vareforbrug − Andre ext. omk. Er komponenterne ikke indberettet, vises rapporteret bruttoresultat (fsa:GrossResult) direkte.
A10: Personaleomkostninger | B10: =-'res_raw'!$F$7 | C10: =-'res_raw'!$E$7 | D10: =-'res_raw'!$D$7 | F10: fsa:EmployeeBenefitsExpense (vises negativt). Lønninger, pension, sociale ydelser.
A11: Af- og nedskrivninger | B11: =-'res_raw'!$F$9 | C11: =-'res_raw'!$E$9 | D11: =-'res_raw'!$D$9 | F11: fsa:Depreciation (vises negativt). Af- og nedskrivninger på materielle og immaterielle anlægsaktiver.
A12: Andre driftsomkostninger | B12: =-'res_raw'!$F$10 | C12: =-'res_raw'!$E$10 | D12: =-'res_raw'!$D$10 | F12: fsa:OtherOperatingExpenses (vises negativt). Typisk 0 eller meget lille post.
A13: Resultat af primær drift | B13: =IF(ABS((SUM(B9:B12))-'res_raw'!$F$11)<=2,SUM(B9:B12),'res_raw'!$F$11) | C13: =IF(ABS((SUM(C9:C12))-'res_raw'!$E$11)<=2,SUM(C9:C12),'res_raw'!$E$11) | D13: =IF(ABS((SUM(D9:D12))-'res_raw'!$D$11)<=2,SUM(D9:D12),'res_raw'!$D$11) | F13: Beregnet: Bruttofortjeneste − Personaleomk. − Af- og nedskrivninger − Andre driftsomk. EBIT.
A14: Finansielle indtægter mv. | B14: =N('res_raw'!$F$12)+N('res_raw'!$F$13) | C14: =N('res_raw'!$E$12)+N('res_raw'!$E$13) | D14: =N('res_raw'!$D$12)+N('res_raw'!$D$13) | F14: fsa:IncomeFromSubsidiaries + fsa:OtherFinanceIncome.
A15: Finansielle omkostninger mv. | B15: =-'res_raw'!$F$14 | C15: =-'res_raw'!$E$14 | D15: =-'res_raw'!$D$14 | F15: fsa:OtherFinanceExpenses (vises negativt). Renteomkostninger, kurstab mv.
A16: Resultat før skat | B16: =IF(ABS((SUM(B13:B15))-'res_raw'!$F$16)<=2,SUM(B13:B15),'res_raw'!$F$16) | C16: =IF(ABS((SUM(C13:C15))-'res_raw'!$E$16)<=2,SUM(C13:C15),'res_raw'!$E$16) | D16: =IF(ABS((SUM(D13:D15))-'res_raw'!$D$16)<=2,SUM(D13:D15),'res_raw'!$D$16) | F16: Beregnet: EBIT + Fin. indtægter + Fin. omk. EBT.
A18: Uddrag af balance
A19: Anlægsaktiver | B19: ='balance_raw'!$F$12 | C19: ='balance_raw'!$E$12 | D19: ='balance_raw'!$D$12 | F19: fsa:NoncurrentAssets. Materielle, immaterielle og finansielle anlægsaktiver.
A20: Omsætningsaktiver | B20: ='balance_raw'!$F$24 | C20: ='balance_raw'!$E$24 | D20: ='balance_raw'!$D$24 | F20: fsa:CurrentAssets. Varebeholdninger, tilgodehavender, likvider.
A21: Aktiver i alt | B21: =SUM(B19:B20) | C21: =SUM(C19:C20) | D21: =SUM(D19:D20) | F21: Beregnet: Anlægsaktiver + Omsætningsaktiver. Bør matche fsa:Assets.
A23: Egenkapital | B23: ='balance_raw'!$F$32 | C23: ='balance_raw'!$E$32 | D23: ='balance_raw'!$D$32 | F23: fsa:Equity. Selskabskapital, overført resultat, reserver.
A24: Forpligtelser | B24: ='balance_raw'!$F$53-'balance_raw'!$F$32 | C24: ='balance_raw'!$E$53-'balance_raw'!$E$32 | D24: ='balance_raw'!$D$53-'balance_raw'!$D$32 | F24: Beregnet: Passiver (fsa:LiabilitiesAndEquity) − Egenkapital. Hensættelser + kort- og langfristet gæld.
A25: Passiver i alt | B25: =SUM(B23:B24) | C25: =SUM(C23:C24) | D25: =SUM(D23:D24) | F25: Beregnet: Egenkapital + Forpligtelser. Bør matche Aktiver i alt.
A27: Udvalgte balanceposter
A28: Varebeholdninger | B28: ='balance_raw'!$F$13 | C28: ='balance_raw'!$E$13 | D28: ='balance_raw'!$D$13 | F28: fsa:Inventories (eller fsa:ManufacturedGoodsAndGoodsForResale hvis total mangler).
A29: Tilgodehavender fra salg | B29: ='balance_raw'!$F$14 | C29: ='balance_raw'!$E$14 | D29: ='balance_raw'!$D$14 | F29: fsa:ShorttermTradeReceivables. Kortfristede tilgodehavender fra kunder.
A30: Kortfristede gældsforpligtelser | B30: ='balance_raw'!$F$51 | C30: ='balance_raw'!$E$51 | D30: ='balance_raw'!$D$51 | F30: fsa:ShorttermLiabilitiesOtherThanProvisions. Gæld der forfalder inden for 1 år.
A32: Rentabilitet
A33: Afkastningsgrad, % | B33: =IFERROR((B13+B14)/B21*100,"") | C33: =IFERROR((C13+C14)/C21*100,"") | D33: =IFERROR((D13+D14)/D21*100,"")
A34: Overskudsgrad, % | B34: =IFERROR((B13+B14)/B5*100,"") | C34: =IFERROR((C13+C14)/C5*100,"") | D34: =IFERROR((D13+D14)/D5*100,"")
A35: Aktivernes omsætningshastighed, gange | B35: =IFERROR(B5/B21,"") | C35: =IFERROR(C5/C21,"") | D35: =IFERROR(D5/D21,"")
A36: Gældsrente, % | B36: =IFERROR(-B15*100/B24,"") | C36: =IFERROR(-C15*100/C24,"") | D36: =IFERROR(-D15*100/D24,"")
A37: Egenkapitalens forrentning, % | B37: =IFERROR(B16/B23*100,"") | C37: =IFERROR(C16/C23*100,"") | D37: =IFERROR(D16/D23*100,"")
A38: Gearing, gange | B38: =IFERROR(B24/B23,"") | C38: =IFERROR(C24/C23,"") | D38: =IFERROR(D24/D23,"")
A40: Indekstal for indtjeningsevne (2023=100)
A41: Nettoomsætning | B41: =IFERROR(B5/$D5*100,"") | C41: =IFERROR(C5/$D5*100,"") | D41: =IFERROR(D5/$D5*100,"")
A42: Vareforbrug | B42: =IFERROR(B7/$D7*100,"") | C42: =IFERROR(C7/$D7*100,"") | D42: =IFERROR(D7/$D7*100,"")
A43: Andre eksterne omk. | B43: =IFERROR(B8/$D8*100,"") | C43: =IFERROR(C8/$D8*100,"") | D43: =IFERROR(D8/$D8*100,"")
A44: Personaleomkostninger | B44: =IFERROR(B10/$D10*100,"") | C44: =IFERROR(C10/$D10*100,"") | D44: =IFERROR(D10/$D10*100,"")
A45: Af- og nedskrivninger | B45: =IFERROR(B11/$D11*100,"") | C45: =IFERROR(C11/$D11*100,"") | D45: =IFERROR(D11/$D11*100,"")
A47: Indekstal for kapitaltilpasningsevne (2023=100)
...

Sheet Noter_info
A1: ørsted — Ukendte XBRL-felter — disse er noter og ikke en del af hoved-regnskabet
A2: Kategori | B2: Dansk navn | C2: XBRL feltnavn | D2: 2021 t.kr. | E2: 2022 t.kr. | F2: 2023 t.kr. | G2: 2024 t.kr. | H2: 2025 t.kr. | I2: Forklaring
A3: Øvrige (ukendt) | B3: ifrs-full:AdjustmentsForDecreaseIncreaseInTradeAccountReceivable | C3: ifrs-full:AdjustmentsForDecreaseIncreaseInTradeAccountReceivable | D3: -2299000 | E3: -2875000 | F3: 1522000 | G3: 2142000 | H3: -969000 | I3: Ingen forklaring tilgængelig.
A4: Øvrige (ukendt) | B4: ifrs-full:AdjustmentsForIncreaseDecreaseInTradeAccountPayable | C4: ifrs-full:AdjustmentsForIncreaseDecreaseInTradeAccountPayable | D4: 5140000 | E4: 3886000 | F4: -5309000 | G4: 2821000 | H4: -1160000 | I4: Ingen forklaring tilgængelig.
A5: Øvrige (ukendt) | B5: ifrs-full:CashFlowsFromUsedInDecreaseIncreaseInRestrictedCashAndCashEquivalents | C5: ifrs-full:CashFlowsFromUsedInDecreaseIncreaseInRestrictedCashAndCashEquivalents | E5: -1113000 | F5: 1448000 | G5: 163000 | H5: -82000 | I5: Ingen forklaring tilgængelig.
A6: Øvrige (ukendt) | B6: ifrs-full:CurrentFinancialAssetsAtFairValueThroughProfitOrLossClassifiedAsHeldForTrading | C6: ifrs-full:CurrentFinancialAssetsAtFairValueThroughProfitOrLossClassifiedAsHeldForTrading | D6: 21228000 | E6: 25197000 | F6: 29902000 | G6: 14532000 | H6: 38317000 | I6: Ingen forklaring tilgængelig.
A7: Øvrige (ukendt) | B7: ifrs-full:GainsLossesOnDisposalsOfInvestments | C7: ifrs-full:GainsLossesOnDisposalsOfInvestments | D7: -742000 | E7: 331000 | F7: 234000 | G7: -11000 | H7: 213000 | I7: Ingen forklaring tilgængelig.
A8: Øvrige (ukendt) | B8: ifrs-full:GainsLossesOnHedgesOfNetInvestmentsInForeignOperationsBeforeTax | C8: ifrs-full:GainsLossesOnHedgesOfNetInvestmentsInForeignOperationsBeforeTax | D8: -3359000 | E8: 738000 | F8: -328000 | G8: -3698000 | H8: 5070000 | I8: Ingen forklaring tilgængelig.
A9: Øvrige (ukendt) | B9: ifrs-full:ImpairmentLossReversalOfImpairmentLossRecognisedInProfitOrLoss | C9: ifrs-full:ImpairmentLossReversalOfImpairmentLossRecognisedInProfitOrLoss | E9: 2529000 | F9: 26775000 | G9: 15563000 | H9: 3633000 | I9: Ingen forklaring tilgængelig.
A10: Øvrige (ukendt) | B10: ifrs-full:NoncurrentContractLiabilities | C10: ifrs-full:NoncurrentContractLiabilities | D10: 3230000 | E10: 3085000 | F10: 3297000 | G10: 8834000 | H10: 8257000 | I10: Ingen forklaring tilgængelig.
A11: Øvrige (ukendt) | B11: ifrs-full:NoncurrentReceivablesDueFromRelatedParties | C11: ifrs-full:NoncurrentReceivablesDueFromRelatedParties | E11: 0 | F11: 77000 | G11: 200000 | H11: 179000 | I11: Ingen forklaring tilgængelig.
A12: Øvrige (ukendt) | B12: ifrs-full:ProceedsFromSalesOrMaturityOfFinancialInstrumentsClassifiedAsInvestingActivities | C12: ifrs-full:ProceedsFromSalesOrMaturityOfFinancialInstrumentsClassifiedAsInvestingActivities | D12: 11656000 | E12: 3780000 | F12: 13935000 | G12: 27318000 | H12: 20419000 | I12: Ingen forklaring tilgængelig.
A13: Øvrige (ukendt) | B13: ifrs-full:ReclassificationAdjustmentsOnHedgesOfNetInvestmentsInForeignOperationsBeforeTax | C13: ifrs-full:ReclassificationAdjustmentsOnHedgesOfNetInvestmentsInForeignOperationsBeforeTax | D13: 145000 | E13: -676000 | F13: 295000 | G13: -12000 | H13: -100000 | I13: Ingen forklaring tilgængelig.
A14: Øvrige (ukendt) | B14: ifrs-full:TradeAndOtherCurrentReceivablesDueFromRelatedParties | C14: ifrs-full:TradeAndOtherCurrentReceivablesDueFromRelatedParties | E14: 0 | F14: 74000 | G14: 41000 | H14: 106000 | I14: Ingen forklaring tilgængelig.
