Workbook

Sheet Overblik_37535699
A1: Too Good To Go Holding ApS (CVR 37535699) — Regnskabsanalyse – Resultatopgørelse & Balance (valuta pr. år - se kolonneoverskrifter) · Klasse C-stor · Revision
H2: Indekstal (2021=100)
A3: Resultatopgørelse valuta pr. år - se kolonneoverskrifter | B3: 2021 | C3: 2022 | D3: 2023 | E3: 2024 | F3: 2025 | H3: 2021 | I3: 2022 | J3: 2023 | K3: 2024 | L3: 2025
A4: Nettoomsætning | B4: ='res_raw_37535699'!$B$2 | C4: ='res_raw_37535699'!$C$2 | D4: ='res_raw_37535699'!$D$2 | E4: ='res_raw_37535699'!$E$2 | F4: ='res_raw_37535699'!$F$2 | H4: =IFERROR(B4/$B$4*100,"") | I4: =IFERROR(C4/$B$4*100,"") | J4: =IFERROR(D4/$B$4*100,"") | K4: =IFERROR(E4/$B$4*100,"") | L4: =IFERROR(F4/$B$4*100,"")
A5: Andre driftsindtægter | B5: ='res_raw_37535699'!$B$3 | C5: ='res_raw_37535699'!$C$3 | D5: ='res_raw_37535699'!$D$3 | E5: ='res_raw_37535699'!$E$3 | F5: ='res_raw_37535699'!$F$3 | H5: =IFERROR(B5/$B$5*100,"") | I5: =IFERROR(C5/$B$5*100,"") | J5: =IFERROR(D5/$B$5*100,"") | K5: =IFERROR(E5/$B$5*100,"") | L5: =IFERROR(F5/$B$5*100,"")
A6: Vareforbrug | B6: ='res_raw_37535699'!$B$4 | C6: ='res_raw_37535699'!$C$4 | D6: ='res_raw_37535699'!$D$4 | E6: ='res_raw_37535699'!$E$4 | F6: ='res_raw_37535699'!$F$4 | H6: =IFERROR(B6/$B$6*100,"") | I6: =IFERROR(C6/$B$6*100,"") | J6: =IFERROR(D6/$B$6*100,"") | K6: =IFERROR(E6/$B$6*100,"") | L6: =IFERROR(F6/$B$6*100,"")
A7: Andre eksterne omkostninger | B7: ='res_raw_37535699'!$B$5 | C7: ='res_raw_37535699'!$C$5 | D7: ='res_raw_37535699'!$D$5 | E7: ='res_raw_37535699'!$E$5 | F7: ='res_raw_37535699'!$F$5 | H7: =IFERROR(B7/$B$7*100,"") | I7: =IFERROR(C7/$B$7*100,"") | J7: =IFERROR(D7/$B$7*100,"") | K7: =IFERROR(E7/$B$7*100,"") | L7: =IFERROR(F7/$B$7*100,"")
A8: Bruttoresultat | B8: ='res_raw_37535699'!$B$6 | C8: ='res_raw_37535699'!$C$6 | D8: ='res_raw_37535699'!$D$6 | E8: ='res_raw_37535699'!$E$6 | F8: ='res_raw_37535699'!$F$6 | H8: =IFERROR(B8/$B$8*100,"") | I8: =IFERROR(C8/$B$8*100,"") | J8: =IFERROR(D8/$B$8*100,"") | K8: =IFERROR(E8/$B$8*100,"") | L8: =IFERROR(F8/$B$8*100,"")
A9: Personaleomkostninger | B9: ='res_raw_37535699'!$B$7 | C9: ='res_raw_37535699'!$C$7 | D9: ='res_raw_37535699'!$D$7 | E9: ='res_raw_37535699'!$E$7 | F9: ='res_raw_37535699'!$F$7 | H9: =IFERROR(B9/$B$9*100,"") | I9: =IFERROR(C9/$B$9*100,"") | J9: =IFERROR(D9/$B$9*100,"") | K9: =IFERROR(E9/$B$9*100,"") | L9: =IFERROR(F9/$B$9*100,"")
A10: Resultat før afskrivninger | B10: =IFERROR($B$8-ABS($B$9),"") | C10: =IFERROR($C$8-ABS($C$9),"") | D10: =IFERROR($D$8-ABS($D$9),"") | E10: =IFERROR($E$8-ABS($E$9),"") | F10: =IFERROR($F$8-ABS($F$9),"") | H10: =IFERROR(B10/$B$10*100,"") | I10: =IFERROR(C10/$B$10*100,"") | J10: =IFERROR(D10/$B$10*100,"") | K10: =IFERROR(E10/$B$10*100,"") | L10: =IFERROR(F10/$B$10*100,"")
A11: Af- og nedskrivninger | B11: ='res_raw_37535699'!$B$9 | C11: ='res_raw_37535699'!$C$9 | D11: ='res_raw_37535699'!$D$9 | E11: ='res_raw_37535699'!$E$9 | F11: ='res_raw_37535699'!$F$9 | H11: =IFERROR(B11/$B$11*100,"") | I11: =IFERROR(C11/$B$11*100,"") | J11: =IFERROR(D11/$B$11*100,"") | K11: =IFERROR(E11/$B$11*100,"") | L11: =IFERROR(F11/$B$11*100,"")
A12: Andre driftsomkostninger | B12: ='res_raw_37535699'!$B$10 | C12: ='res_raw_37535699'!$C$10 | D12: ='res_raw_37535699'!$D$10 | E12: ='res_raw_37535699'!$E$10 | F12: ='res_raw_37535699'!$F$10 | H12: =IFERROR(B12/$B$12*100,"") | I12: =IFERROR(C12/$B$12*100,"") | J12: =IFERROR(D12/$B$12*100,"") | K12: =IFERROR(E12/$B$12*100,"") | L12: =IFERROR(F12/$B$12*100,"")
A13: Resultat af primær drift | B13: ='res_raw_37535699'!$B$11 | C13: ='res_raw_37535699'!$C$11 | D13: ='res_raw_37535699'!$D$11 | E13: ='res_raw_37535699'!$E$11 | F13: ='res_raw_37535699'!$F$11 | H13: =IFERROR(B13/$B$13*100,"") | I13: =IFERROR(C13/$B$13*100,"") | J13: =IFERROR(D13/$B$13*100,"") | K13: =IFERROR(E13/$B$13*100,"") | L13: =IFERROR(F13/$B$13*100,"")
A14: Indtægter af kapitalandele, dattervirksomheder | B14: ='res_raw_37535699'!$B$12 | C14: ='res_raw_37535699'!$C$12 | D14: ='res_raw_37535699'!$D$12 | E14: ='res_raw_37535699'!$E$12 | F14: ='res_raw_37535699'!$F$12 | H14: =IFERROR(B14/$B$14*100,"") | I14: =IFERROR(C14/$B$14*100,"") | J14: =IFERROR(D14/$B$14*100,"") | K14: =IFERROR(E14/$B$14*100,"") | L14: =IFERROR(F14/$B$14*100,"")
A15: Finansielle indtægter | B15: ='res_raw_37535699'!$B$13 | C15: ='res_raw_37535699'!$C$13 | D15: ='res_raw_37535699'!$D$13 | E15: ='res_raw_37535699'!$E$13 | F15: ='res_raw_37535699'!$F$13 | H15: =IFERROR(B15/$B$15*100,"") | I15: =IFERROR(C15/$B$15*100,"") | J15: =IFERROR(D15/$B$15*100,"") | K15: =IFERROR(E15/$B$15*100,"") | L15: =IFERROR(F15/$B$15*100,"")
A16: Finansielle omkostninger | B16: ='res_raw_37535699'!$B$14 | C16: ='res_raw_37535699'!$C$14 | D16: ='res_raw_37535699'!$D$14 | E16: ='res_raw_37535699'!$E$14 | F16: ='res_raw_37535699'!$F$14 | H16: =IFERROR(B16/$B$16*100,"") | I16: =IFERROR(C16/$B$16*100,"") | J16: =IFERROR(D16/$B$16*100,"") | K16: =IFERROR(E16/$B$16*100,"") | L16: =IFERROR(F16/$B$16*100,"")
A17: Finansielle poster, netto | B17: ='res_raw_37535699'!$B$15 | C17: ='res_raw_37535699'!$C$15 | D17: ='res_raw_37535699'!$D$15 | E17: ='res_raw_37535699'!$E$15 | F17: ='res_raw_37535699'!$F$15 | H17: =IFERROR(B17/$B$17*100,"") | I17: =IFERROR(C17/$B$17*100,"") | J17: =IFERROR(D17/$B$17*100,"") | K17: =IFERROR(E17/$B$17*100,"") | L17: =IFERROR(F17/$B$17*100,"")
A18: Resultat før skat | B18: ='res_raw_37535699'!$B$16 | C18: ='res_raw_37535699'!$C$16 | D18: ='res_raw_37535699'!$D$16 | E18: ='res_raw_37535699'!$E$16 | F18: ='res_raw_37535699'!$F$16 | H18: =IFERROR(B18/$B$18*100,"") | I18: =IFERROR(C18/$B$18*100,"") | J18: =IFERROR(D18/$B$18*100,"") | K18: =IFERROR(E18/$B$18*100,"") | L18: =IFERROR(F18/$B$18*100,"")
A19: Skat af årets resultat | B19: ='res_raw_37535699'!$B$17 | C19: ='res_raw_37535699'!$C$17 | D19: ='res_raw_37535699'!$D$17 | E19: ='res_raw_37535699'!$E$17 | F19: ='res_raw_37535699'!$F$17 | H19: =IFERROR(B19/$B$19*100,"") | I19: =IFERROR(C19/$B$19*100,"") | J19: =IFERROR(D19/$B$19*100,"") | K19: =IFERROR(E19/$B$19*100,"") | L19: =IFERROR(F19/$B$19*100,"")
A20: Årets resultat | B20: ='res_raw_37535699'!$B$18 | C20: ='res_raw_37535699'!$C$18 | D20: ='res_raw_37535699'!$D$18 | E20: ='res_raw_37535699'!$E$18 | F20: ='res_raw_37535699'!$F$18 | H20: =IFERROR(B20/$B$20*100,"") | I20: =IFERROR(C20/$B$20*100,"") | J20: =IFERROR(D20/$B$20*100,"") | K20: =IFERROR(E20/$B$20*100,"") | L20: =IFERROR(F20/$B$20*100,"")
A22: AKTIVER valuta pr. år - se kolonneoverskrifter | B22: 2021 | C22: 2022 | D22: 2023 | E22: 2024 | F22: 2025 | H22: 2021 | I22: 2022 | J22: 2023 | K22: 2024 | L22: 2025
A23: Udviklingsprojekter | B23: ='balance_raw_37535699'!$B$2 | C23: ='balance_raw_37535699'!$C$2 | D23: ='balance_raw_37535699'!$D$2 | E23: ='balance_raw_37535699'!$E$2 | F23: ='balance_raw_37535699'!$F$2 | H23: =IFERROR(B23/$B$23*100,"") | I23: =IFERROR(C23/$B$23*100,"") | J23: =IFERROR(D23/$B$23*100,"") | K23: =IFERROR(E23/$B$23*100,"") | L23: =IFERROR(F23/$B$23*100,"")
A24: Patenter, varemærker mv. | B24: ='balance_raw_37535699'!$B$3 | C24: ='balance_raw_37535699'!$C$3 | D24: ='balance_raw_37535699'!$D$3 | E24: ='balance_raw_37535699'!$E$3 | F24: ='balance_raw_37535699'!$F$3 | H24: =IFERROR(B24/$B$24*100,"") | I24: =IFERROR(C24/$B$24*100,"") | J24: =IFERROR(D24/$B$24*100,"") | K24: =IFERROR(E24/$B$24*100,"") | L24: =IFERROR(F24/$B$24*100,"")
A25: Goodwill | B25: ='balance_raw_37535699'!$B$4 | C25: ='balance_raw_37535699'!$C$4 | D25: ='balance_raw_37535699'!$D$4 | E25: ='balance_raw_37535699'!$E$4 | F25: ='balance_raw_37535699'!$F$4 | H25: =IFERROR(B25/$B$25*100,"") | I25: =IFERROR(C25/$B$25*100,"") | J25: =IFERROR(D25/$B$25*100,"") | K25: =IFERROR(E25/$B$25*100,"") | L25: =IFERROR(F25/$B$25*100,"")
A26: Immaterielle anlægsaktiver | B26: ='balance_raw_37535699'!$B$5 | C26: ='balance_raw_37535699'!$C$5 | D26: ='balance_raw_37535699'!$D$5 | E26: ='balance_raw_37535699'!$E$5 | F26: ='balance_raw_37535699'!$F$5 | H26: =IFERROR(B26/$B$26*100,"") | I26: =IFERROR(C26/$B$26*100,"") | J26: =IFERROR(D26/$B$26*100,"") | K26: =IFERROR(E26/$B$26*100,"") | L26: =IFERROR(F26/$B$26*100,"")
A27: Grunde og bygninger | B27: ='balance_raw_37535699'!$B$6 | C27: ='balance_raw_37535699'!$C$6 | D27: ='balance_raw_37535699'!$D$6 | E27: ='balance_raw_37535699'!$E$6 | F27: ='balance_raw_37535699'!$F$6 | H27: =IFERROR(B27/$B$27*100,"") | I27: =IFERROR(C27/$B$27*100,"") | J27: =IFERROR(D27/$B$27*100,"") | K27: =IFERROR(E27/$B$27*100,"") | L27: =IFERROR(F27/$B$27*100,"")
A28: Produktionsanlæg og maskiner | B28: ='balance_raw_37535699'!$B$7 | C28: ='balance_raw_37535699'!$C$7 | D28: ='balance_raw_37535699'!$D$7 | E28: ='balance_raw_37535699'!$E$7 | F28: ='balance_raw_37535699'!$F$7 | H28: =IFERROR(B28/$B$28*100,"") | I28: =IFERROR(C28/$B$28*100,"") | J28: =IFERROR(D28/$B$28*100,"") | K28: =IFERROR(E28/$B$28*100,"") | L28: =IFERROR(F28/$B$28*100,"")
A29: Driftsmateriel og inventar | B29: ='balance_raw_37535699'!$B$8 | C29: ='balance_raw_37535699'!$C$8 | D29: ='balance_raw_37535699'!$D$8 | E29: ='balance_raw_37535699'!$E$8 | F29: ='balance_raw_37535699'!$F$8 | H29: =IFERROR(B29/$B$29*100,"") | I29: =IFERROR(C29/$B$29*100,"") | J29: =IFERROR(D29/$B$29*100,"") | K29: =IFERROR(E29/$B$29*100,"") | L29: =IFERROR(F29/$B$29*100,"")
A30: Indretning af lejede lokaler | B30: ='balance_raw_37535699'!$B$9 | C30: ='balance_raw_37535699'!$C$9 | D30: ='balance_raw_37535699'!$D$9 | E30: ='balance_raw_37535699'!$E$9 | F30: ='balance_raw_37535699'!$F$9 | H30: =IFERROR(B30/$B$30*100,"") | I30: =IFERROR(C30/$B$30*100,"") | J30: =IFERROR(D30/$B$30*100,"") | K30: =IFERROR(E30/$B$30*100,"") | L30: =IFERROR(F30/$B$30*100,"")
A31: Forudbetaling og anlægsaktiver under opførelse | B31: ='balance_raw_37535699'!$B$10 | C31: ='balance_raw_37535699'!$C$10 | D31: ='balance_raw_37535699'!$D$10 | E31: ='balance_raw_37535699'!$E$10 | F31: ='balance_raw_37535699'!$F$10 | H31: =IFERROR(B31/$B$31*100,"") | I31: =IFERROR(C31/$B$31*100,"") | J31: =IFERROR(D31/$B$31*100,"") | K31: =IFERROR(E31/$B$31*100,"") | L31: =IFERROR(F31/$B$31*100,"")
A32: Materielle anlægsaktiver | B32: ='balance_raw_37535699'!$B$11 | C32: ='balance_raw_37535699'!$C$11 | D32: ='balance_raw_37535699'!$D$11 | E32: ='balance_raw_37535699'!$E$11 | F32: ='balance_raw_37535699'!$F$11 | H32: =IFERROR(B32/$B$32*100,"") | I32: =IFERROR(C32/$B$32*100,"") | J32: =IFERROR(D32/$B$32*100,"") | K32: =IFERROR(E32/$B$32*100,"") | L32: =IFERROR(F32/$B$32*100,"")
A33: Kapitalandele, dattervirksomheder | B33: ='balance_raw_37535699'!$B$12 | C33: ='balance_raw_37535699'!$C$12 | D33: ='balance_raw_37535699'!$D$12 | E33: ='balance_raw_37535699'!$E$12 | F33: ='balance_raw_37535699'!$F$12 | H33: =IFERROR(B33/$B$33*100,"") | I33: =IFERROR(C33/$B$33*100,"") | J33: =IFERROR(D33/$B$33*100,"") | K33: =IFERROR(E33/$B$33*100,"") | L33: =IFERROR(F33/$B$33*100,"")
A34: Deposita | B34: ='balance_raw_37535699'!$B$13 | C34: ='balance_raw_37535699'!$C$13 | D34: ='balance_raw_37535699'!$D$13 | E34: ='balance_raw_37535699'!$E$13 | F34: ='balance_raw_37535699'!$F$13 | H34: =IFERROR(B34/$B$34*100,"") | I34: =IFERROR(C34/$B$34*100,"") | J34: =IFERROR(D34/$B$34*100,"") | K34: =IFERROR(E34/$B$34*100,"") | L34: =IFERROR(F34/$B$34*100,"")
A35: Finansielle anlægsaktiver | B35: ='balance_raw_37535699'!$B$14 | C35: ='balance_raw_37535699'!$C$14 | D35: ='balance_raw_37535699'!$D$14 | E35: ='balance_raw_37535699'!$E$14 | F35: ='balance_raw_37535699'!$F$14 | H35: =IFERROR(B35/$B$35*100,"") | I35: =IFERROR(C35/$B$35*100,"") | J35: =IFERROR(D35/$B$35*100,"") | K35: =IFERROR(E35/$B$35*100,"") | L35: =IFERROR(F35/$B$35*100,"")
A36: Anlægsaktiver | B36: ='balance_raw_37535699'!$B$15 | C36: ='balance_raw_37535699'!$C$15 | D36: ='balance_raw_37535699'!$D$15 | E36: ='balance_raw_37535699'!$E$15 | F36: ='balance_raw_37535699'!$F$15 | H36: =IFERROR(B36/$B$36*100,"") | I36: =IFERROR(C36/$B$36*100,"") | J36: =IFERROR(D36/$B$36*100,"") | K36: =IFERROR(E36/$B$36*100,"") | L36: =IFERROR(F36/$B$36*100,"")
A37: Råvarer og hjælpematerialer | B37: ='balance_raw_37535699'!$B$16 | C37: ='balance_raw_37535699'!$C$16 | D37: ='balance_raw_37535699'!$D$16 | E37: ='balance_raw_37535699'!$E$16 | F37: ='balance_raw_37535699'!$F$16 | H37: =IFERROR(B37/$B$37*100,"") | I37: =IFERROR(C37/$B$37*100,"") | J37: =IFERROR(D37/$B$37*100,"") | K37: =IFERROR(E37/$B$37*100,"") | L37: =IFERROR(F37/$B$37*100,"")
A38: Varer under fremstilling | B38: ='balance_raw_37535699'!$B$17 | C38: ='balance_raw_37535699'!$C$17 | D38: ='balance_raw_37535699'!$D$17 | E38: ='balance_raw_37535699'!$E$17 | F38: ='balance_raw_37535699'!$F$17 | H38: =IFERROR(B38/$B$38*100,"") | I38: =IFERROR(C38/$B$38*100,"") | J38: =IFERROR(D38/$B$38*100,"") | K38: =IFERROR(E38/$B$38*100,"") | L38: =IFERROR(F38/$B$38*100,"")
A39: Færdigvarer og handelsvarer | B39: ='balance_raw_37535699'!$B$18 | C39: ='balance_raw_37535699'!$C$18 | D39: ='balance_raw_37535699'!$D$18 | E39: ='balance_raw_37535699'!$E$18 | F39: ='balance_raw_37535699'!$F$18 | H39: =IFERROR(B39/$B$39*100,"") | I39: =IFERROR(C39/$B$39*100,"") | J39: =IFERROR(D39/$B$39*100,"") | K39: =IFERROR(E39/$B$39*100,"") | L39: =IFERROR(F39/$B$39*100,"")
A40: Varebeholdninger | B40: ='balance_raw_37535699'!$B$19 | C40: ='balance_raw_37535699'!$C$19 | D40: ='balance_raw_37535699'!$D$19 | E40: ='balance_raw_37535699'!$E$19 | F40: ='balance_raw_37535699'!$F$19 | H40: =IFERROR(B40/$B$40*100,"") | I40: =IFERROR(C40/$B$40*100,"") | J40: =IFERROR(D40/$B$40*100,"") | K40: =IFERROR(E40/$B$40*100,"") | L40: =IFERROR(F40/$B$40*100,"")
A41: Tilgodehavender fra salg og tjenesteydelser | B41: ='balance_raw_37535699'!$B$20 | C41: ='balance_raw_37535699'!$C$20 | D41: ='balance_raw_37535699'!$D$20 | E41: ='balance_raw_37535699'!$E$20 | F41: ='balance_raw_37535699'!$F$20 | H41: =IFERROR(B41/$B$41*100,"") | I41: =IFERROR(C41/$B$41*100,"") | J41: =IFERROR(D41/$B$41*100,"") | K41: =IFERROR(E41/$B$41*100,"") | L41: =IFERROR(F41/$B$41*100,"")
...

Sheet res_raw_37535699
A1: Too Good To Go Holding ApS (CVR 37535699) — Resultatopgørelse & nøgleoplysninger (valuta pr. år - se kolonneoverskrifter) | B1: 2021 | C1: 2022 | D1: 2023 | E1: 2024 | F1: 2025
A2: Nettoomsætning | B2: 493252 | C2: 102565 | D2: 146535 | E2: 193421 | F2: 249321
A3: Andre driftsindtægter
A4: Vareforbrug | B4: 3858
A5: Andre eksterne omkostninger | B5: 354048 | C5: 33049 | D5: 30378 | E5: 37598 | F5: 48495
A6: Bruttoresultat | B6: 135346
A7: Personaleomkostninger | B7: 462151 | C7: 90749 | D7: 89078 | E7: 101007 | F7: 112424
A8: Resultat før afskrivninger
A9: Af- og nedskrivninger | B9: 17778 | C9: 7221 | D9: 7921 | E9: 8076 | F9: 11826
A10: Andre driftsomkostninger
A11: Resultat af primær drift | B11: -344583 | C11: -39384 | D11: -1806 | E11: 1797 | F11: -5414
A12: Indtægter af kapitalandele, dattervirksomheder | B12: -342020
A13: Finansielle indtægter | B13: 4117 | C13: 10 | D13: 2497 | E13: 2708 | F13: 7320
A14: Finansielle omkostninger | B14: 1734 | C14: 3167 | D14: 2975 | E14: 3335 | F14: 4561
A15: Finansielle poster, netto | B15: 2383 | C15: -3157 | D15: -478 | E15: -627 | F15: 2759
A16: Resultat før skat | B16: -342200 | C16: -42541 | D16: -2284 | E16: 1170 | F16: -2655
A17: Skat af årets resultat | B17: 1601 | C17: -4905 | D17: 1462 | E17: 2481 | F17: 2101
A18: Årets resultat | B18: -343801 | C18: -37636 | D18: -3746 | E18: -1311 | F18: -4756
A19: Gns. antal medarbejdere | B19: 980
A20: Investering i materielle anlægsaktiver | B20: 774 | C20: 481 | D20: 412 | E20: 658 | F20: 622

Sheet balance_raw_37535699
A1: Too Good To Go Holding ApS (CVR 37535699) — Balance (valuta pr. år - se kolonneoverskrifter) | B1: 2021 | C1: 2022 | D1: 2023 | E1: 2024 | F1: 2025
A2: Udviklingsprojekter | B2: 16683
A3: Patenter, varemærker mv.
A4: Goodwill | B4: 2558 | C4: 2520 | D4: 2515 | E4: 2513 | F4: 2509
A5: Immaterielle anlægsaktiver | B5: 22221 | C5: 5611 | D5: 6856 | E5: 10653 | F5: 14380
A6: Grunde og bygninger
A7: Produktionsanlæg og maskiner
A8: Driftsmateriel og inventar | B8: 4419
A9: Indretning af lejede lokaler | B9: 3757
A10: Forudbetaling og anlægsaktiver under opførelse
A11: Materielle anlægsaktiver | B11: 8176 | C11: 876 | D11: 719 | E11: 814 | F11: 897
A12: Kapitalandele, dattervirksomheder | B12: 50100
A13: Deposita | B13: 11399
A14: Finansielle anlægsaktiver | B14: 11399
A15: Anlægsaktiver | B15: 41796 | C15: 28200 | D15: 28878 | E15: 33239 | F15: 36362
A16: Råvarer og hjælpematerialer
A17: Varer under fremstilling
A18: Færdigvarer og handelsvarer | B18: 1332
A19: Varebeholdninger | B19: 1332 | C19: 197 | D19: 1373 | E19: 5703 | F19: 6588
A20: Tilgodehavender fra salg og tjenesteydelser | B20: 10561 | C20: 2776 | D20: 4647 | E20: 3459 | F20: 4850
A21: Tilgodehavender hos tilknyttede virksomheder
A22: Andre tilgodehavender | B22: 4110
A23: Periodeafgrænsningsposter (aktiver) | B23: 8849 | C23: 1559 | D23: 1961 | E23: 2490 | F23: 3092
A24: Udskudt skatteaktiv | C24: 8020 | D24: 8398 | E24: 9186 | F24: 6877
A25: Tilgodehavende skat hos tilknyttede virksomheder
A26: Kortfristede skattetilgodehavender | B26: 0 | C26: 0
A27: Tilgodehavender | B27: 23520 | C27: 53 | D27: 83 | E27: 742 | F27: 977
A28: Værdipapirer
A29: Likvide beholdninger | B29: 240762 | C29: 79762 | D29: 58609 | E29: 69539 | F29: 80644
A30: Omsætningsaktiver | B30: 265614 | C30: 84347 | D30: 104864 | E30: 120046 | F30: 134244
A31: Aktiver | B31: 307410 | C31: 112547 | D31: 133742 | E31: 153285 | F31: 170607
A32: Selskabskapital | B32: 234 | C32: 34 | D32: 34 | E32: 34 | F32: 34
A33: Reserve for nettoopskrivning (indre værdis metode)
A34: Reserve for udviklingsomkostninger | B34: 14785
A35: Reserve for sikringstransaktioner
A36: Andre reserver
A37: Overført resultat | B37: -71697 | C37: 20165 | D37: 24062 | E37: 29739 | F37: 28033
A38: Egenkapital i alt | B38: -56678 | C38: 20002 | D38: 23804 | E38: 28919 | F38: 26088
A39: Hensættelse til udskudt skat | C39: 470 | D39: 375 | E39: 379 | F39: 375
A40: Hensatte forpligtelser | C40: 470 | D40: 375 | E40: 379 | F40: 375
...

Sheet pengestrom_raw_37535699
A1: Too Good To Go Holding ApS (CVR 37535699) — Pengestrømsopgørelse (valuta pr. år - se kolonneoverskrifter) | B1: 2021 | C1: 2022 | D1: 2023 | E1: 2024 | F1: 2025
A2: Pengestrømme fra driftsaktivitet | B2: -232634 | C2: -3416 | D2: 25444 | E2: 23349 | F2: 26444
A3: Pengestrømme fra investeringsaktivitet | B3: -19789 | C3: -5275 | D3: -4669 | E3: -7455 | F3: -9023
A4: Pengestrømme fra finansieringsaktivitet | B4: 251100 | C4: 56230 | D4: -42321 | E4: -5115 | F4: -6376
A5: Årets pengestrøm

Sheet Simpel_arts
A1: Too Good To Go Holding ApS (CVR 37535699) — Regnskabs- og nøgletal (CVR: 37535699) — artsopdelt
A3: Beløb i 1.000 kr. | B3: 2025 | C3: 2024 | D3: 2023 | F3: Note / XBRL-felt
A4: Uddrag af resultatopgørelse
A5: Nettoomsætning | B5: ='res_raw_37535699'!$F$2 | C5: ='res_raw_37535699'!$E$2 | D5: ='res_raw_37535699'!$D$2 | F5: fsa:Revenue
A6: Andre driftsindtægter | B6: ='res_raw_37535699'!$F$3 | C6: ='res_raw_37535699'!$E$3 | D6: ='res_raw_37535699'!$D$3 | F6: fsa:OtherOperatingIncome. Indtægter fra sekundære aktiviteter (huslejeindtægter, avance ved salg af anlæg mv.).
A7: Vareforbrug | B7: =-'res_raw_37535699'!$F$4 | C7: =-'res_raw_37535699'!$E$4 | D7: =-'res_raw_37535699'!$D$4 | F7: fsa:CostOfSales (vises negativt for korrekt SUM-formel).
A8: Andre eksterne omk. mv. | B8: =-'res_raw_37535699'!$F$5 | C8: =-'res_raw_37535699'!$E$5 | D8: =-'res_raw_37535699'!$D$5 | F8: fsa:OtherExternalExpenses (vises negativt). Husleje, energi, kontorhold mv.
A9: Bruttofortjeneste | B9: =IF(ABS((SUM(B5:B8))-'res_raw_37535699'!$F$6)<=2,SUM(B5:B8),'res_raw_37535699'!$F$6) | C9: =IF(ABS((SUM(C5:C8))-'res_raw_37535699'!$E$6)<=2,SUM(C5:C8),'res_raw_37535699'!$E$6) | D9: =IF(ABS((SUM(D5:D8))-'res_raw_37535699'!$D$6)<=2,SUM(D5:D8),'res_raw_37535699'!$D$6) | F9: Beregnet: Nettoomsætning + Andre driftsindt. − Vareforbrug − Andre ext. omk. Er komponenterne ikke indberettet, vises rapporteret bruttoresultat (fsa:GrossResult) direkte.
A10: Personaleomkostninger | B10: =-'res_raw_37535699'!$F$7 | C10: =-'res_raw_37535699'!$E$7 | D10: =-'res_raw_37535699'!$D$7 | F10: fsa:EmployeeBenefitsExpense (vises negativt). Lønninger, pension, sociale ydelser.
A11: Af- og nedskrivninger | B11: =-'res_raw_37535699'!$F$9 | C11: =-'res_raw_37535699'!$E$9 | D11: =-'res_raw_37535699'!$D$9 | F11: fsa:Depreciation (vises negativt). Af- og nedskrivninger på materielle og immaterielle anlægsaktiver.
A12: Andre driftsomkostninger | B12: =-'res_raw_37535699'!$F$10 | C12: =-'res_raw_37535699'!$E$10 | D12: =-'res_raw_37535699'!$D$10 | F12: fsa:OtherOperatingExpenses (vises negativt). Typisk 0 eller meget lille post.
A13: Resultat af primær drift | B13: =IF(ABS((SUM(B9:B12))-'res_raw_37535699'!$F$11)<=2,SUM(B9:B12),'res_raw_37535699'!$F$11) | C13: =IF(ABS((SUM(C9:C12))-'res_raw_37535699'!$E$11)<=2,SUM(C9:C12),'res_raw_37535699'!$E$11) | D13: =IF(ABS((SUM(D9:D12))-'res_raw_37535699'!$D$11)<=2,SUM(D9:D12),'res_raw_37535699'!$D$11) | F13: Beregnet: Bruttofortjeneste − Personaleomk. − Af- og nedskrivninger − Andre driftsomk. EBIT.
A14: Finansielle indtægter mv. | B14: =N('res_raw_37535699'!$F$12)+N('res_raw_37535699'!$F$13) | C14: =N('res_raw_37535699'!$E$12)+N('res_raw_37535699'!$E$13) | D14: =N('res_raw_37535699'!$D$12)+N('res_raw_37535699'!$D$13) | F14: fsa:IncomeFromSubsidiaries + fsa:OtherFinanceIncome.
A15: Finansielle omkostninger mv. | B15: =-'res_raw_37535699'!$F$14 | C15: =-'res_raw_37535699'!$E$14 | D15: =-'res_raw_37535699'!$D$14 | F15: fsa:OtherFinanceExpenses (vises negativt). Renteomkostninger, kurstab mv.
A16: Resultat før skat | B16: =IF(ABS((SUM(B13:B15))-'res_raw_37535699'!$F$16)<=2,SUM(B13:B15),'res_raw_37535699'!$F$16) | C16: =IF(ABS((SUM(C13:C15))-'res_raw_37535699'!$E$16)<=2,SUM(C13:C15),'res_raw_37535699'!$E$16) | D16: =IF(ABS((SUM(D13:D15))-'res_raw_37535699'!$D$16)<=2,SUM(D13:D15),'res_raw_37535699'!$D$16) | F16: Beregnet: EBIT + Fin. indtægter + Fin. omk. EBT.
A18: Uddrag af balance
A19: Anlægsaktiver | B19: ='balance_raw_37535699'!$F$15 | C19: ='balance_raw_37535699'!$E$15 | D19: ='balance_raw_37535699'!$D$15 | F19: fsa:NoncurrentAssets. Materielle, immaterielle og finansielle anlægsaktiver.
A20: Omsætningsaktiver | B20: ='balance_raw_37535699'!$F$30 | C20: ='balance_raw_37535699'!$E$30 | D20: ='balance_raw_37535699'!$D$30 | F20: fsa:CurrentAssets. Varebeholdninger, tilgodehavender, likvider.
A21: Aktiver i alt | B21: =SUM(B19:B20) | C21: =SUM(C19:C20) | D21: =SUM(D19:D20) | F21: Beregnet: Anlægsaktiver + Omsætningsaktiver. Bør matche fsa:Assets.
A23: Egenkapital | B23: ='balance_raw_37535699'!$F$38 | C23: ='balance_raw_37535699'!$E$38 | D23: ='balance_raw_37535699'!$D$38 | F23: fsa:Equity. Selskabskapital, overført resultat, reserver.
A24: Forpligtelser | B24: ='balance_raw_37535699'!$F$59-'balance_raw_37535699'!$F$38 | C24: ='balance_raw_37535699'!$E$59-'balance_raw_37535699'!$E$38 | D24: ='balance_raw_37535699'!$D$59-'balance_raw_37535699'!$D$38 | F24: Beregnet: Passiver (fsa:LiabilitiesAndEquity) − Egenkapital. Hensættelser + kort- og langfristet gæld.
A25: Passiver i alt | B25: =SUM(B23:B24) | C25: =SUM(C23:C24) | D25: =SUM(D23:D24) | F25: Beregnet: Egenkapital + Forpligtelser. Bør matche Aktiver i alt.
A27: Udvalgte balanceposter
A28: Varebeholdninger | B28: ='balance_raw_37535699'!$F$19 | C28: ='balance_raw_37535699'!$E$19 | D28: ='balance_raw_37535699'!$D$19 | F28: fsa:Inventories (eller fsa:ManufacturedGoodsAndGoodsForResale hvis total mangler).
A29: Tilgodehavender fra salg | B29: ='balance_raw_37535699'!$F$20 | C29: ='balance_raw_37535699'!$E$20 | D29: ='balance_raw_37535699'!$D$20 | F29: fsa:ShorttermTradeReceivables. Kortfristede tilgodehavender fra kunder.
A30: Kortfristede gældsforpligtelser | B30: ='balance_raw_37535699'!$F$57 | C30: ='balance_raw_37535699'!$E$57 | D30: ='balance_raw_37535699'!$D$57 | F30: fsa:ShorttermLiabilitiesOtherThanProvisions. Gæld der forfalder inden for 1 år.
A32: Rentabilitet
A33: Afkastningsgrad, % | B33: =IFERROR((B13+B14)/B21*100,"") | C33: =IFERROR((C13+C14)/C21*100,"") | D33: =IFERROR((D13+D14)/D21*100,"")
A34: Overskudsgrad, % | B34: =IFERROR((B13+B14)/B5*100,"") | C34: =IFERROR((C13+C14)/C5*100,"") | D34: =IFERROR((D13+D14)/D5*100,"")
A35: Aktivernes omsætningshastighed, gange | B35: =IFERROR(B5/B21,"") | C35: =IFERROR(C5/C21,"") | D35: =IFERROR(D5/D21,"")
A36: Gældsrente, % | B36: =IFERROR(-B15*100/B24,"") | C36: =IFERROR(-C15*100/C24,"") | D36: =IFERROR(-D15*100/D24,"")
A37: Egenkapitalens forrentning, % | B37: =IFERROR(B16/B23*100,"") | C37: =IFERROR(C16/C23*100,"") | D37: =IFERROR(D16/D23*100,"")
A38: Gearing, gange | B38: =IFERROR(B24/B23,"") | C38: =IFERROR(C24/C23,"") | D38: =IFERROR(D24/D23,"")
A40: Indekstal for indtjeningsevne (2023=100)
A41: Nettoomsætning | B41: =IFERROR(B5/$D5*100,"") | C41: =IFERROR(C5/$D5*100,"") | D41: =IFERROR(D5/$D5*100,"")
A42: Vareforbrug | B42: =IFERROR(B7/$D7*100,"") | C42: =IFERROR(C7/$D7*100,"") | D42: =IFERROR(D7/$D7*100,"")
A43: Andre eksterne omk. | B43: =IFERROR(B8/$D8*100,"") | C43: =IFERROR(C8/$D8*100,"") | D43: =IFERROR(D8/$D8*100,"")
A44: Personaleomkostninger | B44: =IFERROR(B10/$D10*100,"") | C44: =IFERROR(C10/$D10*100,"") | D44: =IFERROR(D10/$D10*100,"")
A45: Af- og nedskrivninger | B45: =IFERROR(B11/$D11*100,"") | C45: =IFERROR(C11/$D11*100,"") | D45: =IFERROR(D11/$D11*100,"")
A47: Indekstal for kapitaltilpasningsevne (2023=100)
...

Sheet Noter_info
A1: Too Good To Go Holding ApS (CVR 37535699) — Ukendte XBRL-felter — disse er noter og ikke en del af hoved-regnskabet
A2: Kategori | B2: Dansk navn | C2: XBRL feltnavn | D2: 2021 t.kr. | E2: 2022 t.kr. | F2: 2023 t.kr. | G2: 2024 t.kr. | H2: 2025 t.kr. | I2: Forklaring
A3: Øvrige (ukendt) | B3: fsa:CashCapitalIncrease | C3: fsa:CashCapitalIncrease | D3: 157097 | I3: Ingen forklaring tilgængelig.
A4: Øvrige (ukendt) | B4: ifrs-full:CurrentInvestments | C4: ifrs-full:CurrentInvestments | F4: 38190 | G4: 38113 | H4: 38094 | I4: Ingen forklaring tilgængelig.
A5: Øvrige (ukendt) | B5: ifrs-full:ReserveOfExchangeDifferencesOnTranslation | C5: ifrs-full:ReserveOfExchangeDifferencesOnTranslation | E5: -197 | F5: -292 | G5: -854 | H5: -1979 | I5: Ingen forklaring tilgængelig.
