Workbook

Sheet Overblik
A1: bogo (CVR None) — Regnskabsanalyse – Resultatopgørelse & Balance (t.kr.)
H2: Indekstal (2022=100)
A3: Resultatopgørelse t.kr. | B3: 2022 | C3: 2023 | D3: 2024 | E3: 2025 | F3: 2026 | H3: 2022 | I3: 2023 | J3: 2024 | K3: 2025 | L3: 2026
A4: Nettoomsætning | B4: ='res_raw'!$B$2 | C4: ='res_raw'!$C$2 | D4: ='res_raw'!$D$2 | E4: ='res_raw'!$E$2 | F4: ='res_raw'!$F$2 | H4: =IFERROR(B4/$B$4*100,"") | I4: =IFERROR(C4/$B$4*100,"") | J4: =IFERROR(D4/$B$4*100,"") | K4: =IFERROR(E4/$B$4*100,"") | L4: =IFERROR(F4/$B$4*100,"")
A5: Produktionsomkostninger | B5: ='res_raw'!$B$3 | C5: ='res_raw'!$C$3 | D5: ='res_raw'!$D$3 | E5: ='res_raw'!$E$3 | F5: ='res_raw'!$F$3 | H5: =IFERROR(B5/$B$5*100,"") | I5: =IFERROR(C5/$B$5*100,"") | J5: =IFERROR(D5/$B$5*100,"") | K5: =IFERROR(E5/$B$5*100,"") | L5: =IFERROR(F5/$B$5*100,"")
A6: Bruttoresultat | B6: ='res_raw'!$B$4 | C6: ='res_raw'!$C$4 | D6: ='res_raw'!$D$4 | E6: ='res_raw'!$E$4 | F6: ='res_raw'!$F$4 | H6: =IFERROR(B6/$B$6*100,"") | I6: =IFERROR(C6/$B$6*100,"") | J6: =IFERROR(D6/$B$6*100,"") | K6: =IFERROR(E6/$B$6*100,"") | L6: =IFERROR(F6/$B$6*100,"")
A7: Salgs- og distributionsomkostninger | B7: ='res_raw'!$B$5 | C7: ='res_raw'!$C$5 | D7: ='res_raw'!$D$5 | E7: ='res_raw'!$E$5 | F7: ='res_raw'!$F$5 | H7: =IFERROR(B7/$B$7*100,"") | I7: =IFERROR(C7/$B$7*100,"") | J7: =IFERROR(D7/$B$7*100,"") | K7: =IFERROR(E7/$B$7*100,"") | L7: =IFERROR(F7/$B$7*100,"")
A8: Administrationsomkostninger | B8: ='res_raw'!$B$6 | C8: ='res_raw'!$C$6 | D8: ='res_raw'!$D$6 | E8: ='res_raw'!$E$6 | F8: ='res_raw'!$F$6 | H8: =IFERROR(B8/$B$8*100,"") | I8: =IFERROR(C8/$B$8*100,"") | J8: =IFERROR(D8/$B$8*100,"") | K8: =IFERROR(E8/$B$8*100,"") | L8: =IFERROR(F8/$B$8*100,"")
A9: Andre driftsindtægter | B9: ='res_raw'!$B$7 | C9: ='res_raw'!$C$7 | D9: ='res_raw'!$D$7 | E9: ='res_raw'!$E$7 | F9: ='res_raw'!$F$7 | H9: =IFERROR(B9/$B$9*100,"") | I9: =IFERROR(C9/$B$9*100,"") | J9: =IFERROR(D9/$B$9*100,"") | K9: =IFERROR(E9/$B$9*100,"") | L9: =IFERROR(F9/$B$9*100,"")
A10: Andre driftsomkostninger | B10: ='res_raw'!$B$8 | C10: ='res_raw'!$C$8 | D10: ='res_raw'!$D$8 | E10: ='res_raw'!$E$8 | F10: ='res_raw'!$F$8 | H10: =IFERROR(B10/$B$10*100,"") | I10: =IFERROR(C10/$B$10*100,"") | J10: =IFERROR(D10/$B$10*100,"") | K10: =IFERROR(E10/$B$10*100,"") | L10: =IFERROR(F10/$B$10*100,"")
A11: Resultat af primær drift | B11: ='res_raw'!$B$9 | C11: ='res_raw'!$C$9 | D11: ='res_raw'!$D$9 | E11: ='res_raw'!$E$9 | F11: ='res_raw'!$F$9 | H11: =IFERROR(B11/$B$11*100,"") | I11: =IFERROR(C11/$B$11*100,"") | J11: =IFERROR(D11/$B$11*100,"") | K11: =IFERROR(E11/$B$11*100,"") | L11: =IFERROR(F11/$B$11*100,"")
A12: Indtægter af kapitalandele, dattervirksomheder | B12: ='res_raw'!$B$10 | C12: ='res_raw'!$C$10 | D12: ='res_raw'!$D$10 | E12: ='res_raw'!$E$10 | F12: ='res_raw'!$F$10 | H12: =IFERROR(B12/$B$12*100,"") | I12: =IFERROR(C12/$B$12*100,"") | J12: =IFERROR(D12/$B$12*100,"") | K12: =IFERROR(E12/$B$12*100,"") | L12: =IFERROR(F12/$B$12*100,"")
A13: Finansielle indtægter | B13: ='res_raw'!$B$11 | C13: ='res_raw'!$C$11 | D13: ='res_raw'!$D$11 | E13: ='res_raw'!$E$11 | F13: ='res_raw'!$F$11 | H13: =IFERROR(B13/$B$13*100,"") | I13: =IFERROR(C13/$B$13*100,"") | J13: =IFERROR(D13/$B$13*100,"") | K13: =IFERROR(E13/$B$13*100,"") | L13: =IFERROR(F13/$B$13*100,"")
A14: Finansielle omkostninger | B14: ='res_raw'!$B$12 | C14: ='res_raw'!$C$12 | D14: ='res_raw'!$D$12 | E14: ='res_raw'!$E$12 | F14: ='res_raw'!$F$12 | H14: =IFERROR(B14/$B$14*100,"") | I14: =IFERROR(C14/$B$14*100,"") | J14: =IFERROR(D14/$B$14*100,"") | K14: =IFERROR(E14/$B$14*100,"") | L14: =IFERROR(F14/$B$14*100,"")
A15: Finansielle poster, netto | B15: ='res_raw'!$B$13 | C15: ='res_raw'!$C$13 | D15: ='res_raw'!$D$13 | E15: ='res_raw'!$E$13 | F15: ='res_raw'!$F$13 | H15: =IFERROR(B15/$B$15*100,"") | I15: =IFERROR(C15/$B$15*100,"") | J15: =IFERROR(D15/$B$15*100,"") | K15: =IFERROR(E15/$B$15*100,"") | L15: =IFERROR(F15/$B$15*100,"")
A16: Resultat før skat | B16: ='res_raw'!$B$14 | C16: ='res_raw'!$C$14 | D16: ='res_raw'!$D$14 | E16: ='res_raw'!$E$14 | F16: ='res_raw'!$F$14 | H16: =IFERROR(B16/$B$16*100,"") | I16: =IFERROR(C16/$B$16*100,"") | J16: =IFERROR(D16/$B$16*100,"") | K16: =IFERROR(E16/$B$16*100,"") | L16: =IFERROR(F16/$B$16*100,"")
A17: Skat af årets resultat | B17: ='res_raw'!$B$15 | C17: ='res_raw'!$C$15 | D17: ='res_raw'!$D$15 | E17: ='res_raw'!$E$15 | F17: ='res_raw'!$F$15 | H17: =IFERROR(B17/$B$17*100,"") | I17: =IFERROR(C17/$B$17*100,"") | J17: =IFERROR(D17/$B$17*100,"") | K17: =IFERROR(E17/$B$17*100,"") | L17: =IFERROR(F17/$B$17*100,"")
A18: Årets resultat | B18: ='res_raw'!$B$16 | C18: ='res_raw'!$C$16 | D18: ='res_raw'!$D$16 | E18: ='res_raw'!$E$16 | F18: ='res_raw'!$F$16 | H18: =IFERROR(B18/$B$18*100,"") | I18: =IFERROR(C18/$B$18*100,"") | J18: =IFERROR(D18/$B$18*100,"") | K18: =IFERROR(E18/$B$18*100,"") | L18: =IFERROR(F18/$B$18*100,"")
A20: AKTIVER t.kr. | B20: 2022 | C20: 2023 | D20: 2024 | E20: 2025 | F20: 2026 | H20: 2022 | I20: 2023 | J20: 2024 | K20: 2025 | L20: 2026
A21: Udviklingsprojekter | B21: ='balance_raw'!$B$2 | C21: ='balance_raw'!$C$2 | D21: ='balance_raw'!$D$2 | E21: ='balance_raw'!$E$2 | F21: ='balance_raw'!$F$2 | H21: =IFERROR(B21/$B$21*100,"") | I21: =IFERROR(C21/$B$21*100,"") | J21: =IFERROR(D21/$B$21*100,"") | K21: =IFERROR(E21/$B$21*100,"") | L21: =IFERROR(F21/$B$21*100,"")
A22: Patenter, varemærker mv. | B22: ='balance_raw'!$B$3 | C22: ='balance_raw'!$C$3 | D22: ='balance_raw'!$D$3 | E22: ='balance_raw'!$E$3 | F22: ='balance_raw'!$F$3 | H22: =IFERROR(B22/$B$22*100,"") | I22: =IFERROR(C22/$B$22*100,"") | J22: =IFERROR(D22/$B$22*100,"") | K22: =IFERROR(E22/$B$22*100,"") | L22: =IFERROR(F22/$B$22*100,"")
A23: Goodwill | B23: ='balance_raw'!$B$4 | C23: ='balance_raw'!$C$4 | D23: ='balance_raw'!$D$4 | E23: ='balance_raw'!$E$4 | F23: ='balance_raw'!$F$4 | H23: =IFERROR(B23/$B$23*100,"") | I23: =IFERROR(C23/$B$23*100,"") | J23: =IFERROR(D23/$B$23*100,"") | K23: =IFERROR(E23/$B$23*100,"") | L23: =IFERROR(F23/$B$23*100,"")
A24: Immaterielle anlægsaktiver | B24: ='balance_raw'!$B$5 | C24: ='balance_raw'!$C$5 | D24: ='balance_raw'!$D$5 | E24: ='balance_raw'!$E$5 | F24: ='balance_raw'!$F$5 | H24: =IFERROR(B24/$B$24*100,"") | I24: =IFERROR(C24/$B$24*100,"") | J24: =IFERROR(D24/$B$24*100,"") | K24: =IFERROR(E24/$B$24*100,"") | L24: =IFERROR(F24/$B$24*100,"")
A25: Materielle anlægsaktiver | B25: ='balance_raw'!$B$6 | C25: ='balance_raw'!$C$6 | D25: ='balance_raw'!$D$6 | E25: ='balance_raw'!$E$6 | F25: ='balance_raw'!$F$6 | H25: =IFERROR(B25/$B$25*100,"") | I25: =IFERROR(C25/$B$25*100,"") | J25: =IFERROR(D25/$B$25*100,"") | K25: =IFERROR(E25/$B$25*100,"") | L25: =IFERROR(F25/$B$25*100,"")
A26: Anlægsaktiver | B26: ='balance_raw'!$B$7 | C26: ='balance_raw'!$C$7 | D26: ='balance_raw'!$D$7 | E26: ='balance_raw'!$E$7 | F26: ='balance_raw'!$F$7 | H26: =IFERROR(B26/$B$26*100,"") | I26: =IFERROR(C26/$B$26*100,"") | J26: =IFERROR(D26/$B$26*100,"") | K26: =IFERROR(E26/$B$26*100,"") | L26: =IFERROR(F26/$B$26*100,"")
A27: Varebeholdninger | B27: ='balance_raw'!$B$8 | C27: ='balance_raw'!$C$8 | D27: ='balance_raw'!$D$8 | E27: ='balance_raw'!$E$8 | F27: ='balance_raw'!$F$8 | H27: =IFERROR(B27/$B$27*100,"") | I27: =IFERROR(C27/$B$27*100,"") | J27: =IFERROR(D27/$B$27*100,"") | K27: =IFERROR(E27/$B$27*100,"") | L27: =IFERROR(F27/$B$27*100,"")
A28: Tilgodehavender fra salg og tjenesteydelser | B28: ='balance_raw'!$B$9 | C28: ='balance_raw'!$C$9 | D28: ='balance_raw'!$D$9 | E28: ='balance_raw'!$E$9 | F28: ='balance_raw'!$F$9 | H28: =IFERROR(B28/$B$28*100,"") | I28: =IFERROR(C28/$B$28*100,"") | J28: =IFERROR(D28/$B$28*100,"") | K28: =IFERROR(E28/$B$28*100,"") | L28: =IFERROR(F28/$B$28*100,"")
A29: Tilgodehavender hos tilknyttede virksomheder | B29: ='balance_raw'!$B$10 | C29: ='balance_raw'!$C$10 | D29: ='balance_raw'!$D$10 | E29: ='balance_raw'!$E$10 | F29: ='balance_raw'!$F$10 | H29: =IFERROR(B29/$B$29*100,"") | I29: =IFERROR(C29/$B$29*100,"") | J29: =IFERROR(D29/$B$29*100,"") | K29: =IFERROR(E29/$B$29*100,"") | L29: =IFERROR(F29/$B$29*100,"")
A30: Andre tilgodehavender | B30: ='balance_raw'!$B$11 | C30: ='balance_raw'!$C$11 | D30: ='balance_raw'!$D$11 | E30: ='balance_raw'!$E$11 | F30: ='balance_raw'!$F$11 | H30: =IFERROR(B30/$B$30*100,"") | I30: =IFERROR(C30/$B$30*100,"") | J30: =IFERROR(D30/$B$30*100,"") | K30: =IFERROR(E30/$B$30*100,"") | L30: =IFERROR(F30/$B$30*100,"")
A31: Periodeafgrænsningsposter (aktiver) | B31: ='balance_raw'!$B$12 | C31: ='balance_raw'!$C$12 | D31: ='balance_raw'!$D$12 | E31: ='balance_raw'!$E$12 | F31: ='balance_raw'!$F$12 | H31: =IFERROR(B31/$B$31*100,"") | I31: =IFERROR(C31/$B$31*100,"") | J31: =IFERROR(D31/$B$31*100,"") | K31: =IFERROR(E31/$B$31*100,"") | L31: =IFERROR(F31/$B$31*100,"")
A32: Udskudt skatteaktiv | B32: ='balance_raw'!$B$13 | C32: ='balance_raw'!$C$13 | D32: ='balance_raw'!$D$13 | E32: ='balance_raw'!$E$13 | F32: ='balance_raw'!$F$13 | H32: =IFERROR(B32/$B$32*100,"") | I32: =IFERROR(C32/$B$32*100,"") | J32: =IFERROR(D32/$B$32*100,"") | K32: =IFERROR(E32/$B$32*100,"") | L32: =IFERROR(F32/$B$32*100,"")
A33: Tilgodehavende skat hos tilknyttede virksomheder | B33: ='balance_raw'!$B$14 | C33: ='balance_raw'!$C$14 | D33: ='balance_raw'!$D$14 | E33: ='balance_raw'!$E$14 | F33: ='balance_raw'!$F$14 | H33: =IFERROR(B33/$B$33*100,"") | I33: =IFERROR(C33/$B$33*100,"") | J33: =IFERROR(D33/$B$33*100,"") | K33: =IFERROR(E33/$B$33*100,"") | L33: =IFERROR(F33/$B$33*100,"")
A34: Kortfristede skattetilgodehavender | B34: ='balance_raw'!$B$15 | C34: ='balance_raw'!$C$15 | D34: ='balance_raw'!$D$15 | E34: ='balance_raw'!$E$15 | F34: ='balance_raw'!$F$15 | H34: =IFERROR(B34/$B$34*100,"") | I34: =IFERROR(C34/$B$34*100,"") | J34: =IFERROR(D34/$B$34*100,"") | K34: =IFERROR(E34/$B$34*100,"") | L34: =IFERROR(F34/$B$34*100,"")
A35: Tilgodehavender | B35: ='balance_raw'!$B$16 | C35: ='balance_raw'!$C$16 | D35: ='balance_raw'!$D$16 | E35: ='balance_raw'!$E$16 | F35: ='balance_raw'!$F$16 | H35: =IFERROR(B35/$B$35*100,"") | I35: =IFERROR(C35/$B$35*100,"") | J35: =IFERROR(D35/$B$35*100,"") | K35: =IFERROR(E35/$B$35*100,"") | L35: =IFERROR(F35/$B$35*100,"")
A36: Værdipapirer | B36: ='balance_raw'!$B$17 | C36: ='balance_raw'!$C$17 | D36: ='balance_raw'!$D$17 | E36: ='balance_raw'!$E$17 | F36: ='balance_raw'!$F$17 | H36: =IFERROR(B36/$B$36*100,"") | I36: =IFERROR(C36/$B$36*100,"") | J36: =IFERROR(D36/$B$36*100,"") | K36: =IFERROR(E36/$B$36*100,"") | L36: =IFERROR(F36/$B$36*100,"")
A37: Likvide beholdninger | B37: ='balance_raw'!$B$18 | C37: ='balance_raw'!$C$18 | D37: ='balance_raw'!$D$18 | E37: ='balance_raw'!$E$18 | F37: ='balance_raw'!$F$18 | H37: =IFERROR(B37/$B$37*100,"") | I37: =IFERROR(C37/$B$37*100,"") | J37: =IFERROR(D37/$B$37*100,"") | K37: =IFERROR(E37/$B$37*100,"") | L37: =IFERROR(F37/$B$37*100,"")
A38: Omsætningsaktiver | B38: ='balance_raw'!$B$19 | C38: ='balance_raw'!$C$19 | D38: ='balance_raw'!$D$19 | E38: ='balance_raw'!$E$19 | F38: ='balance_raw'!$F$19 | H38: =IFERROR(B38/$B$38*100,"") | I38: =IFERROR(C38/$B$38*100,"") | J38: =IFERROR(D38/$B$38*100,"") | K38: =IFERROR(E38/$B$38*100,"") | L38: =IFERROR(F38/$B$38*100,"")
A39: Aktiver | B39: ='balance_raw'!$B$20 | C39: ='balance_raw'!$C$20 | D39: ='balance_raw'!$D$20 | E39: ='balance_raw'!$E$20 | F39: ='balance_raw'!$F$20 | H39: =IFERROR(B39/$B$39*100,"") | I39: =IFERROR(C39/$B$39*100,"") | J39: =IFERROR(D39/$B$39*100,"") | K39: =IFERROR(E39/$B$39*100,"") | L39: =IFERROR(F39/$B$39*100,"")
A41: PASSIVER t.kr. | B41: 2022 | C41: 2023 | D41: 2024 | E41: 2025 | F41: 2026 | H41: 2022 | I41: 2023 | J41: 2024 | K41: 2025 | L41: 2026
A42: Selskabskapital | B42: ='balance_raw'!$B$21 | C42: ='balance_raw'!$C$21 | D42: ='balance_raw'!$D$21 | E42: ='balance_raw'!$E$21 | F42: ='balance_raw'!$F$21 | H42: =IFERROR(B42/$B$42*100,"") | I42: =IFERROR(C42/$B$42*100,"") | J42: =IFERROR(D42/$B$42*100,"") | K42: =IFERROR(E42/$B$42*100,"") | L42: =IFERROR(F42/$B$42*100,"")
...

Sheet res_raw
A1: bogo (CVR None) — Resultatopgørelse & nøgleoplysninger (t.kr.) | B1: 2022 | C1: 2023 | D1: 2024 | E1: 2025 | F1: 2026
A2: Nettoomsætning | B2: 2948000 | C2: 2752000 | D2: 2588000 | E2: 2553000 | F2: 2468000
A3: Produktionsomkostninger | B3: 1612000 | C3: 1537000 | D3: 1209000 | E3: 1149000 | F3: 1032000
A4: Bruttoresultat | B4: 1336000 | C4: 1215000 | D4: 1379000 | E4: 1404000 | F4: 1436000
A5: Salgs- og distributionsomkostninger
A6: Administrationsomkostninger | B6: 136000 | C6: 128000 | D6: 135000 | E6: 153000 | F6: 139000
A7: Andre driftsindtægter | E7: 0 | F7: 11000
A8: Andre driftsomkostninger
A9: Resultat af primær drift | B9: 46000 | C9: -124000 | D9: 18000 | E9: 16000 | F9: -76000
A10: Indtægter af kapitalandele, dattervirksomheder
A11: Finansielle indtægter | B11: 11000 | C11: 28000 | D11: 50000 | E11: 68000 | F11: 84000
A12: Finansielle omkostninger | B12: 65000 | C12: 56000 | D12: 75000 | E12: 82000 | F12: 71000
A13: Finansielle poster, netto
A14: Resultat før skat | B14: -8000 | C14: -152000 | D14: -7000 | E14: 2000 | F14: -63000
A15: Skat af årets resultat | B15: 22000 | C15: -11000 | D15: 10000 | E15: 31000 | F15: 44000
A16: Årets resultat | B16: -30000 | C16: -141000 | D16: -17000 | E16: -29000 | F16: -107000
A17: Gns. antal medarbejdere
A18: Investering i materielle anlægsaktiver | B18: 68000 | C18: 54000 | D18: 55000 | E18: 39000 | F18: 57000

Sheet balance_raw
A1: bogo (CVR None) — Balance (t.kr.) | B1: 2022 | C1: 2023 | D1: 2024 | E1: 2025 | F1: 2026
A2: Udviklingsprojekter | B2: 97000 | C2: 129000 | D2: 150000 | E2: 159000 | F2: 179000
A3: Patenter, varemærker mv.
A4: Goodwill | B4: 42000 | C4: 42000 | D4: 42000 | E4: 42000 | F4: 42000
A5: Immaterielle anlægsaktiver | B5: 334000 | C5: 375000 | D5: 396000 | E5: 447000 | F5: 485000
A6: Materielle anlægsaktiver | B6: 215000 | C6: 215000 | D6: 220000 | E6: 211000 | F6: 214000
A7: Anlægsaktiver | B7: 761000 | C7: 832000 | D7: 864000 | E7: 889000 | F7: 1009000
A8: Varebeholdninger | B8: 629000 | C8: 499000 | D8: 447000 | E8: 447000 | F8: 418000
A9: Tilgodehavender fra salg og tjenesteydelser | B9: 397000 | C9: 341000 | D9: 309000 | E9: 348000 | F9: 300000
A10: Tilgodehavender hos tilknyttede virksomheder
A11: Andre tilgodehavender
A12: Periodeafgrænsningsposter (aktiver) | B12: 28000 | C12: 24000 | D12: 27000 | E12: 42000 | F12: 33000
A13: Udskudt skatteaktiv | B13: 77000 | C13: 99000 | D13: 92000 | E13: 75000 | F13: 41000
A14: Tilgodehavende skat hos tilknyttede virksomheder
A15: Kortfristede skattetilgodehavender | B15: 37000 | C15: 11000 | D15: 32000 | E15: 28000 | F15: 27000
A16: Tilgodehavender | B16: 89000 | C16: 68000 | D16: 53000 | E16: 61000 | F16: 61000
A17: Værdipapirer
A18: Likvide beholdninger | B18: 162000 | C18: 216000 | D18: 177000 | E18: 145000 | F18: 134000
A19: Omsætningsaktiver | B19: 1757000 | C19: 1553000 | D19: 1433000 | E19: 1451000 | F19: 1213000
A20: Aktiver | B20: 2518000 | C20: 2385000 | D20: 2297000 | E20: 2340000 | F20: 2222000
A21: Selskabskapital | B21: 613000 | C21: 613000 | D21: 613000 | E21: 737000 | F21: 737000
A22: Reserve for nettoopskrivning (indre værdis metode)
A23: Reserve for udviklingsomkostninger
A24: Reserve for sikringstransaktioner
A25: Andre reserver | B25: -5000 | C25: -4000 | D25: -2000 | E25: -2000 | F25: -3000
A26: Overført resultat | B26: 460000 | C26: 329000 | D26: 329000 | E26: 402000 | F26: 264000
A27: Egenkapital i alt | B27: 1100000 | C27: 958000 | D27: 956000 | E27: 1144000 | F27: 1006000
A28: Hensættelse til udskudt skat | B28: 6000 | C28: 6000 | D28: 8000 | E28: 8000 | F28: 9000
A29: Hensatte forpligtelser | B29: 12000 | C29: 11000 | D29: 10000 | E29: 15000 | F29: 10000
A30: Ansvarlig lånekapital (langfristet)
A31: Langfristede lån
A32: Leasingforpligtelser (langfristet) | B32: 95000 | C32: 109000 | D32: 117000 | E32: 104000 | F32: 221000
A33: Anden gæld (langfristet) | B33: 58000 | C33: 56000 | D33: 53000 | E33: 50000 | F33: 42000
A34: Langfristede gældsforpligtelser | B34: 233000 | C34: 225000 | D34: 236000 | E34: 216000 | F34: 313000
A35: Ansvarlig lånekapital (kortfristet)
A36: Kortfristet del af langfristede gældsforpligtelser
A37: Kreditinstitutter | B37: 4000 | C37: 3000 | D37: 3000 | E37: 3000 | F37: 3000
A38: Leasingforpligtelser (kortfristet) | B38: 39000 | C38: 37000 | D38: 45000 | E38: 59000 | F38: 70000
A39: Leverandører af varer og tjenesteydelser | B39: 581000 | C39: 565000 | D39: 401000 | E39: 453000 | F39: 313000
A40: Gæld til tilknyttede virksomheder
...

Sheet pengestrom_raw
A1: bogo (CVR None) — Pengestrømsopgørelse (t.kr.) | B1: 2022 | C1: 2023 | D1: 2024 | E1: 2025 | F1: 2026
A2: Pengestrømme fra driftsaktivitet | B2: 76000 | C2: 198000 | D2: 226000 | E2: 256000 | F2: 104000
A3: Pengestrømme fra investeringsaktivitet | B3: -239000 | C3: -204000 | D3: -209000 | E3: -231000 | F3: -105000
A4: Pengestrømme fra finansieringsaktivitet | B4: 145000 | C4: 64000 | D4: -54000 | E4: -58000 | F4: -8000
A5: Årets pengestrøm

Sheet Simpel_funktion
A1: bogo (CVR None) — Regnskabs- og nøgletal — funktionsopdelt
A3: Beløb i 1.000 kr. | B3: 2026 | C3: 2025 | D3: 2024 | F3: Note / XBRL-felt
A4: Uddrag af resultatopgørelse
A5: Nettoomsætning | B5: ='res_raw'!$F$2 | C5: ='res_raw'!$E$2 | D5: ='res_raw'!$D$2 | F5: fsa:Revenue
A6: Produktionsomkostninger | B6: =-'res_raw'!$F$3 | C6: =-'res_raw'!$E$3 | D6: =-'res_raw'!$D$3 | F6: fsa:CostOfProduction (vises negativt). Materialer, lønninger, produktionsoverhead.
A7: Bruttoresultat | B7: =IF(COUNT('res_raw'!$F$2,'res_raw'!$F$3)=0,'res_raw'!$F$4,SUM(B5:B6)) | C7: =IF(COUNT('res_raw'!$E$2,'res_raw'!$E$3)=0,'res_raw'!$E$4,SUM(C5:C6)) | D7: =IF(COUNT('res_raw'!$D$2,'res_raw'!$D$3)=0,'res_raw'!$D$4,SUM(D5:D6)) | F7: Beregnet: Nettoomsætning − Produktionsomkostninger. Matcher fsa:GrossResult. Er komponenterne ikke indberettet, vises rapporteret fsa:GrossResult direkte.
A8: Salgs- og distributionsomk. | B8: =-'res_raw'!$F$5 | C8: =-'res_raw'!$E$5 | D8: =-'res_raw'!$D$5 | F8: fsa:DistributionCosts (vises negativt). Marketing, salg, distribution.
A9: Administrationsomkostninger mv. | B9: =-'res_raw'!$F$6 | C9: =-'res_raw'!$E$6 | D9: =-'res_raw'!$D$6 | F9: fsa:AdministrativeExpenses (vises negativt). Generel administration.
A10: Andre driftsindtægter | B10: ='res_raw'!$F$7 | C10: ='res_raw'!$E$7 | D10: ='res_raw'!$D$7 | F10: fsa:OtherOperatingIncome. Sekundære driftsindtægter (huslejeindtægter, off. tilskud, avancer mv.).
A11: Andre driftsomkostninger | B11: =-'res_raw'!$F$8 | C11: =-'res_raw'!$E$8 | D11: =-'res_raw'!$D$8 | F11: fsa:OtherOperatingExpenses (vises negativt). Sekundære driftsomkostninger.
A12: Resultat af primær drift | B12: =SUM(B7:B11) | C12: =SUM(C7:C11) | D12: =SUM(D7:D11) | F12: Beregnet: Bruttoresultat − Salgs/dist. − Administration + Andre driftsindt. − Andre driftsomk. EBIT.
A13: Finansielle indtægter mv. | B13: =N('res_raw'!$F$10)+N('res_raw'!$F$11) | C13: =N('res_raw'!$E$10)+N('res_raw'!$E$11) | D13: =N('res_raw'!$D$10)+N('res_raw'!$D$11) | F13: fsa:IncomeFromSubsidiaries + fsa:OtherFinanceIncome.
A14: Finansielle omkostninger mv. | B14: =-'res_raw'!$F$12 | C14: =-'res_raw'!$E$12 | D14: =-'res_raw'!$D$12 | F14: fsa:OtherFinanceExpenses (vises negativt). Renteomkostninger, kurstab.
A15: Resultat før skat | B15: =SUM(B12:B14) | C15: =SUM(C12:C14) | D15: =SUM(D12:D14) | F15: Beregnet: EBIT + Fin. indtægter + Fin. omk. EBT.
A17: Uddrag af balance
A18: Anlægsaktiver | B18: ='balance_raw'!$F$7 | C18: ='balance_raw'!$E$7 | D18: ='balance_raw'!$D$7 | F18: fsa:NoncurrentAssets. Materielle, immaterielle og finansielle anlægsaktiver.
A19: Omsætningsaktiver | B19: ='balance_raw'!$F$19 | C19: ='balance_raw'!$E$19 | D19: ='balance_raw'!$D$19 | F19: fsa:CurrentAssets. Varebeholdninger, tilgodehavender, likvider.
A20: Aktiver i alt | B20: =SUM(B18:B19) | C20: =SUM(C18:C19) | D20: =SUM(D18:D19) | F20: Beregnet: Anlægsaktiver + Omsætningsaktiver. Bør matche fsa:Assets.
A22: Egenkapital | B22: ='balance_raw'!$F$27 | C22: ='balance_raw'!$E$27 | D22: ='balance_raw'!$D$27 | F22: fsa:Equity. Selskabskapital, overført resultat, reserver.
A23: Forpligtelser | B23: ='balance_raw'!$F$48-'balance_raw'!$F$27 | C23: ='balance_raw'!$E$48-'balance_raw'!$E$27 | D23: ='balance_raw'!$D$48-'balance_raw'!$D$27 | F23: Beregnet: Passiver (fsa:LiabilitiesAndEquity) − Egenkapital. Hensættelser + kort- og langfristet gæld.
A24: Passiver i alt | B24: =SUM(B22:B23) | C24: =SUM(C22:C23) | D24: =SUM(D22:D23) | F24: Beregnet: Egenkapital + Forpligtelser. Bør matche Aktiver i alt.
A26: Udvalgte balanceposter
A27: Varebeholdninger | B27: ='balance_raw'!$F$8 | C27: ='balance_raw'!$E$8 | D27: ='balance_raw'!$D$8 | F27: fsa:Inventories (eller fsa:ManufacturedGoodsAndGoodsForResale hvis total mangler).
A28: Tilgodehavender fra salg | B28: ='balance_raw'!$F$9 | C28: ='balance_raw'!$E$9 | D28: ='balance_raw'!$D$9 | F28: fsa:ShorttermTradeReceivables. Kortfristede tilgodehavender fra kunder.
A29: Kortfristede gældsforpligtelser | B29: ='balance_raw'!$F$46 | C29: ='balance_raw'!$E$46 | D29: ='balance_raw'!$D$46 | F29: fsa:ShorttermLiabilitiesOtherThanProvisions. Gæld der forfalder inden for 1 år.
A31: Rentabilitet
A32: Afkastningsgrad, % | B32: =IFERROR((B12+B13)/B20*100,"") | C32: =IFERROR((C12+C13)/C20*100,"") | D32: =IFERROR((D12+D13)/D20*100,"")
A33: Overskudsgrad, % | B33: =IFERROR((B12+B13)/B5*100,"") | C33: =IFERROR((C12+C13)/C5*100,"") | D33: =IFERROR((D12+D13)/D5*100,"")
A34: Aktivernes omsætningshastighed, gange | B34: =IFERROR(B5/B20,"") | C34: =IFERROR(C5/C20,"") | D34: =IFERROR(D5/D20,"")
A35: Gældsrente, % | B35: =IFERROR(-B14*100/B23,"") | C35: =IFERROR(-C14*100/C23,"") | D35: =IFERROR(-D14*100/D23,"")
A36: Egenkapitalens forrentning, % | B36: =IFERROR(B15/B22*100,"") | C36: =IFERROR(C15/C22*100,"") | D36: =IFERROR(D15/D22*100,"")
A37: Gearing, gange | B37: =IFERROR(B23/B22,"") | C37: =IFERROR(C23/C22,"") | D37: =IFERROR(D23/D22,"")
A39: Indekstal for indtjeningsevne (2024=100)
A40: Nettoomsætning | B40: =IFERROR(B5/$D5*100,"") | C40: =IFERROR(C5/$D5*100,"") | D40: =IFERROR(D5/$D5*100,"")
A41: Produktionsomkostninger | B41: =IFERROR(B6/$D6*100,"") | C41: =IFERROR(C6/$D6*100,"") | D41: =IFERROR(D6/$D6*100,"")
A42: Salgs- og distributionsomk. | B42: =IFERROR(B8/$D8*100,"") | C42: =IFERROR(C8/$D8*100,"") | D42: =IFERROR(D8/$D8*100,"")
A43: Administrationsomk. | B43: =IFERROR(B9/$D9*100,"") | C43: =IFERROR(C9/$D9*100,"") | D43: =IFERROR(D9/$D9*100,"")
A44: Andre driftsomkostninger | B44: =IFERROR(B11/$D11*100,"") | C44: =IFERROR(C11/$D11*100,"") | D44: =IFERROR(D11/$D11*100,"")
A46: Indekstal for kapitaltilpasningsevne (2024=100)
A47: Nettoomsætning | B47: =IFERROR(B5*100/$D5,"") | C47: =IFERROR(C5*100/$D5,"") | D47: =IFERROR(D5*100/$D5,"")
...

Sheet Noter_info
A1: bogo (CVR None) — Ukendte XBRL-felter — disse er noter og ikke en del af hoved-regnskabet
A2: Kategori | B2: Dansk navn | C2: XBRL feltnavn | D2: 2022 t.kr. | E2: 2023 t.kr. | F2: 2024 t.kr. | G2: 2025 t.kr. | H2: 2026 t.kr. | I2: Forklaring
A3: Øvrige (ukendt) | B3: ifrs-full:AdjustmentsForFinanceIncomeCost | C3: ifrs-full:AdjustmentsForFinanceIncomeCost | D3: -54000 | E3: -28000 | F3: -25000 | G3: -14000 | H3: 13000 | I3: Ingen forklaring tilgængelig.
A4: Øvrige (ukendt) | B4: ifrs-full:OtherInflowsOutflowsOfCashClassifiedAsFinancingActivities | C4: ifrs-full:OtherInflowsOutflowsOfCashClassifiedAsFinancingActivities | D4: -34000 | E4: 0 | I4: Ingen forklaring tilgængelig.
A5: Øvrige (ukendt) | B5: ifrs-full:OtherInflowsOutflowsOfCashClassifiedAsInvestingActivities | C5: ifrs-full:OtherInflowsOutflowsOfCashClassifiedAsInvestingActivities | D5: -2000 | E5: 3000 | F5: 1000 | G5: -2000 | H5: 0 | I5: Ingen forklaring tilgængelig.
A6: Øvrige (ukendt) | B6: ifrs-full:OtherInflowsOutflowsOfCashClassifiedAsOperatingActivities | C6: ifrs-full:OtherInflowsOutflowsOfCashClassifiedAsOperatingActivities | G6: 0 | H6: 25000 | I6: Ingen forklaring tilgængelig.
A7: Øvrige (ukendt) | B7: ifrs-full:ReserveOfExchangeDifferencesOnTranslation | C7: ifrs-full:ReserveOfExchangeDifferencesOnTranslation | D7: 32000 | E7: 20000 | F7: 16000 | G7: 7000 | H7: 8000 | I7: Ingen forklaring tilgængelig.
A8: Øvrige (ukendt) | B8: ifrs-full:SalesAndMarketingExpense | C8: ifrs-full:SalesAndMarketingExpense | D8: 875000 | E8: 910000 | F8: 940000 | G8: 895000 | H8: 1009000 | I8: Ingen forklaring tilgængelig.
