Workbook

Sheet Overblik_45937712
A1: A/S Læsø Fiskeindustri (CVR 45937712) — Regnskabsanalyse – Resultatopgørelse & Balance (t.kr.) · Klasse C-mellem · Revision
H2: Indekstal (2021=100)
A3: Resultatopgørelse t.kr. | B3: 2021 | C3: 2022 | D3: 2023 | E3: 2024 | F3: 2025 | H3: 2021 | I3: 2022 | J3: 2023 | K3: 2024 | L3: 2025
A4: Nettoomsætning | B4: ='res_raw_45937712'!$B$2 | C4: ='res_raw_45937712'!$C$2 | D4: ='res_raw_45937712'!$D$2 | E4: ='res_raw_45937712'!$E$2 | F4: ='res_raw_45937712'!$F$2 | H4: =IFERROR(B4/$B$4*100,"") | I4: =IFERROR(C4/$B$4*100,"") | J4: =IFERROR(D4/$B$4*100,"") | K4: =IFERROR(E4/$B$4*100,"") | L4: =IFERROR(F4/$B$4*100,"")
A5: Andre driftsindtægter | B5: ='res_raw_45937712'!$B$3 | C5: ='res_raw_45937712'!$C$3 | D5: ='res_raw_45937712'!$D$3 | E5: ='res_raw_45937712'!$E$3 | F5: ='res_raw_45937712'!$F$3 | H5: =IFERROR(B5/$B$5*100,"") | I5: =IFERROR(C5/$B$5*100,"") | J5: =IFERROR(D5/$B$5*100,"") | K5: =IFERROR(E5/$B$5*100,"") | L5: =IFERROR(F5/$B$5*100,"")
A6: Vareforbrug | B6: ='res_raw_45937712'!$B$4 | C6: ='res_raw_45937712'!$C$4 | D6: ='res_raw_45937712'!$D$4 | E6: ='res_raw_45937712'!$E$4 | F6: ='res_raw_45937712'!$F$4 | H6: =IFERROR(B6/$B$6*100,"") | I6: =IFERROR(C6/$B$6*100,"") | J6: =IFERROR(D6/$B$6*100,"") | K6: =IFERROR(E6/$B$6*100,"") | L6: =IFERROR(F6/$B$6*100,"")
A7: Andre eksterne omkostninger | B7: ='res_raw_45937712'!$B$5 | C7: ='res_raw_45937712'!$C$5 | D7: ='res_raw_45937712'!$D$5 | E7: ='res_raw_45937712'!$E$5 | F7: ='res_raw_45937712'!$F$5 | H7: =IFERROR(B7/$B$7*100,"") | I7: =IFERROR(C7/$B$7*100,"") | J7: =IFERROR(D7/$B$7*100,"") | K7: =IFERROR(E7/$B$7*100,"") | L7: =IFERROR(F7/$B$7*100,"")
A8: Bruttoresultat | B8: ='res_raw_45937712'!$B$6 | C8: ='res_raw_45937712'!$C$6 | D8: ='res_raw_45937712'!$D$6 | E8: ='res_raw_45937712'!$E$6 | F8: ='res_raw_45937712'!$F$6 | H8: =IFERROR(B8/$B$8*100,"") | I8: =IFERROR(C8/$B$8*100,"") | J8: =IFERROR(D8/$B$8*100,"") | K8: =IFERROR(E8/$B$8*100,"") | L8: =IFERROR(F8/$B$8*100,"")
A9: Personaleomkostninger | B9: ='res_raw_45937712'!$B$7 | C9: ='res_raw_45937712'!$C$7 | D9: ='res_raw_45937712'!$D$7 | E9: ='res_raw_45937712'!$E$7 | F9: ='res_raw_45937712'!$F$7 | H9: =IFERROR(B9/$B$9*100,"") | I9: =IFERROR(C9/$B$9*100,"") | J9: =IFERROR(D9/$B$9*100,"") | K9: =IFERROR(E9/$B$9*100,"") | L9: =IFERROR(F9/$B$9*100,"")
A10: Resultat før afskrivninger | B10: =IFERROR($B$8-ABS($B$9),"") | C10: =IFERROR($C$8-ABS($C$9),"") | D10: =IFERROR($D$8-ABS($D$9),"") | E10: =IFERROR($E$8-ABS($E$9),"") | F10: =IFERROR($F$8-ABS($F$9),"") | H10: =IFERROR(B10/$B$10*100,"") | I10: =IFERROR(C10/$B$10*100,"") | J10: =IFERROR(D10/$B$10*100,"") | K10: =IFERROR(E10/$B$10*100,"") | L10: =IFERROR(F10/$B$10*100,"")
A11: Af- og nedskrivninger | B11: ='res_raw_45937712'!$B$9 | C11: ='res_raw_45937712'!$C$9 | D11: ='res_raw_45937712'!$D$9 | E11: ='res_raw_45937712'!$E$9 | F11: ='res_raw_45937712'!$F$9 | H11: =IFERROR(B11/$B$11*100,"") | I11: =IFERROR(C11/$B$11*100,"") | J11: =IFERROR(D11/$B$11*100,"") | K11: =IFERROR(E11/$B$11*100,"") | L11: =IFERROR(F11/$B$11*100,"")
A12: Andre driftsomkostninger | B12: ='res_raw_45937712'!$B$10 | C12: ='res_raw_45937712'!$C$10 | D12: ='res_raw_45937712'!$D$10 | E12: ='res_raw_45937712'!$E$10 | F12: ='res_raw_45937712'!$F$10 | H12: =IFERROR(B12/$B$12*100,"") | I12: =IFERROR(C12/$B$12*100,"") | J12: =IFERROR(D12/$B$12*100,"") | K12: =IFERROR(E12/$B$12*100,"") | L12: =IFERROR(F12/$B$12*100,"")
A13: Resultat af primær drift | B13: ='res_raw_45937712'!$B$11 | C13: ='res_raw_45937712'!$C$11 | D13: ='res_raw_45937712'!$D$11 | E13: ='res_raw_45937712'!$E$11 | F13: ='res_raw_45937712'!$F$11 | H13: =IFERROR(B13/$B$13*100,"") | I13: =IFERROR(C13/$B$13*100,"") | J13: =IFERROR(D13/$B$13*100,"") | K13: =IFERROR(E13/$B$13*100,"") | L13: =IFERROR(F13/$B$13*100,"")
A14: Indtægter af kapitalandele, dattervirksomheder | B14: ='res_raw_45937712'!$B$12 | C14: ='res_raw_45937712'!$C$12 | D14: ='res_raw_45937712'!$D$12 | E14: ='res_raw_45937712'!$E$12 | F14: ='res_raw_45937712'!$F$12 | H14: =IFERROR(B14/$B$14*100,"") | I14: =IFERROR(C14/$B$14*100,"") | J14: =IFERROR(D14/$B$14*100,"") | K14: =IFERROR(E14/$B$14*100,"") | L14: =IFERROR(F14/$B$14*100,"")
A15: Finansielle indtægter | B15: ='res_raw_45937712'!$B$13 | C15: ='res_raw_45937712'!$C$13 | D15: ='res_raw_45937712'!$D$13 | E15: ='res_raw_45937712'!$E$13 | F15: ='res_raw_45937712'!$F$13 | H15: =IFERROR(B15/$B$15*100,"") | I15: =IFERROR(C15/$B$15*100,"") | J15: =IFERROR(D15/$B$15*100,"") | K15: =IFERROR(E15/$B$15*100,"") | L15: =IFERROR(F15/$B$15*100,"")
A16: Finansielle omkostninger | B16: ='res_raw_45937712'!$B$14 | C16: ='res_raw_45937712'!$C$14 | D16: ='res_raw_45937712'!$D$14 | E16: ='res_raw_45937712'!$E$14 | F16: ='res_raw_45937712'!$F$14 | H16: =IFERROR(B16/$B$16*100,"") | I16: =IFERROR(C16/$B$16*100,"") | J16: =IFERROR(D16/$B$16*100,"") | K16: =IFERROR(E16/$B$16*100,"") | L16: =IFERROR(F16/$B$16*100,"")
A17: Finansielle poster, netto | B17: ='res_raw_45937712'!$B$15 | C17: ='res_raw_45937712'!$C$15 | D17: ='res_raw_45937712'!$D$15 | E17: ='res_raw_45937712'!$E$15 | F17: ='res_raw_45937712'!$F$15 | H17: =IFERROR(B17/$B$17*100,"") | I17: =IFERROR(C17/$B$17*100,"") | J17: =IFERROR(D17/$B$17*100,"") | K17: =IFERROR(E17/$B$17*100,"") | L17: =IFERROR(F17/$B$17*100,"")
A18: Resultat før skat | B18: ='res_raw_45937712'!$B$16 | C18: ='res_raw_45937712'!$C$16 | D18: ='res_raw_45937712'!$D$16 | E18: ='res_raw_45937712'!$E$16 | F18: ='res_raw_45937712'!$F$16 | H18: =IFERROR(B18/$B$18*100,"") | I18: =IFERROR(C18/$B$18*100,"") | J18: =IFERROR(D18/$B$18*100,"") | K18: =IFERROR(E18/$B$18*100,"") | L18: =IFERROR(F18/$B$18*100,"")
A19: Skat af årets resultat | B19: ='res_raw_45937712'!$B$17 | C19: ='res_raw_45937712'!$C$17 | D19: ='res_raw_45937712'!$D$17 | E19: ='res_raw_45937712'!$E$17 | F19: ='res_raw_45937712'!$F$17 | H19: =IFERROR(B19/$B$19*100,"") | I19: =IFERROR(C19/$B$19*100,"") | J19: =IFERROR(D19/$B$19*100,"") | K19: =IFERROR(E19/$B$19*100,"") | L19: =IFERROR(F19/$B$19*100,"")
A20: Årets resultat | B20: ='res_raw_45937712'!$B$18 | C20: ='res_raw_45937712'!$C$18 | D20: ='res_raw_45937712'!$D$18 | E20: ='res_raw_45937712'!$E$18 | F20: ='res_raw_45937712'!$F$18 | H20: =IFERROR(B20/$B$20*100,"") | I20: =IFERROR(C20/$B$20*100,"") | J20: =IFERROR(D20/$B$20*100,"") | K20: =IFERROR(E20/$B$20*100,"") | L20: =IFERROR(F20/$B$20*100,"")
A22: AKTIVER t.kr. | B22: 2021 | C22: 2022 | D22: 2023 | E22: 2024 | F22: 2025 | H22: 2021 | I22: 2022 | J22: 2023 | K22: 2024 | L22: 2025
A23: Immaterielle anlægsaktiver | B23: ='balance_raw_45937712'!$B$2 | C23: ='balance_raw_45937712'!$C$2 | D23: ='balance_raw_45937712'!$D$2 | E23: ='balance_raw_45937712'!$E$2 | F23: ='balance_raw_45937712'!$F$2 | H23: =IFERROR(B23/$B$23*100,"") | I23: =IFERROR(C23/$B$23*100,"") | J23: =IFERROR(D23/$B$23*100,"") | K23: =IFERROR(E23/$B$23*100,"") | L23: =IFERROR(F23/$B$23*100,"")
A24: Grunde og bygninger | B24: ='balance_raw_45937712'!$B$3 | C24: ='balance_raw_45937712'!$C$3 | D24: ='balance_raw_45937712'!$D$3 | E24: ='balance_raw_45937712'!$E$3 | F24: ='balance_raw_45937712'!$F$3 | H24: =IFERROR(B24/$B$24*100,"") | I24: =IFERROR(C24/$B$24*100,"") | J24: =IFERROR(D24/$B$24*100,"") | K24: =IFERROR(E24/$B$24*100,"") | L24: =IFERROR(F24/$B$24*100,"")
A25: Produktionsanlæg og maskiner | B25: ='balance_raw_45937712'!$B$4 | C25: ='balance_raw_45937712'!$C$4 | D25: ='balance_raw_45937712'!$D$4 | E25: ='balance_raw_45937712'!$E$4 | F25: ='balance_raw_45937712'!$F$4 | H25: =IFERROR(B25/$B$25*100,"") | I25: =IFERROR(C25/$B$25*100,"") | J25: =IFERROR(D25/$B$25*100,"") | K25: =IFERROR(E25/$B$25*100,"") | L25: =IFERROR(F25/$B$25*100,"")
A26: Driftsmateriel og inventar | B26: ='balance_raw_45937712'!$B$5 | C26: ='balance_raw_45937712'!$C$5 | D26: ='balance_raw_45937712'!$D$5 | E26: ='balance_raw_45937712'!$E$5 | F26: ='balance_raw_45937712'!$F$5 | H26: =IFERROR(B26/$B$26*100,"") | I26: =IFERROR(C26/$B$26*100,"") | J26: =IFERROR(D26/$B$26*100,"") | K26: =IFERROR(E26/$B$26*100,"") | L26: =IFERROR(F26/$B$26*100,"")
A27: Indretning af lejede lokaler | B27: ='balance_raw_45937712'!$B$6 | C27: ='balance_raw_45937712'!$C$6 | D27: ='balance_raw_45937712'!$D$6 | E27: ='balance_raw_45937712'!$E$6 | F27: ='balance_raw_45937712'!$F$6 | H27: =IFERROR(B27/$B$27*100,"") | I27: =IFERROR(C27/$B$27*100,"") | J27: =IFERROR(D27/$B$27*100,"") | K27: =IFERROR(E27/$B$27*100,"") | L27: =IFERROR(F27/$B$27*100,"")
A28: Forudbetaling og anlægsaktiver under opførelse | B28: ='balance_raw_45937712'!$B$7 | C28: ='balance_raw_45937712'!$C$7 | D28: ='balance_raw_45937712'!$D$7 | E28: ='balance_raw_45937712'!$E$7 | F28: ='balance_raw_45937712'!$F$7 | H28: =IFERROR(B28/$B$28*100,"") | I28: =IFERROR(C28/$B$28*100,"") | J28: =IFERROR(D28/$B$28*100,"") | K28: =IFERROR(E28/$B$28*100,"") | L28: =IFERROR(F28/$B$28*100,"")
A29: Materielle anlægsaktiver | B29: ='balance_raw_45937712'!$B$8 | C29: ='balance_raw_45937712'!$C$8 | D29: ='balance_raw_45937712'!$D$8 | E29: ='balance_raw_45937712'!$E$8 | F29: ='balance_raw_45937712'!$F$8 | H29: =IFERROR(B29/$B$29*100,"") | I29: =IFERROR(C29/$B$29*100,"") | J29: =IFERROR(D29/$B$29*100,"") | K29: =IFERROR(E29/$B$29*100,"") | L29: =IFERROR(F29/$B$29*100,"")
A30: Kapitalandele, dattervirksomheder | B30: ='balance_raw_45937712'!$B$9 | C30: ='balance_raw_45937712'!$C$9 | D30: ='balance_raw_45937712'!$D$9 | E30: ='balance_raw_45937712'!$E$9 | F30: ='balance_raw_45937712'!$F$9 | H30: =IFERROR(B30/$B$30*100,"") | I30: =IFERROR(C30/$B$30*100,"") | J30: =IFERROR(D30/$B$30*100,"") | K30: =IFERROR(E30/$B$30*100,"") | L30: =IFERROR(F30/$B$30*100,"")
A31: Deposita | B31: ='balance_raw_45937712'!$B$10 | C31: ='balance_raw_45937712'!$C$10 | D31: ='balance_raw_45937712'!$D$10 | E31: ='balance_raw_45937712'!$E$10 | F31: ='balance_raw_45937712'!$F$10 | H31: =IFERROR(B31/$B$31*100,"") | I31: =IFERROR(C31/$B$31*100,"") | J31: =IFERROR(D31/$B$31*100,"") | K31: =IFERROR(E31/$B$31*100,"") | L31: =IFERROR(F31/$B$31*100,"")
A32: Finansielle anlægsaktiver | B32: ='balance_raw_45937712'!$B$11 | C32: ='balance_raw_45937712'!$C$11 | D32: ='balance_raw_45937712'!$D$11 | E32: ='balance_raw_45937712'!$E$11 | F32: ='balance_raw_45937712'!$F$11 | H32: =IFERROR(B32/$B$32*100,"") | I32: =IFERROR(C32/$B$32*100,"") | J32: =IFERROR(D32/$B$32*100,"") | K32: =IFERROR(E32/$B$32*100,"") | L32: =IFERROR(F32/$B$32*100,"")
A33: Anlægsaktiver | B33: ='balance_raw_45937712'!$B$12 | C33: ='balance_raw_45937712'!$C$12 | D33: ='balance_raw_45937712'!$D$12 | E33: ='balance_raw_45937712'!$E$12 | F33: ='balance_raw_45937712'!$F$12 | H33: =IFERROR(B33/$B$33*100,"") | I33: =IFERROR(C33/$B$33*100,"") | J33: =IFERROR(D33/$B$33*100,"") | K33: =IFERROR(E33/$B$33*100,"") | L33: =IFERROR(F33/$B$33*100,"")
A34: Råvarer og hjælpematerialer | B34: ='balance_raw_45937712'!$B$13 | C34: ='balance_raw_45937712'!$C$13 | D34: ='balance_raw_45937712'!$D$13 | E34: ='balance_raw_45937712'!$E$13 | F34: ='balance_raw_45937712'!$F$13 | H34: =IFERROR(B34/$B$34*100,"") | I34: =IFERROR(C34/$B$34*100,"") | J34: =IFERROR(D34/$B$34*100,"") | K34: =IFERROR(E34/$B$34*100,"") | L34: =IFERROR(F34/$B$34*100,"")
A35: Varer under fremstilling | B35: ='balance_raw_45937712'!$B$14 | C35: ='balance_raw_45937712'!$C$14 | D35: ='balance_raw_45937712'!$D$14 | E35: ='balance_raw_45937712'!$E$14 | F35: ='balance_raw_45937712'!$F$14 | H35: =IFERROR(B35/$B$35*100,"") | I35: =IFERROR(C35/$B$35*100,"") | J35: =IFERROR(D35/$B$35*100,"") | K35: =IFERROR(E35/$B$35*100,"") | L35: =IFERROR(F35/$B$35*100,"")
A36: Færdigvarer og handelsvarer | B36: ='balance_raw_45937712'!$B$15 | C36: ='balance_raw_45937712'!$C$15 | D36: ='balance_raw_45937712'!$D$15 | E36: ='balance_raw_45937712'!$E$15 | F36: ='balance_raw_45937712'!$F$15 | H36: =IFERROR(B36/$B$36*100,"") | I36: =IFERROR(C36/$B$36*100,"") | J36: =IFERROR(D36/$B$36*100,"") | K36: =IFERROR(E36/$B$36*100,"") | L36: =IFERROR(F36/$B$36*100,"")
A37: Varebeholdninger | B37: ='balance_raw_45937712'!$B$16 | C37: ='balance_raw_45937712'!$C$16 | D37: ='balance_raw_45937712'!$D$16 | E37: ='balance_raw_45937712'!$E$16 | F37: ='balance_raw_45937712'!$F$16 | H37: =IFERROR(B37/$B$37*100,"") | I37: =IFERROR(C37/$B$37*100,"") | J37: =IFERROR(D37/$B$37*100,"") | K37: =IFERROR(E37/$B$37*100,"") | L37: =IFERROR(F37/$B$37*100,"")
A38: Tilgodehavender fra salg og tjenesteydelser | B38: ='balance_raw_45937712'!$B$17 | C38: ='balance_raw_45937712'!$C$17 | D38: ='balance_raw_45937712'!$D$17 | E38: ='balance_raw_45937712'!$E$17 | F38: ='balance_raw_45937712'!$F$17 | H38: =IFERROR(B38/$B$38*100,"") | I38: =IFERROR(C38/$B$38*100,"") | J38: =IFERROR(D38/$B$38*100,"") | K38: =IFERROR(E38/$B$38*100,"") | L38: =IFERROR(F38/$B$38*100,"")
A39: Tilgodehavender hos tilknyttede virksomheder | B39: ='balance_raw_45937712'!$B$18 | C39: ='balance_raw_45937712'!$C$18 | D39: ='balance_raw_45937712'!$D$18 | E39: ='balance_raw_45937712'!$E$18 | F39: ='balance_raw_45937712'!$F$18 | H39: =IFERROR(B39/$B$39*100,"") | I39: =IFERROR(C39/$B$39*100,"") | J39: =IFERROR(D39/$B$39*100,"") | K39: =IFERROR(E39/$B$39*100,"") | L39: =IFERROR(F39/$B$39*100,"")
A40: Andre tilgodehavender | B40: ='balance_raw_45937712'!$B$19 | C40: ='balance_raw_45937712'!$C$19 | D40: ='balance_raw_45937712'!$D$19 | E40: ='balance_raw_45937712'!$E$19 | F40: ='balance_raw_45937712'!$F$19 | H40: =IFERROR(B40/$B$40*100,"") | I40: =IFERROR(C40/$B$40*100,"") | J40: =IFERROR(D40/$B$40*100,"") | K40: =IFERROR(E40/$B$40*100,"") | L40: =IFERROR(F40/$B$40*100,"")
A41: Periodeafgrænsningsposter (aktiver) | B41: ='balance_raw_45937712'!$B$20 | C41: ='balance_raw_45937712'!$C$20 | D41: ='balance_raw_45937712'!$D$20 | E41: ='balance_raw_45937712'!$E$20 | F41: ='balance_raw_45937712'!$F$20 | H41: =IFERROR(B41/$B$41*100,"") | I41: =IFERROR(C41/$B$41*100,"") | J41: =IFERROR(D41/$B$41*100,"") | K41: =IFERROR(E41/$B$41*100,"") | L41: =IFERROR(F41/$B$41*100,"")
...

Sheet res_raw_45937712
A1: A/S Læsø Fiskeindustri (CVR 45937712) — Resultatopgørelse & nøgleoplysninger (t.kr.) | B1: 2021 | C1: 2022 | D1: 2023 | E1: 2024 | F1: 2025
A2: Nettoomsætning | B2: 309763 | C2: 349842 | D2: 326379 | E2: 331820 | F2: 279834
A3: Andre driftsindtægter | B3: 2826 | C3: 1780 | D3: 2189 | E3: 2321 | F3: 2350
A4: Vareforbrug | B4: 214876 | C4: 231995 | D4: 214745 | E4: 221589 | F4: 201480
A5: Andre eksterne omkostninger | B5: 42804 | C5: 53682 | D5: 53891 | E5: 56442 | F5: 38091
A6: Bruttoresultat | B6: 54908 | C6: 65945 | D6: 59932 | E6: 56111 | F6: 42613
A7: Personaleomkostninger | B7: 45961 | C7: 53171 | D7: 59001 | E7: 59720 | F7: 41187
A8: Resultat før afskrivninger
A9: Af- og nedskrivninger | B9: 5805 | C9: 5031 | D9: 4006 | E9: 3817 | F9: 3143
A10: Andre driftsomkostninger | B10: 0 | C10: 0 | D10: 194 | E10: 0 | F10: 2400
A11: Resultat af primær drift | B11: 3143 | C11: 7743 | D11: -3269 | E11: -7426 | F11: -4118
A12: Indtægter af kapitalandele, dattervirksomheder | B12: 1956 | C12: 3934 | D12: 2419 | E12: 0 | F12: -12784
A13: Finansielle indtægter | B13: 2120 | C13: 222 | D13: 739 | E13: 205 | F13: 147
A14: Finansielle omkostninger | B14: 3373 | C14: 3480 | D14: 4935 | E14: 8848 | F14: 3376
A15: Finansielle poster, netto
A16: Resultat før skat | B16: 3874 | C16: 8434 | D16: -4889 | E16: -13852 | F16: -16848
A17: Skat af årets resultat | B17: 337 | C17: 986 | D17: 794 | E17: -7366 | F17: -1592
A18: Årets resultat | B18: 3537 | C18: 7448 | D18: -5683 | E18: -6486 | F18: -15256
A19: Gns. antal medarbejdere | B19: 114 | C19: 136 | D19: 139 | E19: 132 | F19: 79
A20: Investering i materielle anlægsaktiver | B20: -2553 | C20: -4888 | D20: -6403 | E20: -3957 | F20: -1186

Sheet balance_raw_45937712
A1: A/S Læsø Fiskeindustri (CVR 45937712) — Balance (t.kr.) | B1: 2021 | C1: 2022 | D1: 2023 | E1: 2024 | F1: 2025
A2: Immaterielle anlægsaktiver | E2: 6360 | F2: 5842
A3: Grunde og bygninger | B3: 14970 | C3: 14438 | D3: 14707 | E3: 14385 | F3: 10156
A4: Produktionsanlæg og maskiner | B4: 10489 | C4: 9204 | D4: 8104 | E4: 8759 | F4: 5019
A5: Driftsmateriel og inventar | B5: 342 | C5: 1236 | D5: 1167 | E5: 1523 | F5: 1061
A6: Indretning af lejede lokaler
A7: Forudbetaling og anlægsaktiver under opførelse | B7: 1027 | C7: 519 | D7: 5256
A8: Materielle anlægsaktiver | B8: 26829 | C8: 25396 | D8: 29234 | E8: 24667 | F8: 16237
A9: Kapitalandele, dattervirksomheder | B9: 3582 | C9: 0 | D9: 0 | E9: 6981 | F9: 0
A10: Deposita | B10: 2850 | C10: 2216 | D10: 2128 | E10: 2235 | F10: 1532
A11: Finansielle anlægsaktiver | B11: 6533 | C11: 9794 | D11: 12124 | E11: 9277 | F11: 13857
A12: Anlægsaktiver | B12: 33362 | C12: 35190 | D12: 41358 | E12: 40304 | F12: 35936
A13: Råvarer og hjælpematerialer | B13: 27194 | C13: 22760 | D13: 24346 | E13: 63701 | F13: 32665
A14: Varer under fremstilling
A15: Færdigvarer og handelsvarer | B15: 14957 | C15: 13427 | D15: 37535 | E15: 49567 | F15: 20728
A16: Varebeholdninger | B16: 42151 | C16: 36186 | D16: 61882 | E16: 113268 | F16: 53393
A17: Tilgodehavender fra salg og tjenesteydelser | B17: 64461 | C17: 49784 | D17: 50294 | E17: 49216 | F17: 40997
A18: Tilgodehavender hos tilknyttede virksomheder | B18: 0 | C18: 0 | D18: 0
A19: Andre tilgodehavender | B19: 3636 | C19: 3166 | D19: 5028 | E19: 4280 | F19: 16326
A20: Periodeafgrænsningsposter (aktiver) | B20: 396 | C20: 297 | D20: 318 | E20: 262 | F20: 235
A21: Udskudt skatteaktiv | F21: 1306
A22: Tilgodehavende skat hos tilknyttede virksomheder
A23: Kortfristede skattetilgodehavender | B23: 815 | C23: 546 | D23: 700 | E23: 0
A24: Tilgodehavender | B24: 69308 | C24: 53793 | D24: 56340 | E24: 53758 | F24: 76477
A25: Værdipapirer
A26: Likvide beholdninger | B26: 2571 | C26: 5534 | D26: 1500 | E26: 1345 | F26: 12
A27: Omsætningsaktiver | B27: 114030 | C27: 95512 | D27: 119721 | E27: 168371 | F27: 129882
A28: Aktiver | B28: 147393 | C28: 130703 | D28: 161080 | E28: 208675 | F28: 165818
A29: Selskabskapital | B29: 15600 | C29: 15600 | D29: 15600 | E29: 15600 | F29: 15600
A30: Reserve for nettoopskrivning (indre værdis metode) | B30: 3082 | C30: 7016 | D30: 9435 | E30: 6481
A31: Reserve for udviklingsomkostninger
A32: Reserve for sikringstransaktioner | D32: 0
A33: Andre reserver
A34: Overført resultat | B34: 26464 | C34: 28073 | D34: 20653 | E34: 16336 | F34: 8091
A35: Egenkapital i alt | B35: 46507 | C35: 53366 | D35: 45688 | E35: 38417 | F35: 23691
A36: Hensættelse til udskudt skat | B36: 5813 | C36: 6858 | D36: 7653 | E36: 287 | F36: 0
A37: Hensatte forpligtelser | B37: 5813 | C37: 6858 | D37: 7653 | E37: 287 | F37: 0
A38: Ansvarlig lånekapital (langfristet)
A39: Langfristede lån | B39: 2344 | C39: 1462 | D39: 0 | E39: 20936 | F39: 17645
A40: Leasingforpligtelser (langfristet) | B40: 254 | C40: 0
...

Sheet pengestrom_raw_45937712
A1: A/S Læsø Fiskeindustri (CVR 45937712) — Pengestrømsopgørelse (t.kr.) | B1: 2021 | C1: 2022 | D1: 2023 | E1: 2024 | F1: 2025
A2: Pengestrømme fra driftsaktivitet | B2: 10886 | C2: 24491 | D2: -36104 | E2: -40770 | F2: -2548
A3: Pengestrømme fra investeringsaktivitet | B3: -864 | C3: -4133 | D3: -6255 | E3: -210 | F3: 5409
A4: Pengestrømme fra finansieringsaktivitet | B4: -2963 | C4: -17396 | D4: 38325 | E4: 40826 | F4: -2863
A5: Årets pengestrøm

Sheet Simpel_arts
A1: A/S Læsø Fiskeindustri (CVR 45937712) — Regnskabs- og nøgletal (CVR: 45937712) — artsopdelt
A3: Beløb i 1.000 kr. | B3: 2025 | C3: 2024 | D3: 2023 | F3: Note / XBRL-felt
A4: Uddrag af resultatopgørelse
A5: Nettoomsætning | B5: ='res_raw_45937712'!$F$2 | C5: ='res_raw_45937712'!$E$2 | D5: ='res_raw_45937712'!$D$2 | F5: fsa:Revenue
A6: Andre driftsindtægter | B6: ='res_raw_45937712'!$F$3 | C6: ='res_raw_45937712'!$E$3 | D6: ='res_raw_45937712'!$D$3 | F6: fsa:OtherOperatingIncome. Indtægter fra sekundære aktiviteter (huslejeindtægter, avance ved salg af anlæg mv.).
A7: Vareforbrug | B7: =-'res_raw_45937712'!$F$4 | C7: =-'res_raw_45937712'!$E$4 | D7: =-'res_raw_45937712'!$D$4 | F7: fsa:CostOfSales (vises negativt for korrekt SUM-formel).
A8: Andre eksterne omk. mv. | B8: =-'res_raw_45937712'!$F$5 | C8: =-'res_raw_45937712'!$E$5 | D8: =-'res_raw_45937712'!$D$5 | F8: fsa:OtherExternalExpenses (vises negativt). Husleje, energi, kontorhold mv.
A9: Bruttofortjeneste | B9: =IF(ABS((SUM(B5:B8))-'res_raw_45937712'!$F$6)<=2,SUM(B5:B8),'res_raw_45937712'!$F$6) | C9: =IF(ABS((SUM(C5:C8))-'res_raw_45937712'!$E$6)<=2,SUM(C5:C8),'res_raw_45937712'!$E$6) | D9: =IF(ABS((SUM(D5:D8))-'res_raw_45937712'!$D$6)<=2,SUM(D5:D8),'res_raw_45937712'!$D$6) | F9: Beregnet: Nettoomsætning + Andre driftsindt. − Vareforbrug − Andre ext. omk. Er komponenterne ikke indberettet, vises rapporteret bruttoresultat (fsa:GrossResult) direkte.
A10: Personaleomkostninger | B10: =-'res_raw_45937712'!$F$7 | C10: =-'res_raw_45937712'!$E$7 | D10: =-'res_raw_45937712'!$D$7 | F10: fsa:EmployeeBenefitsExpense (vises negativt). Lønninger, pension, sociale ydelser.
A11: Af- og nedskrivninger | B11: =-'res_raw_45937712'!$F$9 | C11: =-'res_raw_45937712'!$E$9 | D11: =-'res_raw_45937712'!$D$9 | F11: fsa:Depreciation (vises negativt). Af- og nedskrivninger på materielle og immaterielle anlægsaktiver.
A12: Andre driftsomkostninger | B12: =-'res_raw_45937712'!$F$10 | C12: =-'res_raw_45937712'!$E$10 | D12: =-'res_raw_45937712'!$D$10 | F12: fsa:OtherOperatingExpenses (vises negativt). Typisk 0 eller meget lille post.
A13: Resultat af primær drift | B13: =IF(ABS((SUM(B9:B12))-'res_raw_45937712'!$F$11)<=2,SUM(B9:B12),'res_raw_45937712'!$F$11) | C13: =IF(ABS((SUM(C9:C12))-'res_raw_45937712'!$E$11)<=2,SUM(C9:C12),'res_raw_45937712'!$E$11) | D13: =IF(ABS((SUM(D9:D12))-'res_raw_45937712'!$D$11)<=2,SUM(D9:D12),'res_raw_45937712'!$D$11) | F13: Beregnet: Bruttofortjeneste − Personaleomk. − Af- og nedskrivninger − Andre driftsomk. EBIT.
A14: Finansielle indtægter mv. | B14: =N('res_raw_45937712'!$F$12)+N('res_raw_45937712'!$F$13) | C14: =N('res_raw_45937712'!$E$12)+N('res_raw_45937712'!$E$13) | D14: =N('res_raw_45937712'!$D$12)+N('res_raw_45937712'!$D$13) | F14: fsa:IncomeFromSubsidiaries + fsa:OtherFinanceIncome.
A15: Finansielle omkostninger mv. | B15: =-'res_raw_45937712'!$F$14 | C15: =-'res_raw_45937712'!$E$14 | D15: =-'res_raw_45937712'!$D$14 | F15: fsa:OtherFinanceExpenses (vises negativt). Renteomkostninger, kurstab mv.
A16: Resultat før skat | B16: =IF(ABS((SUM(B13:B15))-'res_raw_45937712'!$F$16)<=2,SUM(B13:B15),'res_raw_45937712'!$F$16) | C16: =IF(ABS((SUM(C13:C15))-'res_raw_45937712'!$E$16)<=2,SUM(C13:C15),'res_raw_45937712'!$E$16) | D16: =IF(ABS((SUM(D13:D15))-'res_raw_45937712'!$D$16)<=2,SUM(D13:D15),'res_raw_45937712'!$D$16) | F16: Beregnet: EBIT + Fin. indtægter + Fin. omk. EBT.
A18: Uddrag af balance
A19: Anlægsaktiver | B19: ='balance_raw_45937712'!$F$12 | C19: ='balance_raw_45937712'!$E$12 | D19: ='balance_raw_45937712'!$D$12 | F19: fsa:NoncurrentAssets. Materielle, immaterielle og finansielle anlægsaktiver.
A20: Omsætningsaktiver | B20: ='balance_raw_45937712'!$F$27 | C20: ='balance_raw_45937712'!$E$27 | D20: ='balance_raw_45937712'!$D$27 | F20: fsa:CurrentAssets. Varebeholdninger, tilgodehavender, likvider.
A21: Aktiver i alt | B21: =SUM(B19:B20) | C21: =SUM(C19:C20) | D21: =SUM(D19:D20) | F21: Beregnet: Anlægsaktiver + Omsætningsaktiver. Bør matche fsa:Assets.
A23: Egenkapital | B23: ='balance_raw_45937712'!$F$35 | C23: ='balance_raw_45937712'!$E$35 | D23: ='balance_raw_45937712'!$D$35 | F23: fsa:Equity. Selskabskapital, overført resultat, reserver.
A24: Forpligtelser | B24: ='balance_raw_45937712'!$F$56-'balance_raw_45937712'!$F$35 | C24: ='balance_raw_45937712'!$E$56-'balance_raw_45937712'!$E$35 | D24: ='balance_raw_45937712'!$D$56-'balance_raw_45937712'!$D$35 | F24: Beregnet: Passiver (fsa:LiabilitiesAndEquity) − Egenkapital. Hensættelser + kort- og langfristet gæld.
A25: Passiver i alt | B25: =SUM(B23:B24) | C25: =SUM(C23:C24) | D25: =SUM(D23:D24) | F25: Beregnet: Egenkapital + Forpligtelser. Bør matche Aktiver i alt.
A27: Udvalgte balanceposter
A28: Varebeholdninger | B28: ='balance_raw_45937712'!$F$16 | C28: ='balance_raw_45937712'!$E$16 | D28: ='balance_raw_45937712'!$D$16 | F28: fsa:Inventories (eller fsa:ManufacturedGoodsAndGoodsForResale hvis total mangler).
A29: Tilgodehavender fra salg | B29: ='balance_raw_45937712'!$F$17 | C29: ='balance_raw_45937712'!$E$17 | D29: ='balance_raw_45937712'!$D$17 | F29: fsa:ShorttermTradeReceivables. Kortfristede tilgodehavender fra kunder.
A30: Kortfristede gældsforpligtelser | B30: ='balance_raw_45937712'!$F$54 | C30: ='balance_raw_45937712'!$E$54 | D30: ='balance_raw_45937712'!$D$54 | F30: fsa:ShorttermLiabilitiesOtherThanProvisions. Gæld der forfalder inden for 1 år.
A32: Rentabilitet
A33: Afkastningsgrad, % | B33: =IFERROR((B13+B14)/B21*100,"") | C33: =IFERROR((C13+C14)/C21*100,"") | D33: =IFERROR((D13+D14)/D21*100,"")
A34: Overskudsgrad, % | B34: =IFERROR((B13+B14)/B5*100,"") | C34: =IFERROR((C13+C14)/C5*100,"") | D34: =IFERROR((D13+D14)/D5*100,"")
A35: Aktivernes omsætningshastighed, gange | B35: =IFERROR(B5/B21,"") | C35: =IFERROR(C5/C21,"") | D35: =IFERROR(D5/D21,"")
A36: Gældsrente, % | B36: =IFERROR(-B15*100/B24,"") | C36: =IFERROR(-C15*100/C24,"") | D36: =IFERROR(-D15*100/D24,"")
A37: Egenkapitalens forrentning, % | B37: =IFERROR(B16/B23*100,"") | C37: =IFERROR(C16/C23*100,"") | D37: =IFERROR(D16/D23*100,"")
A38: Gearing, gange | B38: =IFERROR(B24/B23,"") | C38: =IFERROR(C24/C23,"") | D38: =IFERROR(D24/D23,"")
A40: Indekstal for indtjeningsevne (2023=100)
A41: Nettoomsætning | B41: =IFERROR(B5/$D5*100,"") | C41: =IFERROR(C5/$D5*100,"") | D41: =IFERROR(D5/$D5*100,"")
A42: Vareforbrug | B42: =IFERROR(B7/$D7*100,"") | C42: =IFERROR(C7/$D7*100,"") | D42: =IFERROR(D7/$D7*100,"")
A43: Andre eksterne omk. | B43: =IFERROR(B8/$D8*100,"") | C43: =IFERROR(C8/$D8*100,"") | D43: =IFERROR(D8/$D8*100,"")
A44: Personaleomkostninger | B44: =IFERROR(B10/$D10*100,"") | C44: =IFERROR(C10/$D10*100,"") | D44: =IFERROR(D10/$D10*100,"")
A45: Af- og nedskrivninger | B45: =IFERROR(B11/$D11*100,"") | C45: =IFERROR(C11/$D11*100,"") | D45: =IFERROR(D11/$D11*100,"")
A47: Indekstal for kapitaltilpasningsevne (2023=100)
...

Sheet Noter_info
A1: A/S Læsø Fiskeindustri (CVR 45937712) — Ukendte XBRL-felter — disse er noter og ikke en del af hoved-regnskabet
A2: Kategori | B2: Dansk navn | C2: XBRL feltnavn | D2: 2021 t.kr. | E2: 2022 t.kr. | F2: 2023 t.kr. | G2: 2024 t.kr. | H2: 2025 t.kr. | I2: Forklaring
A3: Øvrige (ukendt) | B3: fsa:HolidayAllowanceLiabilitiesLongterm | C3: fsa:HolidayAllowanceLiabilitiesLongterm | F3: 1300 | G3: 1314 | H3: 1362 | I3: Ingen forklaring tilgængelig.
A4: Øvrige (ukendt) | B4: fsa:IncomeFromOtherLongtermInvestmentsAndReceivables | C4: fsa:IncomeFromOtherLongtermInvestmentsAndReceivables | D4: 28 | E4: 14 | F4: 156 | G4: 170 | H4: 143 | I4: Ingen forklaring tilgængelig.
A5: Øvrige (ukendt) | B5: fsa:LongtermDeferredIncome | C5: fsa:LongtermDeferredIncome | F5: 1224 | G5: 1936 | I5: Ingen forklaring tilgængelig.
A6: Øvrige (ukendt) | B6: fsa:NominalValueOfTreasurySharesHold | C6: fsa:NominalValueOfTreasurySharesHold | D6: 1030 | E6: 1130 | F6: 1096 | G6: 1315 | H6: 2080 | I6: Ingen forklaring tilgængelig.
A7: Øvrige (ukendt) | B7: fsa:PercentageOfContributedCapitalOfTreasurySharesHold | C7: fsa:PercentageOfContributedCapitalOfTreasurySharesHold | D7: 0 | E7: 0 | F7: 0 | G7: 0 | H7: 0 | I7: Ingen forklaring tilgængelig.
A8: Øvrige (ukendt) | B8: fsa:ProvisionsForInvestmentsInGroupEnterprises | C8: fsa:ProvisionsForInvestmentsInGroupEnterprises | F8: 0 | G8: 0 | H8: 0 | I8: Ingen forklaring tilgængelig.
A9: Øvrige (ukendt) | B9: fsa:SaleOfOtherCompany | C9: fsa:SaleOfOtherCompany | H9: 5999 | I9: Ingen forklaring tilgængelig.
A10: Øvrige (ukendt) | B10: fsa:ShorttermPayablesToAssociates | C10: fsa:ShorttermPayablesToAssociates | H10: 8796 | I10: Ingen forklaring tilgængelig.
