Workbook

Sheet Overblik_57068515
A1: Roblon A/S (CVR 57068515) — Regnskabsanalyse – Resultatopgørelse & Balance (t.kr.) · Revision · Regnskabsår 1/11–31/10 (forskudt)
H2: Indekstal (2021=100)
A3: Resultatopgørelse t.kr. | B3: 2021 | C3: 2022 | D3: 2023 | E3: 2024 | F3: 2025 | H3: 2021 | I3: 2022 | J3: 2023 | K3: 2024 | L3: 2025
A4: Nettoomsætning | B4: ='res_raw_57068515'!$B$2 | C4: ='res_raw_57068515'!$C$2 | D4: ='res_raw_57068515'!$D$2 | E4: ='res_raw_57068515'!$E$2 | F4: ='res_raw_57068515'!$F$2 | H4: =IFERROR(B4/$B$4*100,"") | I4: =IFERROR(C4/$B$4*100,"") | J4: =IFERROR(D4/$B$4*100,"") | K4: =IFERROR(E4/$B$4*100,"") | L4: =IFERROR(F4/$B$4*100,"")
A5: Produktionsomkostninger | B5: ='res_raw_57068515'!$B$3 | C5: ='res_raw_57068515'!$C$3 | D5: ='res_raw_57068515'!$D$3 | E5: ='res_raw_57068515'!$E$3 | F5: ='res_raw_57068515'!$F$3 | H5: =IFERROR(B5/$B$5*100,"") | I5: =IFERROR(C5/$B$5*100,"") | J5: =IFERROR(D5/$B$5*100,"") | K5: =IFERROR(E5/$B$5*100,"") | L5: =IFERROR(F5/$B$5*100,"")
A6: Bruttoresultat | B6: ='res_raw_57068515'!$B$4 | C6: ='res_raw_57068515'!$C$4 | D6: ='res_raw_57068515'!$D$4 | E6: ='res_raw_57068515'!$E$4 | F6: ='res_raw_57068515'!$F$4 | H6: =IFERROR(B6/$B$6*100,"") | I6: =IFERROR(C6/$B$6*100,"") | J6: =IFERROR(D6/$B$6*100,"") | K6: =IFERROR(E6/$B$6*100,"") | L6: =IFERROR(F6/$B$6*100,"")
A7: Udviklingsomkostninger | B7: ='res_raw_57068515'!$B$5 | C7: ='res_raw_57068515'!$C$5 | D7: ='res_raw_57068515'!$D$5 | E7: ='res_raw_57068515'!$E$5 | F7: ='res_raw_57068515'!$F$5 | H7: =IFERROR(B7/$B$7*100,"") | I7: =IFERROR(C7/$B$7*100,"") | J7: =IFERROR(D7/$B$7*100,"") | K7: =IFERROR(E7/$B$7*100,"") | L7: =IFERROR(F7/$B$7*100,"")
A8: Salgs- og distributionsomkostninger | B8: ='res_raw_57068515'!$B$6 | C8: ='res_raw_57068515'!$C$6 | D8: ='res_raw_57068515'!$D$6 | E8: ='res_raw_57068515'!$E$6 | F8: ='res_raw_57068515'!$F$6 | H8: =IFERROR(B8/$B$8*100,"") | I8: =IFERROR(C8/$B$8*100,"") | J8: =IFERROR(D8/$B$8*100,"") | K8: =IFERROR(E8/$B$8*100,"") | L8: =IFERROR(F8/$B$8*100,"")
A9: Administrationsomkostninger | B9: ='res_raw_57068515'!$B$7 | C9: ='res_raw_57068515'!$C$7 | D9: ='res_raw_57068515'!$D$7 | E9: ='res_raw_57068515'!$E$7 | F9: ='res_raw_57068515'!$F$7 | H9: =IFERROR(B9/$B$9*100,"") | I9: =IFERROR(C9/$B$9*100,"") | J9: =IFERROR(D9/$B$9*100,"") | K9: =IFERROR(E9/$B$9*100,"") | L9: =IFERROR(F9/$B$9*100,"")
A10: Andre driftsindtægter | B10: ='res_raw_57068515'!$B$8 | C10: ='res_raw_57068515'!$C$8 | D10: ='res_raw_57068515'!$D$8 | E10: ='res_raw_57068515'!$E$8 | F10: ='res_raw_57068515'!$F$8 | H10: =IFERROR(B10/$B$10*100,"") | I10: =IFERROR(C10/$B$10*100,"") | J10: =IFERROR(D10/$B$10*100,"") | K10: =IFERROR(E10/$B$10*100,"") | L10: =IFERROR(F10/$B$10*100,"")
A11: Andre driftsomkostninger | B11: ='res_raw_57068515'!$B$9 | C11: ='res_raw_57068515'!$C$9 | D11: ='res_raw_57068515'!$D$9 | E11: ='res_raw_57068515'!$E$9 | F11: ='res_raw_57068515'!$F$9 | H11: =IFERROR(B11/$B$11*100,"") | I11: =IFERROR(C11/$B$11*100,"") | J11: =IFERROR(D11/$B$11*100,"") | K11: =IFERROR(E11/$B$11*100,"") | L11: =IFERROR(F11/$B$11*100,"")
A12: Andre eksterne omkostninger | B12: ='res_raw_57068515'!$B$10 | C12: ='res_raw_57068515'!$C$10 | D12: ='res_raw_57068515'!$D$10 | E12: ='res_raw_57068515'!$E$10 | F12: ='res_raw_57068515'!$F$10 | H12: =IFERROR(B12/$B$12*100,"") | I12: =IFERROR(C12/$B$12*100,"") | J12: =IFERROR(D12/$B$12*100,"") | K12: =IFERROR(E12/$B$12*100,"") | L12: =IFERROR(F12/$B$12*100,"")
A13: Personaleomkostninger | B13: ='res_raw_57068515'!$B$11 | C13: ='res_raw_57068515'!$C$11 | D13: ='res_raw_57068515'!$D$11 | E13: ='res_raw_57068515'!$E$11 | F13: ='res_raw_57068515'!$F$11 | H13: =IFERROR(B13/$B$13*100,"") | I13: =IFERROR(C13/$B$13*100,"") | J13: =IFERROR(D13/$B$13*100,"") | K13: =IFERROR(E13/$B$13*100,"") | L13: =IFERROR(F13/$B$13*100,"")
A14: Af- og nedskrivninger | B14: ='res_raw_57068515'!$B$12 | C14: ='res_raw_57068515'!$C$12 | D14: ='res_raw_57068515'!$D$12 | E14: ='res_raw_57068515'!$E$12 | F14: ='res_raw_57068515'!$F$12 | H14: =IFERROR(B14/$B$14*100,"") | I14: =IFERROR(C14/$B$14*100,"") | J14: =IFERROR(D14/$B$14*100,"") | K14: =IFERROR(E14/$B$14*100,"") | L14: =IFERROR(F14/$B$14*100,"")
A15: Resultat af primær drift | B15: ='res_raw_57068515'!$B$13 | C15: ='res_raw_57068515'!$C$13 | D15: ='res_raw_57068515'!$D$13 | E15: ='res_raw_57068515'!$E$13 | F15: ='res_raw_57068515'!$F$13 | H15: =IFERROR(B15/$B$15*100,"") | I15: =IFERROR(C15/$B$15*100,"") | J15: =IFERROR(D15/$B$15*100,"") | K15: =IFERROR(E15/$B$15*100,"") | L15: =IFERROR(F15/$B$15*100,"")
A16: Indtægter af kapitalandele, dattervirksomheder | B16: ='res_raw_57068515'!$B$14 | C16: ='res_raw_57068515'!$C$14 | D16: ='res_raw_57068515'!$D$14 | E16: ='res_raw_57068515'!$E$14 | F16: ='res_raw_57068515'!$F$14 | H16: =IFERROR(B16/$B$16*100,"") | I16: =IFERROR(C16/$B$16*100,"") | J16: =IFERROR(D16/$B$16*100,"") | K16: =IFERROR(E16/$B$16*100,"") | L16: =IFERROR(F16/$B$16*100,"")
A17: Finansielle indtægter | B17: ='res_raw_57068515'!$B$15 | C17: ='res_raw_57068515'!$C$15 | D17: ='res_raw_57068515'!$D$15 | E17: ='res_raw_57068515'!$E$15 | F17: ='res_raw_57068515'!$F$15 | H17: =IFERROR(B17/$B$17*100,"") | I17: =IFERROR(C17/$B$17*100,"") | J17: =IFERROR(D17/$B$17*100,"") | K17: =IFERROR(E17/$B$17*100,"") | L17: =IFERROR(F17/$B$17*100,"")
A18: Finansielle omkostninger | B18: ='res_raw_57068515'!$B$16 | C18: ='res_raw_57068515'!$C$16 | D18: ='res_raw_57068515'!$D$16 | E18: ='res_raw_57068515'!$E$16 | F18: ='res_raw_57068515'!$F$16 | H18: =IFERROR(B18/$B$18*100,"") | I18: =IFERROR(C18/$B$18*100,"") | J18: =IFERROR(D18/$B$18*100,"") | K18: =IFERROR(E18/$B$18*100,"") | L18: =IFERROR(F18/$B$18*100,"")
A19: Finansielle poster, netto | B19: ='res_raw_57068515'!$B$17 | C19: ='res_raw_57068515'!$C$17 | D19: ='res_raw_57068515'!$D$17 | E19: ='res_raw_57068515'!$E$17 | F19: ='res_raw_57068515'!$F$17 | H19: =IFERROR(B19/$B$19*100,"") | I19: =IFERROR(C19/$B$19*100,"") | J19: =IFERROR(D19/$B$19*100,"") | K19: =IFERROR(E19/$B$19*100,"") | L19: =IFERROR(F19/$B$19*100,"")
A20: Resultat før skat | B20: ='res_raw_57068515'!$B$18 | C20: ='res_raw_57068515'!$C$18 | D20: ='res_raw_57068515'!$D$18 | E20: ='res_raw_57068515'!$E$18 | F20: ='res_raw_57068515'!$F$18 | H20: =IFERROR(B20/$B$20*100,"") | I20: =IFERROR(C20/$B$20*100,"") | J20: =IFERROR(D20/$B$20*100,"") | K20: =IFERROR(E20/$B$20*100,"") | L20: =IFERROR(F20/$B$20*100,"")
A21: Skat af årets resultat | B21: ='res_raw_57068515'!$B$19 | C21: ='res_raw_57068515'!$C$19 | D21: ='res_raw_57068515'!$D$19 | E21: ='res_raw_57068515'!$E$19 | F21: ='res_raw_57068515'!$F$19 | H21: =IFERROR(B21/$B$21*100,"") | I21: =IFERROR(C21/$B$21*100,"") | J21: =IFERROR(D21/$B$21*100,"") | K21: =IFERROR(E21/$B$21*100,"") | L21: =IFERROR(F21/$B$21*100,"")
A22: Årets resultat | B22: ='res_raw_57068515'!$B$20 | C22: ='res_raw_57068515'!$C$20 | D22: ='res_raw_57068515'!$D$20 | E22: ='res_raw_57068515'!$E$20 | F22: ='res_raw_57068515'!$F$20 | H22: =IFERROR(B22/$B$22*100,"") | I22: =IFERROR(C22/$B$22*100,"") | J22: =IFERROR(D22/$B$22*100,"") | K22: =IFERROR(E22/$B$22*100,"") | L22: =IFERROR(F22/$B$22*100,"")
A24: AKTIVER t.kr. | B24: 2021 | C24: 2022 | D24: 2023 | E24: 2024 | F24: 2025 | H24: 2021 | I24: 2022 | J24: 2023 | K24: 2024 | L24: 2025
A25: Udviklingsprojekter | B25: ='balance_raw_57068515'!$B$2 | C25: ='balance_raw_57068515'!$C$2 | D25: ='balance_raw_57068515'!$D$2 | E25: ='balance_raw_57068515'!$E$2 | F25: ='balance_raw_57068515'!$F$2 | H25: =IFERROR(B25/$B$25*100,"") | I25: =IFERROR(C25/$B$25*100,"") | J25: =IFERROR(D25/$B$25*100,"") | K25: =IFERROR(E25/$B$25*100,"") | L25: =IFERROR(F25/$B$25*100,"")
A26: Patenter, varemærker mv. | B26: ='balance_raw_57068515'!$B$3 | C26: ='balance_raw_57068515'!$C$3 | D26: ='balance_raw_57068515'!$D$3 | E26: ='balance_raw_57068515'!$E$3 | F26: ='balance_raw_57068515'!$F$3 | H26: =IFERROR(B26/$B$26*100,"") | I26: =IFERROR(C26/$B$26*100,"") | J26: =IFERROR(D26/$B$26*100,"") | K26: =IFERROR(E26/$B$26*100,"") | L26: =IFERROR(F26/$B$26*100,"")
A27: Goodwill | B27: ='balance_raw_57068515'!$B$4 | C27: ='balance_raw_57068515'!$C$4 | D27: ='balance_raw_57068515'!$D$4 | E27: ='balance_raw_57068515'!$E$4 | F27: ='balance_raw_57068515'!$F$4 | H27: =IFERROR(B27/$B$27*100,"") | I27: =IFERROR(C27/$B$27*100,"") | J27: =IFERROR(D27/$B$27*100,"") | K27: =IFERROR(E27/$B$27*100,"") | L27: =IFERROR(F27/$B$27*100,"")
A28: Immaterielle anlægsaktiver | B28: ='balance_raw_57068515'!$B$5 | C28: ='balance_raw_57068515'!$C$5 | D28: ='balance_raw_57068515'!$D$5 | E28: ='balance_raw_57068515'!$E$5 | F28: ='balance_raw_57068515'!$F$5 | H28: =IFERROR(B28/$B$28*100,"") | I28: =IFERROR(C28/$B$28*100,"") | J28: =IFERROR(D28/$B$28*100,"") | K28: =IFERROR(E28/$B$28*100,"") | L28: =IFERROR(F28/$B$28*100,"")
A29: Grunde og bygninger | B29: ='balance_raw_57068515'!$B$6 | C29: ='balance_raw_57068515'!$C$6 | D29: ='balance_raw_57068515'!$D$6 | E29: ='balance_raw_57068515'!$E$6 | F29: ='balance_raw_57068515'!$F$6 | H29: =IFERROR(B29/$B$29*100,"") | I29: =IFERROR(C29/$B$29*100,"") | J29: =IFERROR(D29/$B$29*100,"") | K29: =IFERROR(E29/$B$29*100,"") | L29: =IFERROR(F29/$B$29*100,"")
A30: Produktionsanlæg og maskiner | B30: ='balance_raw_57068515'!$B$7 | C30: ='balance_raw_57068515'!$C$7 | D30: ='balance_raw_57068515'!$D$7 | E30: ='balance_raw_57068515'!$E$7 | F30: ='balance_raw_57068515'!$F$7 | H30: =IFERROR(B30/$B$30*100,"") | I30: =IFERROR(C30/$B$30*100,"") | J30: =IFERROR(D30/$B$30*100,"") | K30: =IFERROR(E30/$B$30*100,"") | L30: =IFERROR(F30/$B$30*100,"")
A31: Driftsmateriel og inventar | B31: ='balance_raw_57068515'!$B$8 | C31: ='balance_raw_57068515'!$C$8 | D31: ='balance_raw_57068515'!$D$8 | E31: ='balance_raw_57068515'!$E$8 | F31: ='balance_raw_57068515'!$F$8 | H31: =IFERROR(B31/$B$31*100,"") | I31: =IFERROR(C31/$B$31*100,"") | J31: =IFERROR(D31/$B$31*100,"") | K31: =IFERROR(E31/$B$31*100,"") | L31: =IFERROR(F31/$B$31*100,"")
A32: Indretning af lejede lokaler | B32: ='balance_raw_57068515'!$B$9 | C32: ='balance_raw_57068515'!$C$9 | D32: ='balance_raw_57068515'!$D$9 | E32: ='balance_raw_57068515'!$E$9 | F32: ='balance_raw_57068515'!$F$9 | H32: =IFERROR(B32/$B$32*100,"") | I32: =IFERROR(C32/$B$32*100,"") | J32: =IFERROR(D32/$B$32*100,"") | K32: =IFERROR(E32/$B$32*100,"") | L32: =IFERROR(F32/$B$32*100,"")
A33: Forudbetaling og anlægsaktiver under opførelse | B33: ='balance_raw_57068515'!$B$10 | C33: ='balance_raw_57068515'!$C$10 | D33: ='balance_raw_57068515'!$D$10 | E33: ='balance_raw_57068515'!$E$10 | F33: ='balance_raw_57068515'!$F$10 | H33: =IFERROR(B33/$B$33*100,"") | I33: =IFERROR(C33/$B$33*100,"") | J33: =IFERROR(D33/$B$33*100,"") | K33: =IFERROR(E33/$B$33*100,"") | L33: =IFERROR(F33/$B$33*100,"")
A34: Materielle anlægsaktiver | B34: ='balance_raw_57068515'!$B$11 | C34: ='balance_raw_57068515'!$C$11 | D34: ='balance_raw_57068515'!$D$11 | E34: ='balance_raw_57068515'!$E$11 | F34: ='balance_raw_57068515'!$F$11 | H34: =IFERROR(B34/$B$34*100,"") | I34: =IFERROR(C34/$B$34*100,"") | J34: =IFERROR(D34/$B$34*100,"") | K34: =IFERROR(E34/$B$34*100,"") | L34: =IFERROR(F34/$B$34*100,"")
A35: Anlægsaktiver | B35: ='balance_raw_57068515'!$B$12 | C35: ='balance_raw_57068515'!$C$12 | D35: ='balance_raw_57068515'!$D$12 | E35: ='balance_raw_57068515'!$E$12 | F35: ='balance_raw_57068515'!$F$12 | H35: =IFERROR(B35/$B$35*100,"") | I35: =IFERROR(C35/$B$35*100,"") | J35: =IFERROR(D35/$B$35*100,"") | K35: =IFERROR(E35/$B$35*100,"") | L35: =IFERROR(F35/$B$35*100,"")
A36: Råvarer og hjælpematerialer | B36: ='balance_raw_57068515'!$B$13 | C36: ='balance_raw_57068515'!$C$13 | D36: ='balance_raw_57068515'!$D$13 | E36: ='balance_raw_57068515'!$E$13 | F36: ='balance_raw_57068515'!$F$13 | H36: =IFERROR(B36/$B$36*100,"") | I36: =IFERROR(C36/$B$36*100,"") | J36: =IFERROR(D36/$B$36*100,"") | K36: =IFERROR(E36/$B$36*100,"") | L36: =IFERROR(F36/$B$36*100,"")
A37: Varer under fremstilling | B37: ='balance_raw_57068515'!$B$14 | C37: ='balance_raw_57068515'!$C$14 | D37: ='balance_raw_57068515'!$D$14 | E37: ='balance_raw_57068515'!$E$14 | F37: ='balance_raw_57068515'!$F$14 | H37: =IFERROR(B37/$B$37*100,"") | I37: =IFERROR(C37/$B$37*100,"") | J37: =IFERROR(D37/$B$37*100,"") | K37: =IFERROR(E37/$B$37*100,"") | L37: =IFERROR(F37/$B$37*100,"")
A38: Færdigvarer og handelsvarer | B38: ='balance_raw_57068515'!$B$15 | C38: ='balance_raw_57068515'!$C$15 | D38: ='balance_raw_57068515'!$D$15 | E38: ='balance_raw_57068515'!$E$15 | F38: ='balance_raw_57068515'!$F$15 | H38: =IFERROR(B38/$B$38*100,"") | I38: =IFERROR(C38/$B$38*100,"") | J38: =IFERROR(D38/$B$38*100,"") | K38: =IFERROR(E38/$B$38*100,"") | L38: =IFERROR(F38/$B$38*100,"")
A39: Varebeholdninger | B39: ='balance_raw_57068515'!$B$16 | C39: ='balance_raw_57068515'!$C$16 | D39: ='balance_raw_57068515'!$D$16 | E39: ='balance_raw_57068515'!$E$16 | F39: ='balance_raw_57068515'!$F$16 | H39: =IFERROR(B39/$B$39*100,"") | I39: =IFERROR(C39/$B$39*100,"") | J39: =IFERROR(D39/$B$39*100,"") | K39: =IFERROR(E39/$B$39*100,"") | L39: =IFERROR(F39/$B$39*100,"")
A40: Tilgodehavender fra salg og tjenesteydelser | B40: ='balance_raw_57068515'!$B$17 | C40: ='balance_raw_57068515'!$C$17 | D40: ='balance_raw_57068515'!$D$17 | E40: ='balance_raw_57068515'!$E$17 | F40: ='balance_raw_57068515'!$F$17 | H40: =IFERROR(B40/$B$40*100,"") | I40: =IFERROR(C40/$B$40*100,"") | J40: =IFERROR(D40/$B$40*100,"") | K40: =IFERROR(E40/$B$40*100,"") | L40: =IFERROR(F40/$B$40*100,"")
A41: Tilgodehavender hos tilknyttede virksomheder | B41: ='balance_raw_57068515'!$B$18 | C41: ='balance_raw_57068515'!$C$18 | D41: ='balance_raw_57068515'!$D$18 | E41: ='balance_raw_57068515'!$E$18 | F41: ='balance_raw_57068515'!$F$18 | H41: =IFERROR(B41/$B$41*100,"") | I41: =IFERROR(C41/$B$41*100,"") | J41: =IFERROR(D41/$B$41*100,"") | K41: =IFERROR(E41/$B$41*100,"") | L41: =IFERROR(F41/$B$41*100,"")
...

Sheet res_raw_57068515
A1: Roblon A/S (CVR 57068515) — Resultatopgørelse & nøgleoplysninger (t.kr.) | B1: 2021 | C1: 2022 | D1: 2023 | E1: 2024 | F1: 2025
A2: Nettoomsætning | B2: 249883 | C2: 380859 | D2: 245015 | E2: 245440 | F2: 236892
A3: Produktionsomkostninger | B3: 133135 | C3: 199709 | D3: 117531 | E3: 96139 | F3: 90632
A4: Bruttoresultat | B4: 116748 | C4: 181150 | D4: 127484 | E4: 149301 | F4: 146260
A5: Udviklingsomkostninger
A6: Salgs- og distributionsomkostninger
A7: Administrationsomkostninger
A8: Andre driftsindtægter | B8: 1307 | C8: 1820 | D8: 717 | E8: 40 | F8: 1314
A9: Andre driftsomkostninger
A10: Andre eksterne omkostninger | B10: 33980 | C10: 38725 | D10: 24796 | E10: 22895 | F10: 26192
A11: Personaleomkostninger | B11: 98930 | C11: 123050 | D11: 79312 | E11: 82541 | F11: 77059
A12: Af- og nedskrivninger | B12: 20324 | C12: 27245 | D12: 17350 | E12: 15630 | F12: 13711
A13: Resultat af primær drift | B13: -32887 | C13: -9931 | D13: 1882 | E13: 5389 | F13: -9114
A14: Indtægter af kapitalandele, dattervirksomheder
A15: Finansielle indtægter | B15: 4345 | C15: 11251 | D15: 854 | E15: 57 | F15: 668
A16: Finansielle omkostninger | B16: 774 | C16: 1993 | D16: 4177 | E16: 2090 | F16: 844
A17: Finansielle poster, netto | B17: 3571 | C17: 9258 | D17: -3323 | E17: -2033 | F17: -176
A18: Resultat før skat | B18: -29316 | C18: -1353 | D18: 24552 | E18: 27218 | F18: 27525
A19: Skat af årets resultat | B19: -8535 | C19: 981 | D19: 4347 | E19: 6220 | F19: 6438
A20: Årets resultat | B20: -20781 | C20: -2334 | D20: 20205 | E20: 20998 | F20: 21087
A21: Gns. antal medarbejdere | B21: 191
A22: Investering i materielle anlægsaktiver | B22: 11144 | C22: 19115 | D22: 21196 | E22: 8423 | F22: 11761

Sheet balance_raw_57068515
A1: Roblon A/S (CVR 57068515) — Balance (t.kr.) | B1: 2021 | C1: 2022 | D1: 2023 | E1: 2024 | F1: 2025
A2: Udviklingsprojekter | B2: 7570 | C2: 6258 | D2: 5223 | E2: 3107 | F2: 1075
A3: Patenter, varemærker mv.
A4: Goodwill
A5: Immaterielle anlægsaktiver | B5: 25036 | C5: 23588 | D5: 15989 | E5: 6993 | F5: 3963
A6: Grunde og bygninger | B6: 17906 | C6: 60064 | D6: 48234 | E6: 50567 | F6: 54126
A7: Produktionsanlæg og maskiner | B7: 38719 | C7: 47692 | D7: 47492 | E7: 32346 | F7: 27277
A8: Driftsmateriel og inventar
A9: Indretning af lejede lokaler
A10: Forudbetaling og anlægsaktiver under opførelse | B10: 1255 | C10: 9814 | D10: 15740 | E10: 1693 | F10: 1572
A11: Materielle anlægsaktiver | B11: 1513 | C11: 2008 | D11: 1035 | E11: 237 | F11: 848
A12: Anlægsaktiver | B12: 99412 | C12: 160701 | D12: 149596 | E12: 96211 | F12: 127270
A13: Råvarer og hjælpematerialer | C13: 199709 | D13: 117531 | E13: 96139 | F13: 90632
A14: Varer under fremstilling
A15: Færdigvarer og handelsvarer
A16: Varebeholdninger | B16: 74989 | C16: 114467 | D16: 98007 | E16: 33689 | F16: 33235
A17: Tilgodehavender fra salg og tjenesteydelser | B17: 55530 | C17: 83618 | D17: 83585 | E17: 56919 | F17: 37485
A18: Tilgodehavender hos tilknyttede virksomheder
A19: Andre tilgodehavender | B19: 1630 | C19: 5401 | D19: 2829 | E19: 1339 | F19: 331
A20: Periodeafgrænsningsposter (aktiver) | B20: 188 | C20: 186 | D20: 1032 | E20: 832 | F20: 497
A21: Udskudt skatteaktiv | B21: 4230 | C21: 6886 | D21: 13640 | E21: 3310 | F21: 4087
A22: Tilgodehavende skat hos tilknyttede virksomheder
A23: Kortfristede skattetilgodehavender | B23: 2539 | C23: 275 | D23: 1140 | E23: 380 | F23: 53
A24: Tilgodehavender | B24: 1406 | C24: 1970 | D24: 1457 | E24: 2077 | F24: 2538
A25: Værdipapirer
A26: Likvide beholdninger | B26: 3677 | C26: 11884 | D26: 33235 | E26: 17904 | F26: 35156
A27: Omsætningsaktiver | B27: 180364 | C27: 212400 | D27: 218456 | E27: 180259 | F27: 108964
A28: Aktiver | B28: 279776 | C28: 373101 | D28: 368052 | E28: 276470 | F28: 236234
A29: Selskabskapital | B29: 35763 | C29: 35763 | D29: 35763 | E29: 35763 | F29: 35763
A30: Reserve for nettoopskrivning (indre værdis metode)
A31: Reserve for udviklingsomkostninger
A32: Reserve for sikringstransaktioner
A33: Andre reserver | B33: -3491 | C33: -146 | D33: -4761 | E33: -7413 | F33: 1645
A34: Overført resultat | B34: 185026 | C34: 183222 | D34: 178613 | E34: 168983 | F34: 122554
A35: Egenkapital i alt | B35: 217298 | C35: 218839 | D35: 209615 | E35: 197333 | F35: 177844
A36: Hensættelse til udskudt skat | B36: 191 | C36: 4876 | D36: 8057 | E36: 6462 | F36: 6260
A37: Hensatte forpligtelser | B37: 0 | C37: 357 | D37: 590 | E37: 106 | F37: 507
A38: Ansvarlig lånekapital (langfristet)
A39: Langfristede lån
A40: Leasingforpligtelser (langfristet) | B40: 8478 | C40: 8176 | D40: 5201 | E40: 559 | F40: 1538
...

Sheet pengestrom_raw_57068515
A1: Roblon A/S (CVR 57068515) — Pengestrømsopgørelse (t.kr.) | B1: 2021 | C1: 2022 | D1: 2023 | E1: 2024 | F1: 2025
A2: Pengestrømme fra driftsaktivitet | B2: -42312 | C2: -27037 | D2: 17779 | E2: 56179 | F2: 31439
A3: Pengestrømme fra investeringsaktivitet | B3: 21793 | C3: -25221 | D3: 5494 | E3: -7410 | F3: -12477
A4: Pengestrømme fra finansieringsaktivitet | B4: 16941 | C4: 60525 | D4: -1893 | E4: -60556 | F4: -5035
A5: Årets pengestrøm

Sheet Simpel_funktion
A1: Roblon A/S (CVR 57068515) — Regnskabs- og nøgletal (CVR: 57068515) — funktionsopdelt
A3: Beløb i 1.000 kr. | B3: 2025 | C3: 2024 | D3: 2023 | F3: Note / XBRL-felt
A4: Uddrag af resultatopgørelse
A5: Nettoomsætning | B5: ='res_raw_57068515'!$F$2 | C5: ='res_raw_57068515'!$E$2 | D5: ='res_raw_57068515'!$D$2 | F5: fsa:Revenue
A6: Produktionsomkostninger | B6: =-'res_raw_57068515'!$F$3 | C6: =-'res_raw_57068515'!$E$3 | D6: =-'res_raw_57068515'!$D$3 | F6: fsa:CostOfProduction (vises negativt). Materialer, lønninger, produktionsoverhead.
A7: Bruttoresultat | B7: =IF(ABS((SUM(B5:B6))-'res_raw_57068515'!$F$4)<=2,SUM(B5:B6),'res_raw_57068515'!$F$4) | C7: =IF(ABS((SUM(C5:C6))-'res_raw_57068515'!$E$4)<=2,SUM(C5:C6),'res_raw_57068515'!$E$4) | D7: =IF(ABS((SUM(D5:D6))-'res_raw_57068515'!$D$4)<=2,SUM(D5:D6),'res_raw_57068515'!$D$4) | F7: Beregnet: Nettoomsætning − Produktionsomkostninger. Matcher fsa:GrossResult. Er komponenterne ikke indberettet, vises rapporteret fsa:GrossResult direkte.
A8: Udviklingsomkostninger | B8: =-'res_raw_57068515'!$F$5 | C8: =-'res_raw_57068515'!$E$5 | D8: =-'res_raw_57068515'!$D$5 | F8: ifrs-full:ResearchAndDevelopmentExpense (vises negativt). Udviklingsomkostninger ført i resultatet (v15_21; B&O m.fl.).
A9: Salgs- og distributionsomk. | B9: =-'res_raw_57068515'!$F$6 | C9: =-'res_raw_57068515'!$E$6 | D9: =-'res_raw_57068515'!$D$6 | F9: fsa:DistributionCosts (vises negativt). Marketing, salg, distribution.
A10: Administrationsomkostninger mv. | B10: =-'res_raw_57068515'!$F$7 | C10: =-'res_raw_57068515'!$E$7 | D10: =-'res_raw_57068515'!$D$7 | F10: fsa:AdministrativeExpenses (vises negativt). Generel administration.
A11: Andre driftsindtægter | B11: ='res_raw_57068515'!$F$8 | C11: ='res_raw_57068515'!$E$8 | D11: ='res_raw_57068515'!$D$8 | F11: fsa:OtherOperatingIncome. Sekundære driftsindtægter (huslejeindtægter, off. tilskud, avancer mv.).
A12: Andre driftsomkostninger | B12: =-'res_raw_57068515'!$F$9 | C12: =-'res_raw_57068515'!$E$9 | D12: =-'res_raw_57068515'!$D$9 | F12: fsa:OtherOperatingExpenses (vises negativt). Sekundære driftsomkostninger.
A13: Resultat af primær drift | B13: =IF(ABS((SUM(B7:B12))-'res_raw_57068515'!$F$13)<=2,SUM(B7:B12),'res_raw_57068515'!$F$13) | C13: =IF(ABS((SUM(C7:C12))-'res_raw_57068515'!$E$13)<=2,SUM(C7:C12),'res_raw_57068515'!$E$13) | D13: =IF(ABS((SUM(D7:D12))-'res_raw_57068515'!$D$13)<=2,SUM(D7:D12),'res_raw_57068515'!$D$13) | F13: Beregnet: Bruttoresultat − Udviklingsomk. − Salgs/dist. − Administration + Andre driftsindt. − Andre driftsomk. EBIT.
A14: Finansielle indtægter mv. | B14: =N('res_raw_57068515'!$F$14)+N('res_raw_57068515'!$F$15) | C14: =N('res_raw_57068515'!$E$14)+N('res_raw_57068515'!$E$15) | D14: =N('res_raw_57068515'!$D$14)+N('res_raw_57068515'!$D$15) | F14: fsa:IncomeFromSubsidiaries + fsa:OtherFinanceIncome.
A15: Finansielle omkostninger mv. | B15: =-'res_raw_57068515'!$F$16 | C15: =-'res_raw_57068515'!$E$16 | D15: =-'res_raw_57068515'!$D$16 | F15: fsa:OtherFinanceExpenses (vises negativt). Renteomkostninger, kurstab.
A16: Resultat før skat | B16: =IF(ABS((SUM(B13:B15))-'res_raw_57068515'!$F$18)<=2,SUM(B13:B15),'res_raw_57068515'!$F$18) | C16: =IF(ABS((SUM(C13:C15))-'res_raw_57068515'!$E$18)<=2,SUM(C13:C15),'res_raw_57068515'!$E$18) | D16: =IF(ABS((SUM(D13:D15))-'res_raw_57068515'!$D$18)<=2,SUM(D13:D15),'res_raw_57068515'!$D$18) | F16: Beregnet: EBIT + Fin. indtægter + Fin. omk. EBT.
A18: Uddrag af balance
A19: Anlægsaktiver | B19: ='balance_raw_57068515'!$F$12 | C19: ='balance_raw_57068515'!$E$12 | D19: ='balance_raw_57068515'!$D$12 | F19: fsa:NoncurrentAssets. Materielle, immaterielle og finansielle anlægsaktiver.
A20: Omsætningsaktiver | B20: ='balance_raw_57068515'!$F$27 | C20: ='balance_raw_57068515'!$E$27 | D20: ='balance_raw_57068515'!$D$27 | F20: fsa:CurrentAssets. Varebeholdninger, tilgodehavender, likvider.
A21: Aktiver i alt | B21: =SUM(B19:B20) | C21: =SUM(C19:C20) | D21: =SUM(D19:D20) | F21: Beregnet: Anlægsaktiver + Omsætningsaktiver. Bør matche fsa:Assets.
A23: Egenkapital | B23: ='balance_raw_57068515'!$F$35 | C23: ='balance_raw_57068515'!$E$35 | D23: ='balance_raw_57068515'!$D$35 | F23: fsa:Equity. Selskabskapital, overført resultat, reserver.
A24: Forpligtelser | B24: ='balance_raw_57068515'!$F$56-'balance_raw_57068515'!$F$35 | C24: ='balance_raw_57068515'!$E$56-'balance_raw_57068515'!$E$35 | D24: ='balance_raw_57068515'!$D$56-'balance_raw_57068515'!$D$35 | F24: Beregnet: Passiver (fsa:LiabilitiesAndEquity) − Egenkapital. Hensættelser + kort- og langfristet gæld.
A25: Passiver i alt | B25: =SUM(B23:B24) | C25: =SUM(C23:C24) | D25: =SUM(D23:D24) | F25: Beregnet: Egenkapital + Forpligtelser. Bør matche Aktiver i alt.
A27: Udvalgte balanceposter
A28: Varebeholdninger | B28: ='balance_raw_57068515'!$F$16 | C28: ='balance_raw_57068515'!$E$16 | D28: ='balance_raw_57068515'!$D$16 | F28: fsa:Inventories (eller fsa:ManufacturedGoodsAndGoodsForResale hvis total mangler).
A29: Tilgodehavender fra salg | B29: ='balance_raw_57068515'!$F$17 | C29: ='balance_raw_57068515'!$E$17 | D29: ='balance_raw_57068515'!$D$17 | F29: fsa:ShorttermTradeReceivables. Kortfristede tilgodehavender fra kunder.
A30: Kortfristede gældsforpligtelser | B30: ='balance_raw_57068515'!$F$54 | C30: ='balance_raw_57068515'!$E$54 | D30: ='balance_raw_57068515'!$D$54 | F30: fsa:ShorttermLiabilitiesOtherThanProvisions. Gæld der forfalder inden for 1 år.
A32: Rentabilitet
A33: Afkastningsgrad, % | B33: =IFERROR((B13+B14)/B21*100,"") | C33: =IFERROR((C13+C14)/C21*100,"") | D33: =IFERROR((D13+D14)/D21*100,"")
A34: Overskudsgrad, % | B34: =IFERROR((B13+B14)/B5*100,"") | C34: =IFERROR((C13+C14)/C5*100,"") | D34: =IFERROR((D13+D14)/D5*100,"")
A35: Aktivernes omsætningshastighed, gange | B35: =IFERROR(B5/B21,"") | C35: =IFERROR(C5/C21,"") | D35: =IFERROR(D5/D21,"")
A36: Gældsrente, % | B36: =IFERROR(-B15*100/B24,"") | C36: =IFERROR(-C15*100/C24,"") | D36: =IFERROR(-D15*100/D24,"")
A37: Egenkapitalens forrentning, % | B37: =IFERROR(B16/B23*100,"") | C37: =IFERROR(C16/C23*100,"") | D37: =IFERROR(D16/D23*100,"")
A38: Gearing, gange | B38: =IFERROR(B24/B23,"") | C38: =IFERROR(C24/C23,"") | D38: =IFERROR(D24/D23,"")
A40: Indekstal for indtjeningsevne (2023=100)
A41: Nettoomsætning | B41: =IFERROR(B5/$D5*100,"") | C41: =IFERROR(C5/$D5*100,"") | D41: =IFERROR(D5/$D5*100,"")
A42: Produktionsomkostninger | B42: =IFERROR(B6/$D6*100,"") | C42: =IFERROR(C6/$D6*100,"") | D42: =IFERROR(D6/$D6*100,"")
A43: Udviklingsomkostninger | B43: =IFERROR(B8/$D8*100,"") | C43: =IFERROR(C8/$D8*100,"") | D43: =IFERROR(D8/$D8*100,"")
A44: Salgs- og distributionsomk. | B44: =IFERROR(B9/$D9*100,"") | C44: =IFERROR(C9/$D9*100,"") | D44: =IFERROR(D9/$D9*100,"")
A45: Administrationsomk. | B45: =IFERROR(B10/$D10*100,"") | C45: =IFERROR(C10/$D10*100,"") | D45: =IFERROR(D10/$D10*100,"")
A46: Andre driftsomkostninger | B46: =IFERROR(B12/$D12*100,"") | C46: =IFERROR(C12/$D12*100,"") | D46: =IFERROR(D12/$D12*100,"")
...

Sheet Noter_info
A1: Roblon A/S (CVR 57068515) — Ukendte XBRL-felter — disse er noter og ikke en del af hoved-regnskabet
A2: Kategori | B2: Dansk navn | C2: XBRL feltnavn | D2: 2021 t.kr. | E2: 2022 t.kr. | F2: 2023 t.kr. | G2: 2024 t.kr. | H2: 2025 t.kr. | I2: Forklaring
A3: Øvrige (ukendt) | B3: ifrs-full:CurrentInvestments | C3: ifrs-full:CurrentInvestments | D3: 42035 | I3: Ingen forklaring tilgængelig.
A4: Øvrige (ukendt) | B4: ifrs-full:CurrentPortionOfLongtermBorrowings | C4: ifrs-full:CurrentPortionOfLongtermBorrowings | D4: 0 | E4: 381 | F4: 3990 | G4: 4000 | H4: 23969 | I4: Ingen forklaring tilgængelig.
A5: Øvrige (ukendt) | B5: ifrs-full:GainsLossesOnExchangeDifferencesOnTranslationNetOfTax | C5: ifrs-full:GainsLossesOnExchangeDifferencesOnTranslationNetOfTax | I5: Ingen forklaring tilgængelig.
A6: Øvrige (ukendt) | B6: ifrs-full:IncomeTaxesRefundClassifiedAsOperatingActivities | C6: ifrs-full:IncomeTaxesRefundClassifiedAsOperatingActivities | D6: 444 | E6: 2133 | F6: 88 | G6: 0 | H6: 348 | I6: Ingen forklaring tilgængelig.
A7: Øvrige (ukendt) | B7: ifrs-full:NoncurrentLoansAndReceivables | C7: ifrs-full:NoncurrentLoansAndReceivables | H7: 33213 | I7: Ingen forklaring tilgængelig.
A8: Øvrige (ukendt) | B8: ifrs-full:OtherComprehensiveIncomeBeforeTaxHedgesOfNetInvestmentsInForeignOperations | C8: ifrs-full:OtherComprehensiveIncomeBeforeTaxHedgesOfNetInvestmentsInForeignOperations | E8: 0 | I8: Ingen forklaring tilgængelig.
A9: Øvrige (ukendt) | B9: ifrs-full:OtherWorkPerformedByEntityAndCapitalised | C9: ifrs-full:OtherWorkPerformedByEntityAndCapitalised | D9: 2292 | E9: 2221 | F9: 3220 | G9: 976 | H9: 963 | I9: Ingen forklaring tilgængelig.
