Workbook

Sheet Overblik_64011715
A1: Danske Spil A/S (CVR 64011715) — Regnskabsanalyse – Resultatopgørelse & Balance (t.kr.) · Revision
H2: Indekstal (2021=100)
A3: Resultatopgørelse t.kr. | B3: 2021 | C3: 2022 | D3: 2023 | E3: 2024 | F3: 2025 | H3: 2021 | I3: 2022 | J3: 2023 | K3: 2024 | L3: 2025
A4: Nettoomsætning | B4: ='res_raw_64011715'!$B$2 | C4: ='res_raw_64011715'!$C$2 | D4: ='res_raw_64011715'!$D$2 | E4: ='res_raw_64011715'!$E$2 | F4: ='res_raw_64011715'!$F$2 | H4: =IFERROR(B4/$B$4*100,"") | I4: =IFERROR(C4/$B$4*100,"") | J4: =IFERROR(D4/$B$4*100,"") | K4: =IFERROR(E4/$B$4*100,"") | L4: =IFERROR(F4/$B$4*100,"")
A5: Andre driftsindtægter | B5: ='res_raw_64011715'!$B$3 | C5: ='res_raw_64011715'!$C$3 | D5: ='res_raw_64011715'!$D$3 | E5: ='res_raw_64011715'!$E$3 | F5: ='res_raw_64011715'!$F$3 | H5: =IFERROR(B5/$B$5*100,"") | I5: =IFERROR(C5/$B$5*100,"") | J5: =IFERROR(D5/$B$5*100,"") | K5: =IFERROR(E5/$B$5*100,"") | L5: =IFERROR(F5/$B$5*100,"")
A6: Vareforbrug | B6: ='res_raw_64011715'!$B$4 | C6: ='res_raw_64011715'!$C$4 | D6: ='res_raw_64011715'!$D$4 | E6: ='res_raw_64011715'!$E$4 | F6: ='res_raw_64011715'!$F$4 | H6: =IFERROR(B6/$B$6*100,"") | I6: =IFERROR(C6/$B$6*100,"") | J6: =IFERROR(D6/$B$6*100,"") | K6: =IFERROR(E6/$B$6*100,"") | L6: =IFERROR(F6/$B$6*100,"")
A7: Andre eksterne omkostninger | B7: ='res_raw_64011715'!$B$5 | C7: ='res_raw_64011715'!$C$5 | D7: ='res_raw_64011715'!$D$5 | E7: ='res_raw_64011715'!$E$5 | F7: ='res_raw_64011715'!$F$5 | H7: =IFERROR(B7/$B$7*100,"") | I7: =IFERROR(C7/$B$7*100,"") | J7: =IFERROR(D7/$B$7*100,"") | K7: =IFERROR(E7/$B$7*100,"") | L7: =IFERROR(F7/$B$7*100,"")
A8: Bruttoresultat | B8: ='res_raw_64011715'!$B$6 | C8: ='res_raw_64011715'!$C$6 | D8: ='res_raw_64011715'!$D$6 | E8: ='res_raw_64011715'!$E$6 | F8: ='res_raw_64011715'!$F$6 | H8: =IFERROR(B8/$B$8*100,"") | I8: =IFERROR(C8/$B$8*100,"") | J8: =IFERROR(D8/$B$8*100,"") | K8: =IFERROR(E8/$B$8*100,"") | L8: =IFERROR(F8/$B$8*100,"")
A9: Personaleomkostninger | B9: ='res_raw_64011715'!$B$7 | C9: ='res_raw_64011715'!$C$7 | D9: ='res_raw_64011715'!$D$7 | E9: ='res_raw_64011715'!$E$7 | F9: ='res_raw_64011715'!$F$7 | H9: =IFERROR(B9/$B$9*100,"") | I9: =IFERROR(C9/$B$9*100,"") | J9: =IFERROR(D9/$B$9*100,"") | K9: =IFERROR(E9/$B$9*100,"") | L9: =IFERROR(F9/$B$9*100,"")
A10: Resultat før afskrivninger | B10: =IFERROR($B$8-ABS($B$9),"") | C10: =IFERROR($C$8-ABS($C$9),"") | D10: =IFERROR($D$8-ABS($D$9),"") | E10: =IFERROR($E$8-ABS($E$9),"") | F10: =IFERROR($F$8-ABS($F$9),"") | H10: =IFERROR(B10/$B$10*100,"") | I10: =IFERROR(C10/$B$10*100,"") | J10: =IFERROR(D10/$B$10*100,"") | K10: =IFERROR(E10/$B$10*100,"") | L10: =IFERROR(F10/$B$10*100,"")
A11: Af- og nedskrivninger | B11: ='res_raw_64011715'!$B$9 | C11: ='res_raw_64011715'!$C$9 | D11: ='res_raw_64011715'!$D$9 | E11: ='res_raw_64011715'!$E$9 | F11: ='res_raw_64011715'!$F$9 | H11: =IFERROR(B11/$B$11*100,"") | I11: =IFERROR(C11/$B$11*100,"") | J11: =IFERROR(D11/$B$11*100,"") | K11: =IFERROR(E11/$B$11*100,"") | L11: =IFERROR(F11/$B$11*100,"")
A12: Andre driftsomkostninger | B12: ='res_raw_64011715'!$B$10 | C12: ='res_raw_64011715'!$C$10 | D12: ='res_raw_64011715'!$D$10 | E12: ='res_raw_64011715'!$E$10 | F12: ='res_raw_64011715'!$F$10 | H12: =IFERROR(B12/$B$12*100,"") | I12: =IFERROR(C12/$B$12*100,"") | J12: =IFERROR(D12/$B$12*100,"") | K12: =IFERROR(E12/$B$12*100,"") | L12: =IFERROR(F12/$B$12*100,"")
A13: Resultat af primær drift | B13: ='res_raw_64011715'!$B$11 | C13: ='res_raw_64011715'!$C$11 | D13: ='res_raw_64011715'!$D$11 | E13: ='res_raw_64011715'!$E$11 | F13: ='res_raw_64011715'!$F$11 | H13: =IFERROR(B13/$B$13*100,"") | I13: =IFERROR(C13/$B$13*100,"") | J13: =IFERROR(D13/$B$13*100,"") | K13: =IFERROR(E13/$B$13*100,"") | L13: =IFERROR(F13/$B$13*100,"")
A14: Indtægter af kapitalandele, dattervirksomheder | B14: ='res_raw_64011715'!$B$12 | C14: ='res_raw_64011715'!$C$12 | D14: ='res_raw_64011715'!$D$12 | E14: ='res_raw_64011715'!$E$12 | F14: ='res_raw_64011715'!$F$12 | H14: =IFERROR(B14/$B$14*100,"") | I14: =IFERROR(C14/$B$14*100,"") | J14: =IFERROR(D14/$B$14*100,"") | K14: =IFERROR(E14/$B$14*100,"") | L14: =IFERROR(F14/$B$14*100,"")
A15: Finansielle indtægter | B15: ='res_raw_64011715'!$B$13 | C15: ='res_raw_64011715'!$C$13 | D15: ='res_raw_64011715'!$D$13 | E15: ='res_raw_64011715'!$E$13 | F15: ='res_raw_64011715'!$F$13 | H15: =IFERROR(B15/$B$15*100,"") | I15: =IFERROR(C15/$B$15*100,"") | J15: =IFERROR(D15/$B$15*100,"") | K15: =IFERROR(E15/$B$15*100,"") | L15: =IFERROR(F15/$B$15*100,"")
A16: Finansielle omkostninger | B16: ='res_raw_64011715'!$B$14 | C16: ='res_raw_64011715'!$C$14 | D16: ='res_raw_64011715'!$D$14 | E16: ='res_raw_64011715'!$E$14 | F16: ='res_raw_64011715'!$F$14 | H16: =IFERROR(B16/$B$16*100,"") | I16: =IFERROR(C16/$B$16*100,"") | J16: =IFERROR(D16/$B$16*100,"") | K16: =IFERROR(E16/$B$16*100,"") | L16: =IFERROR(F16/$B$16*100,"")
A17: Finansielle poster, netto | B17: ='res_raw_64011715'!$B$15 | C17: ='res_raw_64011715'!$C$15 | D17: ='res_raw_64011715'!$D$15 | E17: ='res_raw_64011715'!$E$15 | F17: ='res_raw_64011715'!$F$15 | H17: =IFERROR(B17/$B$17*100,"") | I17: =IFERROR(C17/$B$17*100,"") | J17: =IFERROR(D17/$B$17*100,"") | K17: =IFERROR(E17/$B$17*100,"") | L17: =IFERROR(F17/$B$17*100,"")
A18: Resultat før skat | B18: ='res_raw_64011715'!$B$16 | C18: ='res_raw_64011715'!$C$16 | D18: ='res_raw_64011715'!$D$16 | E18: ='res_raw_64011715'!$E$16 | F18: ='res_raw_64011715'!$F$16 | H18: =IFERROR(B18/$B$18*100,"") | I18: =IFERROR(C18/$B$18*100,"") | J18: =IFERROR(D18/$B$18*100,"") | K18: =IFERROR(E18/$B$18*100,"") | L18: =IFERROR(F18/$B$18*100,"")
A19: Skat af årets resultat | B19: ='res_raw_64011715'!$B$17 | C19: ='res_raw_64011715'!$C$17 | D19: ='res_raw_64011715'!$D$17 | E19: ='res_raw_64011715'!$E$17 | F19: ='res_raw_64011715'!$F$17 | H19: =IFERROR(B19/$B$19*100,"") | I19: =IFERROR(C19/$B$19*100,"") | J19: =IFERROR(D19/$B$19*100,"") | K19: =IFERROR(E19/$B$19*100,"") | L19: =IFERROR(F19/$B$19*100,"")
A20: Årets resultat | B20: ='res_raw_64011715'!$B$18 | C20: ='res_raw_64011715'!$C$18 | D20: ='res_raw_64011715'!$D$18 | E20: ='res_raw_64011715'!$E$18 | F20: ='res_raw_64011715'!$F$18 | H20: =IFERROR(B20/$B$20*100,"") | I20: =IFERROR(C20/$B$20*100,"") | J20: =IFERROR(D20/$B$20*100,"") | K20: =IFERROR(E20/$B$20*100,"") | L20: =IFERROR(F20/$B$20*100,"")
A22: AKTIVER t.kr. | B22: 2021 | C22: 2022 | D22: 2023 | E22: 2024 | F22: 2025 | H22: 2021 | I22: 2022 | J22: 2023 | K22: 2024 | L22: 2025
A23: Udviklingsprojekter | B23: ='balance_raw_64011715'!$B$2 | C23: ='balance_raw_64011715'!$C$2 | D23: ='balance_raw_64011715'!$D$2 | E23: ='balance_raw_64011715'!$E$2 | F23: ='balance_raw_64011715'!$F$2 | H23: =IFERROR(B23/$B$23*100,"") | I23: =IFERROR(C23/$B$23*100,"") | J23: =IFERROR(D23/$B$23*100,"") | K23: =IFERROR(E23/$B$23*100,"") | L23: =IFERROR(F23/$B$23*100,"")
A24: Patenter, varemærker mv. | B24: ='balance_raw_64011715'!$B$3 | C24: ='balance_raw_64011715'!$C$3 | D24: ='balance_raw_64011715'!$D$3 | E24: ='balance_raw_64011715'!$E$3 | F24: ='balance_raw_64011715'!$F$3 | H24: =IFERROR(B24/$B$24*100,"") | I24: =IFERROR(C24/$B$24*100,"") | J24: =IFERROR(D24/$B$24*100,"") | K24: =IFERROR(E24/$B$24*100,"") | L24: =IFERROR(F24/$B$24*100,"")
A25: Goodwill | B25: ='balance_raw_64011715'!$B$4 | C25: ='balance_raw_64011715'!$C$4 | D25: ='balance_raw_64011715'!$D$4 | E25: ='balance_raw_64011715'!$E$4 | F25: ='balance_raw_64011715'!$F$4 | H25: =IFERROR(B25/$B$25*100,"") | I25: =IFERROR(C25/$B$25*100,"") | J25: =IFERROR(D25/$B$25*100,"") | K25: =IFERROR(E25/$B$25*100,"") | L25: =IFERROR(F25/$B$25*100,"")
A26: Immaterielle anlægsaktiver | B26: ='balance_raw_64011715'!$B$5 | C26: ='balance_raw_64011715'!$C$5 | D26: ='balance_raw_64011715'!$D$5 | E26: ='balance_raw_64011715'!$E$5 | F26: ='balance_raw_64011715'!$F$5 | H26: =IFERROR(B26/$B$26*100,"") | I26: =IFERROR(C26/$B$26*100,"") | J26: =IFERROR(D26/$B$26*100,"") | K26: =IFERROR(E26/$B$26*100,"") | L26: =IFERROR(F26/$B$26*100,"")
A27: Grunde og bygninger | B27: ='balance_raw_64011715'!$B$6 | C27: ='balance_raw_64011715'!$C$6 | D27: ='balance_raw_64011715'!$D$6 | E27: ='balance_raw_64011715'!$E$6 | F27: ='balance_raw_64011715'!$F$6 | H27: =IFERROR(B27/$B$27*100,"") | I27: =IFERROR(C27/$B$27*100,"") | J27: =IFERROR(D27/$B$27*100,"") | K27: =IFERROR(E27/$B$27*100,"") | L27: =IFERROR(F27/$B$27*100,"")
A28: Produktionsanlæg og maskiner | B28: ='balance_raw_64011715'!$B$7 | C28: ='balance_raw_64011715'!$C$7 | D28: ='balance_raw_64011715'!$D$7 | E28: ='balance_raw_64011715'!$E$7 | F28: ='balance_raw_64011715'!$F$7 | H28: =IFERROR(B28/$B$28*100,"") | I28: =IFERROR(C28/$B$28*100,"") | J28: =IFERROR(D28/$B$28*100,"") | K28: =IFERROR(E28/$B$28*100,"") | L28: =IFERROR(F28/$B$28*100,"")
A29: Driftsmateriel og inventar | B29: ='balance_raw_64011715'!$B$8 | C29: ='balance_raw_64011715'!$C$8 | D29: ='balance_raw_64011715'!$D$8 | E29: ='balance_raw_64011715'!$E$8 | F29: ='balance_raw_64011715'!$F$8 | H29: =IFERROR(B29/$B$29*100,"") | I29: =IFERROR(C29/$B$29*100,"") | J29: =IFERROR(D29/$B$29*100,"") | K29: =IFERROR(E29/$B$29*100,"") | L29: =IFERROR(F29/$B$29*100,"")
A30: Indretning af lejede lokaler | B30: ='balance_raw_64011715'!$B$9 | C30: ='balance_raw_64011715'!$C$9 | D30: ='balance_raw_64011715'!$D$9 | E30: ='balance_raw_64011715'!$E$9 | F30: ='balance_raw_64011715'!$F$9 | H30: =IFERROR(B30/$B$30*100,"") | I30: =IFERROR(C30/$B$30*100,"") | J30: =IFERROR(D30/$B$30*100,"") | K30: =IFERROR(E30/$B$30*100,"") | L30: =IFERROR(F30/$B$30*100,"")
A31: Forudbetaling og anlægsaktiver under opførelse | B31: ='balance_raw_64011715'!$B$10 | C31: ='balance_raw_64011715'!$C$10 | D31: ='balance_raw_64011715'!$D$10 | E31: ='balance_raw_64011715'!$E$10 | F31: ='balance_raw_64011715'!$F$10 | H31: =IFERROR(B31/$B$31*100,"") | I31: =IFERROR(C31/$B$31*100,"") | J31: =IFERROR(D31/$B$31*100,"") | K31: =IFERROR(E31/$B$31*100,"") | L31: =IFERROR(F31/$B$31*100,"")
A32: Materielle anlægsaktiver | B32: ='balance_raw_64011715'!$B$11 | C32: ='balance_raw_64011715'!$C$11 | D32: ='balance_raw_64011715'!$D$11 | E32: ='balance_raw_64011715'!$E$11 | F32: ='balance_raw_64011715'!$F$11 | H32: =IFERROR(B32/$B$32*100,"") | I32: =IFERROR(C32/$B$32*100,"") | J32: =IFERROR(D32/$B$32*100,"") | K32: =IFERROR(E32/$B$32*100,"") | L32: =IFERROR(F32/$B$32*100,"")
A33: Kapitalandele, dattervirksomheder | B33: ='balance_raw_64011715'!$B$12 | C33: ='balance_raw_64011715'!$C$12 | D33: ='balance_raw_64011715'!$D$12 | E33: ='balance_raw_64011715'!$E$12 | F33: ='balance_raw_64011715'!$F$12 | H33: =IFERROR(B33/$B$33*100,"") | I33: =IFERROR(C33/$B$33*100,"") | J33: =IFERROR(D33/$B$33*100,"") | K33: =IFERROR(E33/$B$33*100,"") | L33: =IFERROR(F33/$B$33*100,"")
A34: Deposita | B34: ='balance_raw_64011715'!$B$13 | C34: ='balance_raw_64011715'!$C$13 | D34: ='balance_raw_64011715'!$D$13 | E34: ='balance_raw_64011715'!$E$13 | F34: ='balance_raw_64011715'!$F$13 | H34: =IFERROR(B34/$B$34*100,"") | I34: =IFERROR(C34/$B$34*100,"") | J34: =IFERROR(D34/$B$34*100,"") | K34: =IFERROR(E34/$B$34*100,"") | L34: =IFERROR(F34/$B$34*100,"")
A35: Finansielle anlægsaktiver | B35: ='balance_raw_64011715'!$B$14 | C35: ='balance_raw_64011715'!$C$14 | D35: ='balance_raw_64011715'!$D$14 | E35: ='balance_raw_64011715'!$E$14 | F35: ='balance_raw_64011715'!$F$14 | H35: =IFERROR(B35/$B$35*100,"") | I35: =IFERROR(C35/$B$35*100,"") | J35: =IFERROR(D35/$B$35*100,"") | K35: =IFERROR(E35/$B$35*100,"") | L35: =IFERROR(F35/$B$35*100,"")
A36: Anlægsaktiver | B36: ='balance_raw_64011715'!$B$15 | C36: ='balance_raw_64011715'!$C$15 | D36: ='balance_raw_64011715'!$D$15 | E36: ='balance_raw_64011715'!$E$15 | F36: ='balance_raw_64011715'!$F$15 | H36: =IFERROR(B36/$B$36*100,"") | I36: =IFERROR(C36/$B$36*100,"") | J36: =IFERROR(D36/$B$36*100,"") | K36: =IFERROR(E36/$B$36*100,"") | L36: =IFERROR(F36/$B$36*100,"")
A37: Varebeholdninger | B37: ='balance_raw_64011715'!$B$16 | C37: ='balance_raw_64011715'!$C$16 | D37: ='balance_raw_64011715'!$D$16 | E37: ='balance_raw_64011715'!$E$16 | F37: ='balance_raw_64011715'!$F$16 | H37: =IFERROR(B37/$B$37*100,"") | I37: =IFERROR(C37/$B$37*100,"") | J37: =IFERROR(D37/$B$37*100,"") | K37: =IFERROR(E37/$B$37*100,"") | L37: =IFERROR(F37/$B$37*100,"")
A38: Tilgodehavender fra salg og tjenesteydelser | B38: ='balance_raw_64011715'!$B$17 | C38: ='balance_raw_64011715'!$C$17 | D38: ='balance_raw_64011715'!$D$17 | E38: ='balance_raw_64011715'!$E$17 | F38: ='balance_raw_64011715'!$F$17 | H38: =IFERROR(B38/$B$38*100,"") | I38: =IFERROR(C38/$B$38*100,"") | J38: =IFERROR(D38/$B$38*100,"") | K38: =IFERROR(E38/$B$38*100,"") | L38: =IFERROR(F38/$B$38*100,"")
A39: Tilgodehavender hos tilknyttede virksomheder | B39: ='balance_raw_64011715'!$B$18 | C39: ='balance_raw_64011715'!$C$18 | D39: ='balance_raw_64011715'!$D$18 | E39: ='balance_raw_64011715'!$E$18 | F39: ='balance_raw_64011715'!$F$18 | H39: =IFERROR(B39/$B$39*100,"") | I39: =IFERROR(C39/$B$39*100,"") | J39: =IFERROR(D39/$B$39*100,"") | K39: =IFERROR(E39/$B$39*100,"") | L39: =IFERROR(F39/$B$39*100,"")
A40: Andre tilgodehavender | B40: ='balance_raw_64011715'!$B$19 | C40: ='balance_raw_64011715'!$C$19 | D40: ='balance_raw_64011715'!$D$19 | E40: ='balance_raw_64011715'!$E$19 | F40: ='balance_raw_64011715'!$F$19 | H40: =IFERROR(B40/$B$40*100,"") | I40: =IFERROR(C40/$B$40*100,"") | J40: =IFERROR(D40/$B$40*100,"") | K40: =IFERROR(E40/$B$40*100,"") | L40: =IFERROR(F40/$B$40*100,"")
A41: Periodeafgrænsningsposter (aktiver) | B41: ='balance_raw_64011715'!$B$20 | C41: ='balance_raw_64011715'!$C$20 | D41: ='balance_raw_64011715'!$D$20 | E41: ='balance_raw_64011715'!$E$20 | F41: ='balance_raw_64011715'!$F$20 | H41: =IFERROR(B41/$B$41*100,"") | I41: =IFERROR(C41/$B$41*100,"") | J41: =IFERROR(D41/$B$41*100,"") | K41: =IFERROR(E41/$B$41*100,"") | L41: =IFERROR(F41/$B$41*100,"")
...

Sheet res_raw_64011715
A1: Danske Spil A/S (CVR 64011715) — Resultatopgørelse & nøgleoplysninger (t.kr.) | B1: 2021 | C1: 2022 | D1: 2023 | E1: 2024 | F1: 2025
A2: Nettoomsætning
A3: Andre driftsindtægter | B3: 34533 | C3: 38804 | D3: 32903 | E3: 32365 | F3: 35628
A4: Vareforbrug
A5: Andre eksterne omkostninger | B5: 712700 | C5: 729331 | D5: 779436 | E5: 784150 | F5: 765014
A6: Bruttoresultat
A7: Personaleomkostninger | B7: 318645 | C7: 353620 | D7: 380956 | E7: 378429 | F7: 381312
A8: Resultat før afskrivninger
A9: Af- og nedskrivninger | B9: 369824 | C9: 246245 | D9: 247483 | E9: 337476 | F9: 190089
A10: Andre driftsomkostninger
A11: Resultat af primær drift | B11: 2096198 | C11: 2310855 | D11: 2316996 | E11: 2480031 | F11: 2582491
A12: Indtægter af kapitalandele, dattervirksomheder
A13: Finansielle indtægter | B13: 26304 | C13: 10970 | D13: 86270 | E13: 91793 | F13: 53648
A14: Finansielle omkostninger | B14: 48127 | C14: 103446 | D14: 52367 | E14: 53783 | F14: 55141
A15: Finansielle poster, netto | B15: -21823 | C15: -92476 | D15: 33903 | E15: 38010 | F15: -1493
A16: Resultat før skat | B16: 2074375 | C16: 2218379 | D16: 2350899 | E16: 2518041 | F16: 2580998
A17: Skat af årets resultat | B17: 447527 | C17: 490663 | D17: 526489 | E17: 569567 | F17: 573243
A18: Årets resultat | B18: 1626848 | C18: 1727716 | D18: 1824410 | E18: 1948474 | F18: 2007755
A19: Gns. antal medarbejdere
A20: Investering i materielle anlægsaktiver | B20: 25900 | C20: 13359 | D20: 33588 | E20: 13976 | F20: 42147

Sheet balance_raw_64011715
A1: Danske Spil A/S (CVR 64011715) — Balance (t.kr.) | B1: 2021 | C1: 2022 | D1: 2023 | E1: 2024 | F1: 2025
A2: Udviklingsprojekter | B2: 366072 | C2: 301400 | D2: 238469 | E2: 206839 | F2: 188639
A3: Patenter, varemærker mv.
A4: Goodwill | B4: 287364 | C4: 287364 | D4: 242364 | E4: 142708 | F4: 122708
A5: Immaterielle anlægsaktiver | B5: 826460 | C5: 734943 | D5: 660110 | E5: 497846 | F5: 469136
A6: Grunde og bygninger | B6: 95606 | C6: 105566 | D6: 97132 | E6: 105538 | F6: 105169
A7: Produktionsanlæg og maskiner
A8: Driftsmateriel og inventar
A9: Indretning af lejede lokaler | B9: 3281 | C9: 2256 | D9: 1877 | E9: 2107 | F9: 1788
A10: Forudbetaling og anlægsaktiver under opførelse
A11: Materielle anlægsaktiver | B11: 108564 | C11: 81166 | D11: 66665 | E11: 59055 | F11: 46915
A12: Kapitalandele, dattervirksomheder | B12: 937 | C12: 937 | D12: 937 | E12: 937 | F12: 937
A13: Deposita | B13: 16484 | C13: 16858 | D13: 19268 | E13: 19825 | F13: 18914
A14: Finansielle anlægsaktiver
A15: Anlægsaktiver | B15: 1109834 | C15: 975832 | D15: 897106 | E15: 708229 | F15: 688407
A16: Varebeholdninger | B16: 8601 | C16: 12354 | D16: 11253 | E16: 9649 | F16: 12922
A17: Tilgodehavender fra salg og tjenesteydelser | B17: 195927 | C17: 256909 | D17: 119878 | E17: 190471 | F17: 158988
A18: Tilgodehavender hos tilknyttede virksomheder
A19: Andre tilgodehavender | B19: 54593 | C19: 174342 | D19: 177517 | E19: 168813 | F19: 161344
A20: Periodeafgrænsningsposter (aktiver) | B20: 20252 | C20: 28371 | D20: 35377 | E20: 41404 | F20: 57654
A21: Udskudt skatteaktiv | B21: 0 | C21: 0 | D21: 0 | E21: 0 | F21: 0
A22: Tilgodehavende skat hos tilknyttede virksomheder
A23: Kortfristede skattetilgodehavender | B23: 0 | C23: 27672 | D23: 17211 | E23: 7351 | F23: 0
A24: Tilgodehavender | B24: 3853 | C24: 14381 | D24: 16739 | E24: 19430 | F24: 14925
A25: Værdipapirer
A26: Likvide beholdninger | B26: 901673 | C26: 1019505 | D26: 920850 | E26: 865039 | F26: 858792
A27: Omsætningsaktiver | B27: 1551634 | C27: 2046012 | D27: 1852063 | E27: 1903587 | F27: 1916093
A28: Aktiver | B28: 2661468 | C28: 3021844 | D28: 2749170 | E28: 2611816 | F28: 2604500
A29: Selskabskapital | B29: 500 | C29: 525 | D29: 525 | E29: 525 | F29: 525
A30: Reserve for nettoopskrivning (indre værdis metode)
A31: Reserve for udviklingsomkostninger
A32: Reserve for sikringstransaktioner
A33: Andre reserver
A34: Overført resultat | B34: 785587 | C34: 900672 | D34: 801200 | E34: 706160 | F34: 739298
A35: Egenkapital i alt | B35: 1615821 | C35: 1707978 | D35: 1573912 | E35: 1450039 | F35: 1399296
A36: Hensættelse til udskudt skat | B36: 71777 | C36: 57737 | D36: 58524 | E36: 58725 | F36: 47257
A37: Hensatte forpligtelser | B37: 71777 | C37: 0 | D37: 0 | E37: 7583 | F37: 7513
A38: Ansvarlig lånekapital (langfristet)
A39: Langfristede lån
A40: Leasingforpligtelser (langfristet) | B40: 40189 | C40: 27056 | D40: 21456 | E40: 18259 | F40: 13470
...

Sheet pengestrom_raw_64011715
A1: Danske Spil A/S (CVR 64011715) — Pengestrømsopgørelse (t.kr.) | B1: 2021 | C1: 2022 | D1: 2023 | E1: 2024 | F1: 2025
A2: Pengestrømme fra driftsaktivitet | B2: 1953795 | C2: 2119635 | D2: 2019063 | E2: 2246631 | F2: 2285602
A3: Pengestrømme fra investeringsaktivitet | B3: -93946 | C3: -147779 | D3: -189685 | E3: -152338 | F3: -217225
A4: Pengestrømme fra finansieringsaktivitet | B4: -2008097 | C4: -1900682 | D4: -1928034 | E4: -2150105 | F4: -2074625
A5: Årets pengestrøm | B5: -147376 | C5: 71175 | D5: -98655 | E5: -55811 | F5: -6247

Sheet Simpel_arts
A1: Danske Spil A/S (CVR 64011715) — Regnskabs- og nøgletal (CVR: 64011715) — artsopdelt
A3: Beløb i 1.000 kr. | B3: 2025 | C3: 2024 | D3: 2023 | F3: Note / XBRL-felt
A4: Uddrag af resultatopgørelse
A5: Nettoomsætning | B5: ='res_raw_64011715'!$F$2 | C5: ='res_raw_64011715'!$E$2 | D5: ='res_raw_64011715'!$D$2 | F5: fsa:Revenue
A6: Andre driftsindtægter | B6: ='res_raw_64011715'!$F$3 | C6: ='res_raw_64011715'!$E$3 | D6: ='res_raw_64011715'!$D$3 | F6: fsa:OtherOperatingIncome. Indtægter fra sekundære aktiviteter (huslejeindtægter, avance ved salg af anlæg mv.).
A7: Vareforbrug | B7: =-'res_raw_64011715'!$F$4 | C7: =-'res_raw_64011715'!$E$4 | D7: =-'res_raw_64011715'!$D$4 | F7: fsa:CostOfSales (vises negativt for korrekt SUM-formel).
A8: Andre eksterne omk. mv. | B8: =-'res_raw_64011715'!$F$5 | C8: =-'res_raw_64011715'!$E$5 | D8: =-'res_raw_64011715'!$D$5 | F8: fsa:OtherExternalExpenses (vises negativt). Husleje, energi, kontorhold mv.
A9: Bruttofortjeneste | B9: =IF(ABS((SUM(B5:B8))-'res_raw_64011715'!$F$6)<=2,SUM(B5:B8),'res_raw_64011715'!$F$6) | C9: =IF(ABS((SUM(C5:C8))-'res_raw_64011715'!$E$6)<=2,SUM(C5:C8),'res_raw_64011715'!$E$6) | D9: =IF(ABS((SUM(D5:D8))-'res_raw_64011715'!$D$6)<=2,SUM(D5:D8),'res_raw_64011715'!$D$6) | F9: Beregnet: Nettoomsætning + Andre driftsindt. − Vareforbrug − Andre ext. omk. Er komponenterne ikke indberettet, vises rapporteret bruttoresultat (fsa:GrossResult) direkte.
A10: Personaleomkostninger | B10: =-'res_raw_64011715'!$F$7 | C10: =-'res_raw_64011715'!$E$7 | D10: =-'res_raw_64011715'!$D$7 | F10: fsa:EmployeeBenefitsExpense (vises negativt). Lønninger, pension, sociale ydelser.
A11: Af- og nedskrivninger | B11: =-'res_raw_64011715'!$F$9 | C11: =-'res_raw_64011715'!$E$9 | D11: =-'res_raw_64011715'!$D$9 | F11: fsa:Depreciation (vises negativt). Af- og nedskrivninger på materielle og immaterielle anlægsaktiver.
A12: Andre driftsomkostninger | B12: =-'res_raw_64011715'!$F$10 | C12: =-'res_raw_64011715'!$E$10 | D12: =-'res_raw_64011715'!$D$10 | F12: fsa:OtherOperatingExpenses (vises negativt). Typisk 0 eller meget lille post.
A13: Resultat af primær drift | B13: =IF(ABS((SUM(B9:B12))-'res_raw_64011715'!$F$11)<=2,SUM(B9:B12),'res_raw_64011715'!$F$11) | C13: =IF(ABS((SUM(C9:C12))-'res_raw_64011715'!$E$11)<=2,SUM(C9:C12),'res_raw_64011715'!$E$11) | D13: =IF(ABS((SUM(D9:D12))-'res_raw_64011715'!$D$11)<=2,SUM(D9:D12),'res_raw_64011715'!$D$11) | F13: Beregnet: Bruttofortjeneste − Personaleomk. − Af- og nedskrivninger − Andre driftsomk. EBIT.
A14: Finansielle indtægter mv. | B14: =N('res_raw_64011715'!$F$12)+N('res_raw_64011715'!$F$13) | C14: =N('res_raw_64011715'!$E$12)+N('res_raw_64011715'!$E$13) | D14: =N('res_raw_64011715'!$D$12)+N('res_raw_64011715'!$D$13) | F14: fsa:IncomeFromSubsidiaries + fsa:OtherFinanceIncome.
A15: Finansielle omkostninger mv. | B15: =-'res_raw_64011715'!$F$14 | C15: =-'res_raw_64011715'!$E$14 | D15: =-'res_raw_64011715'!$D$14 | F15: fsa:OtherFinanceExpenses (vises negativt). Renteomkostninger, kurstab mv.
A16: Resultat før skat | B16: =IF(ABS((SUM(B13:B15))-'res_raw_64011715'!$F$16)<=2,SUM(B13:B15),'res_raw_64011715'!$F$16) | C16: =IF(ABS((SUM(C13:C15))-'res_raw_64011715'!$E$16)<=2,SUM(C13:C15),'res_raw_64011715'!$E$16) | D16: =IF(ABS((SUM(D13:D15))-'res_raw_64011715'!$D$16)<=2,SUM(D13:D15),'res_raw_64011715'!$D$16) | F16: Beregnet: EBIT + Fin. indtægter + Fin. omk. EBT.
A18: Uddrag af balance
A19: Anlægsaktiver | B19: ='balance_raw_64011715'!$F$15 | C19: ='balance_raw_64011715'!$E$15 | D19: ='balance_raw_64011715'!$D$15 | F19: fsa:NoncurrentAssets. Materielle, immaterielle og finansielle anlægsaktiver.
A20: Omsætningsaktiver | B20: ='balance_raw_64011715'!$F$27 | C20: ='balance_raw_64011715'!$E$27 | D20: ='balance_raw_64011715'!$D$27 | F20: fsa:CurrentAssets. Varebeholdninger, tilgodehavender, likvider.
A21: Aktiver i alt | B21: =SUM(B19:B20) | C21: =SUM(C19:C20) | D21: =SUM(D19:D20) | F21: Beregnet: Anlægsaktiver + Omsætningsaktiver. Bør matche fsa:Assets.
A23: Egenkapital | B23: ='balance_raw_64011715'!$F$35 | C23: ='balance_raw_64011715'!$E$35 | D23: ='balance_raw_64011715'!$D$35 | F23: fsa:Equity. Selskabskapital, overført resultat, reserver.
A24: Forpligtelser | B24: ='balance_raw_64011715'!$F$56-'balance_raw_64011715'!$F$35 | C24: ='balance_raw_64011715'!$E$56-'balance_raw_64011715'!$E$35 | D24: ='balance_raw_64011715'!$D$56-'balance_raw_64011715'!$D$35 | F24: Beregnet: Passiver (fsa:LiabilitiesAndEquity) − Egenkapital. Hensættelser + kort- og langfristet gæld.
A25: Passiver i alt | B25: =SUM(B23:B24) | C25: =SUM(C23:C24) | D25: =SUM(D23:D24) | F25: Beregnet: Egenkapital + Forpligtelser. Bør matche Aktiver i alt.
A27: Udvalgte balanceposter
A28: Varebeholdninger | B28: ='balance_raw_64011715'!$F$16 | C28: ='balance_raw_64011715'!$E$16 | D28: ='balance_raw_64011715'!$D$16 | F28: fsa:Inventories (eller fsa:ManufacturedGoodsAndGoodsForResale hvis total mangler).
A29: Tilgodehavender fra salg | B29: ='balance_raw_64011715'!$F$17 | C29: ='balance_raw_64011715'!$E$17 | D29: ='balance_raw_64011715'!$D$17 | F29: fsa:ShorttermTradeReceivables. Kortfristede tilgodehavender fra kunder.
A30: Kortfristede gældsforpligtelser | B30: ='balance_raw_64011715'!$F$54 | C30: ='balance_raw_64011715'!$E$54 | D30: ='balance_raw_64011715'!$D$54 | F30: fsa:ShorttermLiabilitiesOtherThanProvisions. Gæld der forfalder inden for 1 år.
A32: Rentabilitet
A33: Afkastningsgrad, % | B33: =IFERROR((B13+B14)/B21*100,"") | C33: =IFERROR((C13+C14)/C21*100,"") | D33: =IFERROR((D13+D14)/D21*100,"")
A34: Overskudsgrad (af bruttofortjeneste), % | B34: =IFERROR((B13+B14)/B9*100,"") | C34: =IFERROR((C13+C14)/C9*100,"") | D34: =IFERROR((D13+D14)/D9*100,"")
A35: Aktivernes omsætningshastighed (af bruttofortjeneste), gange | B35: =IFERROR(B9/B21,"") | C35: =IFERROR(C9/C21,"") | D35: =IFERROR(D9/D21,"")
A36: Gældsrente, % | B36: =IFERROR(-B15*100/B24,"") | C36: =IFERROR(-C15*100/C24,"") | D36: =IFERROR(-D15*100/D24,"")
A37: Egenkapitalens forrentning, % | B37: =IFERROR(B16/B23*100,"") | C37: =IFERROR(C16/C23*100,"") | D37: =IFERROR(D16/D23*100,"")
A38: Gearing, gange | B38: =IFERROR(B24/B23,"") | C38: =IFERROR(C24/C23,"") | D38: =IFERROR(D24/D23,"")
A40: Indekstal for indtjeningsevne (2023=100)
A41: Bruttofortjeneste | B41: =IFERROR(B9/$D9*100,"") | C41: =IFERROR(C9/$D9*100,"") | D41: =IFERROR(D9/$D9*100,"")
A42: Vareforbrug | B42: =IFERROR(B7/$D7*100,"") | C42: =IFERROR(C7/$D7*100,"") | D42: =IFERROR(D7/$D7*100,"")
A43: Andre eksterne omk. | B43: =IFERROR(B8/$D8*100,"") | C43: =IFERROR(C8/$D8*100,"") | D43: =IFERROR(D8/$D8*100,"")
A44: Personaleomkostninger | B44: =IFERROR(B10/$D10*100,"") | C44: =IFERROR(C10/$D10*100,"") | D44: =IFERROR(D10/$D10*100,"")
A45: Af- og nedskrivninger | B45: =IFERROR(B11/$D11*100,"") | C45: =IFERROR(C11/$D11*100,"") | D45: =IFERROR(D11/$D11*100,"")
A47: Indekstal for kapitaltilpasningsevne (2023=100)
...

Sheet Noter_info
A1: Danske Spil A/S (CVR 64011715) — Ukendte XBRL-felter — disse er noter og ikke en del af hoved-regnskabet
A2: Kategori | B2: Dansk navn | C2: XBRL feltnavn | D2: 2021 t.kr. | E2: 2022 t.kr. | F2: 2023 t.kr. | G2: 2024 t.kr. | H2: 2025 t.kr. | I2: Forklaring
A3: Øvrige (ukendt) | B3: ifrs-full:AdjustmentsForFinanceCosts | C3: ifrs-full:AdjustmentsForFinanceCosts | D3: 48127 | E3: 103446 | F3: 52367 | G3: 53783 | H3: 55141 | I3: Ingen forklaring tilgængelig.
A4: Øvrige (ukendt) | B4: ifrs-full:AdjustmentsForFinanceIncome | C4: ifrs-full:AdjustmentsForFinanceIncome | D4: 26304 | E4: 10970 | F4: 86270 | G4: 91793 | H4: 53648 | I4: Ingen forklaring tilgængelig.
A5: Øvrige (ukendt) | B5: ifrs-full:AdjustmentsForIncomeTaxExpense | C5: ifrs-full:AdjustmentsForIncomeTaxExpense | D5: 447527 | E5: 490663 | F5: 526489 | G5: 569567 | H5: 573243 | I5: Ingen forklaring tilgængelig.
A6: Øvrige (ukendt) | B6: ifrs-full:CashAndCashEquivalentsInSubsidiaryOrBusinessesAcquiredOrDisposed2013 | C6: ifrs-full:CashAndCashEquivalentsInSubsidiaryOrBusinessesAcquiredOrDisposed2013 | D6: 0 | I6: Ingen forklaring tilgængelig.
A7: Øvrige (ukendt) | B7: ifrs-full:CurrentDividendPayables | C7: ifrs-full:CurrentDividendPayables | D7: 36968 | E7: 3976 | F7: 70432 | G7: 22466 | H7: 43947 | I7: Ingen forklaring tilgængelig.
A8: Øvrige (ukendt) | B8: ifrs-full:CurrentFinancialAssetsAtFairValueThroughProfitOrLoss | C8: ifrs-full:CurrentFinancialAssetsAtFairValueThroughProfitOrLoss | D8: 421328 | E8: 686822 | F8: 730756 | G8: 770244 | H8: 812813 | I8: Ingen forklaring tilgængelig.
A9: Øvrige (ukendt) | B9: ifrs-full:CurrentFinancialLiabilitiesAtFairValueThroughProfitOrLoss | C9: ifrs-full:CurrentFinancialLiabilitiesAtFairValueThroughProfitOrLoss | D9: 54593 | E9: 174342 | F9: 177517 | G9: 168813 | H9: 161344 | I9: Ingen forklaring tilgængelig.
A10: Øvrige (ukendt) | B10: ifrs-full:FeeAndCommissionExpense | C10: ifrs-full:FeeAndCommissionExpense | D10: 472790 | E10: 459628 | F10: 435293 | G10: 407008 | H10: 372387 | I10: Ingen forklaring tilgængelig.
A11: Øvrige (ukendt) | B11: ifrs-full:GainsLossesOnDisposalsOfInvestments | C11: ifrs-full:GainsLossesOnDisposalsOfInvestments | F11: 0 | G11: 26688 | H11: 0 | I11: Ingen forklaring tilgængelig.
A12: Øvrige (ukendt) | B12: ifrs-full:IncreaseDecreaseThroughAppropriationOfRetainedEarnings | C12: ifrs-full:IncreaseDecreaseThroughAppropriationOfRetainedEarnings | D12: -1521622 | E12: -1497644 | F12: -1702691 | G12: -1836632 | H12: -1806866 | I12: Ingen forklaring tilgængelig.
A13: Øvrige (ukendt) | B13: ifrs-full:InvestmentsInJointVentures | C13: ifrs-full:InvestmentsInJointVentures | I13: Ingen forklaring tilgængelig.
A14: Øvrige (ukendt) | B14: ifrs-full:InvestmentsInSubsidiariesJointVenturesAndAssociates | C14: ifrs-full:InvestmentsInSubsidiariesJointVenturesAndAssociates | E14: 0 | F14: 0 | G14: 0 | H14: 0 | I14: Ingen forklaring tilgængelig.
A15: Øvrige (ukendt) | B15: ifrs-full:OtherIncomeExpenseFromSubsidiariesJointlyControlledEntitiesAndAssociates | C15: ifrs-full:OtherIncomeExpenseFromSubsidiariesJointlyControlledEntitiesAndAssociates | E15: 0 | F15: 0 | H15: 0 | I15: Ingen forklaring tilgængelig.
A16: Øvrige (ukendt) | B16: ifrs-full:RevenueFromRenderingOfGamingServices | C16: ifrs-full:RevenueFromRenderingOfGamingServices | D16: 4829723 | E16: 4975252 | F16: 5039651 | G16: 5255521 | H16: 5158047 | I16: Ingen forklaring tilgængelig.
A17: Øvrige (ukendt) | B17: ifrs-full:TaxExpenseOtherThanIncomeTaxExpense | C17: ifrs-full:TaxExpenseOtherThanIncomeTaxExpense | D17: 615751 | E17: 644731 | F17: 635435 | G17: 641619 | H17: 621236 | I17: Ingen forklaring tilgængelig.
A18: Øvrige (ukendt) | B18: ifrs-full:TradeAndOtherCurrentReceivablesDueFromRelatedParties | C18: ifrs-full:TradeAndOtherCurrentReceivablesDueFromRelatedParties | E18: 0 | F18: 0 | G18: 0 | H18: 0 | I18: Ingen forklaring tilgængelig.
