Workbook

Sheet Overblik_15233699
A1: Odense Marcipan A/S (CVR 15233699) — Regnskabsanalyse – Resultatopgørelse & Balance (t.kr.) · Klasse C-stor · Revision
H2: Indekstal (2021=100)
A3: Resultatopgørelse t.kr. | B3: 2021 | C3: 2022 | D3: 2023 | E3: 2024 | F3: 2025 | H3: 2021 | I3: 2022 | J3: 2023 | K3: 2024 | L3: 2025
A4: Nettoomsætning | B4: ='res_raw_15233699'!$B$2 | C4: ='res_raw_15233699'!$C$2 | D4: ='res_raw_15233699'!$D$2 | E4: ='res_raw_15233699'!$E$2 | F4: ='res_raw_15233699'!$F$2 | H4: =IFERROR(B4/$B$4*100,"") | I4: =IFERROR(C4/$B$4*100,"") | J4: =IFERROR(D4/$B$4*100,"") | K4: =IFERROR(E4/$B$4*100,"") | L4: =IFERROR(F4/$B$4*100,"")
A5: Produktionsomkostninger | B5: ='res_raw_15233699'!$B$3 | C5: ='res_raw_15233699'!$C$3 | D5: ='res_raw_15233699'!$D$3 | E5: ='res_raw_15233699'!$E$3 | F5: ='res_raw_15233699'!$F$3 | H5: =IFERROR(B5/$B$5*100,"") | I5: =IFERROR(C5/$B$5*100,"") | J5: =IFERROR(D5/$B$5*100,"") | K5: =IFERROR(E5/$B$5*100,"") | L5: =IFERROR(F5/$B$5*100,"")
A6: Bruttoresultat | B6: ='res_raw_15233699'!$B$4 | C6: ='res_raw_15233699'!$C$4 | D6: ='res_raw_15233699'!$D$4 | E6: ='res_raw_15233699'!$E$4 | F6: ='res_raw_15233699'!$F$4 | H6: =IFERROR(B6/$B$6*100,"") | I6: =IFERROR(C6/$B$6*100,"") | J6: =IFERROR(D6/$B$6*100,"") | K6: =IFERROR(E6/$B$6*100,"") | L6: =IFERROR(F6/$B$6*100,"")
A7: Udviklingsomkostninger | B7: ='res_raw_15233699'!$B$5 | C7: ='res_raw_15233699'!$C$5 | D7: ='res_raw_15233699'!$D$5 | E7: ='res_raw_15233699'!$E$5 | F7: ='res_raw_15233699'!$F$5 | H7: =IFERROR(B7/$B$7*100,"") | I7: =IFERROR(C7/$B$7*100,"") | J7: =IFERROR(D7/$B$7*100,"") | K7: =IFERROR(E7/$B$7*100,"") | L7: =IFERROR(F7/$B$7*100,"")
A8: Salgs- og distributionsomkostninger | B8: ='res_raw_15233699'!$B$6 | C8: ='res_raw_15233699'!$C$6 | D8: ='res_raw_15233699'!$D$6 | E8: ='res_raw_15233699'!$E$6 | F8: ='res_raw_15233699'!$F$6 | H8: =IFERROR(B8/$B$8*100,"") | I8: =IFERROR(C8/$B$8*100,"") | J8: =IFERROR(D8/$B$8*100,"") | K8: =IFERROR(E8/$B$8*100,"") | L8: =IFERROR(F8/$B$8*100,"")
A9: Administrationsomkostninger | B9: ='res_raw_15233699'!$B$7 | C9: ='res_raw_15233699'!$C$7 | D9: ='res_raw_15233699'!$D$7 | E9: ='res_raw_15233699'!$E$7 | F9: ='res_raw_15233699'!$F$7 | H9: =IFERROR(B9/$B$9*100,"") | I9: =IFERROR(C9/$B$9*100,"") | J9: =IFERROR(D9/$B$9*100,"") | K9: =IFERROR(E9/$B$9*100,"") | L9: =IFERROR(F9/$B$9*100,"")
A10: Andre driftsindtægter | B10: ='res_raw_15233699'!$B$8 | C10: ='res_raw_15233699'!$C$8 | D10: ='res_raw_15233699'!$D$8 | E10: ='res_raw_15233699'!$E$8 | F10: ='res_raw_15233699'!$F$8 | H10: =IFERROR(B10/$B$10*100,"") | I10: =IFERROR(C10/$B$10*100,"") | J10: =IFERROR(D10/$B$10*100,"") | K10: =IFERROR(E10/$B$10*100,"") | L10: =IFERROR(F10/$B$10*100,"")
A11: Andre driftsomkostninger | B11: ='res_raw_15233699'!$B$9 | C11: ='res_raw_15233699'!$C$9 | D11: ='res_raw_15233699'!$D$9 | E11: ='res_raw_15233699'!$E$9 | F11: ='res_raw_15233699'!$F$9 | H11: =IFERROR(B11/$B$11*100,"") | I11: =IFERROR(C11/$B$11*100,"") | J11: =IFERROR(D11/$B$11*100,"") | K11: =IFERROR(E11/$B$11*100,"") | L11: =IFERROR(F11/$B$11*100,"")
A12: Resultat af primær drift | B12: ='res_raw_15233699'!$B$10 | C12: ='res_raw_15233699'!$C$10 | D12: ='res_raw_15233699'!$D$10 | E12: ='res_raw_15233699'!$E$10 | F12: ='res_raw_15233699'!$F$10 | H12: =IFERROR(B12/$B$12*100,"") | I12: =IFERROR(C12/$B$12*100,"") | J12: =IFERROR(D12/$B$12*100,"") | K12: =IFERROR(E12/$B$12*100,"") | L12: =IFERROR(F12/$B$12*100,"")
A13: Indtægter af kapitalandele, dattervirksomheder | B13: ='res_raw_15233699'!$B$11 | C13: ='res_raw_15233699'!$C$11 | D13: ='res_raw_15233699'!$D$11 | E13: ='res_raw_15233699'!$E$11 | F13: ='res_raw_15233699'!$F$11 | H13: =IFERROR(B13/$B$13*100,"") | I13: =IFERROR(C13/$B$13*100,"") | J13: =IFERROR(D13/$B$13*100,"") | K13: =IFERROR(E13/$B$13*100,"") | L13: =IFERROR(F13/$B$13*100,"")
A14: Finansielle indtægter | B14: ='res_raw_15233699'!$B$12 | C14: ='res_raw_15233699'!$C$12 | D14: ='res_raw_15233699'!$D$12 | E14: ='res_raw_15233699'!$E$12 | F14: ='res_raw_15233699'!$F$12 | H14: =IFERROR(B14/$B$14*100,"") | I14: =IFERROR(C14/$B$14*100,"") | J14: =IFERROR(D14/$B$14*100,"") | K14: =IFERROR(E14/$B$14*100,"") | L14: =IFERROR(F14/$B$14*100,"")
A15: Finansielle omkostninger | B15: ='res_raw_15233699'!$B$13 | C15: ='res_raw_15233699'!$C$13 | D15: ='res_raw_15233699'!$D$13 | E15: ='res_raw_15233699'!$E$13 | F15: ='res_raw_15233699'!$F$13 | H15: =IFERROR(B15/$B$15*100,"") | I15: =IFERROR(C15/$B$15*100,"") | J15: =IFERROR(D15/$B$15*100,"") | K15: =IFERROR(E15/$B$15*100,"") | L15: =IFERROR(F15/$B$15*100,"")
A16: Finansielle poster, netto | B16: ='res_raw_15233699'!$B$14 | C16: ='res_raw_15233699'!$C$14 | D16: ='res_raw_15233699'!$D$14 | E16: ='res_raw_15233699'!$E$14 | F16: ='res_raw_15233699'!$F$14 | H16: =IFERROR(B16/$B$16*100,"") | I16: =IFERROR(C16/$B$16*100,"") | J16: =IFERROR(D16/$B$16*100,"") | K16: =IFERROR(E16/$B$16*100,"") | L16: =IFERROR(F16/$B$16*100,"")
A17: Resultat før skat | B17: ='res_raw_15233699'!$B$15 | C17: ='res_raw_15233699'!$C$15 | D17: ='res_raw_15233699'!$D$15 | E17: ='res_raw_15233699'!$E$15 | F17: ='res_raw_15233699'!$F$15 | H17: =IFERROR(B17/$B$17*100,"") | I17: =IFERROR(C17/$B$17*100,"") | J17: =IFERROR(D17/$B$17*100,"") | K17: =IFERROR(E17/$B$17*100,"") | L17: =IFERROR(F17/$B$17*100,"")
A18: Skat af årets resultat | B18: ='res_raw_15233699'!$B$16 | C18: ='res_raw_15233699'!$C$16 | D18: ='res_raw_15233699'!$D$16 | E18: ='res_raw_15233699'!$E$16 | F18: ='res_raw_15233699'!$F$16 | H18: =IFERROR(B18/$B$18*100,"") | I18: =IFERROR(C18/$B$18*100,"") | J18: =IFERROR(D18/$B$18*100,"") | K18: =IFERROR(E18/$B$18*100,"") | L18: =IFERROR(F18/$B$18*100,"")
A19: Årets resultat | B19: ='res_raw_15233699'!$B$17 | C19: ='res_raw_15233699'!$C$17 | D19: ='res_raw_15233699'!$D$17 | E19: ='res_raw_15233699'!$E$17 | F19: ='res_raw_15233699'!$F$17 | H19: =IFERROR(B19/$B$19*100,"") | I19: =IFERROR(C19/$B$19*100,"") | J19: =IFERROR(D19/$B$19*100,"") | K19: =IFERROR(E19/$B$19*100,"") | L19: =IFERROR(F19/$B$19*100,"")
A21: AKTIVER t.kr. | B21: 2021 | C21: 2022 | D21: 2023 | E21: 2024 | F21: 2025 | H21: 2021 | I21: 2022 | J21: 2023 | K21: 2024 | L21: 2025
A22: Udviklingsprojekter | B22: ='balance_raw_15233699'!$B$2 | C22: ='balance_raw_15233699'!$C$2 | D22: ='balance_raw_15233699'!$D$2 | E22: ='balance_raw_15233699'!$E$2 | F22: ='balance_raw_15233699'!$F$2 | H22: =IFERROR(B22/$B$22*100,"") | I22: =IFERROR(C22/$B$22*100,"") | J22: =IFERROR(D22/$B$22*100,"") | K22: =IFERROR(E22/$B$22*100,"") | L22: =IFERROR(F22/$B$22*100,"")
A23: Patenter, varemærker mv. | B23: ='balance_raw_15233699'!$B$3 | C23: ='balance_raw_15233699'!$C$3 | D23: ='balance_raw_15233699'!$D$3 | E23: ='balance_raw_15233699'!$E$3 | F23: ='balance_raw_15233699'!$F$3 | H23: =IFERROR(B23/$B$23*100,"") | I23: =IFERROR(C23/$B$23*100,"") | J23: =IFERROR(D23/$B$23*100,"") | K23: =IFERROR(E23/$B$23*100,"") | L23: =IFERROR(F23/$B$23*100,"")
A24: Goodwill | B24: ='balance_raw_15233699'!$B$4 | C24: ='balance_raw_15233699'!$C$4 | D24: ='balance_raw_15233699'!$D$4 | E24: ='balance_raw_15233699'!$E$4 | F24: ='balance_raw_15233699'!$F$4 | H24: =IFERROR(B24/$B$24*100,"") | I24: =IFERROR(C24/$B$24*100,"") | J24: =IFERROR(D24/$B$24*100,"") | K24: =IFERROR(E24/$B$24*100,"") | L24: =IFERROR(F24/$B$24*100,"")
A25: Immaterielle anlægsaktiver | B25: ='balance_raw_15233699'!$B$5 | C25: ='balance_raw_15233699'!$C$5 | D25: ='balance_raw_15233699'!$D$5 | E25: ='balance_raw_15233699'!$E$5 | F25: ='balance_raw_15233699'!$F$5 | H25: =IFERROR(B25/$B$25*100,"") | I25: =IFERROR(C25/$B$25*100,"") | J25: =IFERROR(D25/$B$25*100,"") | K25: =IFERROR(E25/$B$25*100,"") | L25: =IFERROR(F25/$B$25*100,"")
A26: Grunde og bygninger | B26: ='balance_raw_15233699'!$B$6 | C26: ='balance_raw_15233699'!$C$6 | D26: ='balance_raw_15233699'!$D$6 | E26: ='balance_raw_15233699'!$E$6 | F26: ='balance_raw_15233699'!$F$6 | H26: =IFERROR(B26/$B$26*100,"") | I26: =IFERROR(C26/$B$26*100,"") | J26: =IFERROR(D26/$B$26*100,"") | K26: =IFERROR(E26/$B$26*100,"") | L26: =IFERROR(F26/$B$26*100,"")
A27: Produktionsanlæg og maskiner | B27: ='balance_raw_15233699'!$B$7 | C27: ='balance_raw_15233699'!$C$7 | D27: ='balance_raw_15233699'!$D$7 | E27: ='balance_raw_15233699'!$E$7 | F27: ='balance_raw_15233699'!$F$7 | H27: =IFERROR(B27/$B$27*100,"") | I27: =IFERROR(C27/$B$27*100,"") | J27: =IFERROR(D27/$B$27*100,"") | K27: =IFERROR(E27/$B$27*100,"") | L27: =IFERROR(F27/$B$27*100,"")
A28: Driftsmateriel og inventar | B28: ='balance_raw_15233699'!$B$8 | C28: ='balance_raw_15233699'!$C$8 | D28: ='balance_raw_15233699'!$D$8 | E28: ='balance_raw_15233699'!$E$8 | F28: ='balance_raw_15233699'!$F$8 | H28: =IFERROR(B28/$B$28*100,"") | I28: =IFERROR(C28/$B$28*100,"") | J28: =IFERROR(D28/$B$28*100,"") | K28: =IFERROR(E28/$B$28*100,"") | L28: =IFERROR(F28/$B$28*100,"")
A29: Indretning af lejede lokaler | B29: ='balance_raw_15233699'!$B$9 | C29: ='balance_raw_15233699'!$C$9 | D29: ='balance_raw_15233699'!$D$9 | E29: ='balance_raw_15233699'!$E$9 | F29: ='balance_raw_15233699'!$F$9 | H29: =IFERROR(B29/$B$29*100,"") | I29: =IFERROR(C29/$B$29*100,"") | J29: =IFERROR(D29/$B$29*100,"") | K29: =IFERROR(E29/$B$29*100,"") | L29: =IFERROR(F29/$B$29*100,"")
A30: Forudbetaling og anlægsaktiver under opførelse | B30: ='balance_raw_15233699'!$B$10 | C30: ='balance_raw_15233699'!$C$10 | D30: ='balance_raw_15233699'!$D$10 | E30: ='balance_raw_15233699'!$E$10 | F30: ='balance_raw_15233699'!$F$10 | H30: =IFERROR(B30/$B$30*100,"") | I30: =IFERROR(C30/$B$30*100,"") | J30: =IFERROR(D30/$B$30*100,"") | K30: =IFERROR(E30/$B$30*100,"") | L30: =IFERROR(F30/$B$30*100,"")
A31: Materielle anlægsaktiver | B31: ='balance_raw_15233699'!$B$11 | C31: ='balance_raw_15233699'!$C$11 | D31: ='balance_raw_15233699'!$D$11 | E31: ='balance_raw_15233699'!$E$11 | F31: ='balance_raw_15233699'!$F$11 | H31: =IFERROR(B31/$B$31*100,"") | I31: =IFERROR(C31/$B$31*100,"") | J31: =IFERROR(D31/$B$31*100,"") | K31: =IFERROR(E31/$B$31*100,"") | L31: =IFERROR(F31/$B$31*100,"")
A32: Kapitalandele, dattervirksomheder | B32: ='balance_raw_15233699'!$B$12 | C32: ='balance_raw_15233699'!$C$12 | D32: ='balance_raw_15233699'!$D$12 | E32: ='balance_raw_15233699'!$E$12 | F32: ='balance_raw_15233699'!$F$12 | H32: =IFERROR(B32/$B$32*100,"") | I32: =IFERROR(C32/$B$32*100,"") | J32: =IFERROR(D32/$B$32*100,"") | K32: =IFERROR(E32/$B$32*100,"") | L32: =IFERROR(F32/$B$32*100,"")
A33: Deposita | B33: ='balance_raw_15233699'!$B$13 | C33: ='balance_raw_15233699'!$C$13 | D33: ='balance_raw_15233699'!$D$13 | E33: ='balance_raw_15233699'!$E$13 | F33: ='balance_raw_15233699'!$F$13 | H33: =IFERROR(B33/$B$33*100,"") | I33: =IFERROR(C33/$B$33*100,"") | J33: =IFERROR(D33/$B$33*100,"") | K33: =IFERROR(E33/$B$33*100,"") | L33: =IFERROR(F33/$B$33*100,"")
A34: Finansielle anlægsaktiver | B34: ='balance_raw_15233699'!$B$14 | C34: ='balance_raw_15233699'!$C$14 | D34: ='balance_raw_15233699'!$D$14 | E34: ='balance_raw_15233699'!$E$14 | F34: ='balance_raw_15233699'!$F$14 | H34: =IFERROR(B34/$B$34*100,"") | I34: =IFERROR(C34/$B$34*100,"") | J34: =IFERROR(D34/$B$34*100,"") | K34: =IFERROR(E34/$B$34*100,"") | L34: =IFERROR(F34/$B$34*100,"")
A35: Anlægsaktiver | B35: ='balance_raw_15233699'!$B$15 | C35: ='balance_raw_15233699'!$C$15 | D35: ='balance_raw_15233699'!$D$15 | E35: ='balance_raw_15233699'!$E$15 | F35: ='balance_raw_15233699'!$F$15 | H35: =IFERROR(B35/$B$35*100,"") | I35: =IFERROR(C35/$B$35*100,"") | J35: =IFERROR(D35/$B$35*100,"") | K35: =IFERROR(E35/$B$35*100,"") | L35: =IFERROR(F35/$B$35*100,"")
A36: Råvarer og hjælpematerialer | B36: ='balance_raw_15233699'!$B$16 | C36: ='balance_raw_15233699'!$C$16 | D36: ='balance_raw_15233699'!$D$16 | E36: ='balance_raw_15233699'!$E$16 | F36: ='balance_raw_15233699'!$F$16 | H36: =IFERROR(B36/$B$36*100,"") | I36: =IFERROR(C36/$B$36*100,"") | J36: =IFERROR(D36/$B$36*100,"") | K36: =IFERROR(E36/$B$36*100,"") | L36: =IFERROR(F36/$B$36*100,"")
A37: Varer under fremstilling | B37: ='balance_raw_15233699'!$B$17 | C37: ='balance_raw_15233699'!$C$17 | D37: ='balance_raw_15233699'!$D$17 | E37: ='balance_raw_15233699'!$E$17 | F37: ='balance_raw_15233699'!$F$17 | H37: =IFERROR(B37/$B$37*100,"") | I37: =IFERROR(C37/$B$37*100,"") | J37: =IFERROR(D37/$B$37*100,"") | K37: =IFERROR(E37/$B$37*100,"") | L37: =IFERROR(F37/$B$37*100,"")
A38: Færdigvarer og handelsvarer | B38: ='balance_raw_15233699'!$B$18 | C38: ='balance_raw_15233699'!$C$18 | D38: ='balance_raw_15233699'!$D$18 | E38: ='balance_raw_15233699'!$E$18 | F38: ='balance_raw_15233699'!$F$18 | H38: =IFERROR(B38/$B$38*100,"") | I38: =IFERROR(C38/$B$38*100,"") | J38: =IFERROR(D38/$B$38*100,"") | K38: =IFERROR(E38/$B$38*100,"") | L38: =IFERROR(F38/$B$38*100,"")
A39: Varebeholdninger | B39: ='balance_raw_15233699'!$B$19 | C39: ='balance_raw_15233699'!$C$19 | D39: ='balance_raw_15233699'!$D$19 | E39: ='balance_raw_15233699'!$E$19 | F39: ='balance_raw_15233699'!$F$19 | H39: =IFERROR(B39/$B$39*100,"") | I39: =IFERROR(C39/$B$39*100,"") | J39: =IFERROR(D39/$B$39*100,"") | K39: =IFERROR(E39/$B$39*100,"") | L39: =IFERROR(F39/$B$39*100,"")
A40: Tilgodehavender fra salg og tjenesteydelser | B40: ='balance_raw_15233699'!$B$20 | C40: ='balance_raw_15233699'!$C$20 | D40: ='balance_raw_15233699'!$D$20 | E40: ='balance_raw_15233699'!$E$20 | F40: ='balance_raw_15233699'!$F$20 | H40: =IFERROR(B40/$B$40*100,"") | I40: =IFERROR(C40/$B$40*100,"") | J40: =IFERROR(D40/$B$40*100,"") | K40: =IFERROR(E40/$B$40*100,"") | L40: =IFERROR(F40/$B$40*100,"")
A41: Tilgodehavender hos tilknyttede virksomheder | B41: ='balance_raw_15233699'!$B$21 | C41: ='balance_raw_15233699'!$C$21 | D41: ='balance_raw_15233699'!$D$21 | E41: ='balance_raw_15233699'!$E$21 | F41: ='balance_raw_15233699'!$F$21 | H41: =IFERROR(B41/$B$41*100,"") | I41: =IFERROR(C41/$B$41*100,"") | J41: =IFERROR(D41/$B$41*100,"") | K41: =IFERROR(E41/$B$41*100,"") | L41: =IFERROR(F41/$B$41*100,"")
...

Sheet res_raw_15233699
A1: Odense Marcipan A/S (CVR 15233699) — Resultatopgørelse & nøgleoplysninger (t.kr.) | B1: 2021 | C1: 2022 | D1: 2023 | E1: 2024 | F1: 2025
A2: Nettoomsætning | B2: 534157 | C2: 553477 | D2: 591213 | E2: 628473 | F2: 667217
A3: Produktionsomkostninger | B3: 399299 | C3: 409930 | D3: 441052 | E3: 471871 | F3: 511234
A4: Bruttoresultat | B4: 134858 | C4: 143547 | D4: 150161 | E4: 156602 | F4: 155983
A5: Udviklingsomkostninger
A6: Salgs- og distributionsomkostninger | B6: 38890 | C6: 43839 | D6: 44582 | E6: 50749 | F6: 53767
A7: Administrationsomkostninger | B7: 35033 | C7: 34143 | D7: 33799 | E7: 39881 | F7: 40700
A8: Andre driftsindtægter
A9: Andre driftsomkostninger
A10: Resultat af primær drift | B10: 60935 | C10: 65565 | D10: 71780 | E10: 65972 | F10: 61516
A11: Indtægter af kapitalandele, dattervirksomheder | B11: 4098 | C11: 2901 | D11: 4097 | E11: 241 | F11: 3730
A12: Finansielle indtægter | E12: 511 | F12: 340
A13: Finansielle omkostninger | B13: 1073 | C13: 1822 | D13: 6146 | E13: 34898 | F13: 9400
A14: Finansielle poster, netto | B14: -1073 | C14: -1822 | D14: -6146 | E14: -11051 | F14: -5330
A15: Resultat før skat | B15: 63960 | C15: 66644 | D15: 69731 | E15: 54921 | F15: 56186
A16: Skat af årets resultat | B16: 12570 | C16: 14732 | D16: 14802 | E16: 11905 | F16: 11851
A17: Årets resultat | B17: 51390 | C17: 51912 | D17: 54929 | E17: 43016 | F17: 44335
A18: Gns. antal medarbejdere | B18: 263 | C18: 257 | D18: 250 | E18: 259 | F18: 266
A19: Investering i materielle anlægsaktiver | B19: 33768 | C19: 30044 | D19: 73030 | E19: 54403 | F19: 13894

Sheet balance_raw_15233699
A1: Odense Marcipan A/S (CVR 15233699) — Balance (t.kr.) | B1: 2021 | C1: 2022 | D1: 2023 | E1: 2024 | F1: 2025
A2: Udviklingsprojekter
A3: Patenter, varemærker mv.
A4: Goodwill | B4: 5479 | C4: 4993 | D4: 4507 | E4: 4021 | F4: 3535
A5: Immaterielle anlægsaktiver | B5: 5479 | C5: 4993 | D5: 4507 | E5: 30771 | F5: 27038
A6: Grunde og bygninger | B6: 61587 | C6: 60076 | D6: 63529 | E6: 78879 | F6: 72625
A7: Produktionsanlæg og maskiner | B7: 48891 | C7: 60176 | D7: 58181 | E7: 86231 | F7: 86817
A8: Driftsmateriel og inventar | B8: 6563 | C8: 9780 | D8: 7805 | E8: 14604 | F8: 16884
A9: Indretning af lejede lokaler
A10: Forudbetaling og anlægsaktiver under opførelse | B10: 15288 | C10: 11724 | D10: 63073 | E10: 12350 | F10: 3018
A11: Materielle anlægsaktiver | B11: 132329 | C11: 141756 | D11: 192588 | E11: 192064 | F11: 179344
A12: Kapitalandele, dattervirksomheder | B12: 26436 | C12: 27115 | D12: 27276 | E12: 26668 | F12: 29037
A13: Deposita
A14: Finansielle anlægsaktiver | B14: 26436 | C14: 27115 | D14: 27276 | E14: 26668 | F14: 29037
A15: Anlægsaktiver | B15: 164244 | C15: 173864 | D15: 224371 | E15: 249503 | F15: 235419
A16: Råvarer og hjælpematerialer | B16: 45103 | C16: 62430 | D16: 51127 | E16: 45959 | F16: 57397
A17: Varer under fremstilling
A18: Færdigvarer og handelsvarer | B18: 22181 | C18: 25131 | D18: 30832 | E18: 39344 | F18: 40551
A19: Varebeholdninger | B19: 67284 | C19: 87561 | D19: 81959 | E19: 85303 | F19: 97948
A20: Tilgodehavender fra salg og tjenesteydelser | B20: 114245 | C20: 112091 | D20: 124147 | E20: 131233 | F20: 130233
A21: Tilgodehavender hos tilknyttede virksomheder | B21: 32517 | C21: 33390 | D21: 27049 | E21: 33162 | F21: 52514
A22: Andre tilgodehavender | B22: 1862 | C22: 8712 | D22: 266 | E22: 3241 | F22: 4635
A23: Periodeafgrænsningsposter (aktiver) | B23: 978 | C23: 1271 | D23: 570 | E23: 768 | F23: 1392
A24: Udskudt skatteaktiv
A25: Tilgodehavende skat hos tilknyttede virksomheder
A26: Kortfristede skattetilgodehavender | B26: 0 | C26: 0 | E26: 7828 | F26: 0
A27: Tilgodehavender | B27: 149602 | C27: 155464 | D27: 152032 | E27: 176232 | F27: 188774
A28: Værdipapirer
A29: Likvide beholdninger | B29: 10 | C29: 18 | D29: 71 | E29: 17 | F29: 21
A30: Omsætningsaktiver | B30: 216896 | C30: 243043 | D30: 234062 | E30: 261552 | F30: 286743
A31: Aktiver | B31: 381140 | C31: 416907 | D31: 458433 | E31: 511055 | F31: 522162
A32: Selskabskapital | B32: 32000 | C32: 32000 | D32: 32000 | E32: 32000 | F32: 32000
A33: Reserve for nettoopskrivning (indre værdis metode) | D33: 5973 | E33: 6214 | F33: 6935
A34: Reserve for udviklingsomkostninger
A35: Reserve for sikringstransaktioner | B35: 378 | C35: -173 | D35: -200 | E35: 760 | F35: -126
A36: Andre reserver
A37: Overført resultat | B37: 68264 | C37: 55166 | D37: 79631 | E37: 87406 | F37: 91020
A38: Egenkapital i alt | B38: 175651 | C38: 149780 | D38: 140147 | E38: 158274 | F38: 168371
A39: Hensættelse til udskudt skat | B39: 5892 | C39: 6508 | D39: 6626 | E39: 14285 | F39: 13859
A40: Hensatte forpligtelser | B40: 6245 | C40: 6861 | D40: 6626 | E40: 14285 | F40: 13859
...

Sheet Simpel_funktion
A1: Odense Marcipan A/S (CVR 15233699) — Regnskabs- og nøgletal (CVR: 15233699) — funktionsopdelt
A3: Beløb i 1.000 kr. | B3: 2025 | C3: 2024 | D3: 2023 | F3: Note / XBRL-felt
A4: Uddrag af resultatopgørelse
A5: Nettoomsætning | B5: ='res_raw_15233699'!$F$2 | C5: ='res_raw_15233699'!$E$2 | D5: ='res_raw_15233699'!$D$2 | F5: fsa:Revenue
A6: Produktionsomkostninger | B6: =-'res_raw_15233699'!$F$3 | C6: =-'res_raw_15233699'!$E$3 | D6: =-'res_raw_15233699'!$D$3 | F6: fsa:CostOfProduction (vises negativt). Materialer, lønninger, produktionsoverhead.
A7: Bruttoresultat | B7: =IF(ABS((SUM(B5:B6))-'res_raw_15233699'!$F$4)<=2,SUM(B5:B6),'res_raw_15233699'!$F$4) | C7: =IF(ABS((SUM(C5:C6))-'res_raw_15233699'!$E$4)<=2,SUM(C5:C6),'res_raw_15233699'!$E$4) | D7: =IF(ABS((SUM(D5:D6))-'res_raw_15233699'!$D$4)<=2,SUM(D5:D6),'res_raw_15233699'!$D$4) | F7: Beregnet: Nettoomsætning − Produktionsomkostninger. Matcher fsa:GrossResult. Er komponenterne ikke indberettet, vises rapporteret fsa:GrossResult direkte.
A8: Udviklingsomkostninger | B8: =-'res_raw_15233699'!$F$5 | C8: =-'res_raw_15233699'!$E$5 | D8: =-'res_raw_15233699'!$D$5 | F8: ifrs-full:ResearchAndDevelopmentExpense (vises negativt). Udviklingsomkostninger ført i resultatet (v15_21; B&O m.fl.).
A9: Salgs- og distributionsomk. | B9: =-'res_raw_15233699'!$F$6 | C9: =-'res_raw_15233699'!$E$6 | D9: =-'res_raw_15233699'!$D$6 | F9: fsa:DistributionCosts (vises negativt). Marketing, salg, distribution.
A10: Administrationsomkostninger mv. | B10: =-'res_raw_15233699'!$F$7 | C10: =-'res_raw_15233699'!$E$7 | D10: =-'res_raw_15233699'!$D$7 | F10: fsa:AdministrativeExpenses (vises negativt). Generel administration.
A11: Andre driftsindtægter | B11: ='res_raw_15233699'!$F$8 | C11: ='res_raw_15233699'!$E$8 | D11: ='res_raw_15233699'!$D$8 | F11: fsa:OtherOperatingIncome. Sekundære driftsindtægter (huslejeindtægter, off. tilskud, avancer mv.).
A12: Andre driftsomkostninger | B12: =-'res_raw_15233699'!$F$9 | C12: =-'res_raw_15233699'!$E$9 | D12: =-'res_raw_15233699'!$D$9 | F12: fsa:OtherOperatingExpenses (vises negativt). Sekundære driftsomkostninger.
A13: Resultat af primær drift | B13: =IF(ABS((SUM(B7:B12))-'res_raw_15233699'!$F$10)<=2,SUM(B7:B12),'res_raw_15233699'!$F$10) | C13: =IF(ABS((SUM(C7:C12))-'res_raw_15233699'!$E$10)<=2,SUM(C7:C12),'res_raw_15233699'!$E$10) | D13: =IF(ABS((SUM(D7:D12))-'res_raw_15233699'!$D$10)<=2,SUM(D7:D12),'res_raw_15233699'!$D$10) | F13: Beregnet: Bruttoresultat − Udviklingsomk. − Salgs/dist. − Administration + Andre driftsindt. − Andre driftsomk. EBIT.
A14: Finansielle indtægter mv. | B14: =N('res_raw_15233699'!$F$11)+N('res_raw_15233699'!$F$12) | C14: =N('res_raw_15233699'!$E$11)+N('res_raw_15233699'!$E$12) | D14: =N('res_raw_15233699'!$D$11)+N('res_raw_15233699'!$D$12) | F14: fsa:IncomeFromSubsidiaries + fsa:OtherFinanceIncome.
A15: Finansielle omkostninger mv. | B15: =-'res_raw_15233699'!$F$13 | C15: =-'res_raw_15233699'!$E$13 | D15: =-'res_raw_15233699'!$D$13 | F15: fsa:OtherFinanceExpenses (vises negativt). Renteomkostninger, kurstab.
A16: Resultat før skat | B16: =IF(ABS((SUM(B13:B15))-'res_raw_15233699'!$F$15)<=2,SUM(B13:B15),'res_raw_15233699'!$F$15) | C16: =IF(ABS((SUM(C13:C15))-'res_raw_15233699'!$E$15)<=2,SUM(C13:C15),'res_raw_15233699'!$E$15) | D16: =IF(ABS((SUM(D13:D15))-'res_raw_15233699'!$D$15)<=2,SUM(D13:D15),'res_raw_15233699'!$D$15) | F16: Beregnet: EBIT + Fin. indtægter + Fin. omk. EBT.
A18: Uddrag af balance
A19: Anlægsaktiver | B19: ='balance_raw_15233699'!$F$15 | C19: ='balance_raw_15233699'!$E$15 | D19: ='balance_raw_15233699'!$D$15 | F19: fsa:NoncurrentAssets. Materielle, immaterielle og finansielle anlægsaktiver.
A20: Omsætningsaktiver | B20: ='balance_raw_15233699'!$F$30 | C20: ='balance_raw_15233699'!$E$30 | D20: ='balance_raw_15233699'!$D$30 | F20: fsa:CurrentAssets. Varebeholdninger, tilgodehavender, likvider.
A21: Aktiver i alt | B21: =SUM(B19:B20) | C21: =SUM(C19:C20) | D21: =SUM(D19:D20) | F21: Beregnet: Anlægsaktiver + Omsætningsaktiver. Bør matche fsa:Assets.
A23: Egenkapital | B23: ='balance_raw_15233699'!$F$38 | C23: ='balance_raw_15233699'!$E$38 | D23: ='balance_raw_15233699'!$D$38 | F23: fsa:Equity. Selskabskapital, overført resultat, reserver.
A24: Forpligtelser | B24: ='balance_raw_15233699'!$F$59-'balance_raw_15233699'!$F$38 | C24: ='balance_raw_15233699'!$E$59-'balance_raw_15233699'!$E$38 | D24: ='balance_raw_15233699'!$D$59-'balance_raw_15233699'!$D$38 | F24: Beregnet: Passiver (fsa:LiabilitiesAndEquity) − Egenkapital. Hensættelser + kort- og langfristet gæld.
A25: Passiver i alt | B25: =SUM(B23:B24) | C25: =SUM(C23:C24) | D25: =SUM(D23:D24) | F25: Beregnet: Egenkapital + Forpligtelser. Bør matche Aktiver i alt.
A27: Udvalgte balanceposter
A28: Varebeholdninger | B28: ='balance_raw_15233699'!$F$19 | C28: ='balance_raw_15233699'!$E$19 | D28: ='balance_raw_15233699'!$D$19 | F28: fsa:Inventories (eller fsa:ManufacturedGoodsAndGoodsForResale hvis total mangler).
A29: Tilgodehavender fra salg | B29: ='balance_raw_15233699'!$F$20 | C29: ='balance_raw_15233699'!$E$20 | D29: ='balance_raw_15233699'!$D$20 | F29: fsa:ShorttermTradeReceivables. Kortfristede tilgodehavender fra kunder.
A30: Kortfristede gældsforpligtelser | B30: ='balance_raw_15233699'!$F$57 | C30: ='balance_raw_15233699'!$E$57 | D30: ='balance_raw_15233699'!$D$57 | F30: fsa:ShorttermLiabilitiesOtherThanProvisions. Gæld der forfalder inden for 1 år.
A32: Rentabilitet
A33: Afkastningsgrad, % | B33: =IFERROR((B13+B14)/B21*100,"") | C33: =IFERROR((C13+C14)/C21*100,"") | D33: =IFERROR((D13+D14)/D21*100,"")
A34: Overskudsgrad, % | B34: =IFERROR((B13+B14)/B5*100,"") | C34: =IFERROR((C13+C14)/C5*100,"") | D34: =IFERROR((D13+D14)/D5*100,"")
A35: Aktivernes omsætningshastighed, gange | B35: =IFERROR(B5/B21,"") | C35: =IFERROR(C5/C21,"") | D35: =IFERROR(D5/D21,"")
A36: Gældsrente, % | B36: =IFERROR(-B15*100/B24,"") | C36: =IFERROR(-C15*100/C24,"") | D36: =IFERROR(-D15*100/D24,"")
A37: Egenkapitalens forrentning, % | B37: =IFERROR(B16/B23*100,"") | C37: =IFERROR(C16/C23*100,"") | D37: =IFERROR(D16/D23*100,"")
A38: Gearing, gange | B38: =IFERROR(B24/B23,"") | C38: =IFERROR(C24/C23,"") | D38: =IFERROR(D24/D23,"")
A40: Indekstal for indtjeningsevne (2023=100)
A41: Nettoomsætning | B41: =IFERROR(B5/$D5*100,"") | C41: =IFERROR(C5/$D5*100,"") | D41: =IFERROR(D5/$D5*100,"")
A42: Produktionsomkostninger | B42: =IFERROR(B6/$D6*100,"") | C42: =IFERROR(C6/$D6*100,"") | D42: =IFERROR(D6/$D6*100,"")
A43: Udviklingsomkostninger | B43: =IFERROR(B8/$D8*100,"") | C43: =IFERROR(C8/$D8*100,"") | D43: =IFERROR(D8/$D8*100,"")
A44: Salgs- og distributionsomk. | B44: =IFERROR(B9/$D9*100,"") | C44: =IFERROR(C9/$D9*100,"") | D44: =IFERROR(D9/$D9*100,"")
A45: Administrationsomk. | B45: =IFERROR(B10/$D10*100,"") | C45: =IFERROR(C10/$D10*100,"") | D45: =IFERROR(D10/$D10*100,"")
A46: Andre driftsomkostninger | B46: =IFERROR(B12/$D12*100,"") | C46: =IFERROR(C12/$D12*100,"") | D46: =IFERROR(D12/$D12*100,"")
...

Sheet Noter_info
A1: Odense Marcipan A/S (CVR 15233699) — Ukendte XBRL-felter — disse er noter og ikke en del af hoved-regnskabet
A2: Kategori | B2: Dansk navn | C2: XBRL feltnavn | D2: 2021 t.kr. | E2: 2022 t.kr. | F2: 2023 t.kr. | G2: 2024 t.kr. | H2: 2025 t.kr. | I2: Forklaring
A3: Øvrige (ukendt) | B3: fsa:Dividend | C3: fsa:Dividend | D3: 0 | E3: -75000 | F3: 65000 | G3: 25000 | H3: 35000 | I3: Ingen forklaring tilgængelig.
A4: Øvrige (ukendt) | B4: fsa:EmployeeExpenseAdministrativeExpenses | C4: fsa:EmployeeExpenseAdministrativeExpenses | H4: 17609 | I4: Ingen forklaring tilgængelig.
A5: Øvrige (ukendt) | B5: fsa:EmployeeExpenseDistributionCosts | C5: fsa:EmployeeExpenseDistributionCosts | H5: 22063 | I5: Ingen forklaring tilgængelig.
A6: Øvrige (ukendt) | B6: fsa:ProvisionsForInvestmentsInGroupEnterprises | C6: fsa:ProvisionsForInvestmentsInGroupEnterprises | D6: 353 | E6: 353 | F6: 0 | I6: Ingen forklaring tilgængelig.
A7: Øvrige (ukendt) | B7: fsa:ReserveForCurrentValueAdjustmentsOfCurrencyGains | C7: fsa:ReserveForCurrentValueAdjustmentsOfCurrencyGains | D7: 9 | E7: -2213 | F7: -2257 | G7: -3106 | H7: -1458 | I7: Ingen forklaring tilgængelig.
