Workbook

Sheet Overblik_26121264
A1: Danish Crown A/S (CVR 26121264) — Regnskabsanalyse – Resultatopgørelse & Balance (t.kr.) · Klasse C-stor · Revision · Regnskabsår 1/10–30/9 (forskudt)
H2: Indekstal (2021=100)
A3: Resultatopgørelse t.kr. | B3: 2021 | C3: 2022 | D3: 2023 | E3: 2024 | F3: 2025 | H3: 2021 | I3: 2022 | J3: 2023 | K3: 2024 | L3: 2025
A4: Nettoomsætning | B4: ='res_raw_26121264'!$B$2 | C4: ='res_raw_26121264'!$C$2 | D4: ='res_raw_26121264'!$D$2 | E4: ='res_raw_26121264'!$E$2 | F4: ='res_raw_26121264'!$F$2 | H4: =IFERROR(B4/$B$4*100,"") | I4: =IFERROR(C4/$B$4*100,"") | J4: =IFERROR(D4/$B$4*100,"") | K4: =IFERROR(E4/$B$4*100,"") | L4: =IFERROR(F4/$B$4*100,"")
A5: Produktionsomkostninger | B5: ='res_raw_26121264'!$B$3 | C5: ='res_raw_26121264'!$C$3 | D5: ='res_raw_26121264'!$D$3 | E5: ='res_raw_26121264'!$E$3 | F5: ='res_raw_26121264'!$F$3 | H5: =IFERROR(B5/$B$5*100,"") | I5: =IFERROR(C5/$B$5*100,"") | J5: =IFERROR(D5/$B$5*100,"") | K5: =IFERROR(E5/$B$5*100,"") | L5: =IFERROR(F5/$B$5*100,"")
A6: Bruttoresultat | B6: ='res_raw_26121264'!$B$4 | C6: ='res_raw_26121264'!$C$4 | D6: ='res_raw_26121264'!$D$4 | E6: ='res_raw_26121264'!$E$4 | F6: ='res_raw_26121264'!$F$4 | H6: =IFERROR(B6/$B$6*100,"") | I6: =IFERROR(C6/$B$6*100,"") | J6: =IFERROR(D6/$B$6*100,"") | K6: =IFERROR(E6/$B$6*100,"") | L6: =IFERROR(F6/$B$6*100,"")
A7: Udviklingsomkostninger | B7: ='res_raw_26121264'!$B$5 | C7: ='res_raw_26121264'!$C$5 | D7: ='res_raw_26121264'!$D$5 | E7: ='res_raw_26121264'!$E$5 | F7: ='res_raw_26121264'!$F$5 | H7: =IFERROR(B7/$B$7*100,"") | I7: =IFERROR(C7/$B$7*100,"") | J7: =IFERROR(D7/$B$7*100,"") | K7: =IFERROR(E7/$B$7*100,"") | L7: =IFERROR(F7/$B$7*100,"")
A8: Salgs- og distributionsomkostninger | B8: ='res_raw_26121264'!$B$6 | C8: ='res_raw_26121264'!$C$6 | D8: ='res_raw_26121264'!$D$6 | E8: ='res_raw_26121264'!$E$6 | F8: ='res_raw_26121264'!$F$6 | H8: =IFERROR(B8/$B$8*100,"") | I8: =IFERROR(C8/$B$8*100,"") | J8: =IFERROR(D8/$B$8*100,"") | K8: =IFERROR(E8/$B$8*100,"") | L8: =IFERROR(F8/$B$8*100,"")
A9: Administrationsomkostninger | B9: ='res_raw_26121264'!$B$7 | C9: ='res_raw_26121264'!$C$7 | D9: ='res_raw_26121264'!$D$7 | E9: ='res_raw_26121264'!$E$7 | F9: ='res_raw_26121264'!$F$7 | H9: =IFERROR(B9/$B$9*100,"") | I9: =IFERROR(C9/$B$9*100,"") | J9: =IFERROR(D9/$B$9*100,"") | K9: =IFERROR(E9/$B$9*100,"") | L9: =IFERROR(F9/$B$9*100,"")
A10: Andre driftsindtægter | B10: ='res_raw_26121264'!$B$8 | C10: ='res_raw_26121264'!$C$8 | D10: ='res_raw_26121264'!$D$8 | E10: ='res_raw_26121264'!$E$8 | F10: ='res_raw_26121264'!$F$8 | H10: =IFERROR(B10/$B$10*100,"") | I10: =IFERROR(C10/$B$10*100,"") | J10: =IFERROR(D10/$B$10*100,"") | K10: =IFERROR(E10/$B$10*100,"") | L10: =IFERROR(F10/$B$10*100,"")
A11: Andre driftsomkostninger | B11: ='res_raw_26121264'!$B$9 | C11: ='res_raw_26121264'!$C$9 | D11: ='res_raw_26121264'!$D$9 | E11: ='res_raw_26121264'!$E$9 | F11: ='res_raw_26121264'!$F$9 | H11: =IFERROR(B11/$B$11*100,"") | I11: =IFERROR(C11/$B$11*100,"") | J11: =IFERROR(D11/$B$11*100,"") | K11: =IFERROR(E11/$B$11*100,"") | L11: =IFERROR(F11/$B$11*100,"")
A12: Resultat af primær drift | B12: ='res_raw_26121264'!$B$10 | C12: ='res_raw_26121264'!$C$10 | D12: ='res_raw_26121264'!$D$10 | E12: ='res_raw_26121264'!$E$10 | F12: ='res_raw_26121264'!$F$10 | H12: =IFERROR(B12/$B$12*100,"") | I12: =IFERROR(C12/$B$12*100,"") | J12: =IFERROR(D12/$B$12*100,"") | K12: =IFERROR(E12/$B$12*100,"") | L12: =IFERROR(F12/$B$12*100,"")
A13: Indtægter af kapitalandele, dattervirksomheder | B13: ='res_raw_26121264'!$B$11 | C13: ='res_raw_26121264'!$C$11 | D13: ='res_raw_26121264'!$D$11 | E13: ='res_raw_26121264'!$E$11 | F13: ='res_raw_26121264'!$F$11 | H13: =IFERROR(B13/$B$13*100,"") | I13: =IFERROR(C13/$B$13*100,"") | J13: =IFERROR(D13/$B$13*100,"") | K13: =IFERROR(E13/$B$13*100,"") | L13: =IFERROR(F13/$B$13*100,"")
A14: Finansielle indtægter | B14: ='res_raw_26121264'!$B$12 | C14: ='res_raw_26121264'!$C$12 | D14: ='res_raw_26121264'!$D$12 | E14: ='res_raw_26121264'!$E$12 | F14: ='res_raw_26121264'!$F$12 | H14: =IFERROR(B14/$B$14*100,"") | I14: =IFERROR(C14/$B$14*100,"") | J14: =IFERROR(D14/$B$14*100,"") | K14: =IFERROR(E14/$B$14*100,"") | L14: =IFERROR(F14/$B$14*100,"")
A15: Finansielle omkostninger | B15: ='res_raw_26121264'!$B$13 | C15: ='res_raw_26121264'!$C$13 | D15: ='res_raw_26121264'!$D$13 | E15: ='res_raw_26121264'!$E$13 | F15: ='res_raw_26121264'!$F$13 | H15: =IFERROR(B15/$B$15*100,"") | I15: =IFERROR(C15/$B$15*100,"") | J15: =IFERROR(D15/$B$15*100,"") | K15: =IFERROR(E15/$B$15*100,"") | L15: =IFERROR(F15/$B$15*100,"")
A16: Finansielle poster, netto | B16: ='res_raw_26121264'!$B$14 | C16: ='res_raw_26121264'!$C$14 | D16: ='res_raw_26121264'!$D$14 | E16: ='res_raw_26121264'!$E$14 | F16: ='res_raw_26121264'!$F$14 | H16: =IFERROR(B16/$B$16*100,"") | I16: =IFERROR(C16/$B$16*100,"") | J16: =IFERROR(D16/$B$16*100,"") | K16: =IFERROR(E16/$B$16*100,"") | L16: =IFERROR(F16/$B$16*100,"")
A17: Resultat før skat | B17: ='res_raw_26121264'!$B$15 | C17: ='res_raw_26121264'!$C$15 | D17: ='res_raw_26121264'!$D$15 | E17: ='res_raw_26121264'!$E$15 | F17: ='res_raw_26121264'!$F$15 | H17: =IFERROR(B17/$B$17*100,"") | I17: =IFERROR(C17/$B$17*100,"") | J17: =IFERROR(D17/$B$17*100,"") | K17: =IFERROR(E17/$B$17*100,"") | L17: =IFERROR(F17/$B$17*100,"")
A18: Skat af årets resultat | B18: ='res_raw_26121264'!$B$16 | C18: ='res_raw_26121264'!$C$16 | D18: ='res_raw_26121264'!$D$16 | E18: ='res_raw_26121264'!$E$16 | F18: ='res_raw_26121264'!$F$16 | H18: =IFERROR(B18/$B$18*100,"") | I18: =IFERROR(C18/$B$18*100,"") | J18: =IFERROR(D18/$B$18*100,"") | K18: =IFERROR(E18/$B$18*100,"") | L18: =IFERROR(F18/$B$18*100,"")
A19: Årets resultat | B19: ='res_raw_26121264'!$B$17 | C19: ='res_raw_26121264'!$C$17 | D19: ='res_raw_26121264'!$D$17 | E19: ='res_raw_26121264'!$E$17 | F19: ='res_raw_26121264'!$F$17 | H19: =IFERROR(B19/$B$19*100,"") | I19: =IFERROR(C19/$B$19*100,"") | J19: =IFERROR(D19/$B$19*100,"") | K19: =IFERROR(E19/$B$19*100,"") | L19: =IFERROR(F19/$B$19*100,"")
A21: AKTIVER t.kr. | B21: 2021 | C21: 2022 | D21: 2023 | E21: 2024 | F21: 2025 | H21: 2021 | I21: 2022 | J21: 2023 | K21: 2024 | L21: 2025
A22: Udviklingsprojekter | B22: ='balance_raw_26121264'!$B$2 | C22: ='balance_raw_26121264'!$C$2 | D22: ='balance_raw_26121264'!$D$2 | E22: ='balance_raw_26121264'!$E$2 | F22: ='balance_raw_26121264'!$F$2 | H22: =IFERROR(B22/$B$22*100,"") | I22: =IFERROR(C22/$B$22*100,"") | J22: =IFERROR(D22/$B$22*100,"") | K22: =IFERROR(E22/$B$22*100,"") | L22: =IFERROR(F22/$B$22*100,"")
A23: Patenter, varemærker mv. | B23: ='balance_raw_26121264'!$B$3 | C23: ='balance_raw_26121264'!$C$3 | D23: ='balance_raw_26121264'!$D$3 | E23: ='balance_raw_26121264'!$E$3 | F23: ='balance_raw_26121264'!$F$3 | H23: =IFERROR(B23/$B$23*100,"") | I23: =IFERROR(C23/$B$23*100,"") | J23: =IFERROR(D23/$B$23*100,"") | K23: =IFERROR(E23/$B$23*100,"") | L23: =IFERROR(F23/$B$23*100,"")
A24: Goodwill | B24: ='balance_raw_26121264'!$B$4 | C24: ='balance_raw_26121264'!$C$4 | D24: ='balance_raw_26121264'!$D$4 | E24: ='balance_raw_26121264'!$E$4 | F24: ='balance_raw_26121264'!$F$4 | H24: =IFERROR(B24/$B$24*100,"") | I24: =IFERROR(C24/$B$24*100,"") | J24: =IFERROR(D24/$B$24*100,"") | K24: =IFERROR(E24/$B$24*100,"") | L24: =IFERROR(F24/$B$24*100,"")
A25: Immaterielle anlægsaktiver | B25: ='balance_raw_26121264'!$B$5 | C25: ='balance_raw_26121264'!$C$5 | D25: ='balance_raw_26121264'!$D$5 | E25: ='balance_raw_26121264'!$E$5 | F25: ='balance_raw_26121264'!$F$5 | H25: =IFERROR(B25/$B$25*100,"") | I25: =IFERROR(C25/$B$25*100,"") | J25: =IFERROR(D25/$B$25*100,"") | K25: =IFERROR(E25/$B$25*100,"") | L25: =IFERROR(F25/$B$25*100,"")
A26: Grunde og bygninger | B26: ='balance_raw_26121264'!$B$6 | C26: ='balance_raw_26121264'!$C$6 | D26: ='balance_raw_26121264'!$D$6 | E26: ='balance_raw_26121264'!$E$6 | F26: ='balance_raw_26121264'!$F$6 | H26: =IFERROR(B26/$B$26*100,"") | I26: =IFERROR(C26/$B$26*100,"") | J26: =IFERROR(D26/$B$26*100,"") | K26: =IFERROR(E26/$B$26*100,"") | L26: =IFERROR(F26/$B$26*100,"")
A27: Produktionsanlæg og maskiner | B27: ='balance_raw_26121264'!$B$7 | C27: ='balance_raw_26121264'!$C$7 | D27: ='balance_raw_26121264'!$D$7 | E27: ='balance_raw_26121264'!$E$7 | F27: ='balance_raw_26121264'!$F$7 | H27: =IFERROR(B27/$B$27*100,"") | I27: =IFERROR(C27/$B$27*100,"") | J27: =IFERROR(D27/$B$27*100,"") | K27: =IFERROR(E27/$B$27*100,"") | L27: =IFERROR(F27/$B$27*100,"")
A28: Driftsmateriel og inventar | B28: ='balance_raw_26121264'!$B$8 | C28: ='balance_raw_26121264'!$C$8 | D28: ='balance_raw_26121264'!$D$8 | E28: ='balance_raw_26121264'!$E$8 | F28: ='balance_raw_26121264'!$F$8 | H28: =IFERROR(B28/$B$28*100,"") | I28: =IFERROR(C28/$B$28*100,"") | J28: =IFERROR(D28/$B$28*100,"") | K28: =IFERROR(E28/$B$28*100,"") | L28: =IFERROR(F28/$B$28*100,"")
A29: Indretning af lejede lokaler | B29: ='balance_raw_26121264'!$B$9 | C29: ='balance_raw_26121264'!$C$9 | D29: ='balance_raw_26121264'!$D$9 | E29: ='balance_raw_26121264'!$E$9 | F29: ='balance_raw_26121264'!$F$9 | H29: =IFERROR(B29/$B$29*100,"") | I29: =IFERROR(C29/$B$29*100,"") | J29: =IFERROR(D29/$B$29*100,"") | K29: =IFERROR(E29/$B$29*100,"") | L29: =IFERROR(F29/$B$29*100,"")
A30: Forudbetaling og anlægsaktiver under opførelse | B30: ='balance_raw_26121264'!$B$10 | C30: ='balance_raw_26121264'!$C$10 | D30: ='balance_raw_26121264'!$D$10 | E30: ='balance_raw_26121264'!$E$10 | F30: ='balance_raw_26121264'!$F$10 | H30: =IFERROR(B30/$B$30*100,"") | I30: =IFERROR(C30/$B$30*100,"") | J30: =IFERROR(D30/$B$30*100,"") | K30: =IFERROR(E30/$B$30*100,"") | L30: =IFERROR(F30/$B$30*100,"")
A31: Materielle anlægsaktiver | B31: ='balance_raw_26121264'!$B$11 | C31: ='balance_raw_26121264'!$C$11 | D31: ='balance_raw_26121264'!$D$11 | E31: ='balance_raw_26121264'!$E$11 | F31: ='balance_raw_26121264'!$F$11 | H31: =IFERROR(B31/$B$31*100,"") | I31: =IFERROR(C31/$B$31*100,"") | J31: =IFERROR(D31/$B$31*100,"") | K31: =IFERROR(E31/$B$31*100,"") | L31: =IFERROR(F31/$B$31*100,"")
A32: Kapitalandele, dattervirksomheder | B32: ='balance_raw_26121264'!$B$12 | C32: ='balance_raw_26121264'!$C$12 | D32: ='balance_raw_26121264'!$D$12 | E32: ='balance_raw_26121264'!$E$12 | F32: ='balance_raw_26121264'!$F$12 | H32: =IFERROR(B32/$B$32*100,"") | I32: =IFERROR(C32/$B$32*100,"") | J32: =IFERROR(D32/$B$32*100,"") | K32: =IFERROR(E32/$B$32*100,"") | L32: =IFERROR(F32/$B$32*100,"")
A33: Deposita | B33: ='balance_raw_26121264'!$B$13 | C33: ='balance_raw_26121264'!$C$13 | D33: ='balance_raw_26121264'!$D$13 | E33: ='balance_raw_26121264'!$E$13 | F33: ='balance_raw_26121264'!$F$13 | H33: =IFERROR(B33/$B$33*100,"") | I33: =IFERROR(C33/$B$33*100,"") | J33: =IFERROR(D33/$B$33*100,"") | K33: =IFERROR(E33/$B$33*100,"") | L33: =IFERROR(F33/$B$33*100,"")
A34: Finansielle anlægsaktiver | B34: ='balance_raw_26121264'!$B$14 | C34: ='balance_raw_26121264'!$C$14 | D34: ='balance_raw_26121264'!$D$14 | E34: ='balance_raw_26121264'!$E$14 | F34: ='balance_raw_26121264'!$F$14 | H34: =IFERROR(B34/$B$34*100,"") | I34: =IFERROR(C34/$B$34*100,"") | J34: =IFERROR(D34/$B$34*100,"") | K34: =IFERROR(E34/$B$34*100,"") | L34: =IFERROR(F34/$B$34*100,"")
A35: Anlægsaktiver | B35: ='balance_raw_26121264'!$B$15 | C35: ='balance_raw_26121264'!$C$15 | D35: ='balance_raw_26121264'!$D$15 | E35: ='balance_raw_26121264'!$E$15 | F35: ='balance_raw_26121264'!$F$15 | H35: =IFERROR(B35/$B$35*100,"") | I35: =IFERROR(C35/$B$35*100,"") | J35: =IFERROR(D35/$B$35*100,"") | K35: =IFERROR(E35/$B$35*100,"") | L35: =IFERROR(F35/$B$35*100,"")
A36: Varebeholdninger | B36: ='balance_raw_26121264'!$B$16 | C36: ='balance_raw_26121264'!$C$16 | D36: ='balance_raw_26121264'!$D$16 | E36: ='balance_raw_26121264'!$E$16 | F36: ='balance_raw_26121264'!$F$16 | H36: =IFERROR(B36/$B$36*100,"") | I36: =IFERROR(C36/$B$36*100,"") | J36: =IFERROR(D36/$B$36*100,"") | K36: =IFERROR(E36/$B$36*100,"") | L36: =IFERROR(F36/$B$36*100,"")
A37: Tilgodehavender fra salg og tjenesteydelser | B37: ='balance_raw_26121264'!$B$17 | C37: ='balance_raw_26121264'!$C$17 | D37: ='balance_raw_26121264'!$D$17 | E37: ='balance_raw_26121264'!$E$17 | F37: ='balance_raw_26121264'!$F$17 | H37: =IFERROR(B37/$B$37*100,"") | I37: =IFERROR(C37/$B$37*100,"") | J37: =IFERROR(D37/$B$37*100,"") | K37: =IFERROR(E37/$B$37*100,"") | L37: =IFERROR(F37/$B$37*100,"")
A38: Tilgodehavender hos tilknyttede virksomheder | B38: ='balance_raw_26121264'!$B$18 | C38: ='balance_raw_26121264'!$C$18 | D38: ='balance_raw_26121264'!$D$18 | E38: ='balance_raw_26121264'!$E$18 | F38: ='balance_raw_26121264'!$F$18 | H38: =IFERROR(B38/$B$38*100,"") | I38: =IFERROR(C38/$B$38*100,"") | J38: =IFERROR(D38/$B$38*100,"") | K38: =IFERROR(E38/$B$38*100,"") | L38: =IFERROR(F38/$B$38*100,"")
A39: Andre tilgodehavender | B39: ='balance_raw_26121264'!$B$19 | C39: ='balance_raw_26121264'!$C$19 | D39: ='balance_raw_26121264'!$D$19 | E39: ='balance_raw_26121264'!$E$19 | F39: ='balance_raw_26121264'!$F$19 | H39: =IFERROR(B39/$B$39*100,"") | I39: =IFERROR(C39/$B$39*100,"") | J39: =IFERROR(D39/$B$39*100,"") | K39: =IFERROR(E39/$B$39*100,"") | L39: =IFERROR(F39/$B$39*100,"")
A40: Periodeafgrænsningsposter (aktiver) | B40: ='balance_raw_26121264'!$B$20 | C40: ='balance_raw_26121264'!$C$20 | D40: ='balance_raw_26121264'!$D$20 | E40: ='balance_raw_26121264'!$E$20 | F40: ='balance_raw_26121264'!$F$20 | H40: =IFERROR(B40/$B$40*100,"") | I40: =IFERROR(C40/$B$40*100,"") | J40: =IFERROR(D40/$B$40*100,"") | K40: =IFERROR(E40/$B$40*100,"") | L40: =IFERROR(F40/$B$40*100,"")
A41: Udskudt skatteaktiv | B41: ='balance_raw_26121264'!$B$21 | C41: ='balance_raw_26121264'!$C$21 | D41: ='balance_raw_26121264'!$D$21 | E41: ='balance_raw_26121264'!$E$21 | F41: ='balance_raw_26121264'!$F$21 | H41: =IFERROR(B41/$B$41*100,"") | I41: =IFERROR(C41/$B$41*100,"") | J41: =IFERROR(D41/$B$41*100,"") | K41: =IFERROR(E41/$B$41*100,"") | L41: =IFERROR(F41/$B$41*100,"")
...

Sheet res_raw_26121264
A1: Danish Crown A/S (CVR 26121264) — Resultatopgørelse & nøgleoplysninger (t.kr.) | B1: 2021 | C1: 2022 | D1: 2023 | E1: 2024 | F1: 2025
A2: Nettoomsætning | B2: 22887000 | C2: 23742000 | D2: 30212000 | E2: 29194000 | F2: 26149000
A3: Produktionsomkostninger | B3: 20806000 | C3: 21136000 | D3: 27240000 | E3: 25742000 | F3: 23421000
A4: Bruttoresultat | B4: 2081000 | C4: 2606000 | D4: 2972000 | E4: 3452000 | F4: 2728000
A5: Udviklingsomkostninger
A6: Salgs- og distributionsomkostninger | B6: 1790000 | C6: 1977000 | D6: 2144000 | E6: 1974000 | F6: 1762000
A7: Administrationsomkostninger | B7: 633000 | C7: 571000 | D7: 821000 | E7: 865000 | F7: 736000
A8: Andre driftsindtægter | B8: 5000 | C8: 1000 | D8: 40000 | E8: 0
A9: Andre driftsomkostninger | B9: 6000 | C9: 0
A10: Resultat af primær drift | B10: -343000 | C10: 59000 | D10: 47000 | E10: 613000 | F10: 230000
A11: Indtægter af kapitalandele, dattervirksomheder | B11: 1056000 | C11: 783000 | D11: 341000 | E11: -621000 | F11: -232000
A12: Finansielle indtægter | B12: 229000 | C12: 229000 | D12: 381000 | E12: 446000 | F12: 514000
A13: Finansielle omkostninger | B13: 273000 | C13: 283000 | D13: 660000 | E13: 778000 | F13: 772000
A14: Finansielle poster, netto | B14: 1112000 | C14: 784000 | D14: 61000 | E14: -644000 | F14: -485000
A15: Resultat før skat | B15: 769000 | C15: 843000 | D15: 108000 | E15: -31000 | F15: -255000
A16: Skat af årets resultat | B16: -53000 | C16: 42000 | D16: -106000 | E16: 66000 | F16: -16000
A17: Årets resultat | B17: 822000 | C17: 801000 | D17: 214000 | E17: -97000 | F17: -239000
A18: Gns. antal medarbejdere | B18: 6468 | C18: 6434 | D18: 7276 | E18: 6244 | F18: 6166
A19: Investering i materielle anlægsaktiver | B19: 406000 | C19: 502000 | D19: 690000 | E19: 344000 | F19: 437000

Sheet balance_raw_26121264
A1: Danish Crown A/S (CVR 26121264) — Balance (t.kr.) | B1: 2021 | C1: 2022 | D1: 2023 | E1: 2024 | F1: 2025
A2: Udviklingsprojekter | E2: 52000 | F2: 30000
A3: Patenter, varemærker mv. | B3: 0 | D3: 100000 | E3: 78000 | F3: 53000
A4: Goodwill | D4: 242000 | E4: 244000 | F4: 226000
A5: Immaterielle anlægsaktiver | B5: 53000 | C5: 34000 | D5: 394000 | E5: 374000 | F5: 309000
A6: Grunde og bygninger | B6: 1653000 | C6: 1530000 | D6: 2051000 | E6: 2010000 | F6: 1878000
A7: Produktionsanlæg og maskiner | B7: 701000 | C7: 673000 | D7: 1139000 | E7: 911000 | F7: 944000
A8: Driftsmateriel og inventar | B8: 45000 | C8: 42000 | D8: 91000 | E8: 69000 | F8: 55000
A9: Indretning af lejede lokaler | E9: 95000
A10: Forudbetaling og anlægsaktiver under opførelse | B10: 378000 | C10: 596000 | D10: 494000 | E10: 424000 | F10: 463000
A11: Materielle anlægsaktiver | B11: 2824000 | C11: 2883000 | D11: 3842000 | E11: 3509000 | F11: 3426000
A12: Kapitalandele, dattervirksomheder | B12: 4920000 | C12: 4994000 | D12: 4466000 | E12: 4251000 | F12: 3960000
A13: Deposita | B13: 4268000 | C13: 4281000 | D13: 4867000 | E13: 5181000 | F13: 5077000
A14: Finansielle anlægsaktiver | B14: 9395000 | C14: 9525000 | D14: 9520000 | E14: 9573000 | F14: 9183000
A15: Anlægsaktiver | B15: 12272000 | C15: 12442000 | D15: 13756000 | E15: 13456000 | F15: 12918000
A16: Varebeholdninger | B16: 1105000 | C16: 1302000 | D16: 1650000 | E16: 1347000 | F16: 1414000
A17: Tilgodehavender fra salg og tjenesteydelser | B17: 1520000 | C17: 1915000 | D17: 2233000 | E17: 2094000 | F17: 2110000
A18: Tilgodehavender hos tilknyttede virksomheder | B18: 3604000 | C18: 5757000 | D18: 6150000 | E18: 5478000 | F18: 5715000
A19: Andre tilgodehavender | B19: 307000 | C19: 379000 | D19: 364000 | E19: 293000 | F19: 331000
A20: Periodeafgrænsningsposter (aktiver) | B20: 25000 | C20: 23000 | D20: 47000 | E20: 34000 | F20: 44000
A21: Udskudt skatteaktiv
A22: Tilgodehavende skat hos tilknyttede virksomheder
A23: Kortfristede skattetilgodehavender | C23: 27000 | D23: 146000 | E23: 0 | F23: 17000
A24: Tilgodehavender | B24: 5468000 | C24: 8122000 | D24: 8981000 | E24: 7941000 | F24: 8236000
A25: Værdipapirer | B25: 39000 | C25: 30000 | D25: 32000 | E25: 0
A26: Likvide beholdninger | B26: 0
A27: Omsætningsaktiver | B27: 6612000 | C27: 9454000 | D27: 10663000 | E27: 9288000 | F27: 9650000
A28: Aktiver | B28: 18884000 | C28: 21896000 | D28: 24419000 | E28: 22744000 | F28: 22568000
A29: Selskabskapital | B29: 38000 | C29: 38000 | D29: 38000 | E29: 38000 | F29: 38000
A30: Reserve for nettoopskrivning (indre værdis metode)
A31: Reserve for udviklingsomkostninger
A32: Reserve for sikringstransaktioner | C32: 0 | D32: 7000 | E32: -52000 | F32: -8000
A33: Andre reserver | B33: 15000
A34: Overført resultat | B34: 3390000 | C34: 3962000 | D34: 4204000 | E34: 4222000 | F34: 3994000
A35: Egenkapital i alt | B35: 3443000 | C35: 4058000 | D35: 4265000 | E35: 4276000 | F35: 4041000
A36: Hensættelse til udskudt skat | B36: 84000 | C36: 274000 | D36: 372000 | E36: 248000 | F36: 268000
A37: Hensatte forpligtelser | B37: 136000 | C37: 383000 | D37: 530000 | E37: 466000 | F37: 441000
A38: Ansvarlig lånekapital (langfristet) | B38: 2500000 | C38: 2500000 | E38: 2500000 | F38: 2500000
A39: Langfristede lån | B39: 2608000 | C39: 2024000 | D39: 2117000 | E39: 2738000 | F39: 2711000
A40: Leasingforpligtelser (langfristet) | B40: 26000 | C40: 18000 | D40: 31000 | E40: 53000 | F40: 53000
...

Sheet Simpel_funktion
A1: Danish Crown A/S (CVR 26121264) — Regnskabs- og nøgletal (CVR: 26121264) — funktionsopdelt
A3: Beløb i 1.000 kr. | B3: 2025 | C3: 2024 | D3: 2023 | F3: Note / XBRL-felt
A4: Uddrag af resultatopgørelse
A5: Nettoomsætning | B5: ='res_raw_26121264'!$F$2 | C5: ='res_raw_26121264'!$E$2 | D5: ='res_raw_26121264'!$D$2 | F5: fsa:Revenue
A6: Produktionsomkostninger | B6: =-'res_raw_26121264'!$F$3 | C6: =-'res_raw_26121264'!$E$3 | D6: =-'res_raw_26121264'!$D$3 | F6: fsa:CostOfProduction (vises negativt). Materialer, lønninger, produktionsoverhead.
A7: Bruttoresultat | B7: =IF(ABS((SUM(B5:B6))-'res_raw_26121264'!$F$4)<=2,SUM(B5:B6),'res_raw_26121264'!$F$4) | C7: =IF(ABS((SUM(C5:C6))-'res_raw_26121264'!$E$4)<=2,SUM(C5:C6),'res_raw_26121264'!$E$4) | D7: =IF(ABS((SUM(D5:D6))-'res_raw_26121264'!$D$4)<=2,SUM(D5:D6),'res_raw_26121264'!$D$4) | F7: Beregnet: Nettoomsætning − Produktionsomkostninger. Matcher fsa:GrossResult. Er komponenterne ikke indberettet, vises rapporteret fsa:GrossResult direkte.
A8: Udviklingsomkostninger | B8: =-'res_raw_26121264'!$F$5 | C8: =-'res_raw_26121264'!$E$5 | D8: =-'res_raw_26121264'!$D$5 | F8: ifrs-full:ResearchAndDevelopmentExpense (vises negativt). Udviklingsomkostninger ført i resultatet (v15_21; B&O m.fl.).
A9: Salgs- og distributionsomk. | B9: =-'res_raw_26121264'!$F$6 | C9: =-'res_raw_26121264'!$E$6 | D9: =-'res_raw_26121264'!$D$6 | F9: fsa:DistributionCosts (vises negativt). Marketing, salg, distribution.
A10: Administrationsomkostninger mv. | B10: =-'res_raw_26121264'!$F$7 | C10: =-'res_raw_26121264'!$E$7 | D10: =-'res_raw_26121264'!$D$7 | F10: fsa:AdministrativeExpenses (vises negativt). Generel administration.
A11: Andre driftsindtægter | B11: ='res_raw_26121264'!$F$8 | C11: ='res_raw_26121264'!$E$8 | D11: ='res_raw_26121264'!$D$8 | F11: fsa:OtherOperatingIncome. Sekundære driftsindtægter (huslejeindtægter, off. tilskud, avancer mv.).
A12: Andre driftsomkostninger | B12: =-'res_raw_26121264'!$F$9 | C12: =-'res_raw_26121264'!$E$9 | D12: =-'res_raw_26121264'!$D$9 | F12: fsa:OtherOperatingExpenses (vises negativt). Sekundære driftsomkostninger.
A13: Resultat af primær drift | B13: =IF(ABS((SUM(B7:B12))-'res_raw_26121264'!$F$10)<=2,SUM(B7:B12),'res_raw_26121264'!$F$10) | C13: =IF(ABS((SUM(C7:C12))-'res_raw_26121264'!$E$10)<=2,SUM(C7:C12),'res_raw_26121264'!$E$10) | D13: =IF(ABS((SUM(D7:D12))-'res_raw_26121264'!$D$10)<=2,SUM(D7:D12),'res_raw_26121264'!$D$10) | F13: Beregnet: Bruttoresultat − Udviklingsomk. − Salgs/dist. − Administration + Andre driftsindt. − Andre driftsomk. EBIT.
A14: Finansielle indtægter mv. | B14: =N('res_raw_26121264'!$F$11)+N('res_raw_26121264'!$F$12) | C14: =N('res_raw_26121264'!$E$11)+N('res_raw_26121264'!$E$12) | D14: =N('res_raw_26121264'!$D$11)+N('res_raw_26121264'!$D$12) | F14: fsa:IncomeFromSubsidiaries + fsa:OtherFinanceIncome.
A15: Finansielle omkostninger mv. | B15: =-'res_raw_26121264'!$F$13 | C15: =-'res_raw_26121264'!$E$13 | D15: =-'res_raw_26121264'!$D$13 | F15: fsa:OtherFinanceExpenses (vises negativt). Renteomkostninger, kurstab.
A16: Resultat før skat | B16: =IF(ABS((SUM(B13:B15))-'res_raw_26121264'!$F$15)<=2,SUM(B13:B15),'res_raw_26121264'!$F$15) | C16: =IF(ABS((SUM(C13:C15))-'res_raw_26121264'!$E$15)<=2,SUM(C13:C15),'res_raw_26121264'!$E$15) | D16: =IF(ABS((SUM(D13:D15))-'res_raw_26121264'!$D$15)<=2,SUM(D13:D15),'res_raw_26121264'!$D$15) | F16: Beregnet: EBIT + Fin. indtægter + Fin. omk. EBT.
A18: Uddrag af balance
A19: Anlægsaktiver | B19: ='balance_raw_26121264'!$F$15 | C19: ='balance_raw_26121264'!$E$15 | D19: ='balance_raw_26121264'!$D$15 | F19: fsa:NoncurrentAssets. Materielle, immaterielle og finansielle anlægsaktiver.
A20: Omsætningsaktiver | B20: ='balance_raw_26121264'!$F$27 | C20: ='balance_raw_26121264'!$E$27 | D20: ='balance_raw_26121264'!$D$27 | F20: fsa:CurrentAssets. Varebeholdninger, tilgodehavender, likvider.
A21: Aktiver i alt | B21: =SUM(B19:B20) | C21: =SUM(C19:C20) | D21: =SUM(D19:D20) | F21: Beregnet: Anlægsaktiver + Omsætningsaktiver. Bør matche fsa:Assets.
A23: Egenkapital | B23: ='balance_raw_26121264'!$F$35 | C23: ='balance_raw_26121264'!$E$35 | D23: ='balance_raw_26121264'!$D$35 | F23: fsa:Equity. Selskabskapital, overført resultat, reserver.
A24: Forpligtelser | B24: ='balance_raw_26121264'!$F$56-'balance_raw_26121264'!$F$35 | C24: ='balance_raw_26121264'!$E$56-'balance_raw_26121264'!$E$35 | D24: ='balance_raw_26121264'!$D$56-'balance_raw_26121264'!$D$35 | F24: Beregnet: Passiver (fsa:LiabilitiesAndEquity) − Egenkapital. Hensættelser + kort- og langfristet gæld.
A25: Passiver i alt | B25: =SUM(B23:B24) | C25: =SUM(C23:C24) | D25: =SUM(D23:D24) | F25: Beregnet: Egenkapital + Forpligtelser. Bør matche Aktiver i alt.
A27: Udvalgte balanceposter
A28: Varebeholdninger | B28: ='balance_raw_26121264'!$F$16 | C28: ='balance_raw_26121264'!$E$16 | D28: ='balance_raw_26121264'!$D$16 | F28: fsa:Inventories (eller fsa:ManufacturedGoodsAndGoodsForResale hvis total mangler).
A29: Tilgodehavender fra salg | B29: ='balance_raw_26121264'!$F$17 | C29: ='balance_raw_26121264'!$E$17 | D29: ='balance_raw_26121264'!$D$17 | F29: fsa:ShorttermTradeReceivables. Kortfristede tilgodehavender fra kunder.
A30: Kortfristede gældsforpligtelser | B30: ='balance_raw_26121264'!$F$54 | C30: ='balance_raw_26121264'!$E$54 | D30: ='balance_raw_26121264'!$D$54 | F30: fsa:ShorttermLiabilitiesOtherThanProvisions. Gæld der forfalder inden for 1 år.
A32: Rentabilitet
A33: Afkastningsgrad, % | B33: =IFERROR((B13+B14)/B21*100,"") | C33: =IFERROR((C13+C14)/C21*100,"") | D33: =IFERROR((D13+D14)/D21*100,"")
A34: Overskudsgrad, % | B34: =IFERROR((B13+B14)/B5*100,"") | C34: =IFERROR((C13+C14)/C5*100,"") | D34: =IFERROR((D13+D14)/D5*100,"")
A35: Aktivernes omsætningshastighed, gange | B35: =IFERROR(B5/B21,"") | C35: =IFERROR(C5/C21,"") | D35: =IFERROR(D5/D21,"")
A36: Gældsrente, % | B36: =IFERROR(-B15*100/B24,"") | C36: =IFERROR(-C15*100/C24,"") | D36: =IFERROR(-D15*100/D24,"")
A37: Egenkapitalens forrentning, % | B37: =IFERROR(B16/B23*100,"") | C37: =IFERROR(C16/C23*100,"") | D37: =IFERROR(D16/D23*100,"")
A38: Gearing, gange | B38: =IFERROR(B24/B23,"") | C38: =IFERROR(C24/C23,"") | D38: =IFERROR(D24/D23,"")
A40: Indekstal for indtjeningsevne (2023=100)
A41: Nettoomsætning | B41: =IFERROR(B5/$D5*100,"") | C41: =IFERROR(C5/$D5*100,"") | D41: =IFERROR(D5/$D5*100,"")
A42: Produktionsomkostninger | B42: =IFERROR(B6/$D6*100,"") | C42: =IFERROR(C6/$D6*100,"") | D42: =IFERROR(D6/$D6*100,"")
A43: Udviklingsomkostninger | B43: =IFERROR(B8/$D8*100,"") | C43: =IFERROR(C8/$D8*100,"") | D43: =IFERROR(D8/$D8*100,"")
A44: Salgs- og distributionsomk. | B44: =IFERROR(B9/$D9*100,"") | C44: =IFERROR(C9/$D9*100,"") | D44: =IFERROR(D9/$D9*100,"")
A45: Administrationsomk. | B45: =IFERROR(B10/$D10*100,"") | C45: =IFERROR(C10/$D10*100,"") | D45: =IFERROR(D10/$D10*100,"")
A46: Andre driftsomkostninger | B46: =IFERROR(B12/$D12*100,"") | C46: =IFERROR(C12/$D12*100,"") | D46: =IFERROR(D12/$D12*100,"")
...

Sheet Noter_info
A1: Danish Crown A/S (CVR 26121264) — Ukendte XBRL-felter — disse er noter og ikke en del af hoved-regnskabet
A2: Kategori | B2: Dansk navn | C2: XBRL feltnavn | D2: 2021 t.kr. | E2: 2022 t.kr. | F2: 2023 t.kr. | G2: 2024 t.kr. | H2: 2025 t.kr. | I2: Forklaring
A3: Øvrige (ukendt) | B3: fsa:Dividend | C3: fsa:Dividend | F3: 0 | I3: Ingen forklaring tilgængelig.
A4: Øvrige (ukendt) | B4: fsa:IncomeFromInvestmentsInParticipatingInterests | C4: fsa:IncomeFromInvestmentsInParticipatingInterests | G4: 309000 | H4: 5000 | I4: Ingen forklaring tilgængelig.
A5: Øvrige (ukendt) | B5: fsa:LongtermParticipatingInterests | C5: fsa:LongtermParticipatingInterests | F5: 187000 | G5: 141000 | H5: 146000 | I5: Ingen forklaring tilgængelig.
A6: Øvrige (ukendt) | B6: fsa:OtherLongtermDebtRaisedByIssuanceOfBonds | C6: fsa:OtherLongtermDebtRaisedByIssuanceOfBonds | D6: 3492000 | E6: 2158000 | F6: 4875000 | G6: 4655000 | H6: 2539000 | I6: Ingen forklaring tilgængelig.
A7: Øvrige (ukendt) | B7: fsa:ReserveForCurrentValueAdjustmentsOfCurrencyGains | C7: fsa:ReserveForCurrentValueAdjustmentsOfCurrencyGains | E7: 58000 | F7: 16000 | G7: 68000 | H7: 17000 | I7: Ingen forklaring tilgængelig.
A8: Øvrige (ukendt) | B8: fsa:ShorttermPayablesToAssociates | C8: fsa:ShorttermPayablesToAssociates | D8: 29000 | I8: Ingen forklaring tilgængelig.
A9: Øvrige (ukendt) | B9: fsa:ShorttermPayablesToParticipatingInterest | C9: fsa:ShorttermPayablesToParticipatingInterest | E9: 72000 | F9: 27000 | G9: 0 | I9: Ingen forklaring tilgængelig.
A10: Øvrige (ukendt) | B10: fsa:ShorttermReceivablesFromParticipatingInterests | C10: fsa:ShorttermReceivablesFromParticipatingInterests | E10: 21000 | F10: 41000 | G10: 42000 | H10: 19000 | I10: Ingen forklaring tilgængelig.
