Workbook

Sheet Overblik_35663908
A1: KOMPAN Holding A/S (CVR 35663908) — Regnskabsanalyse – Resultatopgørelse & Balance (t.kr.) · Klasse C-stor · Independent Auditor’s Report
H2: Indekstal (2021=100)
A3: Resultatopgørelse t.kr. | B3: 2021 | C3: 2022 | D3: 2023 | E3: 2024 | F3: 2025 | H3: 2021 | I3: 2022 | J3: 2023 | K3: 2024 | L3: 2025
A4: Nettoomsætning | B4: ='res_raw_35663908'!$B$2 | C4: ='res_raw_35663908'!$C$2 | D4: ='res_raw_35663908'!$D$2 | E4: ='res_raw_35663908'!$E$2 | F4: ='res_raw_35663908'!$F$2 | H4: =IFERROR(B4/$B$4*100,"") | I4: =IFERROR(C4/$B$4*100,"") | J4: =IFERROR(D4/$B$4*100,"") | K4: =IFERROR(E4/$B$4*100,"") | L4: =IFERROR(F4/$B$4*100,"")
A5: Andre driftsindtægter | B5: ='res_raw_35663908'!$B$3 | C5: ='res_raw_35663908'!$C$3 | D5: ='res_raw_35663908'!$D$3 | E5: ='res_raw_35663908'!$E$3 | F5: ='res_raw_35663908'!$F$3 | H5: =IFERROR(B5/$B$5*100,"") | I5: =IFERROR(C5/$B$5*100,"") | J5: =IFERROR(D5/$B$5*100,"") | K5: =IFERROR(E5/$B$5*100,"") | L5: =IFERROR(F5/$B$5*100,"")
A6: Vareforbrug | B6: ='res_raw_35663908'!$B$4 | C6: ='res_raw_35663908'!$C$4 | D6: ='res_raw_35663908'!$D$4 | E6: ='res_raw_35663908'!$E$4 | F6: ='res_raw_35663908'!$F$4 | H6: =IFERROR(B6/$B$6*100,"") | I6: =IFERROR(C6/$B$6*100,"") | J6: =IFERROR(D6/$B$6*100,"") | K6: =IFERROR(E6/$B$6*100,"") | L6: =IFERROR(F6/$B$6*100,"")
A7: Andre eksterne omkostninger | B7: ='res_raw_35663908'!$B$5 | C7: ='res_raw_35663908'!$C$5 | D7: ='res_raw_35663908'!$D$5 | E7: ='res_raw_35663908'!$E$5 | F7: ='res_raw_35663908'!$F$5 | H7: =IFERROR(B7/$B$7*100,"") | I7: =IFERROR(C7/$B$7*100,"") | J7: =IFERROR(D7/$B$7*100,"") | K7: =IFERROR(E7/$B$7*100,"") | L7: =IFERROR(F7/$B$7*100,"")
A8: Bruttoresultat | B8: ='res_raw_35663908'!$B$6 | C8: ='res_raw_35663908'!$C$6 | D8: ='res_raw_35663908'!$D$6 | E8: ='res_raw_35663908'!$E$6 | F8: ='res_raw_35663908'!$F$6 | H8: =IFERROR(B8/$B$8*100,"") | I8: =IFERROR(C8/$B$8*100,"") | J8: =IFERROR(D8/$B$8*100,"") | K8: =IFERROR(E8/$B$8*100,"") | L8: =IFERROR(F8/$B$8*100,"")
A9: Personaleomkostninger | B9: ='res_raw_35663908'!$B$7 | C9: ='res_raw_35663908'!$C$7 | D9: ='res_raw_35663908'!$D$7 | E9: ='res_raw_35663908'!$E$7 | F9: ='res_raw_35663908'!$F$7 | H9: =IFERROR(B9/$B$9*100,"") | I9: =IFERROR(C9/$B$9*100,"") | J9: =IFERROR(D9/$B$9*100,"") | K9: =IFERROR(E9/$B$9*100,"") | L9: =IFERROR(F9/$B$9*100,"")
A10: Resultat før afskrivninger | B10: =IFERROR($B$8-ABS($B$9),"") | C10: =IFERROR($C$8-ABS($C$9),"") | D10: =IFERROR($D$8-ABS($D$9),"") | E10: =IFERROR($E$8-ABS($E$9),"") | F10: =IFERROR($F$8-ABS($F$9),"") | H10: =IFERROR(B10/$B$10*100,"") | I10: =IFERROR(C10/$B$10*100,"") | J10: =IFERROR(D10/$B$10*100,"") | K10: =IFERROR(E10/$B$10*100,"") | L10: =IFERROR(F10/$B$10*100,"")
A11: Af- og nedskrivninger | B11: ='res_raw_35663908'!$B$9 | C11: ='res_raw_35663908'!$C$9 | D11: ='res_raw_35663908'!$D$9 | E11: ='res_raw_35663908'!$E$9 | F11: ='res_raw_35663908'!$F$9 | H11: =IFERROR(B11/$B$11*100,"") | I11: =IFERROR(C11/$B$11*100,"") | J11: =IFERROR(D11/$B$11*100,"") | K11: =IFERROR(E11/$B$11*100,"") | L11: =IFERROR(F11/$B$11*100,"")
A12: Andre driftsomkostninger | B12: ='res_raw_35663908'!$B$10 | C12: ='res_raw_35663908'!$C$10 | D12: ='res_raw_35663908'!$D$10 | E12: ='res_raw_35663908'!$E$10 | F12: ='res_raw_35663908'!$F$10 | H12: =IFERROR(B12/$B$12*100,"") | I12: =IFERROR(C12/$B$12*100,"") | J12: =IFERROR(D12/$B$12*100,"") | K12: =IFERROR(E12/$B$12*100,"") | L12: =IFERROR(F12/$B$12*100,"")
A13: Resultat af primær drift | B13: ='res_raw_35663908'!$B$11 | C13: ='res_raw_35663908'!$C$11 | D13: ='res_raw_35663908'!$D$11 | E13: ='res_raw_35663908'!$E$11 | F13: ='res_raw_35663908'!$F$11 | H13: =IFERROR(B13/$B$13*100,"") | I13: =IFERROR(C13/$B$13*100,"") | J13: =IFERROR(D13/$B$13*100,"") | K13: =IFERROR(E13/$B$13*100,"") | L13: =IFERROR(F13/$B$13*100,"")
A14: Indtægter af kapitalandele, dattervirksomheder | B14: ='res_raw_35663908'!$B$12 | C14: ='res_raw_35663908'!$C$12 | D14: ='res_raw_35663908'!$D$12 | E14: ='res_raw_35663908'!$E$12 | F14: ='res_raw_35663908'!$F$12 | H14: =IFERROR(B14/$B$14*100,"") | I14: =IFERROR(C14/$B$14*100,"") | J14: =IFERROR(D14/$B$14*100,"") | K14: =IFERROR(E14/$B$14*100,"") | L14: =IFERROR(F14/$B$14*100,"")
A15: Finansielle indtægter | B15: ='res_raw_35663908'!$B$13 | C15: ='res_raw_35663908'!$C$13 | D15: ='res_raw_35663908'!$D$13 | E15: ='res_raw_35663908'!$E$13 | F15: ='res_raw_35663908'!$F$13 | H15: =IFERROR(B15/$B$15*100,"") | I15: =IFERROR(C15/$B$15*100,"") | J15: =IFERROR(D15/$B$15*100,"") | K15: =IFERROR(E15/$B$15*100,"") | L15: =IFERROR(F15/$B$15*100,"")
A16: Finansielle omkostninger | B16: ='res_raw_35663908'!$B$14 | C16: ='res_raw_35663908'!$C$14 | D16: ='res_raw_35663908'!$D$14 | E16: ='res_raw_35663908'!$E$14 | F16: ='res_raw_35663908'!$F$14 | H16: =IFERROR(B16/$B$16*100,"") | I16: =IFERROR(C16/$B$16*100,"") | J16: =IFERROR(D16/$B$16*100,"") | K16: =IFERROR(E16/$B$16*100,"") | L16: =IFERROR(F16/$B$16*100,"")
A17: Finansielle poster, netto | B17: ='res_raw_35663908'!$B$15 | C17: ='res_raw_35663908'!$C$15 | D17: ='res_raw_35663908'!$D$15 | E17: ='res_raw_35663908'!$E$15 | F17: ='res_raw_35663908'!$F$15 | H17: =IFERROR(B17/$B$17*100,"") | I17: =IFERROR(C17/$B$17*100,"") | J17: =IFERROR(D17/$B$17*100,"") | K17: =IFERROR(E17/$B$17*100,"") | L17: =IFERROR(F17/$B$17*100,"")
A18: Resultat før skat | B18: ='res_raw_35663908'!$B$16 | C18: ='res_raw_35663908'!$C$16 | D18: ='res_raw_35663908'!$D$16 | E18: ='res_raw_35663908'!$E$16 | F18: ='res_raw_35663908'!$F$16 | H18: =IFERROR(B18/$B$18*100,"") | I18: =IFERROR(C18/$B$18*100,"") | J18: =IFERROR(D18/$B$18*100,"") | K18: =IFERROR(E18/$B$18*100,"") | L18: =IFERROR(F18/$B$18*100,"")
A19: Skat af årets resultat | B19: ='res_raw_35663908'!$B$17 | C19: ='res_raw_35663908'!$C$17 | D19: ='res_raw_35663908'!$D$17 | E19: ='res_raw_35663908'!$E$17 | F19: ='res_raw_35663908'!$F$17 | H19: =IFERROR(B19/$B$19*100,"") | I19: =IFERROR(C19/$B$19*100,"") | J19: =IFERROR(D19/$B$19*100,"") | K19: =IFERROR(E19/$B$19*100,"") | L19: =IFERROR(F19/$B$19*100,"")
A20: Årets resultat | B20: ='res_raw_35663908'!$B$18 | C20: ='res_raw_35663908'!$C$18 | D20: ='res_raw_35663908'!$D$18 | E20: ='res_raw_35663908'!$E$18 | F20: ='res_raw_35663908'!$F$18 | H20: =IFERROR(B20/$B$20*100,"") | I20: =IFERROR(C20/$B$20*100,"") | J20: =IFERROR(D20/$B$20*100,"") | K20: =IFERROR(E20/$B$20*100,"") | L20: =IFERROR(F20/$B$20*100,"")
A22: AKTIVER t.kr. | B22: 2021 | C22: 2022 | D22: 2023 | E22: 2024 | F22: 2025 | H22: 2021 | I22: 2022 | J22: 2023 | K22: 2024 | L22: 2025
A23: Udviklingsprojekter | B23: ='balance_raw_35663908'!$B$2 | C23: ='balance_raw_35663908'!$C$2 | D23: ='balance_raw_35663908'!$D$2 | E23: ='balance_raw_35663908'!$E$2 | F23: ='balance_raw_35663908'!$F$2 | H23: =IFERROR(B23/$B$23*100,"") | I23: =IFERROR(C23/$B$23*100,"") | J23: =IFERROR(D23/$B$23*100,"") | K23: =IFERROR(E23/$B$23*100,"") | L23: =IFERROR(F23/$B$23*100,"")
A24: Patenter, varemærker mv. | B24: ='balance_raw_35663908'!$B$3 | C24: ='balance_raw_35663908'!$C$3 | D24: ='balance_raw_35663908'!$D$3 | E24: ='balance_raw_35663908'!$E$3 | F24: ='balance_raw_35663908'!$F$3 | H24: =IFERROR(B24/$B$24*100,"") | I24: =IFERROR(C24/$B$24*100,"") | J24: =IFERROR(D24/$B$24*100,"") | K24: =IFERROR(E24/$B$24*100,"") | L24: =IFERROR(F24/$B$24*100,"")
A25: Goodwill | B25: ='balance_raw_35663908'!$B$4 | C25: ='balance_raw_35663908'!$C$4 | D25: ='balance_raw_35663908'!$D$4 | E25: ='balance_raw_35663908'!$E$4 | F25: ='balance_raw_35663908'!$F$4 | H25: =IFERROR(B25/$B$25*100,"") | I25: =IFERROR(C25/$B$25*100,"") | J25: =IFERROR(D25/$B$25*100,"") | K25: =IFERROR(E25/$B$25*100,"") | L25: =IFERROR(F25/$B$25*100,"")
A26: Immaterielle anlægsaktiver | B26: ='balance_raw_35663908'!$B$5 | C26: ='balance_raw_35663908'!$C$5 | D26: ='balance_raw_35663908'!$D$5 | E26: ='balance_raw_35663908'!$E$5 | F26: ='balance_raw_35663908'!$F$5 | H26: =IFERROR(B26/$B$26*100,"") | I26: =IFERROR(C26/$B$26*100,"") | J26: =IFERROR(D26/$B$26*100,"") | K26: =IFERROR(E26/$B$26*100,"") | L26: =IFERROR(F26/$B$26*100,"")
A27: Grunde og bygninger | B27: ='balance_raw_35663908'!$B$6 | C27: ='balance_raw_35663908'!$C$6 | D27: ='balance_raw_35663908'!$D$6 | E27: ='balance_raw_35663908'!$E$6 | F27: ='balance_raw_35663908'!$F$6 | H27: =IFERROR(B27/$B$27*100,"") | I27: =IFERROR(C27/$B$27*100,"") | J27: =IFERROR(D27/$B$27*100,"") | K27: =IFERROR(E27/$B$27*100,"") | L27: =IFERROR(F27/$B$27*100,"")
A28: Produktionsanlæg og maskiner | B28: ='balance_raw_35663908'!$B$7 | C28: ='balance_raw_35663908'!$C$7 | D28: ='balance_raw_35663908'!$D$7 | E28: ='balance_raw_35663908'!$E$7 | F28: ='balance_raw_35663908'!$F$7 | H28: =IFERROR(B28/$B$28*100,"") | I28: =IFERROR(C28/$B$28*100,"") | J28: =IFERROR(D28/$B$28*100,"") | K28: =IFERROR(E28/$B$28*100,"") | L28: =IFERROR(F28/$B$28*100,"")
A29: Driftsmateriel og inventar | B29: ='balance_raw_35663908'!$B$8 | C29: ='balance_raw_35663908'!$C$8 | D29: ='balance_raw_35663908'!$D$8 | E29: ='balance_raw_35663908'!$E$8 | F29: ='balance_raw_35663908'!$F$8 | H29: =IFERROR(B29/$B$29*100,"") | I29: =IFERROR(C29/$B$29*100,"") | J29: =IFERROR(D29/$B$29*100,"") | K29: =IFERROR(E29/$B$29*100,"") | L29: =IFERROR(F29/$B$29*100,"")
A30: Indretning af lejede lokaler | B30: ='balance_raw_35663908'!$B$9 | C30: ='balance_raw_35663908'!$C$9 | D30: ='balance_raw_35663908'!$D$9 | E30: ='balance_raw_35663908'!$E$9 | F30: ='balance_raw_35663908'!$F$9 | H30: =IFERROR(B30/$B$30*100,"") | I30: =IFERROR(C30/$B$30*100,"") | J30: =IFERROR(D30/$B$30*100,"") | K30: =IFERROR(E30/$B$30*100,"") | L30: =IFERROR(F30/$B$30*100,"")
A31: Forudbetaling og anlægsaktiver under opførelse | B31: ='balance_raw_35663908'!$B$10 | C31: ='balance_raw_35663908'!$C$10 | D31: ='balance_raw_35663908'!$D$10 | E31: ='balance_raw_35663908'!$E$10 | F31: ='balance_raw_35663908'!$F$10 | H31: =IFERROR(B31/$B$31*100,"") | I31: =IFERROR(C31/$B$31*100,"") | J31: =IFERROR(D31/$B$31*100,"") | K31: =IFERROR(E31/$B$31*100,"") | L31: =IFERROR(F31/$B$31*100,"")
A32: Materielle anlægsaktiver | B32: ='balance_raw_35663908'!$B$11 | C32: ='balance_raw_35663908'!$C$11 | D32: ='balance_raw_35663908'!$D$11 | E32: ='balance_raw_35663908'!$E$11 | F32: ='balance_raw_35663908'!$F$11 | H32: =IFERROR(B32/$B$32*100,"") | I32: =IFERROR(C32/$B$32*100,"") | J32: =IFERROR(D32/$B$32*100,"") | K32: =IFERROR(E32/$B$32*100,"") | L32: =IFERROR(F32/$B$32*100,"")
A33: Kapitalandele, dattervirksomheder | B33: ='balance_raw_35663908'!$B$12 | C33: ='balance_raw_35663908'!$C$12 | D33: ='balance_raw_35663908'!$D$12 | E33: ='balance_raw_35663908'!$E$12 | F33: ='balance_raw_35663908'!$F$12 | H33: =IFERROR(B33/$B$33*100,"") | I33: =IFERROR(C33/$B$33*100,"") | J33: =IFERROR(D33/$B$33*100,"") | K33: =IFERROR(E33/$B$33*100,"") | L33: =IFERROR(F33/$B$33*100,"")
A34: Deposita | B34: ='balance_raw_35663908'!$B$13 | C34: ='balance_raw_35663908'!$C$13 | D34: ='balance_raw_35663908'!$D$13 | E34: ='balance_raw_35663908'!$E$13 | F34: ='balance_raw_35663908'!$F$13 | H34: =IFERROR(B34/$B$34*100,"") | I34: =IFERROR(C34/$B$34*100,"") | J34: =IFERROR(D34/$B$34*100,"") | K34: =IFERROR(E34/$B$34*100,"") | L34: =IFERROR(F34/$B$34*100,"")
A35: Finansielle anlægsaktiver | B35: ='balance_raw_35663908'!$B$14 | C35: ='balance_raw_35663908'!$C$14 | D35: ='balance_raw_35663908'!$D$14 | E35: ='balance_raw_35663908'!$E$14 | F35: ='balance_raw_35663908'!$F$14 | H35: =IFERROR(B35/$B$35*100,"") | I35: =IFERROR(C35/$B$35*100,"") | J35: =IFERROR(D35/$B$35*100,"") | K35: =IFERROR(E35/$B$35*100,"") | L35: =IFERROR(F35/$B$35*100,"")
A36: Anlægsaktiver | B36: ='balance_raw_35663908'!$B$15 | C36: ='balance_raw_35663908'!$C$15 | D36: ='balance_raw_35663908'!$D$15 | E36: ='balance_raw_35663908'!$E$15 | F36: ='balance_raw_35663908'!$F$15 | H36: =IFERROR(B36/$B$36*100,"") | I36: =IFERROR(C36/$B$36*100,"") | J36: =IFERROR(D36/$B$36*100,"") | K36: =IFERROR(E36/$B$36*100,"") | L36: =IFERROR(F36/$B$36*100,"")
A37: Råvarer og hjælpematerialer | B37: ='balance_raw_35663908'!$B$16 | C37: ='balance_raw_35663908'!$C$16 | D37: ='balance_raw_35663908'!$D$16 | E37: ='balance_raw_35663908'!$E$16 | F37: ='balance_raw_35663908'!$F$16 | H37: =IFERROR(B37/$B$37*100,"") | I37: =IFERROR(C37/$B$37*100,"") | J37: =IFERROR(D37/$B$37*100,"") | K37: =IFERROR(E37/$B$37*100,"") | L37: =IFERROR(F37/$B$37*100,"")
A38: Varer under fremstilling | B38: ='balance_raw_35663908'!$B$17 | C38: ='balance_raw_35663908'!$C$17 | D38: ='balance_raw_35663908'!$D$17 | E38: ='balance_raw_35663908'!$E$17 | F38: ='balance_raw_35663908'!$F$17 | H38: =IFERROR(B38/$B$38*100,"") | I38: =IFERROR(C38/$B$38*100,"") | J38: =IFERROR(D38/$B$38*100,"") | K38: =IFERROR(E38/$B$38*100,"") | L38: =IFERROR(F38/$B$38*100,"")
A39: Færdigvarer og handelsvarer | B39: ='balance_raw_35663908'!$B$18 | C39: ='balance_raw_35663908'!$C$18 | D39: ='balance_raw_35663908'!$D$18 | E39: ='balance_raw_35663908'!$E$18 | F39: ='balance_raw_35663908'!$F$18 | H39: =IFERROR(B39/$B$39*100,"") | I39: =IFERROR(C39/$B$39*100,"") | J39: =IFERROR(D39/$B$39*100,"") | K39: =IFERROR(E39/$B$39*100,"") | L39: =IFERROR(F39/$B$39*100,"")
A40: Varebeholdninger | B40: ='balance_raw_35663908'!$B$19 | C40: ='balance_raw_35663908'!$C$19 | D40: ='balance_raw_35663908'!$D$19 | E40: ='balance_raw_35663908'!$E$19 | F40: ='balance_raw_35663908'!$F$19 | H40: =IFERROR(B40/$B$40*100,"") | I40: =IFERROR(C40/$B$40*100,"") | J40: =IFERROR(D40/$B$40*100,"") | K40: =IFERROR(E40/$B$40*100,"") | L40: =IFERROR(F40/$B$40*100,"")
A41: Tilgodehavender fra salg og tjenesteydelser | B41: ='balance_raw_35663908'!$B$20 | C41: ='balance_raw_35663908'!$C$20 | D41: ='balance_raw_35663908'!$D$20 | E41: ='balance_raw_35663908'!$E$20 | F41: ='balance_raw_35663908'!$F$20 | H41: =IFERROR(B41/$B$41*100,"") | I41: =IFERROR(C41/$B$41*100,"") | J41: =IFERROR(D41/$B$41*100,"") | K41: =IFERROR(E41/$B$41*100,"") | L41: =IFERROR(F41/$B$41*100,"")
...

Sheet res_raw_35663908
A1: KOMPAN Holding A/S (CVR 35663908) — Resultatopgørelse & nøgleoplysninger (t.kr.) | B1: 2021 | C1: 2022 | D1: 2023 | E1: 2024 | F1: 2025
A2: Nettoomsætning | B2: 2381500 | C2: 3128500 | D2: 3377900 | E2: 3455600 | F2: 3822200
A3: Andre driftsindtægter | C3: 16500 | D3: 23600 | E3: 20600 | F3: 28800
A4: Vareforbrug | E4: 1859900 | F4: 2101400
A5: Andre eksterne omkostninger
A6: Bruttoresultat | B6: 1047600 | C6: 1339700 | D6: 1518200 | E6: 1595700 | F6: 1720800
A7: Personaleomkostninger | E7: 881400 | F7: 1025400
A8: Resultat før afskrivninger
A9: Af- og nedskrivninger
A10: Andre driftsomkostninger
A11: Resultat af primær drift | B11: 378200 | C11: 498300 | D11: 621400 | E11: 490800 | F11: 522000
A12: Indtægter af kapitalandele, dattervirksomheder
A13: Finansielle indtægter | B13: 29800 | C13: 101800 | D13: 25500 | E13: 20600 | F13: 42600
A14: Finansielle omkostninger | B14: 34100 | C14: 37200 | D14: 48800 | E14: 55900 | F14: 47300
A15: Finansielle poster, netto
A16: Resultat før skat | B16: 355900 | C16: 562900 | D16: 598100 | E16: 455500 | F16: 517300
A17: Skat af årets resultat | C17: 115400 | D17: 133700 | E17: 116200 | F17: 130000
A18: Årets resultat | B18: 279200 | C18: 447500 | D18: 464400 | E18: 339300 | F18: 387300
A19: Gns. antal medarbejdere | B19: 1488 | C19: 1811 | D19: 3 | E19: 1886 | F19: 2172
A20: Investering i materielle anlægsaktiver | B20: 19900 | C20: 39900 | D20: 59600 | E20: 102600

Sheet balance_raw_35663908
A1: KOMPAN Holding A/S (CVR 35663908) — Balance (t.kr.) | B1: 2021 | C1: 2022 | D1: 2023 | E1: 2024 | F1: 2025
A2: Udviklingsprojekter | E2: 64500 | F2: 54300
A3: Patenter, varemærker mv. | E3: 99800 | F3: 99900
A4: Goodwill | E4: 1056100 | F4: 965700
A5: Immaterielle anlægsaktiver | B5: 1288800 | C5: 1289800 | D5: 1295100 | E5: 1239900 | F5: 1161000
A6: Grunde og bygninger | E6: 156900 | F6: 153000
A7: Produktionsanlæg og maskiner | E7: 81700 | F7: 86300
A8: Driftsmateriel og inventar
A9: Indretning af lejede lokaler
A10: Forudbetaling og anlægsaktiver under opførelse | E10: 4700 | F10: 13000
A11: Materielle anlægsaktiver | C11: 145300 | D11: 179300 | E11: 243300 | F11: 252300
A12: Kapitalandele, dattervirksomheder | E12: 1312400 | F12: 1312400
A13: Deposita | E13: 100 | F13: 0
A14: Finansielle anlægsaktiver | E14: 12800 | F14: 24000
A15: Anlægsaktiver | B15: 1642900 | C15: 1714500 | D15: 1708000 | E15: 1496000 | F15: 1437300
A16: Råvarer og hjælpematerialer | E16: 74000 | F16: 72800
A17: Varer under fremstilling | E17: 59100 | F17: 74600
A18: Færdigvarer og handelsvarer | E18: 105300 | F18: 123800
A19: Varebeholdninger | B19: 168200 | C19: 260200 | D19: 219900 | E19: 238400 | F19: 271200
A20: Tilgodehavender fra salg og tjenesteydelser | B20: 462300 | E20: 554100 | F20: 617900
A21: Tilgodehavender hos tilknyttede virksomheder
A22: Andre tilgodehavender | E22: 43200 | F22: 22700
A23: Periodeafgrænsningsposter (aktiver) | B23: 42700 | C23: 54000 | D23: 48500 | E23: 67400 | F23: 79400
A24: Udskudt skatteaktiv | B24: 5400 | C24: 10100 | D24: 10400 | E24: 11400 | F24: 10900
A25: Tilgodehavende skat hos tilknyttede virksomheder
A26: Kortfristede skattetilgodehavender | C26: 9000 | D26: 0
A27: Tilgodehavender | B27: 38800 | C27: 65200 | D27: 41500 | E27: 732600 | F27: 775800
A28: Værdipapirer
A29: Likvide beholdninger | B29: 116000 | C29: 195100 | D29: 243900 | E29: 228000 | F29: 173800
A30: Omsætningsaktiver | B30: 845900 | C30: 1259600 | D30: 1177800 | E30: 1199000 | F30: 1220700
A31: Aktiver | B31: 2488800 | C31: 2974100 | D31: 2885800 | E31: 2695000 | F31: 2658000
A32: Selskabskapital | B32: 51900 | C32: 51900 | D32: 51900 | E32: 51900 | F32: 51900
A33: Reserve for nettoopskrivning (indre værdis metode)
A34: Reserve for udviklingsomkostninger
A35: Reserve for sikringstransaktioner
A36: Andre reserver | E36: -14400 | F36: -47700
A37: Overført resultat | B37: 756600 | C37: 955900 | D37: 982100 | E37: 821700 | F37: 701200
A38: Egenkapital i alt | B38: 1032100 | C38: 1220400 | D38: 1446800 | E38: 1377900 | F38: 1226500
A39: Hensættelse til udskudt skat | B39: 42800 | C39: 43300 | D39: 45300
A40: Hensatte forpligtelser | B40: 14000 | C40: 43300 | D40: 45300 | E40: 13300 | F40: 19900
...

Sheet pengestrom_raw_35663908
A1: KOMPAN Holding A/S (CVR 35663908) — Pengestrømsopgørelse (t.kr.) | B1: 2021 | C1: 2022 | D1: 2023 | E1: 2024 | F1: 2025
A2: Pengestrømme fra driftsaktivitet | B2: 259600 | C2: 324600 | D2: 711100
A3: Pengestrømme fra investeringsaktivitet | B3: -54800 | C3: -97900 | D3: -126700 | E3: -138800 | F3: -97700
A4: Pengestrømme fra finansieringsaktivitet | B4: -288800 | C4: -148900 | D4: -535500 | E4: -422400 | F4: -469800
A5: Årets pengestrøm | C5: 77800 | D5: 48900

Sheet Simpel_arts
A1: KOMPAN Holding A/S (CVR 35663908) — Regnskabs- og nøgletal (CVR: 35663908) — artsopdelt
A3: Beløb i 1.000 kr. | B3: 2025 | C3: 2024 | D3: 2023 | F3: Note / XBRL-felt
A4: Uddrag af resultatopgørelse
A5: Nettoomsætning | B5: ='res_raw_35663908'!$F$2 | C5: ='res_raw_35663908'!$E$2 | D5: ='res_raw_35663908'!$D$2 | F5: fsa:Revenue
A6: Andre driftsindtægter | B6: ='res_raw_35663908'!$F$3 | C6: ='res_raw_35663908'!$E$3 | D6: ='res_raw_35663908'!$D$3 | F6: fsa:OtherOperatingIncome. Indtægter fra sekundære aktiviteter (huslejeindtægter, avance ved salg af anlæg mv.).
A7: Vareforbrug | B7: =-'res_raw_35663908'!$F$4 | C7: =-'res_raw_35663908'!$E$4 | D7: =-'res_raw_35663908'!$D$4 | F7: fsa:CostOfSales (vises negativt for korrekt SUM-formel).
A8: Andre eksterne omk. mv. | B8: =-'res_raw_35663908'!$F$5 | C8: =-'res_raw_35663908'!$E$5 | D8: =-'res_raw_35663908'!$D$5 | F8: fsa:OtherExternalExpenses (vises negativt). Husleje, energi, kontorhold mv.
A9: Bruttofortjeneste | B9: =IF(COUNT('res_raw_35663908'!$F$2,'res_raw_35663908'!$F$3,'res_raw_35663908'!$F$4,'res_raw_35663908'!$F$5)=0,'res_raw_35663908'!$F$6,SUM(B5:B8)) | C9: =IF(COUNT('res_raw_35663908'!$E$2,'res_raw_35663908'!$E$3,'res_raw_35663908'!$E$4,'res_raw_35663908'!$E$5)=0,'res_raw_35663908'!$E$6,SUM(C5:C8)) | D9: =IF(COUNT('res_raw_35663908'!$D$2,'res_raw_35663908'!$D$3,'res_raw_35663908'!$D$4,'res_raw_35663908'!$D$5)=0,'res_raw_35663908'!$D$6,SUM(D5:D8)) | F9: Beregnet: Nettoomsætning + Andre driftsindt. − Vareforbrug − Andre ext. omk. Er komponenterne ikke indberettet, vises rapporteret bruttoresultat (fsa:GrossResult) direkte.
A10: Personaleomkostninger | B10: =-'res_raw_35663908'!$F$7 | C10: =-'res_raw_35663908'!$E$7 | D10: =-'res_raw_35663908'!$D$7 | F10: fsa:EmployeeBenefitsExpense (vises negativt). Lønninger, pension, sociale ydelser.
A11: Af- og nedskrivninger | B11: =-'res_raw_35663908'!$F$9 | C11: =-'res_raw_35663908'!$E$9 | D11: =-'res_raw_35663908'!$D$9 | F11: fsa:Depreciation (vises negativt). Af- og nedskrivninger på materielle og immaterielle anlægsaktiver.
A12: Andre driftsomkostninger | B12: =-'res_raw_35663908'!$F$10 | C12: =-'res_raw_35663908'!$E$10 | D12: =-'res_raw_35663908'!$D$10 | F12: fsa:OtherOperatingExpenses (vises negativt). Typisk 0 eller meget lille post.
A13: Resultat af primær drift | B13: =SUM(B9:B12) | C13: =SUM(C9:C12) | D13: =SUM(D9:D12) | F13: Beregnet: Bruttofortjeneste − Personaleomk. − Af- og nedskrivninger − Andre driftsomk. EBIT.
A14: Finansielle indtægter mv. | B14: =N('res_raw_35663908'!$F$12)+N('res_raw_35663908'!$F$13) | C14: =N('res_raw_35663908'!$E$12)+N('res_raw_35663908'!$E$13) | D14: =N('res_raw_35663908'!$D$12)+N('res_raw_35663908'!$D$13) | F14: fsa:IncomeFromSubsidiaries + fsa:OtherFinanceIncome.
A15: Finansielle omkostninger mv. | B15: =-'res_raw_35663908'!$F$14 | C15: =-'res_raw_35663908'!$E$14 | D15: =-'res_raw_35663908'!$D$14 | F15: fsa:OtherFinanceExpenses (vises negativt). Renteomkostninger, kurstab mv.
A16: Resultat før skat | B16: =SUM(B13:B15) | C16: =SUM(C13:C15) | D16: =SUM(D13:D15) | F16: Beregnet: EBIT + Fin. indtægter + Fin. omk. EBT.
A18: Uddrag af balance
A19: Anlægsaktiver | B19: ='balance_raw_35663908'!$F$15 | C19: ='balance_raw_35663908'!$E$15 | D19: ='balance_raw_35663908'!$D$15 | F19: fsa:NoncurrentAssets. Materielle, immaterielle og finansielle anlægsaktiver.
A20: Omsætningsaktiver | B20: ='balance_raw_35663908'!$F$30 | C20: ='balance_raw_35663908'!$E$30 | D20: ='balance_raw_35663908'!$D$30 | F20: fsa:CurrentAssets. Varebeholdninger, tilgodehavender, likvider.
A21: Aktiver i alt | B21: =SUM(B19:B20) | C21: =SUM(C19:C20) | D21: =SUM(D19:D20) | F21: Beregnet: Anlægsaktiver + Omsætningsaktiver. Bør matche fsa:Assets.
A23: Egenkapital | B23: ='balance_raw_35663908'!$F$38 | C23: ='balance_raw_35663908'!$E$38 | D23: ='balance_raw_35663908'!$D$38 | F23: fsa:Equity. Selskabskapital, overført resultat, reserver.
A24: Forpligtelser | B24: ='balance_raw_35663908'!$F$59-'balance_raw_35663908'!$F$38 | C24: ='balance_raw_35663908'!$E$59-'balance_raw_35663908'!$E$38 | D24: ='balance_raw_35663908'!$D$59-'balance_raw_35663908'!$D$38 | F24: Beregnet: Passiver (fsa:LiabilitiesAndEquity) − Egenkapital. Hensættelser + kort- og langfristet gæld.
A25: Passiver i alt | B25: =SUM(B23:B24) | C25: =SUM(C23:C24) | D25: =SUM(D23:D24) | F25: Beregnet: Egenkapital + Forpligtelser. Bør matche Aktiver i alt.
A27: Udvalgte balanceposter
A28: Varebeholdninger | B28: ='balance_raw_35663908'!$F$19 | C28: ='balance_raw_35663908'!$E$19 | D28: ='balance_raw_35663908'!$D$19 | F28: fsa:Inventories (eller fsa:ManufacturedGoodsAndGoodsForResale hvis total mangler).
A29: Tilgodehavender fra salg | B29: ='balance_raw_35663908'!$F$20 | C29: ='balance_raw_35663908'!$E$20 | D29: ='balance_raw_35663908'!$D$20 | F29: fsa:ShorttermTradeReceivables. Kortfristede tilgodehavender fra kunder.
A30: Kortfristede gældsforpligtelser | B30: ='balance_raw_35663908'!$F$57 | C30: ='balance_raw_35663908'!$E$57 | D30: ='balance_raw_35663908'!$D$57 | F30: fsa:ShorttermLiabilitiesOtherThanProvisions. Gæld der forfalder inden for 1 år.
A32: Rentabilitet
A33: Afkastningsgrad, % | B33: =IFERROR((B13+B14)/B21*100,"") | C33: =IFERROR((C13+C14)/C21*100,"") | D33: =IFERROR((D13+D14)/D21*100,"")
A34: Overskudsgrad, % | B34: =IFERROR((B13+B14)/B5*100,"") | C34: =IFERROR((C13+C14)/C5*100,"") | D34: =IFERROR((D13+D14)/D5*100,"")
A35: Aktivernes omsætningshastighed, gange | B35: =IFERROR(B5/B21,"") | C35: =IFERROR(C5/C21,"") | D35: =IFERROR(D5/D21,"")
A36: Gældsrente, % | B36: =IFERROR(-B15*100/B24,"") | C36: =IFERROR(-C15*100/C24,"") | D36: =IFERROR(-D15*100/D24,"")
A37: Egenkapitalens forrentning, % | B37: =IFERROR(B16/B23*100,"") | C37: =IFERROR(C16/C23*100,"") | D37: =IFERROR(D16/D23*100,"")
A38: Gearing, gange | B38: =IFERROR(B24/B23,"") | C38: =IFERROR(C24/C23,"") | D38: =IFERROR(D24/D23,"")
A40: Indekstal for indtjeningsevne (2023=100)
A41: Nettoomsætning | B41: =IFERROR(B5/$D5*100,"") | C41: =IFERROR(C5/$D5*100,"") | D41: =IFERROR(D5/$D5*100,"")
A42: Vareforbrug | B42: =IFERROR(B7/$D7*100,"") | C42: =IFERROR(C7/$D7*100,"") | D42: =IFERROR(D7/$D7*100,"")
A43: Andre eksterne omk. | B43: =IFERROR(B8/$D8*100,"") | C43: =IFERROR(C8/$D8*100,"") | D43: =IFERROR(D8/$D8*100,"")
A44: Personaleomkostninger | B44: =IFERROR(B10/$D10*100,"") | C44: =IFERROR(C10/$D10*100,"") | D44: =IFERROR(D10/$D10*100,"")
A45: Af- og nedskrivninger | B45: =IFERROR(B11/$D11*100,"") | C45: =IFERROR(C11/$D11*100,"") | D45: =IFERROR(D11/$D11*100,"")
A47: Indekstal for kapitaltilpasningsevne (2023=100)
...

Sheet Noter_info
A1: KOMPAN Holding A/S (CVR 35663908) — Ukendte XBRL-felter — disse er noter og ikke en del af hoved-regnskabet
A2: Kategori | B2: Dansk navn | C2: XBRL feltnavn | D2: 2021 t.kr. | E2: 2022 t.kr. | F2: 2023 t.kr. | G2: 2024 t.kr. | H2: 2025 t.kr. | I2: Forklaring
A3: Øvrige (ukendt) | B3: fsa:AcquisitionOfCompaniesAndActivitiesSpecification | C3: fsa:AcquisitionOfCompaniesAndActivitiesSpecification | G3: 3600 | H3: 0 | I3: Ingen forklaring tilgængelig.
A4: Øvrige (ukendt) | B4: fsa:CurrentContractAssets | C4: fsa:CurrentContractAssets | G4: 67900 | H4: 55700 | I4: Ingen forklaring tilgængelig.
A5: Øvrige (ukendt) | B5: fsa:CurrentContractLiabilities | C5: fsa:CurrentContractLiabilities | G5: 101400 | H5: 118500 | I5: Ingen forklaring tilgængelig.
A6: Øvrige (ukendt) | B6: fsa:DecreaseOfCapital | C6: fsa:DecreaseOfCapital | H6: 33300 | I6: Ingen forklaring tilgængelig.
A7: Øvrige (ukendt) | B7: fsa:EmployeeExpensesTransferredToAssets | C7: fsa:EmployeeExpensesTransferredToAssets | G7: -15200 | H7: -21300 | I7: Ingen forklaring tilgængelig.
A8: Øvrige (ukendt) | B8: fsa:FeesForAuditorsPerformingOtherAssuranceReports | C8: fsa:FeesForAuditorsPerformingOtherAssuranceReports | G8: 100 | H8: 0 | I8: Ingen forklaring tilgængelig.
A9: Øvrige (ukendt) | B9: fsa:InterestExpenseAssignedToAssociates | C9: fsa:InterestExpenseAssignedToAssociates | G9: 0 | H9: 700 | I9: Ingen forklaring tilgængelig.
A10: Øvrige (ukendt) | B10: fsa:InterestExpenseToParticipatingInterests | C10: fsa:InterestExpenseToParticipatingInterests | G10: 25700 | H10: 17900 | I10: Ingen forklaring tilgængelig.
A11: Øvrige (ukendt) | B11: fsa:InterestReceived | C11: fsa:InterestReceived | G11: -11800 | H11: -7700 | I11: Ingen forklaring tilgængelig.
A12: Øvrige (ukendt) | B12: fsa:LongtermTaxPayables | C12: fsa:LongtermTaxPayables | G12: 53300 | H12: 54100 | I12: Ingen forklaring tilgængelig.
A13: Øvrige (ukendt) | B13: fsa:NoncurrentContractLiabilities | C13: fsa:NoncurrentContractLiabilities | G13: 11100 | H13: 31100 | I13: Ingen forklaring tilgængelig.
A14: Øvrige (ukendt) | B14: fsa:OtherProvisionsLiabilitiesShortterm | C14: fsa:OtherProvisionsLiabilitiesShortterm | G14: 8800 | H14: 5000 | I14: Ingen forklaring tilgængelig.
A15: Øvrige (ukendt) | B15: fsa:PensionLiabilitiesRelatedToManagementCategory | C15: fsa:PensionLiabilitiesRelatedToManagementCategory | G15: 400 | H15: 300 | I15: Ingen forklaring tilgængelig.
A16: Øvrige (ukendt) | B16: fsa:PensionsAndSimilarLiabilitiesLiabilitiesLongterm | C16: fsa:PensionsAndSimilarLiabilitiesLiabilitiesLongterm | G16: 3500 | H16: 3900 | I16: Ingen forklaring tilgængelig.
A17: Øvrige (ukendt) | B17: fsa:SaleOfMinorityShares | C17: fsa:SaleOfMinorityShares | H17: 500 | I17: Ingen forklaring tilgængelig.
A18: Øvrige (ukendt) | B18: fsa:SaleOfTreasuryShares | C18: fsa:SaleOfTreasuryShares | G18: 8600 | H18: 10100 | I18: Ingen forklaring tilgængelig.
A19: Øvrige (ukendt) | B19: fsa:SalesOfTreasuryShares | C19: fsa:SalesOfTreasuryShares | H19: 9600 | I19: Ingen forklaring tilgængelig.
A20: Øvrige (ukendt) | B20: fsa:ShorttermReceivablesDividendsFromGroupEnterprises | C20: fsa:ShorttermReceivablesDividendsFromGroupEnterprises | G20: 7700 | H20: 5200 | I20: Ingen forklaring tilgængelig.
