Workbook

Sheet Overblik
A1: royaluni — Regnskabsanalyse – Resultatopgørelse & Balance (t.kr.)
H2: Indekstal (2021=100)
A3: Resultatopgørelse t.kr. | B3: 2021 | C3: 2022 | D3: 2023 | E3: 2024 | F3: 2025 | H3: 2021 | I3: 2022 | J3: 2023 | K3: 2024 | L3: 2025
A4: Nettoomsætning | B4: ='res_raw'!$B$2 | C4: ='res_raw'!$C$2 | D4: ='res_raw'!$D$2 | E4: ='res_raw'!$E$2 | F4: ='res_raw'!$F$2 | H4: =IFERROR(B4/$B$4*100,"") | I4: =IFERROR(C4/$B$4*100,"") | J4: =IFERROR(D4/$B$4*100,"") | K4: =IFERROR(E4/$B$4*100,"") | L4: =IFERROR(F4/$B$4*100,"")
A5: Produktionsomkostninger | B5: ='res_raw'!$B$3 | C5: ='res_raw'!$C$3 | D5: ='res_raw'!$D$3 | E5: ='res_raw'!$E$3 | F5: ='res_raw'!$F$3 | H5: =IFERROR(B5/$B$5*100,"") | I5: =IFERROR(C5/$B$5*100,"") | J5: =IFERROR(D5/$B$5*100,"") | K5: =IFERROR(E5/$B$5*100,"") | L5: =IFERROR(F5/$B$5*100,"")
A6: Bruttoresultat | B6: ='res_raw'!$B$4 | C6: ='res_raw'!$C$4 | D6: ='res_raw'!$D$4 | E6: ='res_raw'!$E$4 | F6: ='res_raw'!$F$4 | H6: =IFERROR(B6/$B$6*100,"") | I6: =IFERROR(C6/$B$6*100,"") | J6: =IFERROR(D6/$B$6*100,"") | K6: =IFERROR(E6/$B$6*100,"") | L6: =IFERROR(F6/$B$6*100,"")
A7: Udviklingsomkostninger | B7: ='res_raw'!$B$5 | C7: ='res_raw'!$C$5 | D7: ='res_raw'!$D$5 | E7: ='res_raw'!$E$5 | F7: ='res_raw'!$F$5 | H7: =IFERROR(B7/$B$7*100,"") | I7: =IFERROR(C7/$B$7*100,"") | J7: =IFERROR(D7/$B$7*100,"") | K7: =IFERROR(E7/$B$7*100,"") | L7: =IFERROR(F7/$B$7*100,"")
A8: Salgs- og distributionsomkostninger | B8: ='res_raw'!$B$6 | C8: ='res_raw'!$C$6 | D8: ='res_raw'!$D$6 | E8: ='res_raw'!$E$6 | F8: ='res_raw'!$F$6 | H8: =IFERROR(B8/$B$8*100,"") | I8: =IFERROR(C8/$B$8*100,"") | J8: =IFERROR(D8/$B$8*100,"") | K8: =IFERROR(E8/$B$8*100,"") | L8: =IFERROR(F8/$B$8*100,"")
A9: Administrationsomkostninger | B9: ='res_raw'!$B$7 | C9: ='res_raw'!$C$7 | D9: ='res_raw'!$D$7 | E9: ='res_raw'!$E$7 | F9: ='res_raw'!$F$7 | H9: =IFERROR(B9/$B$9*100,"") | I9: =IFERROR(C9/$B$9*100,"") | J9: =IFERROR(D9/$B$9*100,"") | K9: =IFERROR(E9/$B$9*100,"") | L9: =IFERROR(F9/$B$9*100,"")
A10: Andre driftsindtægter | B10: ='res_raw'!$B$8 | C10: ='res_raw'!$C$8 | D10: ='res_raw'!$D$8 | E10: ='res_raw'!$E$8 | F10: ='res_raw'!$F$8 | H10: =IFERROR(B10/$B$10*100,"") | I10: =IFERROR(C10/$B$10*100,"") | J10: =IFERROR(D10/$B$10*100,"") | K10: =IFERROR(E10/$B$10*100,"") | L10: =IFERROR(F10/$B$10*100,"")
A11: Andre driftsomkostninger | B11: ='res_raw'!$B$9 | C11: ='res_raw'!$C$9 | D11: ='res_raw'!$D$9 | E11: ='res_raw'!$E$9 | F11: ='res_raw'!$F$9 | H11: =IFERROR(B11/$B$11*100,"") | I11: =IFERROR(C11/$B$11*100,"") | J11: =IFERROR(D11/$B$11*100,"") | K11: =IFERROR(E11/$B$11*100,"") | L11: =IFERROR(F11/$B$11*100,"")
A12: Resultat af primær drift | B12: ='res_raw'!$B$10 | C12: ='res_raw'!$C$10 | D12: ='res_raw'!$D$10 | E12: ='res_raw'!$E$10 | F12: ='res_raw'!$F$10 | H12: =IFERROR(B12/$B$12*100,"") | I12: =IFERROR(C12/$B$12*100,"") | J12: =IFERROR(D12/$B$12*100,"") | K12: =IFERROR(E12/$B$12*100,"") | L12: =IFERROR(F12/$B$12*100,"")
A13: Indtægter af kapitalandele, dattervirksomheder | B13: ='res_raw'!$B$11 | C13: ='res_raw'!$C$11 | D13: ='res_raw'!$D$11 | E13: ='res_raw'!$E$11 | F13: ='res_raw'!$F$11 | H13: =IFERROR(B13/$B$13*100,"") | I13: =IFERROR(C13/$B$13*100,"") | J13: =IFERROR(D13/$B$13*100,"") | K13: =IFERROR(E13/$B$13*100,"") | L13: =IFERROR(F13/$B$13*100,"")
A14: Finansielle indtægter | B14: ='res_raw'!$B$12 | C14: ='res_raw'!$C$12 | D14: ='res_raw'!$D$12 | E14: ='res_raw'!$E$12 | F14: ='res_raw'!$F$12 | H14: =IFERROR(B14/$B$14*100,"") | I14: =IFERROR(C14/$B$14*100,"") | J14: =IFERROR(D14/$B$14*100,"") | K14: =IFERROR(E14/$B$14*100,"") | L14: =IFERROR(F14/$B$14*100,"")
A15: Finansielle omkostninger | B15: ='res_raw'!$B$13 | C15: ='res_raw'!$C$13 | D15: ='res_raw'!$D$13 | E15: ='res_raw'!$E$13 | F15: ='res_raw'!$F$13 | H15: =IFERROR(B15/$B$15*100,"") | I15: =IFERROR(C15/$B$15*100,"") | J15: =IFERROR(D15/$B$15*100,"") | K15: =IFERROR(E15/$B$15*100,"") | L15: =IFERROR(F15/$B$15*100,"")
A16: Finansielle poster, netto | B16: ='res_raw'!$B$14 | C16: ='res_raw'!$C$14 | D16: ='res_raw'!$D$14 | E16: ='res_raw'!$E$14 | F16: ='res_raw'!$F$14 | H16: =IFERROR(B16/$B$16*100,"") | I16: =IFERROR(C16/$B$16*100,"") | J16: =IFERROR(D16/$B$16*100,"") | K16: =IFERROR(E16/$B$16*100,"") | L16: =IFERROR(F16/$B$16*100,"")
A17: Resultat før skat | B17: ='res_raw'!$B$15 | C17: ='res_raw'!$C$15 | D17: ='res_raw'!$D$15 | E17: ='res_raw'!$E$15 | F17: ='res_raw'!$F$15 | H17: =IFERROR(B17/$B$17*100,"") | I17: =IFERROR(C17/$B$17*100,"") | J17: =IFERROR(D17/$B$17*100,"") | K17: =IFERROR(E17/$B$17*100,"") | L17: =IFERROR(F17/$B$17*100,"")
A18: Skat af årets resultat | B18: ='res_raw'!$B$16 | C18: ='res_raw'!$C$16 | D18: ='res_raw'!$D$16 | E18: ='res_raw'!$E$16 | F18: ='res_raw'!$F$16 | H18: =IFERROR(B18/$B$18*100,"") | I18: =IFERROR(C18/$B$18*100,"") | J18: =IFERROR(D18/$B$18*100,"") | K18: =IFERROR(E18/$B$18*100,"") | L18: =IFERROR(F18/$B$18*100,"")
A19: Årets resultat | B19: ='res_raw'!$B$17 | C19: ='res_raw'!$C$17 | D19: ='res_raw'!$D$17 | E19: ='res_raw'!$E$17 | F19: ='res_raw'!$F$17 | H19: =IFERROR(B19/$B$19*100,"") | I19: =IFERROR(C19/$B$19*100,"") | J19: =IFERROR(D19/$B$19*100,"") | K19: =IFERROR(E19/$B$19*100,"") | L19: =IFERROR(F19/$B$19*100,"")
A21: AKTIVER t.kr. | B21: 2021 | C21: 2022 | D21: 2023 | E21: 2024 | F21: 2025 | H21: 2021 | I21: 2022 | J21: 2023 | K21: 2024 | L21: 2025
A22: Udviklingsprojekter | B22: ='balance_raw'!$B$2 | C22: ='balance_raw'!$C$2 | D22: ='balance_raw'!$D$2 | E22: ='balance_raw'!$E$2 | F22: ='balance_raw'!$F$2 | H22: =IFERROR(B22/$B$22*100,"") | I22: =IFERROR(C22/$B$22*100,"") | J22: =IFERROR(D22/$B$22*100,"") | K22: =IFERROR(E22/$B$22*100,"") | L22: =IFERROR(F22/$B$22*100,"")
A23: Patenter, varemærker mv. | B23: ='balance_raw'!$B$3 | C23: ='balance_raw'!$C$3 | D23: ='balance_raw'!$D$3 | E23: ='balance_raw'!$E$3 | F23: ='balance_raw'!$F$3 | H23: =IFERROR(B23/$B$23*100,"") | I23: =IFERROR(C23/$B$23*100,"") | J23: =IFERROR(D23/$B$23*100,"") | K23: =IFERROR(E23/$B$23*100,"") | L23: =IFERROR(F23/$B$23*100,"")
A24: Goodwill | B24: ='balance_raw'!$B$4 | C24: ='balance_raw'!$C$4 | D24: ='balance_raw'!$D$4 | E24: ='balance_raw'!$E$4 | F24: ='balance_raw'!$F$4 | H24: =IFERROR(B24/$B$24*100,"") | I24: =IFERROR(C24/$B$24*100,"") | J24: =IFERROR(D24/$B$24*100,"") | K24: =IFERROR(E24/$B$24*100,"") | L24: =IFERROR(F24/$B$24*100,"")
A25: Immaterielle anlægsaktiver | B25: ='balance_raw'!$B$5 | C25: ='balance_raw'!$C$5 | D25: ='balance_raw'!$D$5 | E25: ='balance_raw'!$E$5 | F25: ='balance_raw'!$F$5 | H25: =IFERROR(B25/$B$25*100,"") | I25: =IFERROR(C25/$B$25*100,"") | J25: =IFERROR(D25/$B$25*100,"") | K25: =IFERROR(E25/$B$25*100,"") | L25: =IFERROR(F25/$B$25*100,"")
A26: Materielle anlægsaktiver | B26: ='balance_raw'!$B$6 | C26: ='balance_raw'!$C$6 | D26: ='balance_raw'!$D$6 | E26: ='balance_raw'!$E$6 | F26: ='balance_raw'!$F$6 | H26: =IFERROR(B26/$B$26*100,"") | I26: =IFERROR(C26/$B$26*100,"") | J26: =IFERROR(D26/$B$26*100,"") | K26: =IFERROR(E26/$B$26*100,"") | L26: =IFERROR(F26/$B$26*100,"")
A27: Kapitalandele, dattervirksomheder | B27: ='balance_raw'!$B$7 | C27: ='balance_raw'!$C$7 | D27: ='balance_raw'!$D$7 | E27: ='balance_raw'!$E$7 | F27: ='balance_raw'!$F$7 | H27: =IFERROR(B27/$B$27*100,"") | I27: =IFERROR(C27/$B$27*100,"") | J27: =IFERROR(D27/$B$27*100,"") | K27: =IFERROR(E27/$B$27*100,"") | L27: =IFERROR(F27/$B$27*100,"")
A28: Deposita | B28: ='balance_raw'!$B$8 | C28: ='balance_raw'!$C$8 | D28: ='balance_raw'!$D$8 | E28: ='balance_raw'!$E$8 | F28: ='balance_raw'!$F$8 | H28: =IFERROR(B28/$B$28*100,"") | I28: =IFERROR(C28/$B$28*100,"") | J28: =IFERROR(D28/$B$28*100,"") | K28: =IFERROR(E28/$B$28*100,"") | L28: =IFERROR(F28/$B$28*100,"")
A29: Finansielle anlægsaktiver | B29: ='balance_raw'!$B$9 | C29: ='balance_raw'!$C$9 | D29: ='balance_raw'!$D$9 | E29: ='balance_raw'!$E$9 | F29: ='balance_raw'!$F$9 | H29: =IFERROR(B29/$B$29*100,"") | I29: =IFERROR(C29/$B$29*100,"") | J29: =IFERROR(D29/$B$29*100,"") | K29: =IFERROR(E29/$B$29*100,"") | L29: =IFERROR(F29/$B$29*100,"")
A30: Anlægsaktiver | B30: ='balance_raw'!$B$10 | C30: ='balance_raw'!$C$10 | D30: ='balance_raw'!$D$10 | E30: ='balance_raw'!$E$10 | F30: ='balance_raw'!$F$10 | H30: =IFERROR(B30/$B$30*100,"") | I30: =IFERROR(C30/$B$30*100,"") | J30: =IFERROR(D30/$B$30*100,"") | K30: =IFERROR(E30/$B$30*100,"") | L30: =IFERROR(F30/$B$30*100,"")
A31: Varebeholdninger | B31: ='balance_raw'!$B$11 | C31: ='balance_raw'!$C$11 | D31: ='balance_raw'!$D$11 | E31: ='balance_raw'!$E$11 | F31: ='balance_raw'!$F$11 | H31: =IFERROR(B31/$B$31*100,"") | I31: =IFERROR(C31/$B$31*100,"") | J31: =IFERROR(D31/$B$31*100,"") | K31: =IFERROR(E31/$B$31*100,"") | L31: =IFERROR(F31/$B$31*100,"")
A32: Tilgodehavender fra salg og tjenesteydelser | B32: ='balance_raw'!$B$12 | C32: ='balance_raw'!$C$12 | D32: ='balance_raw'!$D$12 | E32: ='balance_raw'!$E$12 | F32: ='balance_raw'!$F$12 | H32: =IFERROR(B32/$B$32*100,"") | I32: =IFERROR(C32/$B$32*100,"") | J32: =IFERROR(D32/$B$32*100,"") | K32: =IFERROR(E32/$B$32*100,"") | L32: =IFERROR(F32/$B$32*100,"")
A33: Tilgodehavender hos tilknyttede virksomheder | B33: ='balance_raw'!$B$13 | C33: ='balance_raw'!$C$13 | D33: ='balance_raw'!$D$13 | E33: ='balance_raw'!$E$13 | F33: ='balance_raw'!$F$13 | H33: =IFERROR(B33/$B$33*100,"") | I33: =IFERROR(C33/$B$33*100,"") | J33: =IFERROR(D33/$B$33*100,"") | K33: =IFERROR(E33/$B$33*100,"") | L33: =IFERROR(F33/$B$33*100,"")
A34: Andre tilgodehavender | B34: ='balance_raw'!$B$14 | C34: ='balance_raw'!$C$14 | D34: ='balance_raw'!$D$14 | E34: ='balance_raw'!$E$14 | F34: ='balance_raw'!$F$14 | H34: =IFERROR(B34/$B$34*100,"") | I34: =IFERROR(C34/$B$34*100,"") | J34: =IFERROR(D34/$B$34*100,"") | K34: =IFERROR(E34/$B$34*100,"") | L34: =IFERROR(F34/$B$34*100,"")
A35: Periodeafgrænsningsposter (aktiver) | B35: ='balance_raw'!$B$15 | C35: ='balance_raw'!$C$15 | D35: ='balance_raw'!$D$15 | E35: ='balance_raw'!$E$15 | F35: ='balance_raw'!$F$15 | H35: =IFERROR(B35/$B$35*100,"") | I35: =IFERROR(C35/$B$35*100,"") | J35: =IFERROR(D35/$B$35*100,"") | K35: =IFERROR(E35/$B$35*100,"") | L35: =IFERROR(F35/$B$35*100,"")
A36: Udskudt skatteaktiv | B36: ='balance_raw'!$B$16 | C36: ='balance_raw'!$C$16 | D36: ='balance_raw'!$D$16 | E36: ='balance_raw'!$E$16 | F36: ='balance_raw'!$F$16 | H36: =IFERROR(B36/$B$36*100,"") | I36: =IFERROR(C36/$B$36*100,"") | J36: =IFERROR(D36/$B$36*100,"") | K36: =IFERROR(E36/$B$36*100,"") | L36: =IFERROR(F36/$B$36*100,"")
A37: Tilgodehavende skat hos tilknyttede virksomheder | B37: ='balance_raw'!$B$17 | C37: ='balance_raw'!$C$17 | D37: ='balance_raw'!$D$17 | E37: ='balance_raw'!$E$17 | F37: ='balance_raw'!$F$17 | H37: =IFERROR(B37/$B$37*100,"") | I37: =IFERROR(C37/$B$37*100,"") | J37: =IFERROR(D37/$B$37*100,"") | K37: =IFERROR(E37/$B$37*100,"") | L37: =IFERROR(F37/$B$37*100,"")
A38: Kortfristede skattetilgodehavender | B38: ='balance_raw'!$B$18 | C38: ='balance_raw'!$C$18 | D38: ='balance_raw'!$D$18 | E38: ='balance_raw'!$E$18 | F38: ='balance_raw'!$F$18 | H38: =IFERROR(B38/$B$38*100,"") | I38: =IFERROR(C38/$B$38*100,"") | J38: =IFERROR(D38/$B$38*100,"") | K38: =IFERROR(E38/$B$38*100,"") | L38: =IFERROR(F38/$B$38*100,"")
A39: Tilgodehavender | B39: ='balance_raw'!$B$19 | C39: ='balance_raw'!$C$19 | D39: ='balance_raw'!$D$19 | E39: ='balance_raw'!$E$19 | F39: ='balance_raw'!$F$19 | H39: =IFERROR(B39/$B$39*100,"") | I39: =IFERROR(C39/$B$39*100,"") | J39: =IFERROR(D39/$B$39*100,"") | K39: =IFERROR(E39/$B$39*100,"") | L39: =IFERROR(F39/$B$39*100,"")
A40: Værdipapirer | B40: ='balance_raw'!$B$20 | C40: ='balance_raw'!$C$20 | D40: ='balance_raw'!$D$20 | E40: ='balance_raw'!$E$20 | F40: ='balance_raw'!$F$20 | H40: =IFERROR(B40/$B$40*100,"") | I40: =IFERROR(C40/$B$40*100,"") | J40: =IFERROR(D40/$B$40*100,"") | K40: =IFERROR(E40/$B$40*100,"") | L40: =IFERROR(F40/$B$40*100,"")
A41: Likvide beholdninger | B41: ='balance_raw'!$B$21 | C41: ='balance_raw'!$C$21 | D41: ='balance_raw'!$D$21 | E41: ='balance_raw'!$E$21 | F41: ='balance_raw'!$F$21 | H41: =IFERROR(B41/$B$41*100,"") | I41: =IFERROR(C41/$B$41*100,"") | J41: =IFERROR(D41/$B$41*100,"") | K41: =IFERROR(E41/$B$41*100,"") | L41: =IFERROR(F41/$B$41*100,"")
...

Sheet res_raw
A1: royaluni — Resultatopgørelse & nøgleoplysninger (t.kr.) | B1: 2021 | C1: 2022 | D1: 2023 | E1: 2024 | F1: 2025
A2: Nettoomsætning | B2: 8746000 | C2: 11487000 | D2: 12927000 | E2: 15036000 | F2: 15723000
A3: Produktionsomkostninger | B3: 4490000 | C3: 6618000 | D3: 7533000 | E3: 8648000 | F3: 8957000
A4: Bruttoresultat | B4: 4256000 | C4: 4869000 | D4: 5394000 | E4: 6388000 | F4: 6766000
A5: Udviklingsomkostninger
A6: Salgs- og distributionsomkostninger | B6: 2189000 | C6: 2926000 | D6: 3158000 | E6: 3626000 | F6: 3638000
A7: Administrationsomkostninger | B7: 415000 | C7: 427000 | D7: 628000 | E7: 794000 | F7: 926000
A8: Andre driftsindtægter | D8: 30000 | E8: 0
A9: Andre driftsomkostninger
A10: Resultat af primær drift | B10: 1652000 | C10: 1516000 | D10: 1638000 | E10: 1968000 | F10: 2202000
A11: Indtægter af kapitalandele, dattervirksomheder | B11: 37000 | C11: 2000 | D11: 18000 | E11: -6000 | F11: 18000
A12: Finansielle indtægter | B12: 7000 | C12: 10000 | D12: 10000 | E12: 229000 | F12: 26000
A13: Finansielle omkostninger | B13: 49000 | C13: 103000 | D13: 260000 | E13: 326000 | F13: 280000
A14: Finansielle poster, netto
A15: Resultat før skat | B15: 1647000 | C15: 1785000 | D15: 1406000 | E15: 1865000 | F15: 1966000
A16: Skat af årets resultat | B16: 349000 | C16: 294000 | D16: 311000 | E16: 401000 | F16: 406000
A17: Årets resultat | B17: 1298000 | C17: 1491000 | D17: 1095000 | E17: 1464000 | F17: 1560000
A18: Gns. antal medarbejdere
A19: Investering i materielle anlægsaktiver | B19: 426000 | C19: 475000 | D19: 602000 | E19: 761000 | F19: 797000

Sheet balance_raw
A1: royaluni — Balance (t.kr.) | B1: 2021 | C1: 2022 | D1: 2023 | E1: 2024 | F1: 2025
A2: Udviklingsprojekter
A3: Patenter, varemærker mv.
A4: Goodwill | F4: 5161000
A5: Immaterielle anlægsaktiver | B5: 5861000 | C5: 7558000 | D5: 9469000 | E5: 9513000 | F5: 4485000
A6: Materielle anlægsaktiver | B6: 2734000 | C6: 3680000 | D6: 4662000 | E6: 4749000 | F6: 5120000
A7: Kapitalandele, dattervirksomheder | B7: 153000 | C7: 99000 | D7: 34000 | E7: 17000
A8: Deposita | B8: 23000 | C8: 79000 | D8: 89000 | E8: 73000 | F8: 65000
A9: Finansielle anlægsaktiver
A10: Anlægsaktiver | B10: 8771000 | C10: 11416000 | D10: 14254000 | E10: 14352000 | F10: 14831000
A11: Varebeholdninger | B11: 780000 | C11: 1213000 | D11: 1401000 | E11: 1340000 | F11: 1286000
A12: Tilgodehavender fra salg og tjenesteydelser | B12: 1188000 | C12: 1500000 | D12: 1901000 | E12: 1944000 | F12: 1918000
A13: Tilgodehavender hos tilknyttede virksomheder
A14: Andre tilgodehavender
A15: Periodeafgrænsningsposter (aktiver) | B15: 89000 | C15: 131000 | D15: 165000 | E15: 147000 | F15: 152000
A16: Udskudt skatteaktiv
A17: Tilgodehavende skat hos tilknyttede virksomheder
A18: Kortfristede skattetilgodehavender
A19: Tilgodehavender
A20: Værdipapirer
A21: Likvide beholdninger | B21: 86000 | C21: 214000 | D21: 57000 | E21: 103000 | F21: 82000
A22: Omsætningsaktiver | B22: 2143000 | C22: 3058000 | D22: 3524000 | E22: 3534000 | F22: 3438000
A23: Aktiver | B23: 10914000 | C23: 14474000 | D23: 17778000 | E23: 17886000 | F23: 18269000
A24: Selskabskapital | B24: 98000 | C24: 100000 | D24: 100000 | E24: 100000 | F24: 100000
A25: Reserve for nettoopskrivning (indre værdis metode)
A26: Reserve for udviklingsomkostninger
A27: Reserve for sikringstransaktioner
A28: Andre reserver | B28: 719000 | C28: 1567000 | D28: 1519000 | E28: 1407000 | F28: 1416000
A29: Overført resultat | B29: 1805000 | C29: 2763000 | D29: 4129000 | E29: 4148000 | F29: 4394000
A30: Egenkapital i alt | B30: 3330000 | C30: 5158000 | D30: 5748000 | E30: 6408000 | F30: 6713000
A31: Hensættelse til udskudt skat | B31: 747000 | C31: 1011000 | D31: 1281000 | E31: 1271000 | F31: 1277000
A32: Hensatte forpligtelser | B32: 11000 | C32: 11000 | D32: 11000 | E32: 11000 | F32: 1277000
A33: Ansvarlig lånekapital (langfristet)
A34: Langfristede lån
A35: Leasingforpligtelser (langfristet)
A36: Anden gæld (langfristet) | B36: 1003000 | C36: 1009000 | D36: 998000 | E36: 986000 | F36: 1009000
A37: Langfristede gældsforpligtelser | B37: 3771000 | C37: 4706000 | D37: 6786000 | E37: 5968000 | F37: 6710000
A38: Ansvarlig lånekapital (kortfristet)
A39: Kortfristet del af langfristede gældsforpligtelser
A40: Kreditinstitutter | B40: 14000 | C40: 2000 | D40: 11000 | E40: 19000
...

Sheet pengestrom_raw
A1: royaluni — Pengestrømsopgørelse (t.kr.) | B1: 2021 | C1: 2022 | D1: 2023 | E1: 2024 | F1: 2025
A2: Pengestrømme fra driftsaktivitet | B2: 1753000 | C2: 1135000 | D2: 1777000 | E2: 2189000 | F2: 2385000
A3: Pengestrømme fra investeringsaktivitet | B3: -1604000 | C3: -744000 | D3: -2925000 | E3: -651000 | F3: -954000
A4: Pengestrømme fra finansieringsaktivitet | B4: -146000 | C4: -252000 | D4: 998000 | E4: -1491000 | F4: -1454000
A5: Årets pengestrøm

Sheet Simpel_funktion
A1: royaluni — Regnskabs- og nøgletal — funktionsopdelt
A3: Beløb i 1.000 kr. | B3: 2025 | C3: 2024 | D3: 2023 | F3: Note / XBRL-felt
A4: Uddrag af resultatopgørelse
A5: Nettoomsætning | B5: ='res_raw'!$F$2 | C5: ='res_raw'!$E$2 | D5: ='res_raw'!$D$2 | F5: fsa:Revenue
A6: Produktionsomkostninger | B6: =-'res_raw'!$F$3 | C6: =-'res_raw'!$E$3 | D6: =-'res_raw'!$D$3 | F6: fsa:CostOfProduction (vises negativt). Materialer, lønninger, produktionsoverhead.
A7: Bruttoresultat | B7: =IF(ABS((SUM(B5:B6))-'res_raw'!$F$4)<=2,SUM(B5:B6),'res_raw'!$F$4) | C7: =IF(ABS((SUM(C5:C6))-'res_raw'!$E$4)<=2,SUM(C5:C6),'res_raw'!$E$4) | D7: =IF(ABS((SUM(D5:D6))-'res_raw'!$D$4)<=2,SUM(D5:D6),'res_raw'!$D$4) | F7: Beregnet: Nettoomsætning − Produktionsomkostninger. Matcher fsa:GrossResult. Er komponenterne ikke indberettet, vises rapporteret fsa:GrossResult direkte.
A8: Udviklingsomkostninger | B8: =-'res_raw'!$F$5 | C8: =-'res_raw'!$E$5 | D8: =-'res_raw'!$D$5 | F8: ifrs-full:ResearchAndDevelopmentExpense (vises negativt). Udviklingsomkostninger ført i resultatet (v15_21; B&O m.fl.).
A9: Salgs- og distributionsomk. | B9: =-'res_raw'!$F$6 | C9: =-'res_raw'!$E$6 | D9: =-'res_raw'!$D$6 | F9: fsa:DistributionCosts (vises negativt). Marketing, salg, distribution.
A10: Administrationsomkostninger mv. | B10: =-'res_raw'!$F$7 | C10: =-'res_raw'!$E$7 | D10: =-'res_raw'!$D$7 | F10: fsa:AdministrativeExpenses (vises negativt). Generel administration.
A11: Andre driftsindtægter | B11: ='res_raw'!$F$8 | C11: ='res_raw'!$E$8 | D11: ='res_raw'!$D$8 | F11: fsa:OtherOperatingIncome. Sekundære driftsindtægter (huslejeindtægter, off. tilskud, avancer mv.).
A12: Andre driftsomkostninger | B12: =-'res_raw'!$F$9 | C12: =-'res_raw'!$E$9 | D12: =-'res_raw'!$D$9 | F12: fsa:OtherOperatingExpenses (vises negativt). Sekundære driftsomkostninger.
A13: Resultat af primær drift | B13: =IF(ABS((SUM(B7:B12))-'res_raw'!$F$10)<=2,SUM(B7:B12),'res_raw'!$F$10) | C13: =IF(ABS((SUM(C7:C12))-'res_raw'!$E$10)<=2,SUM(C7:C12),'res_raw'!$E$10) | D13: =IF(ABS((SUM(D7:D12))-'res_raw'!$D$10)<=2,SUM(D7:D12),'res_raw'!$D$10) | F13: Beregnet: Bruttoresultat − Udviklingsomk. − Salgs/dist. − Administration + Andre driftsindt. − Andre driftsomk. EBIT.
A14: Finansielle indtægter mv. | B14: =N('res_raw'!$F$11)+N('res_raw'!$F$12) | C14: =N('res_raw'!$E$11)+N('res_raw'!$E$12) | D14: =N('res_raw'!$D$11)+N('res_raw'!$D$12) | F14: fsa:IncomeFromSubsidiaries + fsa:OtherFinanceIncome.
A15: Finansielle omkostninger mv. | B15: =-'res_raw'!$F$13 | C15: =-'res_raw'!$E$13 | D15: =-'res_raw'!$D$13 | F15: fsa:OtherFinanceExpenses (vises negativt). Renteomkostninger, kurstab.
A16: Resultat før skat | B16: =IF(ABS((SUM(B13:B15))-'res_raw'!$F$15)<=2,SUM(B13:B15),'res_raw'!$F$15) | C16: =IF(ABS((SUM(C13:C15))-'res_raw'!$E$15)<=2,SUM(C13:C15),'res_raw'!$E$15) | D16: =IF(ABS((SUM(D13:D15))-'res_raw'!$D$15)<=2,SUM(D13:D15),'res_raw'!$D$15) | F16: Beregnet: EBIT + Fin. indtægter + Fin. omk. EBT.
A18: Uddrag af balance
A19: Anlægsaktiver | B19: ='balance_raw'!$F$10 | C19: ='balance_raw'!$E$10 | D19: ='balance_raw'!$D$10 | F19: fsa:NoncurrentAssets. Materielle, immaterielle og finansielle anlægsaktiver.
A20: Omsætningsaktiver | B20: ='balance_raw'!$F$22 | C20: ='balance_raw'!$E$22 | D20: ='balance_raw'!$D$22 | F20: fsa:CurrentAssets. Varebeholdninger, tilgodehavender, likvider.
A21: Aktiver i alt | B21: =SUM(B19:B20) | C21: =SUM(C19:C20) | D21: =SUM(D19:D20) | F21: Beregnet: Anlægsaktiver + Omsætningsaktiver. Bør matche fsa:Assets.
A23: Egenkapital | B23: ='balance_raw'!$F$30 | C23: ='balance_raw'!$E$30 | D23: ='balance_raw'!$D$30 | F23: fsa:Equity. Selskabskapital, overført resultat, reserver.
A24: Forpligtelser | B24: ='balance_raw'!$F$51-'balance_raw'!$F$30 | C24: ='balance_raw'!$E$51-'balance_raw'!$E$30 | D24: ='balance_raw'!$D$51-'balance_raw'!$D$30 | F24: Beregnet: Passiver (fsa:LiabilitiesAndEquity) − Egenkapital. Hensættelser + kort- og langfristet gæld.
A25: Passiver i alt | B25: =SUM(B23:B24) | C25: =SUM(C23:C24) | D25: =SUM(D23:D24) | F25: Beregnet: Egenkapital + Forpligtelser. Bør matche Aktiver i alt.
A27: Udvalgte balanceposter
A28: Varebeholdninger | B28: ='balance_raw'!$F$11 | C28: ='balance_raw'!$E$11 | D28: ='balance_raw'!$D$11 | F28: fsa:Inventories (eller fsa:ManufacturedGoodsAndGoodsForResale hvis total mangler).
A29: Tilgodehavender fra salg | B29: ='balance_raw'!$F$12 | C29: ='balance_raw'!$E$12 | D29: ='balance_raw'!$D$12 | F29: fsa:ShorttermTradeReceivables. Kortfristede tilgodehavender fra kunder.
A30: Kortfristede gældsforpligtelser | B30: ='balance_raw'!$F$49 | C30: ='balance_raw'!$E$49 | D30: ='balance_raw'!$D$49 | F30: fsa:ShorttermLiabilitiesOtherThanProvisions. Gæld der forfalder inden for 1 år.
A32: Rentabilitet
A33: Afkastningsgrad, % | B33: =IFERROR((B13+B14)/B21*100,"") | C33: =IFERROR((C13+C14)/C21*100,"") | D33: =IFERROR((D13+D14)/D21*100,"")
A34: Overskudsgrad, % | B34: =IFERROR((B13+B14)/B5*100,"") | C34: =IFERROR((C13+C14)/C5*100,"") | D34: =IFERROR((D13+D14)/D5*100,"")
A35: Aktivernes omsætningshastighed, gange | B35: =IFERROR(B5/B21,"") | C35: =IFERROR(C5/C21,"") | D35: =IFERROR(D5/D21,"")
A36: Gældsrente, % | B36: =IFERROR(-B15*100/B24,"") | C36: =IFERROR(-C15*100/C24,"") | D36: =IFERROR(-D15*100/D24,"")
A37: Egenkapitalens forrentning, % | B37: =IFERROR(B16/B23*100,"") | C37: =IFERROR(C16/C23*100,"") | D37: =IFERROR(D16/D23*100,"")
A38: Gearing, gange | B38: =IFERROR(B24/B23,"") | C38: =IFERROR(C24/C23,"") | D38: =IFERROR(D24/D23,"")
A40: Indekstal for indtjeningsevne (2023=100)
A41: Nettoomsætning | B41: =IFERROR(B5/$D5*100,"") | C41: =IFERROR(C5/$D5*100,"") | D41: =IFERROR(D5/$D5*100,"")
A42: Produktionsomkostninger | B42: =IFERROR(B6/$D6*100,"") | C42: =IFERROR(C6/$D6*100,"") | D42: =IFERROR(D6/$D6*100,"")
A43: Udviklingsomkostninger | B43: =IFERROR(B8/$D8*100,"") | C43: =IFERROR(C8/$D8*100,"") | D43: =IFERROR(D8/$D8*100,"")
A44: Salgs- og distributionsomk. | B44: =IFERROR(B9/$D9*100,"") | C44: =IFERROR(C9/$D9*100,"") | D44: =IFERROR(D9/$D9*100,"")
A45: Administrationsomk. | B45: =IFERROR(B10/$D10*100,"") | C45: =IFERROR(C10/$D10*100,"") | D45: =IFERROR(D10/$D10*100,"")
A46: Andre driftsomkostninger | B46: =IFERROR(B12/$D12*100,"") | C46: =IFERROR(C12/$D12*100,"") | D46: =IFERROR(D12/$D12*100,"")
...
