Workbook

Sheet Overblik_43705660
A1: THURØ BRYGHUS APS (CVR 43705660) — Regnskabsanalyse – Resultatopgørelse & Balance (t.kr.) · Klasse B · Andre erklæringer uden sikkerh
G2: Indekstal (2022=100)
A3: Resultatopgørelse t.kr. | B3: 2022 | C3: 2023 | D3: 2024 | E3: 2025 | G3: 2022 | H3: 2023 | I3: 2024 | J3: 2025
A4: Nettoomsætning | B4: ='res_raw_43705660'!$B$2 | C4: ='res_raw_43705660'!$C$2 | D4: ='res_raw_43705660'!$D$2 | E4: ='res_raw_43705660'!$E$2 | G4: =IFERROR(B4/$B$4*100,"") | H4: =IFERROR(C4/$B$4*100,"") | I4: =IFERROR(D4/$B$4*100,"") | J4: =IFERROR(E4/$B$4*100,"")
A5: Andre driftsindtægter | B5: ='res_raw_43705660'!$B$3 | C5: ='res_raw_43705660'!$C$3 | D5: ='res_raw_43705660'!$D$3 | E5: ='res_raw_43705660'!$E$3 | G5: =IFERROR(B5/$B$5*100,"") | H5: =IFERROR(C5/$B$5*100,"") | I5: =IFERROR(D5/$B$5*100,"") | J5: =IFERROR(E5/$B$5*100,"")
A6: Vareforbrug | B6: ='res_raw_43705660'!$B$4 | C6: ='res_raw_43705660'!$C$4 | D6: ='res_raw_43705660'!$D$4 | E6: ='res_raw_43705660'!$E$4 | G6: =IFERROR(B6/$B$6*100,"") | H6: =IFERROR(C6/$B$6*100,"") | I6: =IFERROR(D6/$B$6*100,"") | J6: =IFERROR(E6/$B$6*100,"")
A7: Andre eksterne omkostninger | B7: ='res_raw_43705660'!$B$5 | C7: ='res_raw_43705660'!$C$5 | D7: ='res_raw_43705660'!$D$5 | E7: ='res_raw_43705660'!$E$5 | G7: =IFERROR(B7/$B$7*100,"") | H7: =IFERROR(C7/$B$7*100,"") | I7: =IFERROR(D7/$B$7*100,"") | J7: =IFERROR(E7/$B$7*100,"")
A8: Bruttoresultat | B8: ='res_raw_43705660'!$B$6 | C8: ='res_raw_43705660'!$C$6 | D8: ='res_raw_43705660'!$D$6 | E8: ='res_raw_43705660'!$E$6 | G8: =IFERROR(B8/$B$8*100,"") | H8: =IFERROR(C8/$B$8*100,"") | I8: =IFERROR(D8/$B$8*100,"") | J8: =IFERROR(E8/$B$8*100,"")
A9: Personaleomkostninger | B9: ='res_raw_43705660'!$B$7 | C9: ='res_raw_43705660'!$C$7 | D9: ='res_raw_43705660'!$D$7 | E9: ='res_raw_43705660'!$E$7 | G9: =IFERROR(B9/$B$9*100,"") | H9: =IFERROR(C9/$B$9*100,"") | I9: =IFERROR(D9/$B$9*100,"") | J9: =IFERROR(E9/$B$9*100,"")
A10: Resultat før afskrivninger | B10: =IFERROR($B$8-ABS($B$9),"") | C10: =IFERROR($C$8-ABS($C$9),"") | D10: =IFERROR($D$8-ABS($D$9),"") | E10: =IFERROR($E$8-ABS($E$9),"") | G10: =IFERROR(B10/$B$10*100,"") | H10: =IFERROR(C10/$B$10*100,"") | I10: =IFERROR(D10/$B$10*100,"") | J10: =IFERROR(E10/$B$10*100,"")
A11: Af- og nedskrivninger | B11: ='res_raw_43705660'!$B$9 | C11: ='res_raw_43705660'!$C$9 | D11: ='res_raw_43705660'!$D$9 | E11: ='res_raw_43705660'!$E$9 | G11: =IFERROR(B11/$B$11*100,"") | H11: =IFERROR(C11/$B$11*100,"") | I11: =IFERROR(D11/$B$11*100,"") | J11: =IFERROR(E11/$B$11*100,"")
A12: Andre driftsomkostninger | B12: ='res_raw_43705660'!$B$10 | C12: ='res_raw_43705660'!$C$10 | D12: ='res_raw_43705660'!$D$10 | E12: ='res_raw_43705660'!$E$10 | G12: =IFERROR(B12/$B$12*100,"") | H12: =IFERROR(C12/$B$12*100,"") | I12: =IFERROR(D12/$B$12*100,"") | J12: =IFERROR(E12/$B$12*100,"")
A13: Resultat af primær drift | B13: ='res_raw_43705660'!$B$11 | C13: ='res_raw_43705660'!$C$11 | D13: ='res_raw_43705660'!$D$11 | E13: ='res_raw_43705660'!$E$11 | G13: =IFERROR(B13/$B$13*100,"") | H13: =IFERROR(C13/$B$13*100,"") | I13: =IFERROR(D13/$B$13*100,"") | J13: =IFERROR(E13/$B$13*100,"")
A14: Indtægter af kapitalandele, dattervirksomheder | B14: ='res_raw_43705660'!$B$12 | C14: ='res_raw_43705660'!$C$12 | D14: ='res_raw_43705660'!$D$12 | E14: ='res_raw_43705660'!$E$12 | G14: =IFERROR(B14/$B$14*100,"") | H14: =IFERROR(C14/$B$14*100,"") | I14: =IFERROR(D14/$B$14*100,"") | J14: =IFERROR(E14/$B$14*100,"")
A15: Finansielle indtægter | B15: ='res_raw_43705660'!$B$13 | C15: ='res_raw_43705660'!$C$13 | D15: ='res_raw_43705660'!$D$13 | E15: ='res_raw_43705660'!$E$13 | G15: =IFERROR(B15/$B$15*100,"") | H15: =IFERROR(C15/$B$15*100,"") | I15: =IFERROR(D15/$B$15*100,"") | J15: =IFERROR(E15/$B$15*100,"")
A16: Finansielle omkostninger | B16: ='res_raw_43705660'!$B$14 | C16: ='res_raw_43705660'!$C$14 | D16: ='res_raw_43705660'!$D$14 | E16: ='res_raw_43705660'!$E$14 | G16: =IFERROR(B16/$B$16*100,"") | H16: =IFERROR(C16/$B$16*100,"") | I16: =IFERROR(D16/$B$16*100,"") | J16: =IFERROR(E16/$B$16*100,"")
A17: Finansielle poster, netto | B17: ='res_raw_43705660'!$B$15 | C17: ='res_raw_43705660'!$C$15 | D17: ='res_raw_43705660'!$D$15 | E17: ='res_raw_43705660'!$E$15 | G17: =IFERROR(B17/$B$17*100,"") | H17: =IFERROR(C17/$B$17*100,"") | I17: =IFERROR(D17/$B$17*100,"") | J17: =IFERROR(E17/$B$17*100,"")
A18: Resultat før skat | B18: ='res_raw_43705660'!$B$16 | C18: ='res_raw_43705660'!$C$16 | D18: ='res_raw_43705660'!$D$16 | E18: ='res_raw_43705660'!$E$16 | G18: =IFERROR(B18/$B$18*100,"") | H18: =IFERROR(C18/$B$18*100,"") | I18: =IFERROR(D18/$B$18*100,"") | J18: =IFERROR(E18/$B$18*100,"")
A19: Skat af årets resultat | B19: ='res_raw_43705660'!$B$17 | C19: ='res_raw_43705660'!$C$17 | D19: ='res_raw_43705660'!$D$17 | E19: ='res_raw_43705660'!$E$17 | G19: =IFERROR(B19/$B$19*100,"") | H19: =IFERROR(C19/$B$19*100,"") | I19: =IFERROR(D19/$B$19*100,"") | J19: =IFERROR(E19/$B$19*100,"")
A20: Årets resultat | B20: ='res_raw_43705660'!$B$18 | C20: ='res_raw_43705660'!$C$18 | D20: ='res_raw_43705660'!$D$18 | E20: ='res_raw_43705660'!$E$18 | G20: =IFERROR(B20/$B$20*100,"") | H20: =IFERROR(C20/$B$20*100,"") | I20: =IFERROR(D20/$B$20*100,"") | J20: =IFERROR(E20/$B$20*100,"")
A22: AKTIVER t.kr. | B22: 2022 | C22: 2023 | D22: 2024 | E22: 2025 | G22: 2022 | H22: 2023 | I22: 2024 | J22: 2025
A23: Grunde og bygninger | B23: ='balance_raw_43705660'!$B$2 | C23: ='balance_raw_43705660'!$C$2 | D23: ='balance_raw_43705660'!$D$2 | E23: ='balance_raw_43705660'!$E$2 | G23: =IFERROR(B23/$B$23*100,"") | H23: =IFERROR(C23/$B$23*100,"") | I23: =IFERROR(D23/$B$23*100,"") | J23: =IFERROR(E23/$B$23*100,"")
A24: Produktionsanlæg og maskiner | B24: ='balance_raw_43705660'!$B$3 | C24: ='balance_raw_43705660'!$C$3 | D24: ='balance_raw_43705660'!$D$3 | E24: ='balance_raw_43705660'!$E$3 | G24: =IFERROR(B24/$B$24*100,"") | H24: =IFERROR(C24/$B$24*100,"") | I24: =IFERROR(D24/$B$24*100,"") | J24: =IFERROR(E24/$B$24*100,"")
A25: Driftsmateriel og inventar | B25: ='balance_raw_43705660'!$B$4 | C25: ='balance_raw_43705660'!$C$4 | D25: ='balance_raw_43705660'!$D$4 | E25: ='balance_raw_43705660'!$E$4 | G25: =IFERROR(B25/$B$25*100,"") | H25: =IFERROR(C25/$B$25*100,"") | I25: =IFERROR(D25/$B$25*100,"") | J25: =IFERROR(E25/$B$25*100,"")
A26: Indretning af lejede lokaler | B26: ='balance_raw_43705660'!$B$5 | C26: ='balance_raw_43705660'!$C$5 | D26: ='balance_raw_43705660'!$D$5 | E26: ='balance_raw_43705660'!$E$5 | G26: =IFERROR(B26/$B$26*100,"") | H26: =IFERROR(C26/$B$26*100,"") | I26: =IFERROR(D26/$B$26*100,"") | J26: =IFERROR(E26/$B$26*100,"")
A27: Forudbetaling og anlægsaktiver under opførelse | B27: ='balance_raw_43705660'!$B$6 | C27: ='balance_raw_43705660'!$C$6 | D27: ='balance_raw_43705660'!$D$6 | E27: ='balance_raw_43705660'!$E$6 | G27: =IFERROR(B27/$B$27*100,"") | H27: =IFERROR(C27/$B$27*100,"") | I27: =IFERROR(D27/$B$27*100,"") | J27: =IFERROR(E27/$B$27*100,"")
A28: Materielle anlægsaktiver | B28: ='balance_raw_43705660'!$B$7 | C28: ='balance_raw_43705660'!$C$7 | D28: ='balance_raw_43705660'!$D$7 | E28: ='balance_raw_43705660'!$E$7 | G28: =IFERROR(B28/$B$28*100,"") | H28: =IFERROR(C28/$B$28*100,"") | I28: =IFERROR(D28/$B$28*100,"") | J28: =IFERROR(E28/$B$28*100,"")
A29: Kapitalandele, dattervirksomheder | B29: ='balance_raw_43705660'!$B$8 | C29: ='balance_raw_43705660'!$C$8 | D29: ='balance_raw_43705660'!$D$8 | E29: ='balance_raw_43705660'!$E$8 | G29: =IFERROR(B29/$B$29*100,"") | H29: =IFERROR(C29/$B$29*100,"") | I29: =IFERROR(D29/$B$29*100,"") | J29: =IFERROR(E29/$B$29*100,"")
A30: Deposita | B30: ='balance_raw_43705660'!$B$9 | C30: ='balance_raw_43705660'!$C$9 | D30: ='balance_raw_43705660'!$D$9 | E30: ='balance_raw_43705660'!$E$9 | G30: =IFERROR(B30/$B$30*100,"") | H30: =IFERROR(C30/$B$30*100,"") | I30: =IFERROR(D30/$B$30*100,"") | J30: =IFERROR(E30/$B$30*100,"")
A31: Finansielle anlægsaktiver | B31: ='balance_raw_43705660'!$B$10 | C31: ='balance_raw_43705660'!$C$10 | D31: ='balance_raw_43705660'!$D$10 | E31: ='balance_raw_43705660'!$E$10 | G31: =IFERROR(B31/$B$31*100,"") | H31: =IFERROR(C31/$B$31*100,"") | I31: =IFERROR(D31/$B$31*100,"") | J31: =IFERROR(E31/$B$31*100,"")
A32: Anlægsaktiver | B32: ='balance_raw_43705660'!$B$11 | C32: ='balance_raw_43705660'!$C$11 | D32: ='balance_raw_43705660'!$D$11 | E32: ='balance_raw_43705660'!$E$11 | G32: =IFERROR(B32/$B$32*100,"") | H32: =IFERROR(C32/$B$32*100,"") | I32: =IFERROR(D32/$B$32*100,"") | J32: =IFERROR(E32/$B$32*100,"")
A33: Råvarer og hjælpematerialer | B33: ='balance_raw_43705660'!$B$12 | C33: ='balance_raw_43705660'!$C$12 | D33: ='balance_raw_43705660'!$D$12 | E33: ='balance_raw_43705660'!$E$12 | G33: =IFERROR(B33/$B$33*100,"") | H33: =IFERROR(C33/$B$33*100,"") | I33: =IFERROR(D33/$B$33*100,"") | J33: =IFERROR(E33/$B$33*100,"")
A34: Varer under fremstilling | B34: ='balance_raw_43705660'!$B$13 | C34: ='balance_raw_43705660'!$C$13 | D34: ='balance_raw_43705660'!$D$13 | E34: ='balance_raw_43705660'!$E$13 | G34: =IFERROR(B34/$B$34*100,"") | H34: =IFERROR(C34/$B$34*100,"") | I34: =IFERROR(D34/$B$34*100,"") | J34: =IFERROR(E34/$B$34*100,"")
A35: Færdigvarer og handelsvarer | B35: ='balance_raw_43705660'!$B$14 | C35: ='balance_raw_43705660'!$C$14 | D35: ='balance_raw_43705660'!$D$14 | E35: ='balance_raw_43705660'!$E$14 | G35: =IFERROR(B35/$B$35*100,"") | H35: =IFERROR(C35/$B$35*100,"") | I35: =IFERROR(D35/$B$35*100,"") | J35: =IFERROR(E35/$B$35*100,"")
A36: Varebeholdninger | B36: ='balance_raw_43705660'!$B$15 | C36: ='balance_raw_43705660'!$C$15 | D36: ='balance_raw_43705660'!$D$15 | E36: ='balance_raw_43705660'!$E$15 | G36: =IFERROR(B36/$B$36*100,"") | H36: =IFERROR(C36/$B$36*100,"") | I36: =IFERROR(D36/$B$36*100,"") | J36: =IFERROR(E36/$B$36*100,"")
A37: Tilgodehavender fra salg og tjenesteydelser | B37: ='balance_raw_43705660'!$B$16 | C37: ='balance_raw_43705660'!$C$16 | D37: ='balance_raw_43705660'!$D$16 | E37: ='balance_raw_43705660'!$E$16 | G37: =IFERROR(B37/$B$37*100,"") | H37: =IFERROR(C37/$B$37*100,"") | I37: =IFERROR(D37/$B$37*100,"") | J37: =IFERROR(E37/$B$37*100,"")
A38: Tilgodehavender hos tilknyttede virksomheder | B38: ='balance_raw_43705660'!$B$17 | C38: ='balance_raw_43705660'!$C$17 | D38: ='balance_raw_43705660'!$D$17 | E38: ='balance_raw_43705660'!$E$17 | G38: =IFERROR(B38/$B$38*100,"") | H38: =IFERROR(C38/$B$38*100,"") | I38: =IFERROR(D38/$B$38*100,"") | J38: =IFERROR(E38/$B$38*100,"")
A39: Andre tilgodehavender | B39: ='balance_raw_43705660'!$B$18 | C39: ='balance_raw_43705660'!$C$18 | D39: ='balance_raw_43705660'!$D$18 | E39: ='balance_raw_43705660'!$E$18 | G39: =IFERROR(B39/$B$39*100,"") | H39: =IFERROR(C39/$B$39*100,"") | I39: =IFERROR(D39/$B$39*100,"") | J39: =IFERROR(E39/$B$39*100,"")
A40: Periodeafgrænsningsposter (aktiver) | B40: ='balance_raw_43705660'!$B$19 | C40: ='balance_raw_43705660'!$C$19 | D40: ='balance_raw_43705660'!$D$19 | E40: ='balance_raw_43705660'!$E$19 | G40: =IFERROR(B40/$B$40*100,"") | H40: =IFERROR(C40/$B$40*100,"") | I40: =IFERROR(D40/$B$40*100,"") | J40: =IFERROR(E40/$B$40*100,"")
A41: Udskudt skatteaktiv | B41: ='balance_raw_43705660'!$B$20 | C41: ='balance_raw_43705660'!$C$20 | D41: ='balance_raw_43705660'!$D$20 | E41: ='balance_raw_43705660'!$E$20 | G41: =IFERROR(B41/$B$41*100,"") | H41: =IFERROR(C41/$B$41*100,"") | I41: =IFERROR(D41/$B$41*100,"") | J41: =IFERROR(E41/$B$41*100,"")
...

Sheet res_raw_43705660
A1: THURØ BRYGHUS APS (CVR 43705660) — Resultatopgørelse & nøgleoplysninger (t.kr.) | B1: 2022 | C1: 2023 | D1: 2024 | E1: 2025
A2: Nettoomsætning
A3: Andre driftsindtægter
A4: Vareforbrug
A5: Andre eksterne omkostninger
A6: Bruttoresultat | C6: 316 | D6: 781 | E6: 858
A7: Personaleomkostninger | C7: 328 | D7: 414 | E7: 400
A8: Resultat før afskrivninger
A9: Af- og nedskrivninger | C9: 78 | D9: 111 | E9: 132
A10: Andre driftsomkostninger
A11: Resultat af primær drift | C11: -90 | D11: 256 | E11: 325
A12: Indtægter af kapitalandele, dattervirksomheder
A13: Finansielle indtægter | C13: 0 | D13: 0 | E13: 0
A14: Finansielle omkostninger | C14: 72 | D14: 68 | E14: 72
A15: Finansielle poster, netto
A16: Resultat før skat | C16: -162 | D16: 188 | E16: 254
A17: Skat af årets resultat | C17: -29 | D17: 43 | E17: 57
A18: Årets resultat | C18: -133 | D18: 145 | E18: 197
A19: Gns. antal medarbejdere | C19: 2 | D19: 2 | E19: 2
A20: Investering i materielle anlægsaktiver

Sheet balance_raw_43705660
A1: THURØ BRYGHUS APS (CVR 43705660) — Balance (t.kr.) | B1: 2022 | C1: 2023 | D1: 2024 | E1: 2025
A2: Grunde og bygninger
A3: Produktionsanlæg og maskiner
A4: Driftsmateriel og inventar | C4: 916 | D4: 1146 | E4: 1071
A5: Indretning af lejede lokaler
A6: Forudbetaling og anlægsaktiver under opførelse | E6: 295
A7: Materielle anlægsaktiver | C7: 916 | D7: 1146 | E7: 1366
A8: Kapitalandele, dattervirksomheder
A9: Deposita | C9: 10 | D9: 10 | E9: 10
A10: Finansielle anlægsaktiver | C10: 10 | D10: 10 | E10: 10
A11: Anlægsaktiver | C11: 926 | D11: 1156 | E11: 1376
A12: Råvarer og hjælpematerialer | C12: 79 | D12: 142 | E12: 39
A13: Varer under fremstilling
A14: Færdigvarer og handelsvarer | C14: 259 | D14: 260 | E14: 274
A15: Varebeholdninger | C15: 338 | D15: 402 | E15: 314
A16: Tilgodehavender fra salg og tjenesteydelser | C16: 57 | D16: 111 | E16: 97
A17: Tilgodehavender hos tilknyttede virksomheder | E17: 6
A18: Andre tilgodehavender | C18: 25 | D18: 22 | E18: 17
A19: Periodeafgrænsningsposter (aktiver) | C19: 27 | D19: 0
A20: Udskudt skatteaktiv | C20: 29 | D20: 0
A21: Tilgodehavende skat hos tilknyttede virksomheder
A22: Kortfristede skattetilgodehavender | C22: 0 | D22: 0
A23: Tilgodehavender | C23: 138 | D23: 133 | E23: 119
A24: Værdipapirer
A25: Likvide beholdninger | C25: 16 | D25: 3 | E25: 131
A26: Omsætningsaktiver | C26: 492 | D26: 538 | E26: 563
A27: Aktiver | C27: 1418 | D27: 1694 | E27: 1940
A28: Selskabskapital | C28: 40 | D28: 40 | E28: 40
A29: Reserve for nettoopskrivning (indre værdis metode)
A30: Reserve for udviklingsomkostninger
A31: Reserve for sikringstransaktioner
A32: Andre reserver
A33: Overført resultat | C33: -132 | D33: 13 | E33: 210
A34: Egenkapital i alt | B34: 40 | C34: -92 | D34: 53 | E34: 250
A35: Hensættelse til udskudt skat | C35: 0 | D35: 13 | E35: 70
A36: Hensatte forpligtelser | C36: 0 | D36: 13 | E36: 70
A37: Ansvarlig lånekapital (langfristet)
A38: Langfristede lån | C38: 662 | D38: 727 | E38: 851
A39: Leasingforpligtelser (langfristet)
A40: Anden gæld (langfristet)
...

Sheet Simpel_arts
A1: THURØ BRYGHUS APS (CVR 43705660) — Regnskabs- og nøgletal (CVR: 43705660) — artsopdelt
A3: Beløb i 1.000 kr. | B3: 2025 | C3: 2024 | D3: 2023 | F3: Note / XBRL-felt
A4: Uddrag af resultatopgørelse
A5: Nettoomsætning | B5: ='res_raw_43705660'!$E$2 | C5: ='res_raw_43705660'!$D$2 | D5: ='res_raw_43705660'!$C$2 | F5: fsa:Revenue
A6: Andre driftsindtægter | B6: ='res_raw_43705660'!$E$3 | C6: ='res_raw_43705660'!$D$3 | D6: ='res_raw_43705660'!$C$3 | F6: fsa:OtherOperatingIncome. Indtægter fra sekundære aktiviteter (huslejeindtægter, avance ved salg af anlæg mv.).
A7: Vareforbrug | B7: =-'res_raw_43705660'!$E$4 | C7: =-'res_raw_43705660'!$D$4 | D7: =-'res_raw_43705660'!$C$4 | F7: fsa:CostOfSales (vises negativt for korrekt SUM-formel).
A8: Andre eksterne omk. mv. | B8: =-'res_raw_43705660'!$E$5 | C8: =-'res_raw_43705660'!$D$5 | D8: =-'res_raw_43705660'!$C$5 | F8: fsa:OtherExternalExpenses (vises negativt). Husleje, energi, kontorhold mv.
A9: Bruttofortjeneste | B9: =SUM(B5:B8) | C9: =SUM(C5:C8) | D9: =SUM(D5:D8) | F9: Beregnet: Nettoomsætning + Andre driftsindt. − Vareforbrug − Andre ext. omk.
A10: Personaleomkostninger | B10: =-'res_raw_43705660'!$E$7 | C10: =-'res_raw_43705660'!$D$7 | D10: =-'res_raw_43705660'!$C$7 | F10: fsa:EmployeeBenefitsExpense (vises negativt). Lønninger, pension, sociale ydelser.
A11: Af- og nedskrivninger | B11: =-'res_raw_43705660'!$E$9 | C11: =-'res_raw_43705660'!$D$9 | D11: =-'res_raw_43705660'!$C$9 | F11: fsa:Depreciation (vises negativt). Af- og nedskrivninger på materielle og immaterielle anlægsaktiver.
A12: Andre driftsomkostninger | B12: =-'res_raw_43705660'!$E$10 | C12: =-'res_raw_43705660'!$D$10 | D12: =-'res_raw_43705660'!$C$10 | F12: fsa:OtherOperatingExpenses (vises negativt). Typisk 0 eller meget lille post.
A13: Resultat af primær drift | B13: =SUM(B9:B12) | C13: =SUM(C9:C12) | D13: =SUM(D9:D12) | F13: Beregnet: Bruttofortjeneste − Personaleomk. − Af- og nedskrivninger − Andre driftsomk. EBIT.
A14: Finansielle indtægter mv. | B14: =N('res_raw_43705660'!$E$12)+N('res_raw_43705660'!$E$13) | C14: =N('res_raw_43705660'!$D$12)+N('res_raw_43705660'!$D$13) | D14: =N('res_raw_43705660'!$C$12)+N('res_raw_43705660'!$C$13) | F14: fsa:IncomeFromSubsidiaries + fsa:OtherFinanceIncome.
A15: Finansielle omkostninger mv. | B15: =-'res_raw_43705660'!$E$14 | C15: =-'res_raw_43705660'!$D$14 | D15: =-'res_raw_43705660'!$C$14 | F15: fsa:OtherFinanceExpenses (vises negativt). Renteomkostninger, kurstab mv.
A16: Resultat før skat | B16: =SUM(B13:B15) | C16: =SUM(C13:C15) | D16: =SUM(D13:D15) | F16: Beregnet: EBIT + Fin. indtægter + Fin. omk. EBT.
A18: Uddrag af balance
A19: Anlægsaktiver | B19: ='balance_raw_43705660'!$E$11 | C19: ='balance_raw_43705660'!$D$11 | D19: ='balance_raw_43705660'!$C$11 | F19: fsa:NoncurrentAssets. Materielle, immaterielle og finansielle anlægsaktiver.
A20: Omsætningsaktiver | B20: ='balance_raw_43705660'!$E$26 | C20: ='balance_raw_43705660'!$D$26 | D20: ='balance_raw_43705660'!$C$26 | F20: fsa:CurrentAssets. Varebeholdninger, tilgodehavender, likvider.
A21: Aktiver i alt | B21: =SUM(B19:B20) | C21: =SUM(C19:C20) | D21: =SUM(D19:D20) | F21: Beregnet: Anlægsaktiver + Omsætningsaktiver. Bør matche fsa:Assets.
A23: Egenkapital | B23: ='balance_raw_43705660'!$E$34 | C23: ='balance_raw_43705660'!$D$34 | D23: ='balance_raw_43705660'!$C$34 | F23: fsa:Equity. Selskabskapital, overført resultat, reserver.
A24: Forpligtelser | B24: ='balance_raw_43705660'!$E$55-'balance_raw_43705660'!$E$34 | C24: ='balance_raw_43705660'!$D$55-'balance_raw_43705660'!$D$34 | D24: ='balance_raw_43705660'!$C$55-'balance_raw_43705660'!$C$34 | F24: Beregnet: Passiver (fsa:LiabilitiesAndEquity) − Egenkapital. Hensættelser + kort- og langfristet gæld.
A25: Passiver i alt | B25: =SUM(B23:B24) | C25: =SUM(C23:C24) | D25: =SUM(D23:D24) | F25: Beregnet: Egenkapital + Forpligtelser. Bør matche Aktiver i alt.
A27: Udvalgte balanceposter
A28: Varebeholdninger | B28: ='balance_raw_43705660'!$E$15 | C28: ='balance_raw_43705660'!$D$15 | D28: ='balance_raw_43705660'!$C$15 | F28: fsa:Inventories (eller fsa:ManufacturedGoodsAndGoodsForResale hvis total mangler).
A29: Tilgodehavender fra salg | B29: ='balance_raw_43705660'!$E$16 | C29: ='balance_raw_43705660'!$D$16 | D29: ='balance_raw_43705660'!$C$16 | F29: fsa:ShorttermTradeReceivables. Kortfristede tilgodehavender fra kunder.
A30: Kortfristede gældsforpligtelser | B30: ='balance_raw_43705660'!$E$53 | C30: ='balance_raw_43705660'!$D$53 | D30: ='balance_raw_43705660'!$C$53 | F30: fsa:ShorttermLiabilitiesOtherThanProvisions. Gæld der forfalder inden for 1 år.
A32: Rentabilitet
A33: Afkastningsgrad, % | B33: =IFERROR((B13+B14)/B21*100,"") | C33: =IFERROR((C13+C14)/C21*100,"") | D33: =IFERROR((D13+D14)/D21*100,"")
A34: Overskudsgrad, % | B34: =IFERROR((B13+B14)/B5*100,"") | C34: =IFERROR((C13+C14)/C5*100,"") | D34: =IFERROR((D13+D14)/D5*100,"")
A35: Aktivernes omsætningshastighed, gange | B35: =IFERROR(B5/B21,"") | C35: =IFERROR(C5/C21,"") | D35: =IFERROR(D5/D21,"")
A36: Gældsrente, % | B36: =IFERROR(-B15*100/B24,"") | C36: =IFERROR(-C15*100/C24,"") | D36: =IFERROR(-D15*100/D24,"")
A37: Egenkapitalens forrentning, % | B37: =IFERROR(B16/B23*100,"") | C37: =IFERROR(C16/C23*100,"") | D37: =IFERROR(D16/D23*100,"")
A38: Gearing, gange | B38: =IFERROR(B24/B23,"") | C38: =IFERROR(C24/C23,"") | D38: =IFERROR(D24/D23,"")
A40: Indekstal for indtjeningsevne (2023=100)
A41: Nettoomsætning | B41: =IFERROR(B5/$D5*100,"") | C41: =IFERROR(C5/$D5*100,"") | D41: =IFERROR(D5/$D5*100,"")
A42: Vareforbrug | B42: =IFERROR(B7/$D7*100,"") | C42: =IFERROR(C7/$D7*100,"") | D42: =IFERROR(D7/$D7*100,"")
A43: Andre eksterne omk. | B43: =IFERROR(B8/$D8*100,"") | C43: =IFERROR(C8/$D8*100,"") | D43: =IFERROR(D8/$D8*100,"")
A44: Personaleomkostninger | B44: =IFERROR(B10/$D10*100,"") | C44: =IFERROR(C10/$D10*100,"") | D44: =IFERROR(D10/$D10*100,"")
A45: Af- og nedskrivninger | B45: =IFERROR(B11/$D11*100,"") | C45: =IFERROR(C11/$D11*100,"") | D45: =IFERROR(D11/$D11*100,"")
A47: Indekstal for kapitaltilpasningsevne (2023=100)
...

Sheet Noter_info
A1: THURØ BRYGHUS APS (CVR 43705660) — Ukendte XBRL-felter — disse er noter og ikke en del af hoved-regnskabet
A2: Kategori | B2: Dansk navn | C2: XBRL feltnavn | D2: 2022 t.kr. | E2: 2023 t.kr. | F2: 2024 t.kr. | G2: 2025 t.kr. | H2: Forklaring
A3: Øvrige (ukendt) | B3: fsa:IncreaseDecreaseOfEquityThroughChangesInAccountingPolicies | C3: fsa:IncreaseDecreaseOfEquityThroughChangesInAccountingPolicies | F3: 32 | H3: Ingen forklaring tilgængelig.
