Workbook

Sheet Overblik_80673612
A1: Scanpan A/S (CVR 80673612) — Regnskabsanalyse – Resultatopgørelse & Balance (t.kr.) · Klasse C-mellem · Revision
H2: Indekstal (2021=100)
A3: Resultatopgørelse t.kr. | B3: 2021 | C3: 2022 | D3: 2023 | E3: 2024 | F3: 2025 | H3: 2021 | I3: 2022 | J3: 2023 | K3: 2024 | L3: 2025
A4: Nettoomsætning | B4: ='res_raw_80673612'!$B$2 | C4: ='res_raw_80673612'!$C$2 | D4: ='res_raw_80673612'!$D$2 | E4: ='res_raw_80673612'!$E$2 | F4: ='res_raw_80673612'!$F$2 | H4: =IFERROR(B4/$B$4*100,"") | I4: =IFERROR(C4/$B$4*100,"") | J4: =IFERROR(D4/$B$4*100,"") | K4: =IFERROR(E4/$B$4*100,"") | L4: =IFERROR(F4/$B$4*100,"")
A5: Produktionsomkostninger | B5: ='res_raw_80673612'!$B$3 | C5: ='res_raw_80673612'!$C$3 | D5: ='res_raw_80673612'!$D$3 | E5: ='res_raw_80673612'!$E$3 | F5: ='res_raw_80673612'!$F$3 | H5: =IFERROR(B5/$B$5*100,"") | I5: =IFERROR(C5/$B$5*100,"") | J5: =IFERROR(D5/$B$5*100,"") | K5: =IFERROR(E5/$B$5*100,"") | L5: =IFERROR(F5/$B$5*100,"")
A6: Bruttoresultat | B6: ='res_raw_80673612'!$B$4 | C6: ='res_raw_80673612'!$C$4 | D6: ='res_raw_80673612'!$D$4 | E6: ='res_raw_80673612'!$E$4 | F6: ='res_raw_80673612'!$F$4 | H6: =IFERROR(B6/$B$6*100,"") | I6: =IFERROR(C6/$B$6*100,"") | J6: =IFERROR(D6/$B$6*100,"") | K6: =IFERROR(E6/$B$6*100,"") | L6: =IFERROR(F6/$B$6*100,"")
A7: Udviklingsomkostninger | B7: ='res_raw_80673612'!$B$5 | C7: ='res_raw_80673612'!$C$5 | D7: ='res_raw_80673612'!$D$5 | E7: ='res_raw_80673612'!$E$5 | F7: ='res_raw_80673612'!$F$5 | H7: =IFERROR(B7/$B$7*100,"") | I7: =IFERROR(C7/$B$7*100,"") | J7: =IFERROR(D7/$B$7*100,"") | K7: =IFERROR(E7/$B$7*100,"") | L7: =IFERROR(F7/$B$7*100,"")
A8: Salgs- og distributionsomkostninger | B8: ='res_raw_80673612'!$B$6 | C8: ='res_raw_80673612'!$C$6 | D8: ='res_raw_80673612'!$D$6 | E8: ='res_raw_80673612'!$E$6 | F8: ='res_raw_80673612'!$F$6 | H8: =IFERROR(B8/$B$8*100,"") | I8: =IFERROR(C8/$B$8*100,"") | J8: =IFERROR(D8/$B$8*100,"") | K8: =IFERROR(E8/$B$8*100,"") | L8: =IFERROR(F8/$B$8*100,"")
A9: Administrationsomkostninger | B9: ='res_raw_80673612'!$B$7 | C9: ='res_raw_80673612'!$C$7 | D9: ='res_raw_80673612'!$D$7 | E9: ='res_raw_80673612'!$E$7 | F9: ='res_raw_80673612'!$F$7 | H9: =IFERROR(B9/$B$9*100,"") | I9: =IFERROR(C9/$B$9*100,"") | J9: =IFERROR(D9/$B$9*100,"") | K9: =IFERROR(E9/$B$9*100,"") | L9: =IFERROR(F9/$B$9*100,"")
A10: Andre driftsindtægter | B10: ='res_raw_80673612'!$B$8 | C10: ='res_raw_80673612'!$C$8 | D10: ='res_raw_80673612'!$D$8 | E10: ='res_raw_80673612'!$E$8 | F10: ='res_raw_80673612'!$F$8 | H10: =IFERROR(B10/$B$10*100,"") | I10: =IFERROR(C10/$B$10*100,"") | J10: =IFERROR(D10/$B$10*100,"") | K10: =IFERROR(E10/$B$10*100,"") | L10: =IFERROR(F10/$B$10*100,"")
A11: Andre driftsomkostninger | B11: ='res_raw_80673612'!$B$9 | C11: ='res_raw_80673612'!$C$9 | D11: ='res_raw_80673612'!$D$9 | E11: ='res_raw_80673612'!$E$9 | F11: ='res_raw_80673612'!$F$9 | H11: =IFERROR(B11/$B$11*100,"") | I11: =IFERROR(C11/$B$11*100,"") | J11: =IFERROR(D11/$B$11*100,"") | K11: =IFERROR(E11/$B$11*100,"") | L11: =IFERROR(F11/$B$11*100,"")
A12: Resultat af primær drift | B12: ='res_raw_80673612'!$B$10 | C12: ='res_raw_80673612'!$C$10 | D12: ='res_raw_80673612'!$D$10 | E12: ='res_raw_80673612'!$E$10 | F12: ='res_raw_80673612'!$F$10 | H12: =IFERROR(B12/$B$12*100,"") | I12: =IFERROR(C12/$B$12*100,"") | J12: =IFERROR(D12/$B$12*100,"") | K12: =IFERROR(E12/$B$12*100,"") | L12: =IFERROR(F12/$B$12*100,"")
A13: Indtægter af kapitalandele, dattervirksomheder | B13: ='res_raw_80673612'!$B$11 | C13: ='res_raw_80673612'!$C$11 | D13: ='res_raw_80673612'!$D$11 | E13: ='res_raw_80673612'!$E$11 | F13: ='res_raw_80673612'!$F$11 | H13: =IFERROR(B13/$B$13*100,"") | I13: =IFERROR(C13/$B$13*100,"") | J13: =IFERROR(D13/$B$13*100,"") | K13: =IFERROR(E13/$B$13*100,"") | L13: =IFERROR(F13/$B$13*100,"")
A14: Finansielle indtægter | B14: ='res_raw_80673612'!$B$12 | C14: ='res_raw_80673612'!$C$12 | D14: ='res_raw_80673612'!$D$12 | E14: ='res_raw_80673612'!$E$12 | F14: ='res_raw_80673612'!$F$12 | H14: =IFERROR(B14/$B$14*100,"") | I14: =IFERROR(C14/$B$14*100,"") | J14: =IFERROR(D14/$B$14*100,"") | K14: =IFERROR(E14/$B$14*100,"") | L14: =IFERROR(F14/$B$14*100,"")
A15: Finansielle omkostninger | B15: ='res_raw_80673612'!$B$13 | C15: ='res_raw_80673612'!$C$13 | D15: ='res_raw_80673612'!$D$13 | E15: ='res_raw_80673612'!$E$13 | F15: ='res_raw_80673612'!$F$13 | H15: =IFERROR(B15/$B$15*100,"") | I15: =IFERROR(C15/$B$15*100,"") | J15: =IFERROR(D15/$B$15*100,"") | K15: =IFERROR(E15/$B$15*100,"") | L15: =IFERROR(F15/$B$15*100,"")
A16: Finansielle poster, netto | B16: ='res_raw_80673612'!$B$14 | C16: ='res_raw_80673612'!$C$14 | D16: ='res_raw_80673612'!$D$14 | E16: ='res_raw_80673612'!$E$14 | F16: ='res_raw_80673612'!$F$14 | H16: =IFERROR(B16/$B$16*100,"") | I16: =IFERROR(C16/$B$16*100,"") | J16: =IFERROR(D16/$B$16*100,"") | K16: =IFERROR(E16/$B$16*100,"") | L16: =IFERROR(F16/$B$16*100,"")
A17: Resultat før skat | B17: ='res_raw_80673612'!$B$15 | C17: ='res_raw_80673612'!$C$15 | D17: ='res_raw_80673612'!$D$15 | E17: ='res_raw_80673612'!$E$15 | F17: ='res_raw_80673612'!$F$15 | H17: =IFERROR(B17/$B$17*100,"") | I17: =IFERROR(C17/$B$17*100,"") | J17: =IFERROR(D17/$B$17*100,"") | K17: =IFERROR(E17/$B$17*100,"") | L17: =IFERROR(F17/$B$17*100,"")
A18: Skat af årets resultat | B18: ='res_raw_80673612'!$B$16 | C18: ='res_raw_80673612'!$C$16 | D18: ='res_raw_80673612'!$D$16 | E18: ='res_raw_80673612'!$E$16 | F18: ='res_raw_80673612'!$F$16 | H18: =IFERROR(B18/$B$18*100,"") | I18: =IFERROR(C18/$B$18*100,"") | J18: =IFERROR(D18/$B$18*100,"") | K18: =IFERROR(E18/$B$18*100,"") | L18: =IFERROR(F18/$B$18*100,"")
A19: Årets resultat | B19: ='res_raw_80673612'!$B$17 | C19: ='res_raw_80673612'!$C$17 | D19: ='res_raw_80673612'!$D$17 | E19: ='res_raw_80673612'!$E$17 | F19: ='res_raw_80673612'!$F$17 | H19: =IFERROR(B19/$B$19*100,"") | I19: =IFERROR(C19/$B$19*100,"") | J19: =IFERROR(D19/$B$19*100,"") | K19: =IFERROR(E19/$B$19*100,"") | L19: =IFERROR(F19/$B$19*100,"")
A21: AKTIVER t.kr. | B21: 2021 | C21: 2022 | D21: 2023 | E21: 2024 | F21: 2025 | H21: 2021 | I21: 2022 | J21: 2023 | K21: 2024 | L21: 2025
A22: Immaterielle anlægsaktiver | B22: ='balance_raw_80673612'!$B$2 | C22: ='balance_raw_80673612'!$C$2 | D22: ='balance_raw_80673612'!$D$2 | E22: ='balance_raw_80673612'!$E$2 | F22: ='balance_raw_80673612'!$F$2 | H22: =IFERROR(B22/$B$22*100,"") | I22: =IFERROR(C22/$B$22*100,"") | J22: =IFERROR(D22/$B$22*100,"") | K22: =IFERROR(E22/$B$22*100,"") | L22: =IFERROR(F22/$B$22*100,"")
A23: Grunde og bygninger | B23: ='balance_raw_80673612'!$B$3 | C23: ='balance_raw_80673612'!$C$3 | D23: ='balance_raw_80673612'!$D$3 | E23: ='balance_raw_80673612'!$E$3 | F23: ='balance_raw_80673612'!$F$3 | H23: =IFERROR(B23/$B$23*100,"") | I23: =IFERROR(C23/$B$23*100,"") | J23: =IFERROR(D23/$B$23*100,"") | K23: =IFERROR(E23/$B$23*100,"") | L23: =IFERROR(F23/$B$23*100,"")
A24: Produktionsanlæg og maskiner | B24: ='balance_raw_80673612'!$B$4 | C24: ='balance_raw_80673612'!$C$4 | D24: ='balance_raw_80673612'!$D$4 | E24: ='balance_raw_80673612'!$E$4 | F24: ='balance_raw_80673612'!$F$4 | H24: =IFERROR(B24/$B$24*100,"") | I24: =IFERROR(C24/$B$24*100,"") | J24: =IFERROR(D24/$B$24*100,"") | K24: =IFERROR(E24/$B$24*100,"") | L24: =IFERROR(F24/$B$24*100,"")
A25: Driftsmateriel og inventar | B25: ='balance_raw_80673612'!$B$5 | C25: ='balance_raw_80673612'!$C$5 | D25: ='balance_raw_80673612'!$D$5 | E25: ='balance_raw_80673612'!$E$5 | F25: ='balance_raw_80673612'!$F$5 | H25: =IFERROR(B25/$B$25*100,"") | I25: =IFERROR(C25/$B$25*100,"") | J25: =IFERROR(D25/$B$25*100,"") | K25: =IFERROR(E25/$B$25*100,"") | L25: =IFERROR(F25/$B$25*100,"")
A26: Indretning af lejede lokaler | B26: ='balance_raw_80673612'!$B$6 | C26: ='balance_raw_80673612'!$C$6 | D26: ='balance_raw_80673612'!$D$6 | E26: ='balance_raw_80673612'!$E$6 | F26: ='balance_raw_80673612'!$F$6 | H26: =IFERROR(B26/$B$26*100,"") | I26: =IFERROR(C26/$B$26*100,"") | J26: =IFERROR(D26/$B$26*100,"") | K26: =IFERROR(E26/$B$26*100,"") | L26: =IFERROR(F26/$B$26*100,"")
A27: Forudbetaling og anlægsaktiver under opførelse | B27: ='balance_raw_80673612'!$B$7 | C27: ='balance_raw_80673612'!$C$7 | D27: ='balance_raw_80673612'!$D$7 | E27: ='balance_raw_80673612'!$E$7 | F27: ='balance_raw_80673612'!$F$7 | H27: =IFERROR(B27/$B$27*100,"") | I27: =IFERROR(C27/$B$27*100,"") | J27: =IFERROR(D27/$B$27*100,"") | K27: =IFERROR(E27/$B$27*100,"") | L27: =IFERROR(F27/$B$27*100,"")
A28: Materielle anlægsaktiver | B28: ='balance_raw_80673612'!$B$8 | C28: ='balance_raw_80673612'!$C$8 | D28: ='balance_raw_80673612'!$D$8 | E28: ='balance_raw_80673612'!$E$8 | F28: ='balance_raw_80673612'!$F$8 | H28: =IFERROR(B28/$B$28*100,"") | I28: =IFERROR(C28/$B$28*100,"") | J28: =IFERROR(D28/$B$28*100,"") | K28: =IFERROR(E28/$B$28*100,"") | L28: =IFERROR(F28/$B$28*100,"")
A29: Kapitalandele, dattervirksomheder | B29: ='balance_raw_80673612'!$B$9 | C29: ='balance_raw_80673612'!$C$9 | D29: ='balance_raw_80673612'!$D$9 | E29: ='balance_raw_80673612'!$E$9 | F29: ='balance_raw_80673612'!$F$9 | H29: =IFERROR(B29/$B$29*100,"") | I29: =IFERROR(C29/$B$29*100,"") | J29: =IFERROR(D29/$B$29*100,"") | K29: =IFERROR(E29/$B$29*100,"") | L29: =IFERROR(F29/$B$29*100,"")
A30: Deposita | B30: ='balance_raw_80673612'!$B$10 | C30: ='balance_raw_80673612'!$C$10 | D30: ='balance_raw_80673612'!$D$10 | E30: ='balance_raw_80673612'!$E$10 | F30: ='balance_raw_80673612'!$F$10 | H30: =IFERROR(B30/$B$30*100,"") | I30: =IFERROR(C30/$B$30*100,"") | J30: =IFERROR(D30/$B$30*100,"") | K30: =IFERROR(E30/$B$30*100,"") | L30: =IFERROR(F30/$B$30*100,"")
A31: Finansielle anlægsaktiver | B31: ='balance_raw_80673612'!$B$11 | C31: ='balance_raw_80673612'!$C$11 | D31: ='balance_raw_80673612'!$D$11 | E31: ='balance_raw_80673612'!$E$11 | F31: ='balance_raw_80673612'!$F$11 | H31: =IFERROR(B31/$B$31*100,"") | I31: =IFERROR(C31/$B$31*100,"") | J31: =IFERROR(D31/$B$31*100,"") | K31: =IFERROR(E31/$B$31*100,"") | L31: =IFERROR(F31/$B$31*100,"")
A32: Anlægsaktiver | B32: ='balance_raw_80673612'!$B$12 | C32: ='balance_raw_80673612'!$C$12 | D32: ='balance_raw_80673612'!$D$12 | E32: ='balance_raw_80673612'!$E$12 | F32: ='balance_raw_80673612'!$F$12 | H32: =IFERROR(B32/$B$32*100,"") | I32: =IFERROR(C32/$B$32*100,"") | J32: =IFERROR(D32/$B$32*100,"") | K32: =IFERROR(E32/$B$32*100,"") | L32: =IFERROR(F32/$B$32*100,"")
A33: Råvarer og hjælpematerialer | B33: ='balance_raw_80673612'!$B$13 | C33: ='balance_raw_80673612'!$C$13 | D33: ='balance_raw_80673612'!$D$13 | E33: ='balance_raw_80673612'!$E$13 | F33: ='balance_raw_80673612'!$F$13 | H33: =IFERROR(B33/$B$33*100,"") | I33: =IFERROR(C33/$B$33*100,"") | J33: =IFERROR(D33/$B$33*100,"") | K33: =IFERROR(E33/$B$33*100,"") | L33: =IFERROR(F33/$B$33*100,"")
A34: Varer under fremstilling | B34: ='balance_raw_80673612'!$B$14 | C34: ='balance_raw_80673612'!$C$14 | D34: ='balance_raw_80673612'!$D$14 | E34: ='balance_raw_80673612'!$E$14 | F34: ='balance_raw_80673612'!$F$14 | H34: =IFERROR(B34/$B$34*100,"") | I34: =IFERROR(C34/$B$34*100,"") | J34: =IFERROR(D34/$B$34*100,"") | K34: =IFERROR(E34/$B$34*100,"") | L34: =IFERROR(F34/$B$34*100,"")
A35: Færdigvarer og handelsvarer | B35: ='balance_raw_80673612'!$B$15 | C35: ='balance_raw_80673612'!$C$15 | D35: ='balance_raw_80673612'!$D$15 | E35: ='balance_raw_80673612'!$E$15 | F35: ='balance_raw_80673612'!$F$15 | H35: =IFERROR(B35/$B$35*100,"") | I35: =IFERROR(C35/$B$35*100,"") | J35: =IFERROR(D35/$B$35*100,"") | K35: =IFERROR(E35/$B$35*100,"") | L35: =IFERROR(F35/$B$35*100,"")
A36: Varebeholdninger | B36: ='balance_raw_80673612'!$B$16 | C36: ='balance_raw_80673612'!$C$16 | D36: ='balance_raw_80673612'!$D$16 | E36: ='balance_raw_80673612'!$E$16 | F36: ='balance_raw_80673612'!$F$16 | H36: =IFERROR(B36/$B$36*100,"") | I36: =IFERROR(C36/$B$36*100,"") | J36: =IFERROR(D36/$B$36*100,"") | K36: =IFERROR(E36/$B$36*100,"") | L36: =IFERROR(F36/$B$36*100,"")
A37: Tilgodehavender fra salg og tjenesteydelser | B37: ='balance_raw_80673612'!$B$17 | C37: ='balance_raw_80673612'!$C$17 | D37: ='balance_raw_80673612'!$D$17 | E37: ='balance_raw_80673612'!$E$17 | F37: ='balance_raw_80673612'!$F$17 | H37: =IFERROR(B37/$B$37*100,"") | I37: =IFERROR(C37/$B$37*100,"") | J37: =IFERROR(D37/$B$37*100,"") | K37: =IFERROR(E37/$B$37*100,"") | L37: =IFERROR(F37/$B$37*100,"")
A38: Tilgodehavender hos tilknyttede virksomheder | B38: ='balance_raw_80673612'!$B$18 | C38: ='balance_raw_80673612'!$C$18 | D38: ='balance_raw_80673612'!$D$18 | E38: ='balance_raw_80673612'!$E$18 | F38: ='balance_raw_80673612'!$F$18 | H38: =IFERROR(B38/$B$38*100,"") | I38: =IFERROR(C38/$B$38*100,"") | J38: =IFERROR(D38/$B$38*100,"") | K38: =IFERROR(E38/$B$38*100,"") | L38: =IFERROR(F38/$B$38*100,"")
A39: Andre tilgodehavender | B39: ='balance_raw_80673612'!$B$19 | C39: ='balance_raw_80673612'!$C$19 | D39: ='balance_raw_80673612'!$D$19 | E39: ='balance_raw_80673612'!$E$19 | F39: ='balance_raw_80673612'!$F$19 | H39: =IFERROR(B39/$B$39*100,"") | I39: =IFERROR(C39/$B$39*100,"") | J39: =IFERROR(D39/$B$39*100,"") | K39: =IFERROR(E39/$B$39*100,"") | L39: =IFERROR(F39/$B$39*100,"")
A40: Periodeafgrænsningsposter (aktiver) | B40: ='balance_raw_80673612'!$B$20 | C40: ='balance_raw_80673612'!$C$20 | D40: ='balance_raw_80673612'!$D$20 | E40: ='balance_raw_80673612'!$E$20 | F40: ='balance_raw_80673612'!$F$20 | H40: =IFERROR(B40/$B$40*100,"") | I40: =IFERROR(C40/$B$40*100,"") | J40: =IFERROR(D40/$B$40*100,"") | K40: =IFERROR(E40/$B$40*100,"") | L40: =IFERROR(F40/$B$40*100,"")
A41: Udskudt skatteaktiv | B41: ='balance_raw_80673612'!$B$21 | C41: ='balance_raw_80673612'!$C$21 | D41: ='balance_raw_80673612'!$D$21 | E41: ='balance_raw_80673612'!$E$21 | F41: ='balance_raw_80673612'!$F$21 | H41: =IFERROR(B41/$B$41*100,"") | I41: =IFERROR(C41/$B$41*100,"") | J41: =IFERROR(D41/$B$41*100,"") | K41: =IFERROR(E41/$B$41*100,"") | L41: =IFERROR(F41/$B$41*100,"")
...

Sheet res_raw_80673612
A1: Scanpan A/S (CVR 80673612) — Resultatopgørelse & nøgleoplysninger (t.kr.) | B1: 2021 | C1: 2022 | D1: 2023 | E1: 2024 | F1: 2025
A2: Nettoomsætning
A3: Produktionsomkostninger
A4: Bruttoresultat | B4: 75873 | C4: 52019 | D4: 31064 | E4: 44876 | F4: 54264
A5: Udviklingsomkostninger
A6: Salgs- og distributionsomkostninger | B6: 26983 | C6: 25379 | D6: 24645 | E6: 26429 | F6: 27637
A7: Administrationsomkostninger | B7: 17351 | C7: 16466 | D7: 19296 | E7: 21534 | F7: 22151
A8: Andre driftsindtægter
A9: Andre driftsomkostninger | B9: 15 | C9: 0 | D9: 4 | E9: 0 | F9: 5
A10: Resultat af primær drift | B10: 31524 | C10: 10175 | D10: -12881 | E10: -3088 | F10: 4471
A11: Indtægter af kapitalandele, dattervirksomheder | B11: 0 | C11: 0 | D11: 0 | E11: 0 | F11: 0
A12: Finansielle indtægter | B12: 674 | C12: 664 | D12: 338 | E12: 309 | F12: 509
A13: Finansielle omkostninger | B13: 836 | C13: 1067 | D13: 628 | E13: 1603 | F13: 2502
A14: Finansielle poster, netto | B14: -162 | C14: -404 | D14: -290 | E14: -1294 | F14: -1993
A15: Resultat før skat | B15: 46170 | C15: 23988 | D15: -7153 | E15: 1475 | F15: 7257
A16: Skat af årets resultat | B16: 6583 | C16: 2299 | D16: -2815 | E16: -723 | F16: 515
A17: Årets resultat | B17: 39587 | C17: 21689 | D17: -4338 | E17: 2198 | F17: 6742
A18: Gns. antal medarbejdere | B18: 126 | C18: 120 | D18: 107 | E18: 98 | F18: 104
A19: Investering i materielle anlægsaktiver | B19: 4719 | C19: 1831 | D19: 462 | E19: 2585 | F19: 1745

Sheet balance_raw_80673612
A1: Scanpan A/S (CVR 80673612) — Balance (t.kr.) | B1: 2021 | C1: 2022 | D1: 2023 | E1: 2024 | F1: 2025
A2: Immaterielle anlægsaktiver | E2: 750 | F2: 520
A3: Grunde og bygninger | B3: 9802 | C3: 10123 | D3: 9858 | E3: 9327 | F3: 8796
A4: Produktionsanlæg og maskiner | B4: 4968 | C4: 3870 | D4: 2700 | E4: 1626 | F4: 2308
A5: Driftsmateriel og inventar | B5: 3161 | C5: 2074 | D5: 998 | E5: 2263 | F5: 1422
A6: Indretning af lejede lokaler | B6: 1904 | C6: 1425 | D6: 1050 | E6: 736 | F6: 449
A7: Forudbetaling og anlægsaktiver under opførelse
A8: Materielle anlægsaktiver | B8: 19834 | C8: 17492 | D8: 14607 | E8: 13952 | F8: 12974
A9: Kapitalandele, dattervirksomheder | B9: 0 | C9: 0 | D9: 0 | E9: 0 | F9: 0
A10: Deposita | B10: 768 | C10: 858 | D10: 852 | E10: 851 | F10: 851
A11: Finansielle anlægsaktiver | B11: 45793 | C11: 46059 | D11: 40745 | E11: 49360 | F11: 43734
A12: Anlægsaktiver | B12: 65627 | C12: 63551 | D12: 55352 | E12: 64062 | F12: 57228
A13: Råvarer og hjælpematerialer | B13: 31701 | C13: 29329 | D13: 22573 | E13: 27079 | F13: 27956
A14: Varer under fremstilling | B14: 7155 | C14: 7196 | D14: 8674 | E14: 7935 | F14: 7972
A15: Færdigvarer og handelsvarer | B15: 24519 | C15: 37011 | D15: 35611 | E15: 33732 | F15: 38552
A16: Varebeholdninger | B16: 63375 | C16: 73536 | D16: 66858 | E16: 68747 | F16: 74480
A17: Tilgodehavender fra salg og tjenesteydelser | B17: 33119 | C17: 25329 | D17: 25076 | E17: 24017 | F17: 28227
A18: Tilgodehavender hos tilknyttede virksomheder | B18: 0 | C18: 0 | D18: 0 | E18: 0 | F18: 0
A19: Andre tilgodehavender | B19: 728 | C19: 28 | D19: 2745 | E19: 990 | F19: 1604
A20: Periodeafgrænsningsposter (aktiver) | B20: 1473 | C20: 236 | D20: 176 | E20: 522 | F20: 397
A21: Udskudt skatteaktiv | D21: 2104 | E21: 2912 | F21: 2480
A22: Tilgodehavende skat hos tilknyttede virksomheder
A23: Kortfristede skattetilgodehavender | D23: 94 | E23: 534 | F23: 267
A24: Tilgodehavender | B24: 40981 | C24: 26347 | D24: 34743 | E24: 33480 | F24: 34182
A25: Værdipapirer
A26: Likvide beholdninger | B26: 24104 | C26: 18311 | D26: 25798 | E26: 32459 | F26: 22306
A27: Omsætningsaktiver | B27: 128461 | C27: 118195 | D27: 127399 | E27: 134685 | F27: 130968
A28: Aktiver | B28: 194088 | C28: 181746 | D28: 182751 | E28: 198748 | F28: 188196
A29: Selskabskapital | B29: 1000 | C29: 1000 | D29: 1000 | E29: 1000 | F29: 1000
A30: Reserve for nettoopskrivning (indre værdis metode) | B30: 55200 | C30: 56809 | D30: 34732 | E30: 43348 | F30: 37722
A31: Reserve for udviklingsomkostninger
A32: Reserve for sikringstransaktioner | B32: 131 | C32: 0
A33: Andre reserver
A34: Overført resultat | B34: 64913 | C34: 89365 | D34: 105227 | E34: 92146 | F34: 87989
A35: Egenkapital i alt | B35: 125244 | C35: 147174 | D35: 140959 | E35: 146494 | F35: 136711
A36: Hensættelse til udskudt skat | B36: 607 | C36: 727 | D36: 0 | E36: 2104 | F36: 2912
A37: Hensatte forpligtelser | B37: 2774 | C37: 2934 | D37: 2000 | E37: 1866 | F37: 1786
A38: Ansvarlig lånekapital (langfristet)
A39: Langfristede lån | B39: 4203 | C39: 0
A40: Leasingforpligtelser (langfristet) | B40: 2073 | C40: 1182 | D40: 193 | E40: 1908 | F40: 269
...

Sheet pengestrom_raw_80673612
A1: Scanpan A/S (CVR 80673612) — Pengestrømsopgørelse (t.kr.) | B1: 2021 | C1: 2022 | D1: 2023 | E1: 2024 | F1: 2025
A2: Pengestrømme fra driftsaktivitet | B2: -602 | C2: -5340 | D2: -6923 | E2: -7788 | F2: 27
A3: Pengestrømme fra investeringsaktivitet | B3: 11016 | C3: 16101 | D3: 9873 | E3: -3375 | F3: 3628
A4: Pengestrømme fra finansieringsaktivitet | B4: -1144 | C4: -16554 | D4: 4537 | E4: 17824 | F4: -13808
A5: Årets pengestrøm

Sheet Simpel_funktion
A1: Scanpan A/S (CVR 80673612) — Regnskabs- og nøgletal (CVR: 80673612) — funktionsopdelt
A3: Beløb i 1.000 kr. | B3: 2025 | C3: 2024 | D3: 2023 | F3: Note / XBRL-felt
A4: Uddrag af resultatopgørelse
A5: Nettoomsætning | B5: ='res_raw_80673612'!$F$2 | C5: ='res_raw_80673612'!$E$2 | D5: ='res_raw_80673612'!$D$2 | F5: fsa:Revenue
A6: Produktionsomkostninger | B6: =-'res_raw_80673612'!$F$3 | C6: =-'res_raw_80673612'!$E$3 | D6: =-'res_raw_80673612'!$D$3 | F6: fsa:CostOfProduction (vises negativt). Materialer, lønninger, produktionsoverhead.
A7: Bruttoresultat | B7: =IF(ABS((SUM(B5:B6))-'res_raw_80673612'!$F$4)<=2,SUM(B5:B6),'res_raw_80673612'!$F$4) | C7: =IF(ABS((SUM(C5:C6))-'res_raw_80673612'!$E$4)<=2,SUM(C5:C6),'res_raw_80673612'!$E$4) | D7: =IF(ABS((SUM(D5:D6))-'res_raw_80673612'!$D$4)<=2,SUM(D5:D6),'res_raw_80673612'!$D$4) | F7: Beregnet: Nettoomsætning − Produktionsomkostninger. Matcher fsa:GrossResult. Er komponenterne ikke indberettet, vises rapporteret fsa:GrossResult direkte.
A8: Udviklingsomkostninger | B8: =-'res_raw_80673612'!$F$5 | C8: =-'res_raw_80673612'!$E$5 | D8: =-'res_raw_80673612'!$D$5 | F8: ifrs-full:ResearchAndDevelopmentExpense (vises negativt). Udviklingsomkostninger ført i resultatet (v15_21; B&O m.fl.).
A9: Salgs- og distributionsomk. | B9: =-'res_raw_80673612'!$F$6 | C9: =-'res_raw_80673612'!$E$6 | D9: =-'res_raw_80673612'!$D$6 | F9: fsa:DistributionCosts (vises negativt). Marketing, salg, distribution.
A10: Administrationsomkostninger mv. | B10: =-'res_raw_80673612'!$F$7 | C10: =-'res_raw_80673612'!$E$7 | D10: =-'res_raw_80673612'!$D$7 | F10: fsa:AdministrativeExpenses (vises negativt). Generel administration.
A11: Andre driftsindtægter | B11: ='res_raw_80673612'!$F$8 | C11: ='res_raw_80673612'!$E$8 | D11: ='res_raw_80673612'!$D$8 | F11: fsa:OtherOperatingIncome. Sekundære driftsindtægter (huslejeindtægter, off. tilskud, avancer mv.).
A12: Andre driftsomkostninger | B12: =-'res_raw_80673612'!$F$9 | C12: =-'res_raw_80673612'!$E$9 | D12: =-'res_raw_80673612'!$D$9 | F12: fsa:OtherOperatingExpenses (vises negativt). Sekundære driftsomkostninger.
A13: Resultat af primær drift | B13: =IF(ABS((SUM(B7:B12))-'res_raw_80673612'!$F$10)<=2,SUM(B7:B12),'res_raw_80673612'!$F$10) | C13: =IF(ABS((SUM(C7:C12))-'res_raw_80673612'!$E$10)<=2,SUM(C7:C12),'res_raw_80673612'!$E$10) | D13: =IF(ABS((SUM(D7:D12))-'res_raw_80673612'!$D$10)<=2,SUM(D7:D12),'res_raw_80673612'!$D$10) | F13: Beregnet: Bruttoresultat − Udviklingsomk. − Salgs/dist. − Administration + Andre driftsindt. − Andre driftsomk. EBIT.
A14: Finansielle indtægter mv. | B14: =N('res_raw_80673612'!$F$11)+N('res_raw_80673612'!$F$12) | C14: =N('res_raw_80673612'!$E$11)+N('res_raw_80673612'!$E$12) | D14: =N('res_raw_80673612'!$D$11)+N('res_raw_80673612'!$D$12) | F14: fsa:IncomeFromSubsidiaries + fsa:OtherFinanceIncome.
A15: Finansielle omkostninger mv. | B15: =-'res_raw_80673612'!$F$13 | C15: =-'res_raw_80673612'!$E$13 | D15: =-'res_raw_80673612'!$D$13 | F15: fsa:OtherFinanceExpenses (vises negativt). Renteomkostninger, kurstab.
A16: Resultat før skat | B16: =IF(ABS((SUM(B13:B15))-'res_raw_80673612'!$F$15)<=2,SUM(B13:B15),'res_raw_80673612'!$F$15) | C16: =IF(ABS((SUM(C13:C15))-'res_raw_80673612'!$E$15)<=2,SUM(C13:C15),'res_raw_80673612'!$E$15) | D16: =IF(ABS((SUM(D13:D15))-'res_raw_80673612'!$D$15)<=2,SUM(D13:D15),'res_raw_80673612'!$D$15) | F16: Beregnet: EBIT + Fin. indtægter + Fin. omk. EBT.
A18: Uddrag af balance
A19: Anlægsaktiver | B19: ='balance_raw_80673612'!$F$12 | C19: ='balance_raw_80673612'!$E$12 | D19: ='balance_raw_80673612'!$D$12 | F19: fsa:NoncurrentAssets. Materielle, immaterielle og finansielle anlægsaktiver.
A20: Omsætningsaktiver | B20: ='balance_raw_80673612'!$F$27 | C20: ='balance_raw_80673612'!$E$27 | D20: ='balance_raw_80673612'!$D$27 | F20: fsa:CurrentAssets. Varebeholdninger, tilgodehavender, likvider.
A21: Aktiver i alt | B21: =SUM(B19:B20) | C21: =SUM(C19:C20) | D21: =SUM(D19:D20) | F21: Beregnet: Anlægsaktiver + Omsætningsaktiver. Bør matche fsa:Assets.
A23: Egenkapital | B23: ='balance_raw_80673612'!$F$35 | C23: ='balance_raw_80673612'!$E$35 | D23: ='balance_raw_80673612'!$D$35 | F23: fsa:Equity. Selskabskapital, overført resultat, reserver.
A24: Forpligtelser | B24: ='balance_raw_80673612'!$F$56-'balance_raw_80673612'!$F$35 | C24: ='balance_raw_80673612'!$E$56-'balance_raw_80673612'!$E$35 | D24: ='balance_raw_80673612'!$D$56-'balance_raw_80673612'!$D$35 | F24: Beregnet: Passiver (fsa:LiabilitiesAndEquity) − Egenkapital. Hensættelser + kort- og langfristet gæld.
A25: Passiver i alt | B25: =SUM(B23:B24) | C25: =SUM(C23:C24) | D25: =SUM(D23:D24) | F25: Beregnet: Egenkapital + Forpligtelser. Bør matche Aktiver i alt.
A27: Udvalgte balanceposter
A28: Varebeholdninger | B28: ='balance_raw_80673612'!$F$16 | C28: ='balance_raw_80673612'!$E$16 | D28: ='balance_raw_80673612'!$D$16 | F28: fsa:Inventories (eller fsa:ManufacturedGoodsAndGoodsForResale hvis total mangler).
A29: Tilgodehavender fra salg | B29: ='balance_raw_80673612'!$F$17 | C29: ='balance_raw_80673612'!$E$17 | D29: ='balance_raw_80673612'!$D$17 | F29: fsa:ShorttermTradeReceivables. Kortfristede tilgodehavender fra kunder.
A30: Kortfristede gældsforpligtelser | B30: ='balance_raw_80673612'!$F$54 | C30: ='balance_raw_80673612'!$E$54 | D30: ='balance_raw_80673612'!$D$54 | F30: fsa:ShorttermLiabilitiesOtherThanProvisions. Gæld der forfalder inden for 1 år.
A32: Rentabilitet
A33: Afkastningsgrad, % | B33: =IFERROR((B13+B14)/B21*100,"") | C33: =IFERROR((C13+C14)/C21*100,"") | D33: =IFERROR((D13+D14)/D21*100,"")
A34: Overskudsgrad (af bruttofortjeneste), % | B34: =IFERROR((B13+B14)/B7*100,"") | C34: =IFERROR((C13+C14)/C7*100,"") | D34: =IFERROR((D13+D14)/D7*100,"")
A35: Aktivernes omsætningshastighed (af bruttofortjeneste), gange | B35: =IFERROR(B7/B21,"") | C35: =IFERROR(C7/C21,"") | D35: =IFERROR(D7/D21,"")
A36: Gældsrente, % | B36: =IFERROR(-B15*100/B24,"") | C36: =IFERROR(-C15*100/C24,"") | D36: =IFERROR(-D15*100/D24,"")
A37: Egenkapitalens forrentning, % | B37: =IFERROR(B16/B23*100,"") | C37: =IFERROR(C16/C23*100,"") | D37: =IFERROR(D16/D23*100,"")
A38: Gearing, gange | B38: =IFERROR(B24/B23,"") | C38: =IFERROR(C24/C23,"") | D38: =IFERROR(D24/D23,"")
A40: Indekstal for indtjeningsevne (2023=100)
A41: Bruttofortjeneste | B41: =IFERROR(B7/$D7*100,"") | C41: =IFERROR(C7/$D7*100,"") | D41: =IFERROR(D7/$D7*100,"")
A42: Produktionsomkostninger | B42: =IFERROR(B6/$D6*100,"") | C42: =IFERROR(C6/$D6*100,"") | D42: =IFERROR(D6/$D6*100,"")
A43: Udviklingsomkostninger | B43: =IFERROR(B8/$D8*100,"") | C43: =IFERROR(C8/$D8*100,"") | D43: =IFERROR(D8/$D8*100,"")
A44: Salgs- og distributionsomk. | B44: =IFERROR(B9/$D9*100,"") | C44: =IFERROR(C9/$D9*100,"") | D44: =IFERROR(D9/$D9*100,"")
A45: Administrationsomk. | B45: =IFERROR(B10/$D10*100,"") | C45: =IFERROR(C10/$D10*100,"") | D45: =IFERROR(D10/$D10*100,"")
A46: Andre driftsomkostninger | B46: =IFERROR(B12/$D12*100,"") | C46: =IFERROR(C12/$D12*100,"") | D46: =IFERROR(D12/$D12*100,"")
...

Sheet Noter_info
A1: Scanpan A/S (CVR 80673612) — Ukendte XBRL-felter — disse er noter og ikke en del af hoved-regnskabet
A2: Kategori | B2: Dansk navn | C2: XBRL feltnavn | D2: 2021 t.kr. | E2: 2022 t.kr. | F2: 2023 t.kr. | G2: 2024 t.kr. | H2: 2025 t.kr. | I2: Forklaring
A3: Øvrige (ukendt) | B3: fsa:ExchangeRateAdjustmentsOtherFinanceExpenses | C3: fsa:ExchangeRateAdjustmentsOtherFinanceExpenses | D3: 8 | E3: 217 | F3: 0 | I3: Ingen forklaring tilgængelig.
A4: Øvrige (ukendt) | B4: fsa:Loans | C4: fsa:Loans | D4: -50 | E4: -90 | F4: 0 | I4: Ingen forklaring tilgængelig.
A5: Øvrige (ukendt) | B5: fsa:RaisingOfLongtermDebt | C5: fsa:RaisingOfLongtermDebt | G5: 1715 | H5: 0 | I5: Ingen forklaring tilgængelig.
A6: Øvrige (ukendt) | B6: fsa:ReductionOfLeaseCommitments | C6: fsa:ReductionOfLeaseCommitments | D6: -1810 | E6: -1236 | F6: -741 | G6: 0 | I6: Ingen forklaring tilgængelig.
A7: Øvrige (ukendt) | B7: fsa:RepaymentOfMortgageDebt | C7: fsa:RepaymentOfMortgageDebt | D7: -335 | E7: -4203 | F7: 0 | I7: Ingen forklaring tilgængelig.
A8: Øvrige (ukendt) | B8: fsa:ShorttermPayablesToAssociates | C8: fsa:ShorttermPayablesToAssociates | D8: 122 | E8: 0 | I8: Ingen forklaring tilgængelig.
