Workbook

Sheet Overblik_22460218
A1: TORM A/S (CVR 22460218) — Regnskabsanalyse – Resultatopgørelse & Balance (t.USD) · Klasse C-stor · Revision
H2: Indekstal (2021=100)
A3: Resultatopgørelse t.USD | B3: 2021 | C3: 2022 | D3: 2023 | E3: 2024 | F3: 2025 | H3: 2021 | I3: 2022 | J3: 2023 | K3: 2024 | L3: 2025
A4: Nettoomsætning | B4: ='res_raw_22460218'!$B$2 | C4: ='res_raw_22460218'!$C$2 | D4: ='res_raw_22460218'!$D$2 | E4: ='res_raw_22460218'!$E$2 | F4: ='res_raw_22460218'!$F$2 | H4: =IFERROR(B4/$B$4*100,"") | I4: =IFERROR(C4/$B$4*100,"") | J4: =IFERROR(D4/$B$4*100,"") | K4: =IFERROR(E4/$B$4*100,"") | L4: =IFERROR(F4/$B$4*100,"")
A5: Produktionsomkostninger | B5: ='res_raw_22460218'!$B$3 | C5: ='res_raw_22460218'!$C$3 | D5: ='res_raw_22460218'!$D$3 | E5: ='res_raw_22460218'!$E$3 | F5: ='res_raw_22460218'!$F$3 | H5: =IFERROR(B5/$B$5*100,"") | I5: =IFERROR(C5/$B$5*100,"") | J5: =IFERROR(D5/$B$5*100,"") | K5: =IFERROR(E5/$B$5*100,"") | L5: =IFERROR(F5/$B$5*100,"")
A6: Bruttoresultat | B6: ='res_raw_22460218'!$B$4 | C6: ='res_raw_22460218'!$C$4 | D6: ='res_raw_22460218'!$D$4 | E6: ='res_raw_22460218'!$E$4 | F6: ='res_raw_22460218'!$F$4 | H6: =IFERROR(B6/$B$6*100,"") | I6: =IFERROR(C6/$B$6*100,"") | J6: =IFERROR(D6/$B$6*100,"") | K6: =IFERROR(E6/$B$6*100,"") | L6: =IFERROR(F6/$B$6*100,"")
A7: Salgs- og distributionsomkostninger | B7: ='res_raw_22460218'!$B$5 | C7: ='res_raw_22460218'!$C$5 | D7: ='res_raw_22460218'!$D$5 | E7: ='res_raw_22460218'!$E$5 | F7: ='res_raw_22460218'!$F$5 | H7: =IFERROR(B7/$B$7*100,"") | I7: =IFERROR(C7/$B$7*100,"") | J7: =IFERROR(D7/$B$7*100,"") | K7: =IFERROR(E7/$B$7*100,"") | L7: =IFERROR(F7/$B$7*100,"")
A8: Administrationsomkostninger | B8: ='res_raw_22460218'!$B$6 | C8: ='res_raw_22460218'!$C$6 | D8: ='res_raw_22460218'!$D$6 | E8: ='res_raw_22460218'!$E$6 | F8: ='res_raw_22460218'!$F$6 | H8: =IFERROR(B8/$B$8*100,"") | I8: =IFERROR(C8/$B$8*100,"") | J8: =IFERROR(D8/$B$8*100,"") | K8: =IFERROR(E8/$B$8*100,"") | L8: =IFERROR(F8/$B$8*100,"")
A9: Andre driftsindtægter | B9: ='res_raw_22460218'!$B$7 | C9: ='res_raw_22460218'!$C$7 | D9: ='res_raw_22460218'!$D$7 | E9: ='res_raw_22460218'!$E$7 | F9: ='res_raw_22460218'!$F$7 | H9: =IFERROR(B9/$B$9*100,"") | I9: =IFERROR(C9/$B$9*100,"") | J9: =IFERROR(D9/$B$9*100,"") | K9: =IFERROR(E9/$B$9*100,"") | L9: =IFERROR(F9/$B$9*100,"")
A10: Andre driftsomkostninger | B10: ='res_raw_22460218'!$B$8 | C10: ='res_raw_22460218'!$C$8 | D10: ='res_raw_22460218'!$D$8 | E10: ='res_raw_22460218'!$E$8 | F10: ='res_raw_22460218'!$F$8 | H10: =IFERROR(B10/$B$10*100,"") | I10: =IFERROR(C10/$B$10*100,"") | J10: =IFERROR(D10/$B$10*100,"") | K10: =IFERROR(E10/$B$10*100,"") | L10: =IFERROR(F10/$B$10*100,"")
A11: Resultat af primær drift | B11: ='res_raw_22460218'!$B$9 | C11: ='res_raw_22460218'!$C$9 | D11: ='res_raw_22460218'!$D$9 | E11: ='res_raw_22460218'!$E$9 | F11: ='res_raw_22460218'!$F$9 | H11: =IFERROR(B11/$B$11*100,"") | I11: =IFERROR(C11/$B$11*100,"") | J11: =IFERROR(D11/$B$11*100,"") | K11: =IFERROR(E11/$B$11*100,"") | L11: =IFERROR(F11/$B$11*100,"")
A12: Indtægter af kapitalandele, dattervirksomheder | B12: ='res_raw_22460218'!$B$10 | C12: ='res_raw_22460218'!$C$10 | D12: ='res_raw_22460218'!$D$10 | E12: ='res_raw_22460218'!$E$10 | F12: ='res_raw_22460218'!$F$10 | H12: =IFERROR(B12/$B$12*100,"") | I12: =IFERROR(C12/$B$12*100,"") | J12: =IFERROR(D12/$B$12*100,"") | K12: =IFERROR(E12/$B$12*100,"") | L12: =IFERROR(F12/$B$12*100,"")
A13: Finansielle indtægter | B13: ='res_raw_22460218'!$B$11 | C13: ='res_raw_22460218'!$C$11 | D13: ='res_raw_22460218'!$D$11 | E13: ='res_raw_22460218'!$E$11 | F13: ='res_raw_22460218'!$F$11 | H13: =IFERROR(B13/$B$13*100,"") | I13: =IFERROR(C13/$B$13*100,"") | J13: =IFERROR(D13/$B$13*100,"") | K13: =IFERROR(E13/$B$13*100,"") | L13: =IFERROR(F13/$B$13*100,"")
A14: Finansielle omkostninger | B14: ='res_raw_22460218'!$B$12 | C14: ='res_raw_22460218'!$C$12 | D14: ='res_raw_22460218'!$D$12 | E14: ='res_raw_22460218'!$E$12 | F14: ='res_raw_22460218'!$F$12 | H14: =IFERROR(B14/$B$14*100,"") | I14: =IFERROR(C14/$B$14*100,"") | J14: =IFERROR(D14/$B$14*100,"") | K14: =IFERROR(E14/$B$14*100,"") | L14: =IFERROR(F14/$B$14*100,"")
A15: Finansielle poster, netto | B15: ='res_raw_22460218'!$B$13 | C15: ='res_raw_22460218'!$C$13 | D15: ='res_raw_22460218'!$D$13 | E15: ='res_raw_22460218'!$E$13 | F15: ='res_raw_22460218'!$F$13 | H15: =IFERROR(B15/$B$15*100,"") | I15: =IFERROR(C15/$B$15*100,"") | J15: =IFERROR(D15/$B$15*100,"") | K15: =IFERROR(E15/$B$15*100,"") | L15: =IFERROR(F15/$B$15*100,"")
A16: Resultat før skat | B16: ='res_raw_22460218'!$B$14 | C16: ='res_raw_22460218'!$C$14 | D16: ='res_raw_22460218'!$D$14 | E16: ='res_raw_22460218'!$E$14 | F16: ='res_raw_22460218'!$F$14 | H16: =IFERROR(B16/$B$16*100,"") | I16: =IFERROR(C16/$B$16*100,"") | J16: =IFERROR(D16/$B$16*100,"") | K16: =IFERROR(E16/$B$16*100,"") | L16: =IFERROR(F16/$B$16*100,"")
A17: Skat af årets resultat | B17: ='res_raw_22460218'!$B$15 | C17: ='res_raw_22460218'!$C$15 | D17: ='res_raw_22460218'!$D$15 | E17: ='res_raw_22460218'!$E$15 | F17: ='res_raw_22460218'!$F$15 | H17: =IFERROR(B17/$B$17*100,"") | I17: =IFERROR(C17/$B$17*100,"") | J17: =IFERROR(D17/$B$17*100,"") | K17: =IFERROR(E17/$B$17*100,"") | L17: =IFERROR(F17/$B$17*100,"")
A18: Årets resultat | B18: ='res_raw_22460218'!$B$16 | C18: ='res_raw_22460218'!$C$16 | D18: ='res_raw_22460218'!$D$16 | E18: ='res_raw_22460218'!$E$16 | F18: ='res_raw_22460218'!$F$16 | H18: =IFERROR(B18/$B$18*100,"") | I18: =IFERROR(C18/$B$18*100,"") | J18: =IFERROR(D18/$B$18*100,"") | K18: =IFERROR(E18/$B$18*100,"") | L18: =IFERROR(F18/$B$18*100,"")
A20: AKTIVER t.USD | B20: 2021 | C20: 2022 | D20: 2023 | E20: 2024 | F20: 2025 | H20: 2021 | I20: 2022 | J20: 2023 | K20: 2024 | L20: 2025
A21: Immaterielle anlægsaktiver | B21: ='balance_raw_22460218'!$B$2 | C21: ='balance_raw_22460218'!$C$2 | D21: ='balance_raw_22460218'!$D$2 | E21: ='balance_raw_22460218'!$E$2 | F21: ='balance_raw_22460218'!$F$2 | H21: =IFERROR(B21/$B$21*100,"") | I21: =IFERROR(C21/$B$21*100,"") | J21: =IFERROR(D21/$B$21*100,"") | K21: =IFERROR(E21/$B$21*100,"") | L21: =IFERROR(F21/$B$21*100,"")
A22: Grunde og bygninger | B22: ='balance_raw_22460218'!$B$3 | C22: ='balance_raw_22460218'!$C$3 | D22: ='balance_raw_22460218'!$D$3 | E22: ='balance_raw_22460218'!$E$3 | F22: ='balance_raw_22460218'!$F$3 | H22: =IFERROR(B22/$B$22*100,"") | I22: =IFERROR(C22/$B$22*100,"") | J22: =IFERROR(D22/$B$22*100,"") | K22: =IFERROR(E22/$B$22*100,"") | L22: =IFERROR(F22/$B$22*100,"")
A23: Produktionsanlæg og maskiner | B23: ='balance_raw_22460218'!$B$4 | C23: ='balance_raw_22460218'!$C$4 | D23: ='balance_raw_22460218'!$D$4 | E23: ='balance_raw_22460218'!$E$4 | F23: ='balance_raw_22460218'!$F$4 | H23: =IFERROR(B23/$B$23*100,"") | I23: =IFERROR(C23/$B$23*100,"") | J23: =IFERROR(D23/$B$23*100,"") | K23: =IFERROR(E23/$B$23*100,"") | L23: =IFERROR(F23/$B$23*100,"")
A24: Driftsmateriel og inventar | B24: ='balance_raw_22460218'!$B$5 | C24: ='balance_raw_22460218'!$C$5 | D24: ='balance_raw_22460218'!$D$5 | E24: ='balance_raw_22460218'!$E$5 | F24: ='balance_raw_22460218'!$F$5 | H24: =IFERROR(B24/$B$24*100,"") | I24: =IFERROR(C24/$B$24*100,"") | J24: =IFERROR(D24/$B$24*100,"") | K24: =IFERROR(E24/$B$24*100,"") | L24: =IFERROR(F24/$B$24*100,"")
A25: Indretning af lejede lokaler | B25: ='balance_raw_22460218'!$B$6 | C25: ='balance_raw_22460218'!$C$6 | D25: ='balance_raw_22460218'!$D$6 | E25: ='balance_raw_22460218'!$E$6 | F25: ='balance_raw_22460218'!$F$6 | H25: =IFERROR(B25/$B$25*100,"") | I25: =IFERROR(C25/$B$25*100,"") | J25: =IFERROR(D25/$B$25*100,"") | K25: =IFERROR(E25/$B$25*100,"") | L25: =IFERROR(F25/$B$25*100,"")
A26: Forudbetaling og anlægsaktiver under opførelse | B26: ='balance_raw_22460218'!$B$7 | C26: ='balance_raw_22460218'!$C$7 | D26: ='balance_raw_22460218'!$D$7 | E26: ='balance_raw_22460218'!$E$7 | F26: ='balance_raw_22460218'!$F$7 | H26: =IFERROR(B26/$B$26*100,"") | I26: =IFERROR(C26/$B$26*100,"") | J26: =IFERROR(D26/$B$26*100,"") | K26: =IFERROR(E26/$B$26*100,"") | L26: =IFERROR(F26/$B$26*100,"")
A27: Materielle anlægsaktiver | B27: ='balance_raw_22460218'!$B$8 | C27: ='balance_raw_22460218'!$C$8 | D27: ='balance_raw_22460218'!$D$8 | E27: ='balance_raw_22460218'!$E$8 | F27: ='balance_raw_22460218'!$F$8 | H27: =IFERROR(B27/$B$27*100,"") | I27: =IFERROR(C27/$B$27*100,"") | J27: =IFERROR(D27/$B$27*100,"") | K27: =IFERROR(E27/$B$27*100,"") | L27: =IFERROR(F27/$B$27*100,"")
A28: Kapitalandele, dattervirksomheder | B28: ='balance_raw_22460218'!$B$9 | C28: ='balance_raw_22460218'!$C$9 | D28: ='balance_raw_22460218'!$D$9 | E28: ='balance_raw_22460218'!$E$9 | F28: ='balance_raw_22460218'!$F$9 | H28: =IFERROR(B28/$B$28*100,"") | I28: =IFERROR(C28/$B$28*100,"") | J28: =IFERROR(D28/$B$28*100,"") | K28: =IFERROR(E28/$B$28*100,"") | L28: =IFERROR(F28/$B$28*100,"")
A29: Deposita | B29: ='balance_raw_22460218'!$B$10 | C29: ='balance_raw_22460218'!$C$10 | D29: ='balance_raw_22460218'!$D$10 | E29: ='balance_raw_22460218'!$E$10 | F29: ='balance_raw_22460218'!$F$10 | H29: =IFERROR(B29/$B$29*100,"") | I29: =IFERROR(C29/$B$29*100,"") | J29: =IFERROR(D29/$B$29*100,"") | K29: =IFERROR(E29/$B$29*100,"") | L29: =IFERROR(F29/$B$29*100,"")
A30: Finansielle anlægsaktiver | B30: ='balance_raw_22460218'!$B$11 | C30: ='balance_raw_22460218'!$C$11 | D30: ='balance_raw_22460218'!$D$11 | E30: ='balance_raw_22460218'!$E$11 | F30: ='balance_raw_22460218'!$F$11 | H30: =IFERROR(B30/$B$30*100,"") | I30: =IFERROR(C30/$B$30*100,"") | J30: =IFERROR(D30/$B$30*100,"") | K30: =IFERROR(E30/$B$30*100,"") | L30: =IFERROR(F30/$B$30*100,"")
A31: Anlægsaktiver | B31: ='balance_raw_22460218'!$B$12 | C31: ='balance_raw_22460218'!$C$12 | D31: ='balance_raw_22460218'!$D$12 | E31: ='balance_raw_22460218'!$E$12 | F31: ='balance_raw_22460218'!$F$12 | H31: =IFERROR(B31/$B$31*100,"") | I31: =IFERROR(C31/$B$31*100,"") | J31: =IFERROR(D31/$B$31*100,"") | K31: =IFERROR(E31/$B$31*100,"") | L31: =IFERROR(F31/$B$31*100,"")
A32: Varebeholdninger | B32: ='balance_raw_22460218'!$B$13 | C32: ='balance_raw_22460218'!$C$13 | D32: ='balance_raw_22460218'!$D$13 | E32: ='balance_raw_22460218'!$E$13 | F32: ='balance_raw_22460218'!$F$13 | H32: =IFERROR(B32/$B$32*100,"") | I32: =IFERROR(C32/$B$32*100,"") | J32: =IFERROR(D32/$B$32*100,"") | K32: =IFERROR(E32/$B$32*100,"") | L32: =IFERROR(F32/$B$32*100,"")
A33: Tilgodehavender fra salg og tjenesteydelser | B33: ='balance_raw_22460218'!$B$14 | C33: ='balance_raw_22460218'!$C$14 | D33: ='balance_raw_22460218'!$D$14 | E33: ='balance_raw_22460218'!$E$14 | F33: ='balance_raw_22460218'!$F$14 | H33: =IFERROR(B33/$B$33*100,"") | I33: =IFERROR(C33/$B$33*100,"") | J33: =IFERROR(D33/$B$33*100,"") | K33: =IFERROR(E33/$B$33*100,"") | L33: =IFERROR(F33/$B$33*100,"")
A34: Tilgodehavender hos tilknyttede virksomheder | B34: ='balance_raw_22460218'!$B$15 | C34: ='balance_raw_22460218'!$C$15 | D34: ='balance_raw_22460218'!$D$15 | E34: ='balance_raw_22460218'!$E$15 | F34: ='balance_raw_22460218'!$F$15 | H34: =IFERROR(B34/$B$34*100,"") | I34: =IFERROR(C34/$B$34*100,"") | J34: =IFERROR(D34/$B$34*100,"") | K34: =IFERROR(E34/$B$34*100,"") | L34: =IFERROR(F34/$B$34*100,"")
A35: Andre tilgodehavender | B35: ='balance_raw_22460218'!$B$16 | C35: ='balance_raw_22460218'!$C$16 | D35: ='balance_raw_22460218'!$D$16 | E35: ='balance_raw_22460218'!$E$16 | F35: ='balance_raw_22460218'!$F$16 | H35: =IFERROR(B35/$B$35*100,"") | I35: =IFERROR(C35/$B$35*100,"") | J35: =IFERROR(D35/$B$35*100,"") | K35: =IFERROR(E35/$B$35*100,"") | L35: =IFERROR(F35/$B$35*100,"")
A36: Periodeafgrænsningsposter (aktiver) | B36: ='balance_raw_22460218'!$B$17 | C36: ='balance_raw_22460218'!$C$17 | D36: ='balance_raw_22460218'!$D$17 | E36: ='balance_raw_22460218'!$E$17 | F36: ='balance_raw_22460218'!$F$17 | H36: =IFERROR(B36/$B$36*100,"") | I36: =IFERROR(C36/$B$36*100,"") | J36: =IFERROR(D36/$B$36*100,"") | K36: =IFERROR(E36/$B$36*100,"") | L36: =IFERROR(F36/$B$36*100,"")
A37: Udskudt skatteaktiv | B37: ='balance_raw_22460218'!$B$18 | C37: ='balance_raw_22460218'!$C$18 | D37: ='balance_raw_22460218'!$D$18 | E37: ='balance_raw_22460218'!$E$18 | F37: ='balance_raw_22460218'!$F$18 | H37: =IFERROR(B37/$B$37*100,"") | I37: =IFERROR(C37/$B$37*100,"") | J37: =IFERROR(D37/$B$37*100,"") | K37: =IFERROR(E37/$B$37*100,"") | L37: =IFERROR(F37/$B$37*100,"")
A38: Tilgodehavende skat hos tilknyttede virksomheder | B38: ='balance_raw_22460218'!$B$19 | C38: ='balance_raw_22460218'!$C$19 | D38: ='balance_raw_22460218'!$D$19 | E38: ='balance_raw_22460218'!$E$19 | F38: ='balance_raw_22460218'!$F$19 | H38: =IFERROR(B38/$B$38*100,"") | I38: =IFERROR(C38/$B$38*100,"") | J38: =IFERROR(D38/$B$38*100,"") | K38: =IFERROR(E38/$B$38*100,"") | L38: =IFERROR(F38/$B$38*100,"")
A39: Kortfristede skattetilgodehavender | B39: ='balance_raw_22460218'!$B$20 | C39: ='balance_raw_22460218'!$C$20 | D39: ='balance_raw_22460218'!$D$20 | E39: ='balance_raw_22460218'!$E$20 | F39: ='balance_raw_22460218'!$F$20 | H39: =IFERROR(B39/$B$39*100,"") | I39: =IFERROR(C39/$B$39*100,"") | J39: =IFERROR(D39/$B$39*100,"") | K39: =IFERROR(E39/$B$39*100,"") | L39: =IFERROR(F39/$B$39*100,"")
A40: Tilgodehavender | B40: ='balance_raw_22460218'!$B$21 | C40: ='balance_raw_22460218'!$C$21 | D40: ='balance_raw_22460218'!$D$21 | E40: ='balance_raw_22460218'!$E$21 | F40: ='balance_raw_22460218'!$F$21 | H40: =IFERROR(B40/$B$40*100,"") | I40: =IFERROR(C40/$B$40*100,"") | J40: =IFERROR(D40/$B$40*100,"") | K40: =IFERROR(E40/$B$40*100,"") | L40: =IFERROR(F40/$B$40*100,"")
A41: Værdipapirer | B41: ='balance_raw_22460218'!$B$22 | C41: ='balance_raw_22460218'!$C$22 | D41: ='balance_raw_22460218'!$D$22 | E41: ='balance_raw_22460218'!$E$22 | F41: ='balance_raw_22460218'!$F$22 | H41: =IFERROR(B41/$B$41*100,"") | I41: =IFERROR(C41/$B$41*100,"") | J41: =IFERROR(D41/$B$41*100,"") | K41: =IFERROR(E41/$B$41*100,"") | L41: =IFERROR(F41/$B$41*100,"")
...

Sheet res_raw_22460218
A1: TORM A/S (CVR 22460218) — Resultatopgørelse & nøgleoplysninger (t.USD) | B1: 2021 | C1: 2022 | D1: 2023 | E1: 2024 | F1: 2025
A2: Nettoomsætning | B2: 619000 | C2: 1440000 | D2: 1481363 | E2: 1463625 | F2: 1018993
A3: Produktionsomkostninger
A4: Bruttoresultat | B4: 127460 | C4: 743708 | D4: 720935 | E4: 639096 | F4: 387980
A5: Salgs- og distributionsomkostninger
A6: Administrationsomkostninger | B6: 35023 | C6: 32837 | D6: 49579 | E6: 55899 | F6: 61070
A7: Andre driftsindtægter | B7: 625 | C7: 8214 | D7: 74521 | E7: 283840 | F7: 6728
A8: Andre driftsomkostninger | B8: 16704 | C8: 11325 | D8: 13655 | E8: 22257 | F8: 27099
A9: Resultat af primær drift | B9: 45000 | C9: 587000 | D9: 597072 | E9: 707220 | F9: 119221
A10: Indtægter af kapitalandele, dattervirksomheder | B10: 19054 | C10: 8129 | D10: 20515 | E10: 307852 | F10: 1017
A11: Finansielle indtægter | B11: 341 | C11: 5465 | D11: 34894 | E11: 15112 | F11: 10611
A12: Finansielle omkostninger | B12: 30762 | C12: 60184 | D12: 80959 | E12: 48160 | F12: 29531
A13: Finansielle poster, netto | B13: -30000 | C13: -55000
A14: Resultat før skat | B14: 26406 | C14: 544685 | D14: 571522 | E14: 982024 | F14: 101318
A15: Skat af årets resultat | B15: 1193 | C15: 1087 | D15: 1351 | E15: 775 | F15: 1060
A16: Årets resultat | B16: 25213 | C16: 543598 | D16: 570171 | E16: 981249 | F16: 100258
A17: Gns. antal medarbejdere | B17: 243 | C17: 227
A18: Investering i materielle anlægsaktiver | B18: 643000 | C18: 153000

Sheet balance_raw_22460218
A1: TORM A/S (CVR 22460218) — Balance (t.USD) | B1: 2021 | C1: 2022 | D1: 2023 | E1: 2024 | F1: 2025
A2: Immaterielle anlægsaktiver | B2: 0 | C2: 651 | D2: 792 | E2: 1006 | F2: 1526
A3: Grunde og bygninger | B3: 2934 | C3: 1842 | D3: 757 | E3: 5245 | F3: 3965
A4: Produktionsanlæg og maskiner | B4: 4850 | C4: 2926 | D4: 2285 | E4: 1098 | F4: 488
A5: Driftsmateriel og inventar
A6: Indretning af lejede lokaler
A7: Forudbetaling og anlægsaktiver under opførelse | B7: 11996 | C7: 0
A8: Materielle anlægsaktiver | B8: 1663731 | C8: 1618912 | D8: 1696527 | E8: 1636247 | F8: 1392728
A9: Kapitalandele, dattervirksomheder | B9: 126261 | C9: 128429 | D9: 179033 | E9: 6810 | F9: 12410
A10: Deposita
A11: Finansielle anlægsaktiver | B11: 127734 | C11: 128701 | D11: 179109 | E11: 6886 | F11: 12410
A12: Anlægsaktiver | B12: 1791465 | C12: 1748264 | D12: 1876428 | E12: 1644139 | F12: 1406664
A13: Varebeholdninger | B13: 48658 | C13: 60991 | D13: 57400 | E13: 55047 | F13: 49620
A14: Tilgodehavender fra salg og tjenesteydelser | B14: 83218 | C14: 255618 | D14: 193525 | E14: 128885 | F14: 130463
A15: Tilgodehavender hos tilknyttede virksomheder | B15: 5039 | C15: 93 | D15: 66747 | E15: 3139 | F15: 15047
A16: Andre tilgodehavender | B16: 31123 | C16: 16983 | D16: 21748 | E16: 28762 | F16: 8049
A17: Periodeafgrænsningsposter (aktiver) | B17: 4981 | C17: 9147 | D17: 8738 | E17: 10034 | F17: 36523
A18: Udskudt skatteaktiv
A19: Tilgodehavende skat hos tilknyttede virksomheder
A20: Kortfristede skattetilgodehavender
A21: Tilgodehavender
A22: Værdipapirer
A23: Likvide beholdninger | B23: 143840 | C23: 296863 | D23: 262989 | E23: 169449 | F23: 128235
A24: Omsætningsaktiver | B24: 316859 | C24: 639695 | D24: 611147 | E24: 395316 | F24: 367937
A25: Aktiver | B25: 2108000 | C25: 2388000 | D25: 2487575 | E25: 2039455 | F25: 1774601
A26: Selskabskapital | B26: 141946 | C26: 141946 | D26: 141946 | E26: 180773 | F26: 180773
A27: Reserve for nettoopskrivning (indre værdis metode)
A28: Reserve for udviklingsomkostninger
A29: Reserve for sikringstransaktioner
A30: Andre reserver | B30: 5896 | C30: 5896 | D30: 5896 | E30: 5896 | F30: 5896
A31: Overført resultat | B31: 397884 | C31: 943037 | D31: 1411890 | E31: 1139987 | F31: 1264116
A32: Egenkapital i alt | B32: 544000 | C32: 1091000 | D32: 1559777 | E32: 1324484 | F32: 1451569
A33: Hensatte forpligtelser | B33: 18300 | C33: 6500 | D33: 0
A34: Ansvarlig lånekapital (langfristet)
A35: Langfristede lån | B35: 440815 | C35: 484030 | D35: 496369 | E35: 444362 | F35: 27113
A36: Leasingforpligtelser (langfristet)
A37: Anden gæld (langfristet) | B37: 806276 | C37: 0
A38: Langfristede gældsforpligtelser | B38: 1292267 | C38: 531356 | D38: 543806 | E38: 491854 | F38: 74895
A39: Ansvarlig lånekapital (kortfristet)
A40: Kortfristet del af langfristede gældsforpligtelser
...

Sheet Simpel_funktion
A1: TORM A/S (CVR 22460218) — Regnskabs- og nøgletal (CVR: 22460218) — funktionsopdelt
A3: Beløb i 1.000 kr. | B3: 2025 | C3: 2024 | D3: 2023 | F3: Note / XBRL-felt
A4: Uddrag af resultatopgørelse
A5: Nettoomsætning | B5: ='res_raw_22460218'!$F$2 | C5: ='res_raw_22460218'!$E$2 | D5: ='res_raw_22460218'!$D$2 | F5: fsa:Revenue
A6: Produktionsomkostninger | B6: =-'res_raw_22460218'!$F$3 | C6: =-'res_raw_22460218'!$E$3 | D6: =-'res_raw_22460218'!$D$3 | F6: fsa:CostOfProduction (vises negativt). Materialer, lønninger, produktionsoverhead.
A7: Bruttoresultat | B7: =SUM(B5:B6) | C7: =SUM(C5:C6) | D7: =SUM(D5:D6) | F7: Beregnet: Nettoomsætning − Produktionsomkostninger. Matcher fsa:GrossResult.
A8: Salgs- og distributionsomk. | B8: =-'res_raw_22460218'!$F$5 | C8: =-'res_raw_22460218'!$E$5 | D8: =-'res_raw_22460218'!$D$5 | F8: fsa:DistributionCosts (vises negativt). Marketing, salg, distribution.
A9: Administrationsomkostninger mv. | B9: =-'res_raw_22460218'!$F$6 | C9: =-'res_raw_22460218'!$E$6 | D9: =-'res_raw_22460218'!$D$6 | F9: fsa:AdministrativeExpenses (vises negativt). Generel administration.
A10: Andre driftsindtægter | B10: ='res_raw_22460218'!$F$7 | C10: ='res_raw_22460218'!$E$7 | D10: ='res_raw_22460218'!$D$7 | F10: fsa:OtherOperatingIncome. Sekundære driftsindtægter (huslejeindtægter, off. tilskud, avancer mv.).
A11: Andre driftsomkostninger | B11: =-'res_raw_22460218'!$F$8 | C11: =-'res_raw_22460218'!$E$8 | D11: =-'res_raw_22460218'!$D$8 | F11: fsa:OtherOperatingExpenses (vises negativt). Sekundære driftsomkostninger.
A12: Resultat af primær drift | B12: =SUM(B7:B11) | C12: =SUM(C7:C11) | D12: =SUM(D7:D11) | F12: Beregnet: Bruttoresultat − Salgs/dist. − Administration + Andre driftsindt. − Andre driftsomk. EBIT.
A13: Finansielle indtægter mv. | B13: =N('res_raw_22460218'!$F$10)+N('res_raw_22460218'!$F$11) | C13: =N('res_raw_22460218'!$E$10)+N('res_raw_22460218'!$E$11) | D13: =N('res_raw_22460218'!$D$10)+N('res_raw_22460218'!$D$11) | F13: fsa:IncomeFromSubsidiaries + fsa:OtherFinanceIncome.
A14: Finansielle omkostninger mv. | B14: =-'res_raw_22460218'!$F$12 | C14: =-'res_raw_22460218'!$E$12 | D14: =-'res_raw_22460218'!$D$12 | F14: fsa:OtherFinanceExpenses (vises negativt). Renteomkostninger, kurstab.
A15: Resultat før skat | B15: =SUM(B12:B14) | C15: =SUM(C12:C14) | D15: =SUM(D12:D14) | F15: Beregnet: EBIT + Fin. indtægter + Fin. omk. EBT.
A17: Uddrag af balance
A18: Anlægsaktiver | B18: ='balance_raw_22460218'!$F$12 | C18: ='balance_raw_22460218'!$E$12 | D18: ='balance_raw_22460218'!$D$12 | F18: fsa:NoncurrentAssets. Materielle, immaterielle og finansielle anlægsaktiver.
A19: Omsætningsaktiver | B19: ='balance_raw_22460218'!$F$24 | C19: ='balance_raw_22460218'!$E$24 | D19: ='balance_raw_22460218'!$D$24 | F19: fsa:CurrentAssets. Varebeholdninger, tilgodehavender, likvider.
A20: Aktiver i alt | B20: =SUM(B18:B19) | C20: =SUM(C18:C19) | D20: =SUM(D18:D19) | F20: Beregnet: Anlægsaktiver + Omsætningsaktiver. Bør matche fsa:Assets.
A22: Egenkapital | B22: ='balance_raw_22460218'!$F$32 | C22: ='balance_raw_22460218'!$E$32 | D22: ='balance_raw_22460218'!$D$32 | F22: fsa:Equity. Selskabskapital, overført resultat, reserver.
A23: Forpligtelser | B23: ='balance_raw_22460218'!$F$52-'balance_raw_22460218'!$F$32 | C23: ='balance_raw_22460218'!$E$52-'balance_raw_22460218'!$E$32 | D23: ='balance_raw_22460218'!$D$52-'balance_raw_22460218'!$D$32 | F23: Beregnet: Passiver (fsa:LiabilitiesAndEquity) − Egenkapital. Hensættelser + kort- og langfristet gæld.
A24: Passiver i alt | B24: =SUM(B22:B23) | C24: =SUM(C22:C23) | D24: =SUM(D22:D23) | F24: Beregnet: Egenkapital + Forpligtelser. Bør matche Aktiver i alt.
A26: Udvalgte balanceposter
A27: Varebeholdninger | B27: ='balance_raw_22460218'!$F$13 | C27: ='balance_raw_22460218'!$E$13 | D27: ='balance_raw_22460218'!$D$13 | F27: fsa:Inventories (eller fsa:ManufacturedGoodsAndGoodsForResale hvis total mangler).
A28: Tilgodehavender fra salg | B28: ='balance_raw_22460218'!$F$14 | C28: ='balance_raw_22460218'!$E$14 | D28: ='balance_raw_22460218'!$D$14 | F28: fsa:ShorttermTradeReceivables. Kortfristede tilgodehavender fra kunder.
A29: Kortfristede gældsforpligtelser | B29: ='balance_raw_22460218'!$F$50 | C29: ='balance_raw_22460218'!$E$50 | D29: ='balance_raw_22460218'!$D$50 | F29: fsa:ShorttermLiabilitiesOtherThanProvisions. Gæld der forfalder inden for 1 år.
A31: Rentabilitet
A32: Afkastningsgrad, % | B32: =IFERROR((B12+B13)/B20*100,"") | C32: =IFERROR((C12+C13)/C20*100,"") | D32: =IFERROR((D12+D13)/D20*100,"")
A33: Overskudsgrad, % | B33: =IFERROR((B12+B13)/B5*100,"") | C33: =IFERROR((C12+C13)/C5*100,"") | D33: =IFERROR((D12+D13)/D5*100,"")
A34: Aktivernes omsætningshastighed, gange | B34: =IFERROR(B5/B20,"") | C34: =IFERROR(C5/C20,"") | D34: =IFERROR(D5/D20,"")
A35: Gældsrente, % | B35: =IFERROR(-B14*100/B23,"") | C35: =IFERROR(-C14*100/C23,"") | D35: =IFERROR(-D14*100/D23,"")
A36: Egenkapitalens forrentning, % | B36: =IFERROR(B15/B22*100,"") | C36: =IFERROR(C15/C22*100,"") | D36: =IFERROR(D15/D22*100,"")
A37: Gearing, gange | B37: =IFERROR(B23/B22,"") | C37: =IFERROR(C23/C22,"") | D37: =IFERROR(D23/D22,"")
A39: Indekstal for indtjeningsevne (2023=100)
A40: Nettoomsætning | B40: =IFERROR(B5/$D5*100,"") | C40: =IFERROR(C5/$D5*100,"") | D40: =IFERROR(D5/$D5*100,"")
A41: Produktionsomkostninger | B41: =IFERROR(B6/$D6*100,"") | C41: =IFERROR(C6/$D6*100,"") | D41: =IFERROR(D6/$D6*100,"")
A42: Salgs- og distributionsomk. | B42: =IFERROR(B8/$D8*100,"") | C42: =IFERROR(C8/$D8*100,"") | D42: =IFERROR(D8/$D8*100,"")
A43: Administrationsomk. | B43: =IFERROR(B9/$D9*100,"") | C43: =IFERROR(C9/$D9*100,"") | D43: =IFERROR(D9/$D9*100,"")
A44: Andre driftsomkostninger | B44: =IFERROR(B11/$D11*100,"") | C44: =IFERROR(C11/$D11*100,"") | D44: =IFERROR(D11/$D11*100,"")
A46: Indekstal for kapitaltilpasningsevne (2023=100)
A47: Nettoomsætning | B47: =IFERROR(B5*100/$D5,"") | C47: =IFERROR(C5*100/$D5,"") | D47: =IFERROR(D5*100/$D5,"")
...

Sheet Noter_info
A1: TORM A/S (CVR 22460218) — Ukendte XBRL-felter — disse er noter og ikke en del af hoved-regnskabet
A2: Kategori | B2: Dansk navn | C2: XBRL feltnavn | D2: 2021 t.kr. | E2: 2022 t.kr. | F2: 2023 t.kr. | G2: 2024 t.kr. | H2: 2025 t.kr. | I2: Forklaring
A3: Øvrige (ukendt) | B3: fsa:Dividend | C3: fsa:Dividend | F3: 117125 | I3: Ingen forklaring tilgængelig.
A4: Øvrige (ukendt) | B4: fsa:HedgeFund | C4: fsa:HedgeFund | D4: -1534 | E4: 386 | F4: 45 | G4: -2172 | H4: 784 | I4: Ingen forklaring tilgængelig.
A5: Øvrige (ukendt) | B5: fsa:IncomeFromInvestmentsInParticipatingInterests | C5: fsa:IncomeFromInvestmentsInParticipatingInterests | D5: -104 | E5: 153 | F5: 0 | I5: Ingen forklaring tilgængelig.
A6: Øvrige (ukendt) | B6: fsa:LongtermParticipatingInterests | C6: fsa:LongtermParticipatingInterests | D6: 1473 | E6: 76 | F6: 76 | G6: 76 | H6: 0 | I6: Ingen forklaring tilgængelig.
A7: Øvrige (ukendt) | B7: fsa:LongtermTaxPayables | C7: fsa:LongtermTaxPayables | D7: 45176 | E7: 45176 | F7: 45176 | G7: 45176 | H7: 45176 | I7: Ingen forklaring tilgængelig.
A8: Øvrige (ukendt) | B8: fsa:Ships | C8: fsa:Ships | D8: 1643951 | E8: 1614144 | F8: 1693485 | G8: 1629904 | H8: 1388275 | I8: Ingen forklaring tilgængelig.
