Workbook

Sheet Overblik_25834844
A1: Regnskabsanalyse – Resultatopgørelse & Balance (t.kr.) · Klasse C-stor · Revision
H2: Indekstal (2020=100)
A3: Resultatopgørelse t.kr. | B3: 2020 | C3: 2021 | D3: 2022 | E3: 2023 | F3: 2024 | H3: 2020 | I3: 2021 | J3: 2022 | K3: 2023 | L3: 2024
A4: Nettoomsætning | B4: ='res_raw_25834844'!$B$2 | C4: ='res_raw_25834844'!$C$2 | D4: ='res_raw_25834844'!$D$2 | E4: ='res_raw_25834844'!$E$2 | F4: ='res_raw_25834844'!$F$2 | H4: =IFERROR(B4/$B$4*100,"") | I4: =IFERROR(C4/$B$4*100,"") | J4: =IFERROR(D4/$B$4*100,"") | K4: =IFERROR(E4/$B$4*100,"") | L4: =IFERROR(F4/$B$4*100,"")
A5: Produktionsomkostninger | B5: ='res_raw_25834844'!$B$3 | C5: ='res_raw_25834844'!$C$3 | D5: ='res_raw_25834844'!$D$3 | E5: ='res_raw_25834844'!$E$3 | F5: ='res_raw_25834844'!$F$3 | H5: =IFERROR(B5/$B$5*100,"") | I5: =IFERROR(C5/$B$5*100,"") | J5: =IFERROR(D5/$B$5*100,"") | K5: =IFERROR(E5/$B$5*100,"") | L5: =IFERROR(F5/$B$5*100,"")
A6: Bruttoresultat | B6: ='res_raw_25834844'!$B$4 | C6: ='res_raw_25834844'!$C$4 | D6: ='res_raw_25834844'!$D$4 | E6: ='res_raw_25834844'!$E$4 | F6: ='res_raw_25834844'!$F$4 | H6: =IFERROR(B6/$B$6*100,"") | I6: =IFERROR(C6/$B$6*100,"") | J6: =IFERROR(D6/$B$6*100,"") | K6: =IFERROR(E6/$B$6*100,"") | L6: =IFERROR(F6/$B$6*100,"")
A7: Salgs- og distributionsomkostninger | B7: ='res_raw_25834844'!$B$5 | C7: ='res_raw_25834844'!$C$5 | D7: ='res_raw_25834844'!$D$5 | E7: ='res_raw_25834844'!$E$5 | F7: ='res_raw_25834844'!$F$5 | H7: =IFERROR(B7/$B$7*100,"") | I7: =IFERROR(C7/$B$7*100,"") | J7: =IFERROR(D7/$B$7*100,"") | K7: =IFERROR(E7/$B$7*100,"") | L7: =IFERROR(F7/$B$7*100,"")
A8: Administrationsomkostninger | B8: ='res_raw_25834844'!$B$6 | C8: ='res_raw_25834844'!$C$6 | D8: ='res_raw_25834844'!$D$6 | E8: ='res_raw_25834844'!$E$6 | F8: ='res_raw_25834844'!$F$6 | H8: =IFERROR(B8/$B$8*100,"") | I8: =IFERROR(C8/$B$8*100,"") | J8: =IFERROR(D8/$B$8*100,"") | K8: =IFERROR(E8/$B$8*100,"") | L8: =IFERROR(F8/$B$8*100,"")
A9: Andre driftsindtægter | B9: ='res_raw_25834844'!$B$7 | C9: ='res_raw_25834844'!$C$7 | D9: ='res_raw_25834844'!$D$7 | E9: ='res_raw_25834844'!$E$7 | F9: ='res_raw_25834844'!$F$7 | H9: =IFERROR(B9/$B$9*100,"") | I9: =IFERROR(C9/$B$9*100,"") | J9: =IFERROR(D9/$B$9*100,"") | K9: =IFERROR(E9/$B$9*100,"") | L9: =IFERROR(F9/$B$9*100,"")
A10: Andre driftsomkostninger | B10: ='res_raw_25834844'!$B$8 | C10: ='res_raw_25834844'!$C$8 | D10: ='res_raw_25834844'!$D$8 | E10: ='res_raw_25834844'!$E$8 | F10: ='res_raw_25834844'!$F$8 | H10: =IFERROR(B10/$B$10*100,"") | I10: =IFERROR(C10/$B$10*100,"") | J10: =IFERROR(D10/$B$10*100,"") | K10: =IFERROR(E10/$B$10*100,"") | L10: =IFERROR(F10/$B$10*100,"")
A11: Resultat af primær drift | B11: ='res_raw_25834844'!$B$9 | C11: ='res_raw_25834844'!$C$9 | D11: ='res_raw_25834844'!$D$9 | E11: ='res_raw_25834844'!$E$9 | F11: ='res_raw_25834844'!$F$9 | H11: =IFERROR(B11/$B$11*100,"") | I11: =IFERROR(C11/$B$11*100,"") | J11: =IFERROR(D11/$B$11*100,"") | K11: =IFERROR(E11/$B$11*100,"") | L11: =IFERROR(F11/$B$11*100,"")
A12: Indtægter af kapitalandele, dattervirksomheder | B12: ='res_raw_25834844'!$B$10 | C12: ='res_raw_25834844'!$C$10 | D12: ='res_raw_25834844'!$D$10 | E12: ='res_raw_25834844'!$E$10 | F12: ='res_raw_25834844'!$F$10 | H12: =IFERROR(B12/$B$12*100,"") | I12: =IFERROR(C12/$B$12*100,"") | J12: =IFERROR(D12/$B$12*100,"") | K12: =IFERROR(E12/$B$12*100,"") | L12: =IFERROR(F12/$B$12*100,"")
A13: Finansielle indtægter | B13: ='res_raw_25834844'!$B$11 | C13: ='res_raw_25834844'!$C$11 | D13: ='res_raw_25834844'!$D$11 | E13: ='res_raw_25834844'!$E$11 | F13: ='res_raw_25834844'!$F$11 | H13: =IFERROR(B13/$B$13*100,"") | I13: =IFERROR(C13/$B$13*100,"") | J13: =IFERROR(D13/$B$13*100,"") | K13: =IFERROR(E13/$B$13*100,"") | L13: =IFERROR(F13/$B$13*100,"")
A14: Finansielle omkostninger | B14: ='res_raw_25834844'!$B$12 | C14: ='res_raw_25834844'!$C$12 | D14: ='res_raw_25834844'!$D$12 | E14: ='res_raw_25834844'!$E$12 | F14: ='res_raw_25834844'!$F$12 | H14: =IFERROR(B14/$B$14*100,"") | I14: =IFERROR(C14/$B$14*100,"") | J14: =IFERROR(D14/$B$14*100,"") | K14: =IFERROR(E14/$B$14*100,"") | L14: =IFERROR(F14/$B$14*100,"")
A15: Finansielle poster, netto | B15: ='res_raw_25834844'!$B$13 | C15: ='res_raw_25834844'!$C$13 | D15: ='res_raw_25834844'!$D$13 | E15: ='res_raw_25834844'!$E$13 | F15: ='res_raw_25834844'!$F$13 | H15: =IFERROR(B15/$B$15*100,"") | I15: =IFERROR(C15/$B$15*100,"") | J15: =IFERROR(D15/$B$15*100,"") | K15: =IFERROR(E15/$B$15*100,"") | L15: =IFERROR(F15/$B$15*100,"")
A16: Resultat før skat | B16: ='res_raw_25834844'!$B$14 | C16: ='res_raw_25834844'!$C$14 | D16: ='res_raw_25834844'!$D$14 | E16: ='res_raw_25834844'!$E$14 | F16: ='res_raw_25834844'!$F$14 | H16: =IFERROR(B16/$B$16*100,"") | I16: =IFERROR(C16/$B$16*100,"") | J16: =IFERROR(D16/$B$16*100,"") | K16: =IFERROR(E16/$B$16*100,"") | L16: =IFERROR(F16/$B$16*100,"")
A17: Skat af årets resultat | B17: ='res_raw_25834844'!$B$15 | C17: ='res_raw_25834844'!$C$15 | D17: ='res_raw_25834844'!$D$15 | E17: ='res_raw_25834844'!$E$15 | F17: ='res_raw_25834844'!$F$15 | H17: =IFERROR(B17/$B$17*100,"") | I17: =IFERROR(C17/$B$17*100,"") | J17: =IFERROR(D17/$B$17*100,"") | K17: =IFERROR(E17/$B$17*100,"") | L17: =IFERROR(F17/$B$17*100,"")
A18: Årets resultat | B18: ='res_raw_25834844'!$B$16 | C18: ='res_raw_25834844'!$C$16 | D18: ='res_raw_25834844'!$D$16 | E18: ='res_raw_25834844'!$E$16 | F18: ='res_raw_25834844'!$F$16 | H18: =IFERROR(B18/$B$18*100,"") | I18: =IFERROR(C18/$B$18*100,"") | J18: =IFERROR(D18/$B$18*100,"") | K18: =IFERROR(E18/$B$18*100,"") | L18: =IFERROR(F18/$B$18*100,"")
A20: AKTIVER t.kr. | B20: 2020 | C20: 2021 | D20: 2022 | E20: 2023 | F20: 2024 | H20: 2020 | I20: 2021 | J20: 2022 | K20: 2023 | L20: 2024
A21: Udviklingsprojekter | B21: ='balance_raw_25834844'!$B$2 | C21: ='balance_raw_25834844'!$C$2 | D21: ='balance_raw_25834844'!$D$2 | E21: ='balance_raw_25834844'!$E$2 | F21: ='balance_raw_25834844'!$F$2 | H21: =IFERROR(B21/$B$21*100,"") | I21: =IFERROR(C21/$B$21*100,"") | J21: =IFERROR(D21/$B$21*100,"") | K21: =IFERROR(E21/$B$21*100,"") | L21: =IFERROR(F21/$B$21*100,"")
A22: Patenter, varemærker mv. | B22: ='balance_raw_25834844'!$B$3 | C22: ='balance_raw_25834844'!$C$3 | D22: ='balance_raw_25834844'!$D$3 | E22: ='balance_raw_25834844'!$E$3 | F22: ='balance_raw_25834844'!$F$3 | H22: =IFERROR(B22/$B$22*100,"") | I22: =IFERROR(C22/$B$22*100,"") | J22: =IFERROR(D22/$B$22*100,"") | K22: =IFERROR(E22/$B$22*100,"") | L22: =IFERROR(F22/$B$22*100,"")
A23: Goodwill | B23: ='balance_raw_25834844'!$B$4 | C23: ='balance_raw_25834844'!$C$4 | D23: ='balance_raw_25834844'!$D$4 | E23: ='balance_raw_25834844'!$E$4 | F23: ='balance_raw_25834844'!$F$4 | H23: =IFERROR(B23/$B$23*100,"") | I23: =IFERROR(C23/$B$23*100,"") | J23: =IFERROR(D23/$B$23*100,"") | K23: =IFERROR(E23/$B$23*100,"") | L23: =IFERROR(F23/$B$23*100,"")
A24: Immaterielle anlægsaktiver | B24: ='balance_raw_25834844'!$B$5 | C24: ='balance_raw_25834844'!$C$5 | D24: ='balance_raw_25834844'!$D$5 | E24: ='balance_raw_25834844'!$E$5 | F24: ='balance_raw_25834844'!$F$5 | H24: =IFERROR(B24/$B$24*100,"") | I24: =IFERROR(C24/$B$24*100,"") | J24: =IFERROR(D24/$B$24*100,"") | K24: =IFERROR(E24/$B$24*100,"") | L24: =IFERROR(F24/$B$24*100,"")
A25: Grunde og bygninger | B25: ='balance_raw_25834844'!$B$6 | C25: ='balance_raw_25834844'!$C$6 | D25: ='balance_raw_25834844'!$D$6 | E25: ='balance_raw_25834844'!$E$6 | F25: ='balance_raw_25834844'!$F$6 | H25: =IFERROR(B25/$B$25*100,"") | I25: =IFERROR(C25/$B$25*100,"") | J25: =IFERROR(D25/$B$25*100,"") | K25: =IFERROR(E25/$B$25*100,"") | L25: =IFERROR(F25/$B$25*100,"")
A26: Produktionsanlæg og maskiner | B26: ='balance_raw_25834844'!$B$7 | C26: ='balance_raw_25834844'!$C$7 | D26: ='balance_raw_25834844'!$D$7 | E26: ='balance_raw_25834844'!$E$7 | F26: ='balance_raw_25834844'!$F$7 | H26: =IFERROR(B26/$B$26*100,"") | I26: =IFERROR(C26/$B$26*100,"") | J26: =IFERROR(D26/$B$26*100,"") | K26: =IFERROR(E26/$B$26*100,"") | L26: =IFERROR(F26/$B$26*100,"")
A27: Driftsmateriel og inventar | B27: ='balance_raw_25834844'!$B$8 | C27: ='balance_raw_25834844'!$C$8 | D27: ='balance_raw_25834844'!$D$8 | E27: ='balance_raw_25834844'!$E$8 | F27: ='balance_raw_25834844'!$F$8 | H27: =IFERROR(B27/$B$27*100,"") | I27: =IFERROR(C27/$B$27*100,"") | J27: =IFERROR(D27/$B$27*100,"") | K27: =IFERROR(E27/$B$27*100,"") | L27: =IFERROR(F27/$B$27*100,"")
A28: Indretning af lejede lokaler | B28: ='balance_raw_25834844'!$B$9 | C28: ='balance_raw_25834844'!$C$9 | D28: ='balance_raw_25834844'!$D$9 | E28: ='balance_raw_25834844'!$E$9 | F28: ='balance_raw_25834844'!$F$9 | H28: =IFERROR(B28/$B$28*100,"") | I28: =IFERROR(C28/$B$28*100,"") | J28: =IFERROR(D28/$B$28*100,"") | K28: =IFERROR(E28/$B$28*100,"") | L28: =IFERROR(F28/$B$28*100,"")
A29: Forudbetaling og anlægsaktiver under opførelse | B29: ='balance_raw_25834844'!$B$10 | C29: ='balance_raw_25834844'!$C$10 | D29: ='balance_raw_25834844'!$D$10 | E29: ='balance_raw_25834844'!$E$10 | F29: ='balance_raw_25834844'!$F$10 | H29: =IFERROR(B29/$B$29*100,"") | I29: =IFERROR(C29/$B$29*100,"") | J29: =IFERROR(D29/$B$29*100,"") | K29: =IFERROR(E29/$B$29*100,"") | L29: =IFERROR(F29/$B$29*100,"")
A30: Materielle anlægsaktiver | B30: ='balance_raw_25834844'!$B$11 | C30: ='balance_raw_25834844'!$C$11 | D30: ='balance_raw_25834844'!$D$11 | E30: ='balance_raw_25834844'!$E$11 | F30: ='balance_raw_25834844'!$F$11 | H30: =IFERROR(B30/$B$30*100,"") | I30: =IFERROR(C30/$B$30*100,"") | J30: =IFERROR(D30/$B$30*100,"") | K30: =IFERROR(E30/$B$30*100,"") | L30: =IFERROR(F30/$B$30*100,"")
A31: Kapitalandele, dattervirksomheder | B31: ='balance_raw_25834844'!$B$12 | C31: ='balance_raw_25834844'!$C$12 | D31: ='balance_raw_25834844'!$D$12 | E31: ='balance_raw_25834844'!$E$12 | F31: ='balance_raw_25834844'!$F$12 | H31: =IFERROR(B31/$B$31*100,"") | I31: =IFERROR(C31/$B$31*100,"") | J31: =IFERROR(D31/$B$31*100,"") | K31: =IFERROR(E31/$B$31*100,"") | L31: =IFERROR(F31/$B$31*100,"")
A32: Deposita | B32: ='balance_raw_25834844'!$B$13 | C32: ='balance_raw_25834844'!$C$13 | D32: ='balance_raw_25834844'!$D$13 | E32: ='balance_raw_25834844'!$E$13 | F32: ='balance_raw_25834844'!$F$13 | H32: =IFERROR(B32/$B$32*100,"") | I32: =IFERROR(C32/$B$32*100,"") | J32: =IFERROR(D32/$B$32*100,"") | K32: =IFERROR(E32/$B$32*100,"") | L32: =IFERROR(F32/$B$32*100,"")
A33: Finansielle anlægsaktiver | B33: ='balance_raw_25834844'!$B$14 | C33: ='balance_raw_25834844'!$C$14 | D33: ='balance_raw_25834844'!$D$14 | E33: ='balance_raw_25834844'!$E$14 | F33: ='balance_raw_25834844'!$F$14 | H33: =IFERROR(B33/$B$33*100,"") | I33: =IFERROR(C33/$B$33*100,"") | J33: =IFERROR(D33/$B$33*100,"") | K33: =IFERROR(E33/$B$33*100,"") | L33: =IFERROR(F33/$B$33*100,"")
A34: Anlægsaktiver | B34: ='balance_raw_25834844'!$B$15 | C34: ='balance_raw_25834844'!$C$15 | D34: ='balance_raw_25834844'!$D$15 | E34: ='balance_raw_25834844'!$E$15 | F34: ='balance_raw_25834844'!$F$15 | H34: =IFERROR(B34/$B$34*100,"") | I34: =IFERROR(C34/$B$34*100,"") | J34: =IFERROR(D34/$B$34*100,"") | K34: =IFERROR(E34/$B$34*100,"") | L34: =IFERROR(F34/$B$34*100,"")
A35: Råvarer og hjælpematerialer | B35: ='balance_raw_25834844'!$B$16 | C35: ='balance_raw_25834844'!$C$16 | D35: ='balance_raw_25834844'!$D$16 | E35: ='balance_raw_25834844'!$E$16 | F35: ='balance_raw_25834844'!$F$16 | H35: =IFERROR(B35/$B$35*100,"") | I35: =IFERROR(C35/$B$35*100,"") | J35: =IFERROR(D35/$B$35*100,"") | K35: =IFERROR(E35/$B$35*100,"") | L35: =IFERROR(F35/$B$35*100,"")
A36: Varer under fremstilling | B36: ='balance_raw_25834844'!$B$17 | C36: ='balance_raw_25834844'!$C$17 | D36: ='balance_raw_25834844'!$D$17 | E36: ='balance_raw_25834844'!$E$17 | F36: ='balance_raw_25834844'!$F$17 | H36: =IFERROR(B36/$B$36*100,"") | I36: =IFERROR(C36/$B$36*100,"") | J36: =IFERROR(D36/$B$36*100,"") | K36: =IFERROR(E36/$B$36*100,"") | L36: =IFERROR(F36/$B$36*100,"")
A37: Færdigvarer og handelsvarer | B37: ='balance_raw_25834844'!$B$18 | C37: ='balance_raw_25834844'!$C$18 | D37: ='balance_raw_25834844'!$D$18 | E37: ='balance_raw_25834844'!$E$18 | F37: ='balance_raw_25834844'!$F$18 | H37: =IFERROR(B37/$B$37*100,"") | I37: =IFERROR(C37/$B$37*100,"") | J37: =IFERROR(D37/$B$37*100,"") | K37: =IFERROR(E37/$B$37*100,"") | L37: =IFERROR(F37/$B$37*100,"")
A38: Varebeholdninger | B38: ='balance_raw_25834844'!$B$19 | C38: ='balance_raw_25834844'!$C$19 | D38: ='balance_raw_25834844'!$D$19 | E38: ='balance_raw_25834844'!$E$19 | F38: ='balance_raw_25834844'!$F$19 | H38: =IFERROR(B38/$B$38*100,"") | I38: =IFERROR(C38/$B$38*100,"") | J38: =IFERROR(D38/$B$38*100,"") | K38: =IFERROR(E38/$B$38*100,"") | L38: =IFERROR(F38/$B$38*100,"")
A39: Tilgodehavender fra salg og tjenesteydelser | B39: ='balance_raw_25834844'!$B$20 | C39: ='balance_raw_25834844'!$C$20 | D39: ='balance_raw_25834844'!$D$20 | E39: ='balance_raw_25834844'!$E$20 | F39: ='balance_raw_25834844'!$F$20 | H39: =IFERROR(B39/$B$39*100,"") | I39: =IFERROR(C39/$B$39*100,"") | J39: =IFERROR(D39/$B$39*100,"") | K39: =IFERROR(E39/$B$39*100,"") | L39: =IFERROR(F39/$B$39*100,"")
A40: Tilgodehavender hos tilknyttede virksomheder | B40: ='balance_raw_25834844'!$B$21 | C40: ='balance_raw_25834844'!$C$21 | D40: ='balance_raw_25834844'!$D$21 | E40: ='balance_raw_25834844'!$E$21 | F40: ='balance_raw_25834844'!$F$21 | H40: =IFERROR(B40/$B$40*100,"") | I40: =IFERROR(C40/$B$40*100,"") | J40: =IFERROR(D40/$B$40*100,"") | K40: =IFERROR(E40/$B$40*100,"") | L40: =IFERROR(F40/$B$40*100,"")
A41: Andre tilgodehavender | B41: ='balance_raw_25834844'!$B$22 | C41: ='balance_raw_25834844'!$C$22 | D41: ='balance_raw_25834844'!$D$22 | E41: ='balance_raw_25834844'!$E$22 | F41: ='balance_raw_25834844'!$F$22 | H41: =IFERROR(B41/$B$41*100,"") | I41: =IFERROR(C41/$B$41*100,"") | J41: =IFERROR(D41/$B$41*100,"") | K41: =IFERROR(E41/$B$41*100,"") | L41: =IFERROR(F41/$B$41*100,"")
...

Sheet res_raw_25834844
A1: Resultatopgørelse & nøgleoplysninger (t.kr.) | B1: 2020 | C1: 2021 | D1: 2022 | E1: 2023 | F1: 2024
A2: Nettoomsætning | B2: 991107 | C2: 932545 | D2: 892580 | E2: 1012566 | F2: 1104175
A3: Produktionsomkostninger | B3: 744713 | C3: 771161 | D3: 867416 | E3: 978422 | F3: 1004228
A4: Bruttoresultat | B4: 246394 | C4: 161384 | D4: 25164 | E4: 34144 | F4: 99947
A5: Salgs- og distributionsomkostninger | B5: 21724 | C5: 19854 | D5: 39516 | E5: 43450 | F5: 41686
A6: Administrationsomkostninger | B6: 32852 | C6: 45182 | D6: 60457 | E6: 66597 | F6: 75017
A7: Andre driftsindtægter | B7: 40200 | C7: 0 | F7: 15
A8: Andre driftsomkostninger | F8: 44
A9: Resultat af primær drift | B9: 232018 | C9: 96348 | D9: -74809 | E9: -75903 | F9: -165996
A10: Indtægter af kapitalandele, dattervirksomheder | B10: -7646 | C10: -13069 | D10: -24831 | E10: -37072 | F10: -84018
A11: Finansielle indtægter | B11: 758 | C11: 1144 | D11: 134 | E11: 3998 | F11: 16375
A12: Finansielle omkostninger | B12: 26667 | C12: 29513 | D12: 14083 | E12: 53997 | F12: 74042
A13: Finansielle poster, netto | B13: -26000 | C13: -28000 | D13: -39000 | E13: -87000 | F13: -142000
A14: Resultat før skat | B14: 198463 | C14: 54910 | D14: -113589 | E14: -162974 | F14: -307681
A15: Skat af årets resultat | B15: 43052 | C15: 17268 | D15: -22213 | E15: -26273 | F15: -48670
A16: Årets resultat | B16: 155411 | C16: 37642 | D16: -91376 | E16: -136701 | F16: -259011
A17: Gns. antal medarbejdere | B17: 622 | C17: 654 | D17: 690 | E17: 798 | F17: 868
A18: Investering i materielle anlægsaktiver | B18: -61000 | C18: -123000 | D18: -158000 | E18: 123000 | F18: 101000

Sheet balance_raw_25834844
A1: Balance (t.kr.) | B1: 2020 | C1: 2021 | D1: 2022 | E1: 2023 | F1: 2024
A2: Udviklingsprojekter | B2: 74169 | C2: 138100 | D2: 149497 | E2: 166428 | F2: 172678
A3: Patenter, varemærker mv.
A4: Goodwill | E4: 73894 | F4: 154664
A5: Immaterielle anlægsaktiver | B5: 354281 | C5: 372548 | D5: 421824 | E5: 481249 | F5: 606130
A6: Grunde og bygninger | B6: 522537 | C6: 496262 | D6: 486193 | E6: 456633 | F6: 452872
A7: Produktionsanlæg og maskiner | B7: 497943 | C7: 485156 | D7: 445169 | E7: 418644 | F7: 454139
A8: Driftsmateriel og inventar | B8: 8782 | C8: 6709 | D8: 4680 | E8: 4438 | F8: 7872
A9: Indretning af lejede lokaler | B9: 414 | C9: 287 | D9: 159 | E9: 32 | F9: 0
A10: Forudbetaling og anlægsaktiver under opførelse | B10: 69146 | C10: 136164 | D10: 240272 | E10: 313499 | F10: 172246
A11: Materielle anlægsaktiver | B11: 1098822 | C11: 1124578 | D11: 1176473 | E11: 1193246 | F11: 1087129
A12: Kapitalandele, dattervirksomheder | B12: 81818 | C12: 79711 | D12: 65747 | E12: 67663 | F12: 119458
A13: Deposita
A14: Finansielle anlægsaktiver | B14: 81818 | C14: 79711 | D14: 65747 | E14: 67663 | F14: 119458
A15: Anlægsaktiver | B15: 1534921 | C15: 1576837 | D15: 1664044 | E15: 1742158 | F15: 1812717
A16: Råvarer og hjælpematerialer | B16: 77256 | C16: 124065 | D16: 144678 | E16: 145576 | F16: 124160
A17: Varer under fremstilling | B17: 26809 | C17: 13392 | D17: 30001 | E17: 31358 | F17: 27572
A18: Færdigvarer og handelsvarer | B18: 56575 | C18: 61293 | D18: 43917 | E18: 96315 | F18: 101504
A19: Varebeholdninger | B19: 160640 | C19: 198750 | D19: 218596 | E19: 273249 | F19: 253236
A20: Tilgodehavender fra salg og tjenesteydelser | B20: 208029 | C20: 146069 | D20: 156794 | E20: 149426 | F20: 139857
A21: Tilgodehavender hos tilknyttede virksomheder | B21: 18432 | C21: 55830 | D21: 177215 | E21: 315001 | F21: 338362
A22: Andre tilgodehavender | B22: 10351 | C22: 4284 | D22: 355 | E22: 1755 | F22: 8894
A23: Periodeafgrænsningsposter (aktiver) | B23: 3034 | C23: 3291 | D23: 6072 | E23: 10198 | F23: 9655
A24: Udskudt skatteaktiv
A25: Tilgodehavende skat hos tilknyttede virksomheder
A26: Kortfristede skattetilgodehavender
A27: Tilgodehavender | B27: 239846 | C27: 209474 | D27: 340436 | E27: 476970 | F27: 496768
A28: Værdipapirer
A29: Likvide beholdninger | B29: 62977 | C29: 36428 | D29: 26399 | E29: 5822 | F29: 8064
A30: Omsætningsaktiver | B30: 463463 | C30: 444652 | D30: 585431 | E30: 756041 | F30: 758068
A31: Aktiver | B31: 1998384 | C31: 2021489 | D31: 2249475 | E31: 2498199 | F31: 2570785
A32: Selskabskapital | B32: 70510 | C32: 70510 | D32: 70511 | E32: 70511 | F32: 1370511
A33: Reserve for nettoopskrivning (indre værdis metode)
A34: Reserve for udviklingsomkostninger | B34: 206148 | C34: 234984 | D34: 267929 | E34: 318198 | F34: 352143
A35: Reserve for sikringstransaktioner
A36: Andre reserver
A37: Overført resultat | B37: 367081 | C37: 372701 | D37: 248380 | E37: 61410 | F37: -219104
A38: Egenkapital i alt | B38: 770126 | C38: 681404 | D38: 596345 | E38: 458408 | F38: 1503550
A39: Hensættelse til udskudt skat | B39: 150464 | C39: 160726 | D39: 139981 | E39: 125775 | F39: 91832
A40: Hensatte forpligtelser | B40: 150464 | C40: 160726 | D40: 139981 | E40: 125775 | F40: 91832
...

Sheet Simpel_funktion
A1: Regnskabs- og nøgletal (CVR: 25834844) — funktionsopdelt
A3: Beløb i 1.000 kr. | B3: 2024 | C3: 2023 | D3: 2022 | F3: Note / XBRL-felt
A4: Uddrag af resultatopgørelse
A5: Nettoomsætning | B5: ='res_raw_25834844'!$F$2 | C5: ='res_raw_25834844'!$E$2 | D5: ='res_raw_25834844'!$D$2 | F5: fsa:Revenue
A6: Produktionsomkostninger | B6: =-'res_raw_25834844'!$F$3 | C6: =-'res_raw_25834844'!$E$3 | D6: =-'res_raw_25834844'!$D$3 | F6: fsa:CostOfProduction (vises negativt). Materialer, lønninger, produktionsoverhead.
A7: Bruttoresultat | B7: =SUM(B5:B6) | C7: =SUM(C5:C6) | D7: =SUM(D5:D6) | F7: Beregnet: Nettoomsætning − Produktionsomkostninger. Matcher fsa:GrossResult.
A8: Salgs- og distributionsomk. | B8: =-'res_raw_25834844'!$F$5 | C8: =-'res_raw_25834844'!$E$5 | D8: =-'res_raw_25834844'!$D$5 | F8: fsa:DistributionCosts (vises negativt). Marketing, salg, distribution.
A9: Administrationsomkostninger mv. | B9: =-'res_raw_25834844'!$F$6 | C9: =-'res_raw_25834844'!$E$6 | D9: =-'res_raw_25834844'!$D$6 | F9: fsa:AdministrativeExpenses (vises negativt). Generel administration.
A10: Andre driftsindtægter | B10: ='res_raw_25834844'!$F$7 | C10: ='res_raw_25834844'!$E$7 | D10: ='res_raw_25834844'!$D$7 | F10: fsa:OtherOperatingIncome. Sekundære driftsindtægter (huslejeindtægter, off. tilskud, avancer mv.).
A11: Andre driftsomkostninger | B11: =-'res_raw_25834844'!$F$8 | C11: =-'res_raw_25834844'!$E$8 | D11: =-'res_raw_25834844'!$D$8 | F11: fsa:OtherOperatingExpenses (vises negativt). Sekundære driftsomkostninger.
A12: Resultat af primær drift | B12: =SUM(B7:B11) | C12: =SUM(C7:C11) | D12: =SUM(D7:D11) | F12: Beregnet: Bruttoresultat − Salgs/dist. − Administration + Andre driftsindt. − Andre driftsomk. EBIT.
A13: Finansielle indtægter mv. | B13: =N('res_raw_25834844'!$F$10)+N('res_raw_25834844'!$F$11) | C13: =N('res_raw_25834844'!$E$10)+N('res_raw_25834844'!$E$11) | D13: =N('res_raw_25834844'!$D$10)+N('res_raw_25834844'!$D$11) | F13: fsa:IncomeFromSubsidiaries + fsa:OtherFinanceIncome.
A14: Finansielle omkostninger mv. | B14: =-'res_raw_25834844'!$F$12 | C14: =-'res_raw_25834844'!$E$12 | D14: =-'res_raw_25834844'!$D$12 | F14: fsa:OtherFinanceExpenses (vises negativt). Renteomkostninger, kurstab.
A15: Resultat før skat | B15: =SUM(B12:B14) | C15: =SUM(C12:C14) | D15: =SUM(D12:D14) | F15: Beregnet: EBIT + Fin. indtægter + Fin. omk. EBT.
A17: Uddrag af balance
A18: Anlægsaktiver | B18: ='balance_raw_25834844'!$F$15 | C18: ='balance_raw_25834844'!$E$15 | D18: ='balance_raw_25834844'!$D$15 | F18: fsa:NoncurrentAssets. Materielle, immaterielle og finansielle anlægsaktiver.
A19: Omsætningsaktiver | B19: ='balance_raw_25834844'!$F$30 | C19: ='balance_raw_25834844'!$E$30 | D19: ='balance_raw_25834844'!$D$30 | F19: fsa:CurrentAssets. Varebeholdninger, tilgodehavender, likvider.
A20: Aktiver i alt | B20: =SUM(B18:B19) | C20: =SUM(C18:C19) | D20: =SUM(D18:D19) | F20: Beregnet: Anlægsaktiver + Omsætningsaktiver. Bør matche fsa:Assets.
A22: Egenkapital | B22: ='balance_raw_25834844'!$F$38 | C22: ='balance_raw_25834844'!$E$38 | D22: ='balance_raw_25834844'!$D$38 | F22: fsa:Equity. Selskabskapital, overført resultat, reserver.
A23: Forpligtelser | B23: ='balance_raw_25834844'!$F$59-'balance_raw_25834844'!$F$38 | C23: ='balance_raw_25834844'!$E$59-'balance_raw_25834844'!$E$38 | D23: ='balance_raw_25834844'!$D$59-'balance_raw_25834844'!$D$38 | F23: Beregnet: Passiver (fsa:LiabilitiesAndEquity) − Egenkapital. Hensættelser + kort- og langfristet gæld.
A24: Passiver i alt | B24: =SUM(B22:B23) | C24: =SUM(C22:C23) | D24: =SUM(D22:D23) | F24: Beregnet: Egenkapital + Forpligtelser. Bør matche Aktiver i alt.
A26: Udvalgte balanceposter
A27: Varebeholdninger | B27: ='balance_raw_25834844'!$F$19 | C27: ='balance_raw_25834844'!$E$19 | D27: ='balance_raw_25834844'!$D$19 | F27: fsa:Inventories (eller fsa:ManufacturedGoodsAndGoodsForResale hvis total mangler).
A28: Tilgodehavender fra salg | B28: ='balance_raw_25834844'!$F$20 | C28: ='balance_raw_25834844'!$E$20 | D28: ='balance_raw_25834844'!$D$20 | F28: fsa:ShorttermTradeReceivables. Kortfristede tilgodehavender fra kunder.
A29: Kortfristede gældsforpligtelser | B29: ='balance_raw_25834844'!$F$57 | C29: ='balance_raw_25834844'!$E$57 | D29: ='balance_raw_25834844'!$D$57 | F29: fsa:ShorttermLiabilitiesOtherThanProvisions. Gæld der forfalder inden for 1 år.
A31: Rentabilitet
A32: Afkastningsgrad, % | B32: =IFERROR((B12+B13)/B20*100,"") | C32: =IFERROR((C12+C13)/C20*100,"") | D32: =IFERROR((D12+D13)/D20*100,"")
A33: Overskudsgrad, % | B33: =IFERROR((B12+B13)/B5*100,"") | C33: =IFERROR((C12+C13)/C5*100,"") | D33: =IFERROR((D12+D13)/D5*100,"")
A34: Aktivernes omsætningshastighed, gange | B34: =IFERROR(B5/B20,"") | C34: =IFERROR(C5/C20,"") | D34: =IFERROR(D5/D20,"")
A35: Gældsrente, % | B35: =IFERROR(-B14*100/B23,"") | C35: =IFERROR(-C14*100/C23,"") | D35: =IFERROR(-D14*100/D23,"")
A36: Egenkapitalens forrentning, % | B36: =IFERROR(B15/B22*100,"") | C36: =IFERROR(C15/C22*100,"") | D36: =IFERROR(D15/D22*100,"")
A37: Gearing, gange | B37: =IFERROR(B23/B22,"") | C37: =IFERROR(C23/C22,"") | D37: =IFERROR(D23/D22,"")
A39: Indekstal for indtjeningsevne (2022=100)
A40: Nettoomsætning | B40: =IFERROR(B5/$D5*100,"") | C40: =IFERROR(C5/$D5*100,"") | D40: =IFERROR(D5/$D5*100,"")
A41: Produktionsomkostninger | B41: =IFERROR(B6/$D6*100,"") | C41: =IFERROR(C6/$D6*100,"") | D41: =IFERROR(D6/$D6*100,"")
A42: Salgs- og distributionsomk. | B42: =IFERROR(B8/$D8*100,"") | C42: =IFERROR(C8/$D8*100,"") | D42: =IFERROR(D8/$D8*100,"")
A43: Administrationsomk. | B43: =IFERROR(B9/$D9*100,"") | C43: =IFERROR(C9/$D9*100,"") | D43: =IFERROR(D9/$D9*100,"")
A44: Andre driftsomkostninger | B44: =IFERROR(B11/$D11*100,"") | C44: =IFERROR(C11/$D11*100,"") | D44: =IFERROR(D11/$D11*100,"")
A46: Indekstal for kapitaltilpasningsevne (2022=100)
A47: Nettoomsætning | B47: =IFERROR(B5*100/$D5,"") | C47: =IFERROR(C5*100/$D5,"") | D47: =IFERROR(D5*100/$D5,"")
...

Sheet Noter_info
A1: Ukendte XBRL-felter — disse er noter og ikke en del af hoved-regnskabet
A2: Kategori | B2: Dansk navn | C2: XBRL feltnavn | D2: 2020 t.kr. | E2: 2021 t.kr. | F2: 2022 t.kr. | G2: 2023 t.kr. | H2: 2024 t.kr. | I2: Forklaring
A3: Øvrige (ukendt) | B3: fsa:AdjustmentsForDeferredTaxCashFlow | C3: fsa:AdjustmentsForDeferredTaxCashFlow | D3: 36925 | E3: 10262 | I3: Ingen forklaring tilgængelig.
A4: Øvrige (ukendt) | B4: fsa:RaisingOfDebtToAssociates | C4: fsa:RaisingOfDebtToAssociates | D4: -22495 | E4: 0 | I4: Ingen forklaring tilgængelig.
A5: Øvrige (ukendt) | B5: fsa:RefundInJointAssessment | C5: fsa:RefundInJointAssessment | H5: 14727 | I5: Ingen forklaring tilgængelig.
A6: Øvrige (ukendt) | B6: fsa:ResearchAndDevelopmentExpenditure | C6: fsa:ResearchAndDevelopmentExpenditure | H6: 149211 | I6: Ingen forklaring tilgængelig.
A7: Øvrige (ukendt) | B7: fsa:ReserveForCurrentValueAdjustmentsOfCurrencyGains | C7: fsa:ReserveForCurrentValueAdjustmentsOfCurrencyGains | D7: -3613 | E7: 3209 | F7: 9525 | G7: 8289 | I7: Ingen forklaring tilgængelig.
A8: Øvrige (ukendt) | B8: fsa:TransferredToFromOtherStatutoryReserves | C8: fsa:TransferredToFromOtherStatutoryReserves | G8: 50269 | H8: 33945 | I8: Ingen forklaring tilgængelig.
