Workbook

Sheet Overblik_27528406
A1: Matas A/S (CVR 27528406) — Regnskabsanalyse – Resultatopgørelse & Balance (t.kr.) · Revision · Regnskabsår 1/4–31/3 (forskudt)
H2: Indekstal (2021=100)
A3: Resultatopgørelse t.kr. | B3: 2021 | C3: 2022 | D3: 2023 | E3: 2024 | F3: 2025 | H3: 2021 | I3: 2022 | J3: 2023 | K3: 2024 | L3: 2025
A4: Nettoomsætning | B4: ='res_raw_27528406'!$B$2 | C4: ='res_raw_27528406'!$C$2 | D4: ='res_raw_27528406'!$D$2 | E4: ='res_raw_27528406'!$E$2 | F4: ='res_raw_27528406'!$F$2 | H4: =IFERROR(B4/$B$4*100,"") | I4: =IFERROR(C4/$B$4*100,"") | J4: =IFERROR(D4/$B$4*100,"") | K4: =IFERROR(E4/$B$4*100,"") | L4: =IFERROR(F4/$B$4*100,"")
A5: Produktionsomkostninger | B5: ='res_raw_27528406'!$B$3 | C5: ='res_raw_27528406'!$C$3 | D5: ='res_raw_27528406'!$D$3 | E5: ='res_raw_27528406'!$E$3 | F5: ='res_raw_27528406'!$F$3 | H5: =IFERROR(B5/$B$5*100,"") | I5: =IFERROR(C5/$B$5*100,"") | J5: =IFERROR(D5/$B$5*100,"") | K5: =IFERROR(E5/$B$5*100,"") | L5: =IFERROR(F5/$B$5*100,"")
A6: Bruttoresultat | B6: ='res_raw_27528406'!$B$4 | C6: ='res_raw_27528406'!$C$4 | D6: ='res_raw_27528406'!$D$4 | E6: ='res_raw_27528406'!$E$4 | F6: ='res_raw_27528406'!$F$4 | H6: =IFERROR(B6/$B$6*100,"") | I6: =IFERROR(C6/$B$6*100,"") | J6: =IFERROR(D6/$B$6*100,"") | K6: =IFERROR(E6/$B$6*100,"") | L6: =IFERROR(F6/$B$6*100,"")
A7: Salgs- og distributionsomkostninger | B7: ='res_raw_27528406'!$B$5 | C7: ='res_raw_27528406'!$C$5 | D7: ='res_raw_27528406'!$D$5 | E7: ='res_raw_27528406'!$E$5 | F7: ='res_raw_27528406'!$F$5 | H7: =IFERROR(B7/$B$7*100,"") | I7: =IFERROR(C7/$B$7*100,"") | J7: =IFERROR(D7/$B$7*100,"") | K7: =IFERROR(E7/$B$7*100,"") | L7: =IFERROR(F7/$B$7*100,"")
A8: Administrationsomkostninger | B8: ='res_raw_27528406'!$B$6 | C8: ='res_raw_27528406'!$C$6 | D8: ='res_raw_27528406'!$D$6 | E8: ='res_raw_27528406'!$E$6 | F8: ='res_raw_27528406'!$F$6 | H8: =IFERROR(B8/$B$8*100,"") | I8: =IFERROR(C8/$B$8*100,"") | J8: =IFERROR(D8/$B$8*100,"") | K8: =IFERROR(E8/$B$8*100,"") | L8: =IFERROR(F8/$B$8*100,"")
A9: Andre driftsindtægter | B9: ='res_raw_27528406'!$B$7 | C9: ='res_raw_27528406'!$C$7 | D9: ='res_raw_27528406'!$D$7 | E9: ='res_raw_27528406'!$E$7 | F9: ='res_raw_27528406'!$F$7 | H9: =IFERROR(B9/$B$9*100,"") | I9: =IFERROR(C9/$B$9*100,"") | J9: =IFERROR(D9/$B$9*100,"") | K9: =IFERROR(E9/$B$9*100,"") | L9: =IFERROR(F9/$B$9*100,"")
A10: Andre driftsomkostninger | B10: ='res_raw_27528406'!$B$8 | C10: ='res_raw_27528406'!$C$8 | D10: ='res_raw_27528406'!$D$8 | E10: ='res_raw_27528406'!$E$8 | F10: ='res_raw_27528406'!$F$8 | H10: =IFERROR(B10/$B$10*100,"") | I10: =IFERROR(C10/$B$10*100,"") | J10: =IFERROR(D10/$B$10*100,"") | K10: =IFERROR(E10/$B$10*100,"") | L10: =IFERROR(F10/$B$10*100,"")
A11: Resultat af primær drift | B11: ='res_raw_27528406'!$B$9 | C11: ='res_raw_27528406'!$C$9 | D11: ='res_raw_27528406'!$D$9 | E11: ='res_raw_27528406'!$E$9 | F11: ='res_raw_27528406'!$F$9 | H11: =IFERROR(B11/$B$11*100,"") | I11: =IFERROR(C11/$B$11*100,"") | J11: =IFERROR(D11/$B$11*100,"") | K11: =IFERROR(E11/$B$11*100,"") | L11: =IFERROR(F11/$B$11*100,"")
A12: Indtægter af kapitalandele, dattervirksomheder | B12: ='res_raw_27528406'!$B$10 | C12: ='res_raw_27528406'!$C$10 | D12: ='res_raw_27528406'!$D$10 | E12: ='res_raw_27528406'!$E$10 | F12: ='res_raw_27528406'!$F$10 | H12: =IFERROR(B12/$B$12*100,"") | I12: =IFERROR(C12/$B$12*100,"") | J12: =IFERROR(D12/$B$12*100,"") | K12: =IFERROR(E12/$B$12*100,"") | L12: =IFERROR(F12/$B$12*100,"")
A13: Finansielle indtægter | B13: ='res_raw_27528406'!$B$11 | C13: ='res_raw_27528406'!$C$11 | D13: ='res_raw_27528406'!$D$11 | E13: ='res_raw_27528406'!$E$11 | F13: ='res_raw_27528406'!$F$11 | H13: =IFERROR(B13/$B$13*100,"") | I13: =IFERROR(C13/$B$13*100,"") | J13: =IFERROR(D13/$B$13*100,"") | K13: =IFERROR(E13/$B$13*100,"") | L13: =IFERROR(F13/$B$13*100,"")
A14: Finansielle omkostninger | B14: ='res_raw_27528406'!$B$12 | C14: ='res_raw_27528406'!$C$12 | D14: ='res_raw_27528406'!$D$12 | E14: ='res_raw_27528406'!$E$12 | F14: ='res_raw_27528406'!$F$12 | H14: =IFERROR(B14/$B$14*100,"") | I14: =IFERROR(C14/$B$14*100,"") | J14: =IFERROR(D14/$B$14*100,"") | K14: =IFERROR(E14/$B$14*100,"") | L14: =IFERROR(F14/$B$14*100,"")
A15: Finansielle poster, netto | B15: ='res_raw_27528406'!$B$13 | C15: ='res_raw_27528406'!$C$13 | D15: ='res_raw_27528406'!$D$13 | E15: ='res_raw_27528406'!$E$13 | F15: ='res_raw_27528406'!$F$13 | H15: =IFERROR(B15/$B$15*100,"") | I15: =IFERROR(C15/$B$15*100,"") | J15: =IFERROR(D15/$B$15*100,"") | K15: =IFERROR(E15/$B$15*100,"") | L15: =IFERROR(F15/$B$15*100,"")
A16: Resultat før skat | B16: ='res_raw_27528406'!$B$14 | C16: ='res_raw_27528406'!$C$14 | D16: ='res_raw_27528406'!$D$14 | E16: ='res_raw_27528406'!$E$14 | F16: ='res_raw_27528406'!$F$14 | H16: =IFERROR(B16/$B$16*100,"") | I16: =IFERROR(C16/$B$16*100,"") | J16: =IFERROR(D16/$B$16*100,"") | K16: =IFERROR(E16/$B$16*100,"") | L16: =IFERROR(F16/$B$16*100,"")
A17: Skat af årets resultat | B17: ='res_raw_27528406'!$B$15 | C17: ='res_raw_27528406'!$C$15 | D17: ='res_raw_27528406'!$D$15 | E17: ='res_raw_27528406'!$E$15 | F17: ='res_raw_27528406'!$F$15 | H17: =IFERROR(B17/$B$17*100,"") | I17: =IFERROR(C17/$B$17*100,"") | J17: =IFERROR(D17/$B$17*100,"") | K17: =IFERROR(E17/$B$17*100,"") | L17: =IFERROR(F17/$B$17*100,"")
A18: Årets resultat | B18: ='res_raw_27528406'!$B$16 | C18: ='res_raw_27528406'!$C$16 | D18: ='res_raw_27528406'!$D$16 | E18: ='res_raw_27528406'!$E$16 | F18: ='res_raw_27528406'!$F$16 | H18: =IFERROR(B18/$B$18*100,"") | I18: =IFERROR(C18/$B$18*100,"") | J18: =IFERROR(D18/$B$18*100,"") | K18: =IFERROR(E18/$B$18*100,"") | L18: =IFERROR(F18/$B$18*100,"")
A20: AKTIVER t.kr. | B20: 2021 | C20: 2022 | D20: 2023 | E20: 2024 | F20: 2025 | H20: 2021 | I20: 2022 | J20: 2023 | K20: 2024 | L20: 2025
A21: Udviklingsprojekter | B21: ='balance_raw_27528406'!$B$2 | C21: ='balance_raw_27528406'!$C$2 | D21: ='balance_raw_27528406'!$D$2 | E21: ='balance_raw_27528406'!$E$2 | F21: ='balance_raw_27528406'!$F$2 | H21: =IFERROR(B21/$B$21*100,"") | I21: =IFERROR(C21/$B$21*100,"") | J21: =IFERROR(D21/$B$21*100,"") | K21: =IFERROR(E21/$B$21*100,"") | L21: =IFERROR(F21/$B$21*100,"")
A22: Patenter, varemærker mv. | B22: ='balance_raw_27528406'!$B$3 | C22: ='balance_raw_27528406'!$C$3 | D22: ='balance_raw_27528406'!$D$3 | E22: ='balance_raw_27528406'!$E$3 | F22: ='balance_raw_27528406'!$F$3 | H22: =IFERROR(B22/$B$22*100,"") | I22: =IFERROR(C22/$B$22*100,"") | J22: =IFERROR(D22/$B$22*100,"") | K22: =IFERROR(E22/$B$22*100,"") | L22: =IFERROR(F22/$B$22*100,"")
A23: Goodwill | B23: ='balance_raw_27528406'!$B$4 | C23: ='balance_raw_27528406'!$C$4 | D23: ='balance_raw_27528406'!$D$4 | E23: ='balance_raw_27528406'!$E$4 | F23: ='balance_raw_27528406'!$F$4 | H23: =IFERROR(B23/$B$23*100,"") | I23: =IFERROR(C23/$B$23*100,"") | J23: =IFERROR(D23/$B$23*100,"") | K23: =IFERROR(E23/$B$23*100,"") | L23: =IFERROR(F23/$B$23*100,"")
A24: Immaterielle anlægsaktiver | B24: ='balance_raw_27528406'!$B$5 | C24: ='balance_raw_27528406'!$C$5 | D24: ='balance_raw_27528406'!$D$5 | E24: ='balance_raw_27528406'!$E$5 | F24: ='balance_raw_27528406'!$F$5 | H24: =IFERROR(B24/$B$24*100,"") | I24: =IFERROR(C24/$B$24*100,"") | J24: =IFERROR(D24/$B$24*100,"") | K24: =IFERROR(E24/$B$24*100,"") | L24: =IFERROR(F24/$B$24*100,"")
A25: Grunde og bygninger | B25: ='balance_raw_27528406'!$B$6 | C25: ='balance_raw_27528406'!$C$6 | D25: ='balance_raw_27528406'!$D$6 | E25: ='balance_raw_27528406'!$E$6 | F25: ='balance_raw_27528406'!$F$6 | H25: =IFERROR(B25/$B$25*100,"") | I25: =IFERROR(C25/$B$25*100,"") | J25: =IFERROR(D25/$B$25*100,"") | K25: =IFERROR(E25/$B$25*100,"") | L25: =IFERROR(F25/$B$25*100,"")
A26: Produktionsanlæg og maskiner | B26: ='balance_raw_27528406'!$B$7 | C26: ='balance_raw_27528406'!$C$7 | D26: ='balance_raw_27528406'!$D$7 | E26: ='balance_raw_27528406'!$E$7 | F26: ='balance_raw_27528406'!$F$7 | H26: =IFERROR(B26/$B$26*100,"") | I26: =IFERROR(C26/$B$26*100,"") | J26: =IFERROR(D26/$B$26*100,"") | K26: =IFERROR(E26/$B$26*100,"") | L26: =IFERROR(F26/$B$26*100,"")
A27: Driftsmateriel og inventar | B27: ='balance_raw_27528406'!$B$8 | C27: ='balance_raw_27528406'!$C$8 | D27: ='balance_raw_27528406'!$D$8 | E27: ='balance_raw_27528406'!$E$8 | F27: ='balance_raw_27528406'!$F$8 | H27: =IFERROR(B27/$B$27*100,"") | I27: =IFERROR(C27/$B$27*100,"") | J27: =IFERROR(D27/$B$27*100,"") | K27: =IFERROR(E27/$B$27*100,"") | L27: =IFERROR(F27/$B$27*100,"")
A28: Indretning af lejede lokaler | B28: ='balance_raw_27528406'!$B$9 | C28: ='balance_raw_27528406'!$C$9 | D28: ='balance_raw_27528406'!$D$9 | E28: ='balance_raw_27528406'!$E$9 | F28: ='balance_raw_27528406'!$F$9 | H28: =IFERROR(B28/$B$28*100,"") | I28: =IFERROR(C28/$B$28*100,"") | J28: =IFERROR(D28/$B$28*100,"") | K28: =IFERROR(E28/$B$28*100,"") | L28: =IFERROR(F28/$B$28*100,"")
A29: Forudbetaling og anlægsaktiver under opførelse | B29: ='balance_raw_27528406'!$B$10 | C29: ='balance_raw_27528406'!$C$10 | D29: ='balance_raw_27528406'!$D$10 | E29: ='balance_raw_27528406'!$E$10 | F29: ='balance_raw_27528406'!$F$10 | H29: =IFERROR(B29/$B$29*100,"") | I29: =IFERROR(C29/$B$29*100,"") | J29: =IFERROR(D29/$B$29*100,"") | K29: =IFERROR(E29/$B$29*100,"") | L29: =IFERROR(F29/$B$29*100,"")
A30: Materielle anlægsaktiver | B30: ='balance_raw_27528406'!$B$11 | C30: ='balance_raw_27528406'!$C$11 | D30: ='balance_raw_27528406'!$D$11 | E30: ='balance_raw_27528406'!$E$11 | F30: ='balance_raw_27528406'!$F$11 | H30: =IFERROR(B30/$B$30*100,"") | I30: =IFERROR(C30/$B$30*100,"") | J30: =IFERROR(D30/$B$30*100,"") | K30: =IFERROR(E30/$B$30*100,"") | L30: =IFERROR(F30/$B$30*100,"")
A31: Kapitalandele, dattervirksomheder | B31: ='balance_raw_27528406'!$B$12 | C31: ='balance_raw_27528406'!$C$12 | D31: ='balance_raw_27528406'!$D$12 | E31: ='balance_raw_27528406'!$E$12 | F31: ='balance_raw_27528406'!$F$12 | H31: =IFERROR(B31/$B$31*100,"") | I31: =IFERROR(C31/$B$31*100,"") | J31: =IFERROR(D31/$B$31*100,"") | K31: =IFERROR(E31/$B$31*100,"") | L31: =IFERROR(F31/$B$31*100,"")
A32: Deposita | B32: ='balance_raw_27528406'!$B$13 | C32: ='balance_raw_27528406'!$C$13 | D32: ='balance_raw_27528406'!$D$13 | E32: ='balance_raw_27528406'!$E$13 | F32: ='balance_raw_27528406'!$F$13 | H32: =IFERROR(B32/$B$32*100,"") | I32: =IFERROR(C32/$B$32*100,"") | J32: =IFERROR(D32/$B$32*100,"") | K32: =IFERROR(E32/$B$32*100,"") | L32: =IFERROR(F32/$B$32*100,"")
A33: Finansielle anlægsaktiver | B33: ='balance_raw_27528406'!$B$14 | C33: ='balance_raw_27528406'!$C$14 | D33: ='balance_raw_27528406'!$D$14 | E33: ='balance_raw_27528406'!$E$14 | F33: ='balance_raw_27528406'!$F$14 | H33: =IFERROR(B33/$B$33*100,"") | I33: =IFERROR(C33/$B$33*100,"") | J33: =IFERROR(D33/$B$33*100,"") | K33: =IFERROR(E33/$B$33*100,"") | L33: =IFERROR(F33/$B$33*100,"")
A34: Anlægsaktiver | B34: ='balance_raw_27528406'!$B$15 | C34: ='balance_raw_27528406'!$C$15 | D34: ='balance_raw_27528406'!$D$15 | E34: ='balance_raw_27528406'!$E$15 | F34: ='balance_raw_27528406'!$F$15 | H34: =IFERROR(B34/$B$34*100,"") | I34: =IFERROR(C34/$B$34*100,"") | J34: =IFERROR(D34/$B$34*100,"") | K34: =IFERROR(E34/$B$34*100,"") | L34: =IFERROR(F34/$B$34*100,"")
A35: Råvarer og hjælpematerialer | B35: ='balance_raw_27528406'!$B$16 | C35: ='balance_raw_27528406'!$C$16 | D35: ='balance_raw_27528406'!$D$16 | E35: ='balance_raw_27528406'!$E$16 | F35: ='balance_raw_27528406'!$F$16 | H35: =IFERROR(B35/$B$35*100,"") | I35: =IFERROR(C35/$B$35*100,"") | J35: =IFERROR(D35/$B$35*100,"") | K35: =IFERROR(E35/$B$35*100,"") | L35: =IFERROR(F35/$B$35*100,"")
A36: Varer under fremstilling | B36: ='balance_raw_27528406'!$B$17 | C36: ='balance_raw_27528406'!$C$17 | D36: ='balance_raw_27528406'!$D$17 | E36: ='balance_raw_27528406'!$E$17 | F36: ='balance_raw_27528406'!$F$17 | H36: =IFERROR(B36/$B$36*100,"") | I36: =IFERROR(C36/$B$36*100,"") | J36: =IFERROR(D36/$B$36*100,"") | K36: =IFERROR(E36/$B$36*100,"") | L36: =IFERROR(F36/$B$36*100,"")
A37: Færdigvarer og handelsvarer | B37: ='balance_raw_27528406'!$B$18 | C37: ='balance_raw_27528406'!$C$18 | D37: ='balance_raw_27528406'!$D$18 | E37: ='balance_raw_27528406'!$E$18 | F37: ='balance_raw_27528406'!$F$18 | H37: =IFERROR(B37/$B$37*100,"") | I37: =IFERROR(C37/$B$37*100,"") | J37: =IFERROR(D37/$B$37*100,"") | K37: =IFERROR(E37/$B$37*100,"") | L37: =IFERROR(F37/$B$37*100,"")
A38: Varebeholdninger | B38: ='balance_raw_27528406'!$B$19 | C38: ='balance_raw_27528406'!$C$19 | D38: ='balance_raw_27528406'!$D$19 | E38: ='balance_raw_27528406'!$E$19 | F38: ='balance_raw_27528406'!$F$19 | H38: =IFERROR(B38/$B$38*100,"") | I38: =IFERROR(C38/$B$38*100,"") | J38: =IFERROR(D38/$B$38*100,"") | K38: =IFERROR(E38/$B$38*100,"") | L38: =IFERROR(F38/$B$38*100,"")
A39: Tilgodehavender fra salg og tjenesteydelser | B39: ='balance_raw_27528406'!$B$20 | C39: ='balance_raw_27528406'!$C$20 | D39: ='balance_raw_27528406'!$D$20 | E39: ='balance_raw_27528406'!$E$20 | F39: ='balance_raw_27528406'!$F$20 | H39: =IFERROR(B39/$B$39*100,"") | I39: =IFERROR(C39/$B$39*100,"") | J39: =IFERROR(D39/$B$39*100,"") | K39: =IFERROR(E39/$B$39*100,"") | L39: =IFERROR(F39/$B$39*100,"")
A40: Tilgodehavender hos tilknyttede virksomheder | B40: ='balance_raw_27528406'!$B$21 | C40: ='balance_raw_27528406'!$C$21 | D40: ='balance_raw_27528406'!$D$21 | E40: ='balance_raw_27528406'!$E$21 | F40: ='balance_raw_27528406'!$F$21 | H40: =IFERROR(B40/$B$40*100,"") | I40: =IFERROR(C40/$B$40*100,"") | J40: =IFERROR(D40/$B$40*100,"") | K40: =IFERROR(E40/$B$40*100,"") | L40: =IFERROR(F40/$B$40*100,"")
A41: Andre tilgodehavender | B41: ='balance_raw_27528406'!$B$22 | C41: ='balance_raw_27528406'!$C$22 | D41: ='balance_raw_27528406'!$D$22 | E41: ='balance_raw_27528406'!$E$22 | F41: ='balance_raw_27528406'!$F$22 | H41: =IFERROR(B41/$B$41*100,"") | I41: =IFERROR(C41/$B$41*100,"") | J41: =IFERROR(D41/$B$41*100,"") | K41: =IFERROR(E41/$B$41*100,"") | L41: =IFERROR(F41/$B$41*100,"")
...

Sheet res_raw_27528406
A1: Matas A/S (CVR 27528406) — Resultatopgørelse & nøgleoplysninger (t.kr.) | B1: 2021 | C1: 2022 | D1: 2023 | E1: 2024 | F1: 2025
A2: Nettoomsætning | B2: 4163600 | C2: 4344200 | D2: 4489600 | E2: 6701000 | F2: 8379000
A3: Produktionsomkostninger | B3: 2322400 | C3: 2378200 | D3: 2475200
A4: Bruttoresultat | B4: 1841200 | C4: 1966000 | D4: 2014400
A5: Salgs- og distributionsomkostninger
A6: Administrationsomkostninger
A7: Andre driftsindtægter | B7: 10400
A8: Andre driftsomkostninger
A9: Resultat af primær drift | B9: 380400 | C9: 388300 | D9: 423100 | E9: 379000 | F9: 565000
A10: Indtægter af kapitalandele, dattervirksomheder | B10: 700 | C10: -4600 | D10: -4900 | E10: 1000 | F10: 1000
A11: Finansielle indtægter | B11: 17500 | C11: 5300 | D11: 500 | E11: 12000 | F11: 1000
A12: Finansielle omkostninger | B12: 45200 | C12: 37900 | D12: 45900 | E12: 144000 | F12: 183000
A13: Finansielle poster, netto
A14: Resultat før skat | B14: 353400 | C14: 351100 | D14: 372800 | E14: 248000 | F14: 384000
A15: Skat af årets resultat | B15: 84400 | C15: 74600 | D15: 92100 | E15: 79000 | F15: 102000
A16: Årets resultat | B16: 269000 | C16: 276500 | D16: 280700 | E16: 169000 | F16: 282000
A17: Gns. antal medarbejdere | B17: 2152
A18: Investering i materielle anlægsaktiver | B18: 50500 | C18: 50500 | D18: 92200 | E18: 250000 | F18: 477000

Sheet balance_raw_27528406
A1: Matas A/S (CVR 27528406) — Balance (t.kr.) | B1: 2021 | C1: 2022 | D1: 2023 | E1: 2024 | F1: 2025
A2: Udviklingsprojekter | B2: 130300 | C2: 186800 | D2: 235800 | E2: 132000 | F2: 86000
A3: Patenter, varemærker mv. | B3: 143600 | C3: 67800 | D3: 58100 | E3: 184000 | F3: 183000
A4: Goodwill | B4: 3930600 | C4: 3993600 | D4: 3999400 | E4: 4096000 | F4: 4102000
A5: Immaterielle anlægsaktiver | B5: 4204500 | C5: 4248200 | D5: 4293300 | E5: 4671000 | F5: 4741000
A6: Grunde og bygninger | B6: 90800 | C6: 86600 | D6: 87500 | E6: 108000 | F6: 107000
A7: Produktionsanlæg og maskiner
A8: Driftsmateriel og inventar
A9: Indretning af lejede lokaler | B9: 51500 | C9: 40300 | D9: 27300 | E9: 208000 | F9: 243000
A10: Forudbetaling og anlægsaktiver under opførelse | B10: 0 | C10: 9600 | D10: 59700 | E10: 169000 | F10: 510000
A11: Materielle anlægsaktiver | B11: 651800 | C11: 500200 | D11: 622300 | E11: 1157000 | F11: 1178000
A12: Kapitalandele, dattervirksomheder | B12: 12400 | C12: 7300 | D12: 1400 | E12: 1000 | F12: 1000
A13: Deposita | B13: 600 | C13: 600 | D13: 700 | E13: 1000 | F13: 1000
A14: Finansielle anlægsaktiver
A15: Anlægsaktiver | B15: 5158900 | C15: 5026300 | D15: 5201700 | E15: 6468000 | F15: 6965000
A16: Råvarer og hjælpematerialer | E16: 3623000 | F16: 4509000
A17: Varer under fremstilling
A18: Færdigvarer og handelsvarer
A19: Varebeholdninger | B19: 866700 | C19: 890100 | D19: 911800 | E19: 1864000 | F19: 2269000
A20: Tilgodehavender fra salg og tjenesteydelser | B20: 15200 | C20: 26600 | D20: 43700 | E20: 76000 | F20: 93000
A21: Tilgodehavender hos tilknyttede virksomheder
A22: Andre tilgodehavender | B22: 158600 | C22: 154500 | D22: 161400 | E22: 221000 | F22: 235000
A23: Periodeafgrænsningsposter (aktiver) | D23: 40800 | E23: 74000 | F23: 130000
A24: Udskudt skatteaktiv | E24: 17000 | F24: 33000
A25: Tilgodehavende skat hos tilknyttede virksomheder
A26: Kortfristede skattetilgodehavender | B26: 19400 | C26: 45500 | D26: 20600 | E26: 17000 | F26: 19000
A27: Tilgodehavender | B27: 4600 | C27: 7100 | D27: 24900 | E27: 38000 | F27: 22000
A28: Værdipapirer
A29: Likvide beholdninger | B29: 40700 | C29: 28200 | D29: 36700 | E29: 131000 | F29: 76000
A30: Omsætningsaktiver | B30: 984200 | C30: 1029000 | D30: 1078500 | E30: 2200000 | F30: 2609000
A31: Aktiver | B31: 6143100 | C31: 6055300 | D31: 6280200 | E31: 8668000 | F31: 9574000
A32: Selskabskapital | B32: 95700 | C32: 95700 | D32: 95700 | E32: 96000 | F32: 96000
A33: Reserve for nettoopskrivning (indre værdis metode)
A34: Reserve for udviklingsomkostninger
A35: Reserve for sikringstransaktioner
A36: Andre reserver | B36: -1300 | C36: 0 | E36: 0 | F36: 3000
A37: Overført resultat | B37: 2600 | C37: 76000 | D37: 43500 | E37: 43000 | F37: 39000
A38: Egenkapital i alt | B38: 3038900 | C38: 3151800 | D38: 3362600 | E38: 3461000 | F38: 3715000
A39: Hensættelse til udskudt skat | B39: 199200 | C39: 192800 | D39: 198800 | E39: 227000 | F39: 212000
A40: Hensatte forpligtelser | B40: 27700 | C40: 28000 | D40: 28000 | E40: 28000 | F40: 28000
...

Sheet pengestrom_raw_27528406
A1: Matas A/S (CVR 27528406) — Pengestrømsopgørelse (t.kr.) | B1: 2021 | C1: 2022 | D1: 2023 | E1: 2024 | F1: 2025
A2: Pengestrømme fra driftsaktivitet | B2: 952000 | C2: 510500 | D2: 679000 | E2: 645000 | F2: 715000
A3: Pengestrømme fra investeringsaktivitet | B3: -177900 | C3: -231600 | D3: -255800 | E3: -1021000 | F3: -717000
A4: Pengestrømme fra finansieringsaktivitet | B4: -840000 | C4: -291400 | D4: -414700 | E4: 466000 | F4: -56000
A5: Årets pengestrøm | B5: -65900 | C5: -12500 | D5: 8500

Sheet Simpel_funktion
A1: Matas A/S (CVR 27528406) — Regnskabs- og nøgletal (CVR: 27528406) — funktionsopdelt
A3: Beløb i 1.000 kr. | B3: 2025 | C3: 2024 | D3: 2023 | F3: Note / XBRL-felt
A4: Uddrag af resultatopgørelse
A5: Nettoomsætning | B5: ='res_raw_27528406'!$F$2 | C5: ='res_raw_27528406'!$E$2 | D5: ='res_raw_27528406'!$D$2 | F5: fsa:Revenue
A6: Produktionsomkostninger | B6: =-'res_raw_27528406'!$F$3 | C6: =-'res_raw_27528406'!$E$3 | D6: =-'res_raw_27528406'!$D$3 | F6: fsa:CostOfProduction (vises negativt). Materialer, lønninger, produktionsoverhead.
A7: Bruttoresultat | B7: =SUM(B5:B6) | C7: =SUM(C5:C6) | D7: =SUM(D5:D6) | F7: Beregnet: Nettoomsætning − Produktionsomkostninger. Matcher fsa:GrossResult.
A8: Salgs- og distributionsomk. | B8: =-'res_raw_27528406'!$F$5 | C8: =-'res_raw_27528406'!$E$5 | D8: =-'res_raw_27528406'!$D$5 | F8: fsa:DistributionCosts (vises negativt). Marketing, salg, distribution.
A9: Administrationsomkostninger mv. | B9: =-'res_raw_27528406'!$F$6 | C9: =-'res_raw_27528406'!$E$6 | D9: =-'res_raw_27528406'!$D$6 | F9: fsa:AdministrativeExpenses (vises negativt). Generel administration.
A10: Andre driftsindtægter | B10: ='res_raw_27528406'!$F$7 | C10: ='res_raw_27528406'!$E$7 | D10: ='res_raw_27528406'!$D$7 | F10: fsa:OtherOperatingIncome. Sekundære driftsindtægter (huslejeindtægter, off. tilskud, avancer mv.).
A11: Andre driftsomkostninger | B11: =-'res_raw_27528406'!$F$8 | C11: =-'res_raw_27528406'!$E$8 | D11: =-'res_raw_27528406'!$D$8 | F11: fsa:OtherOperatingExpenses (vises negativt). Sekundære driftsomkostninger.
A12: Resultat af primær drift | B12: =SUM(B7:B11) | C12: =SUM(C7:C11) | D12: =SUM(D7:D11) | F12: Beregnet: Bruttoresultat − Salgs/dist. − Administration + Andre driftsindt. − Andre driftsomk. EBIT.
A13: Finansielle indtægter mv. | B13: =N('res_raw_27528406'!$F$10)+N('res_raw_27528406'!$F$11) | C13: =N('res_raw_27528406'!$E$10)+N('res_raw_27528406'!$E$11) | D13: =N('res_raw_27528406'!$D$10)+N('res_raw_27528406'!$D$11) | F13: fsa:IncomeFromSubsidiaries + fsa:OtherFinanceIncome.
A14: Finansielle omkostninger mv. | B14: =-'res_raw_27528406'!$F$12 | C14: =-'res_raw_27528406'!$E$12 | D14: =-'res_raw_27528406'!$D$12 | F14: fsa:OtherFinanceExpenses (vises negativt). Renteomkostninger, kurstab.
A15: Resultat før skat | B15: =SUM(B12:B14) | C15: =SUM(C12:C14) | D15: =SUM(D12:D14) | F15: Beregnet: EBIT + Fin. indtægter + Fin. omk. EBT.
A17: Uddrag af balance
A18: Anlægsaktiver | B18: ='balance_raw_27528406'!$F$15 | C18: ='balance_raw_27528406'!$E$15 | D18: ='balance_raw_27528406'!$D$15 | F18: fsa:NoncurrentAssets. Materielle, immaterielle og finansielle anlægsaktiver.
A19: Omsætningsaktiver | B19: ='balance_raw_27528406'!$F$30 | C19: ='balance_raw_27528406'!$E$30 | D19: ='balance_raw_27528406'!$D$30 | F19: fsa:CurrentAssets. Varebeholdninger, tilgodehavender, likvider.
A20: Aktiver i alt | B20: =SUM(B18:B19) | C20: =SUM(C18:C19) | D20: =SUM(D18:D19) | F20: Beregnet: Anlægsaktiver + Omsætningsaktiver. Bør matche fsa:Assets.
A22: Egenkapital | B22: ='balance_raw_27528406'!$F$38 | C22: ='balance_raw_27528406'!$E$38 | D22: ='balance_raw_27528406'!$D$38 | F22: fsa:Equity. Selskabskapital, overført resultat, reserver.
A23: Forpligtelser | B23: ='balance_raw_27528406'!$F$59-'balance_raw_27528406'!$F$38 | C23: ='balance_raw_27528406'!$E$59-'balance_raw_27528406'!$E$38 | D23: ='balance_raw_27528406'!$D$59-'balance_raw_27528406'!$D$38 | F23: Beregnet: Passiver (fsa:LiabilitiesAndEquity) − Egenkapital. Hensættelser + kort- og langfristet gæld.
A24: Passiver i alt | B24: =SUM(B22:B23) | C24: =SUM(C22:C23) | D24: =SUM(D22:D23) | F24: Beregnet: Egenkapital + Forpligtelser. Bør matche Aktiver i alt.
A26: Udvalgte balanceposter
A27: Varebeholdninger | B27: ='balance_raw_27528406'!$F$19 | C27: ='balance_raw_27528406'!$E$19 | D27: ='balance_raw_27528406'!$D$19 | F27: fsa:Inventories (eller fsa:ManufacturedGoodsAndGoodsForResale hvis total mangler).
A28: Tilgodehavender fra salg | B28: ='balance_raw_27528406'!$F$20 | C28: ='balance_raw_27528406'!$E$20 | D28: ='balance_raw_27528406'!$D$20 | F28: fsa:ShorttermTradeReceivables. Kortfristede tilgodehavender fra kunder.
A29: Kortfristede gældsforpligtelser | B29: ='balance_raw_27528406'!$F$57 | C29: ='balance_raw_27528406'!$E$57 | D29: ='balance_raw_27528406'!$D$57 | F29: fsa:ShorttermLiabilitiesOtherThanProvisions. Gæld der forfalder inden for 1 år.
A31: Rentabilitet
A32: Afkastningsgrad, % | B32: =IFERROR((B12+B13)/B20*100,"") | C32: =IFERROR((C12+C13)/C20*100,"") | D32: =IFERROR((D12+D13)/D20*100,"")
A33: Overskudsgrad, % | B33: =IFERROR((B12+B13)/B5*100,"") | C33: =IFERROR((C12+C13)/C5*100,"") | D33: =IFERROR((D12+D13)/D5*100,"")
A34: Aktivernes omsætningshastighed, gange | B34: =IFERROR(B5/B20,"") | C34: =IFERROR(C5/C20,"") | D34: =IFERROR(D5/D20,"")
A35: Gældsrente, % | B35: =IFERROR(-B14*100/B23,"") | C35: =IFERROR(-C14*100/C23,"") | D35: =IFERROR(-D14*100/D23,"")
A36: Egenkapitalens forrentning, % | B36: =IFERROR(B15/B22*100,"") | C36: =IFERROR(C15/C22*100,"") | D36: =IFERROR(D15/D22*100,"")
A37: Gearing, gange | B37: =IFERROR(B23/B22,"") | C37: =IFERROR(C23/C22,"") | D37: =IFERROR(D23/D22,"")
A39: Indekstal for indtjeningsevne (2023=100)
A40: Nettoomsætning | B40: =IFERROR(B5/$D5*100,"") | C40: =IFERROR(C5/$D5*100,"") | D40: =IFERROR(D5/$D5*100,"")
A41: Produktionsomkostninger | B41: =IFERROR(B6/$D6*100,"") | C41: =IFERROR(C6/$D6*100,"") | D41: =IFERROR(D6/$D6*100,"")
A42: Salgs- og distributionsomk. | B42: =IFERROR(B8/$D8*100,"") | C42: =IFERROR(C8/$D8*100,"") | D42: =IFERROR(D8/$D8*100,"")
A43: Administrationsomk. | B43: =IFERROR(B9/$D9*100,"") | C43: =IFERROR(C9/$D9*100,"") | D43: =IFERROR(D9/$D9*100,"")
A44: Andre driftsomkostninger | B44: =IFERROR(B11/$D11*100,"") | C44: =IFERROR(C11/$D11*100,"") | D44: =IFERROR(D11/$D11*100,"")
A46: Indekstal for kapitaltilpasningsevne (2023=100)
A47: Nettoomsætning | B47: =IFERROR(B5*100/$D5,"") | C47: =IFERROR(C5*100/$D5,"") | D47: =IFERROR(D5*100/$D5,"")
...

Sheet Noter_info
A1: Matas A/S (CVR 27528406) — Ukendte XBRL-felter — disse er noter og ikke en del af hoved-regnskabet
A2: Kategori | B2: Dansk navn | C2: XBRL feltnavn | D2: 2021 t.kr. | E2: 2022 t.kr. | F2: 2023 t.kr. | G2: 2024 t.kr. | H2: 2025 t.kr. | I2: Forklaring
A3: Øvrige (ukendt) | B3: ifrs-full:AdjustmentsForFinanceCosts | C3: ifrs-full:AdjustmentsForFinanceCosts | D3: 45200 | E3: 37900 | F3: 45900 | G3: 144000 | H3: 183000 | I3: Ingen forklaring tilgængelig.
A4: Øvrige (ukendt) | B4: ifrs-full:AdjustmentsForFinanceIncome | C4: ifrs-full:AdjustmentsForFinanceIncome | D4: 17500 | E4: 5300 | F4: 500 | G4: 12000 | H4: 1000 | I4: Ingen forklaring tilgængelig.
A5: Øvrige (ukendt) | B5: ifrs-full:AdjustmentsForUndistributedProfitsOfAssociates | C5: ifrs-full:AdjustmentsForUndistributedProfitsOfAssociates | D5: 700 | E5: -4600 | F5: -4900 | G5: 1000 | H5: 1000 | I5: Ingen forklaring tilgængelig.
A6: Øvrige (ukendt) | B6: ifrs-full:ComputerSoftware | C6: ifrs-full:ComputerSoftware | G6: 258000 | H6: 253000 | I6: Ingen forklaring tilgængelig.
A7: Øvrige (ukendt) | B7: ifrs-full:DividendsRecognisedAsDistributionsToOwnersPerShare | C7: ifrs-full:DividendsRecognisedAsDistributionsToOwnersPerShare | F7: 0 | G7: 0 | I7: Ingen forklaring tilgængelig.
A8: Øvrige (ukendt) | B8: ifrs-full:ProceedsFromExerciseOfOptions | C8: ifrs-full:ProceedsFromExerciseOfOptions | G8: 0 | H8: 10000 | I8: Ingen forklaring tilgængelig.
A9: Øvrige (ukendt) | B9: ifrs-full:ReserveOfExchangeDifferencesOnTranslation | C9: ifrs-full:ReserveOfExchangeDifferencesOnTranslation | D9: 300 | E9: 300 | F9: 300 | G9: 17000 | H9: 45000 | I9: Ingen forklaring tilgængelig.
