Workbook

Sheet Overblik
A1: iss (CVR None) — Regnskabsanalyse – Resultatopgørelse & Balance (t.kr.)
H2: Indekstal (2021=100)
A3: Resultatopgørelse t.kr. | B3: 2021 | C3: 2022 | D3: 2023 | E3: 2024 | F3: 2025 | H3: 2021 | I3: 2022 | J3: 2023 | K3: 2024 | L3: 2025
A4: Nettoomsætning | B4: ='res_raw'!$B$2 | C4: ='res_raw'!$C$2 | D4: ='res_raw'!$D$2 | E4: ='res_raw'!$E$2 | F4: ='res_raw'!$F$2 | H4: =IFERROR(B4/$B$4*100,"") | I4: =IFERROR(C4/$B$4*100,"") | J4: =IFERROR(D4/$B$4*100,"") | K4: =IFERROR(E4/$B$4*100,"") | L4: =IFERROR(F4/$B$4*100,"")
A5: Andre driftsindtægter | B5: ='res_raw'!$B$3 | C5: ='res_raw'!$C$3 | D5: ='res_raw'!$D$3 | E5: ='res_raw'!$E$3 | F5: ='res_raw'!$F$3 | H5: =IFERROR(B5/$B$5*100,"") | I5: =IFERROR(C5/$B$5*100,"") | J5: =IFERROR(D5/$B$5*100,"") | K5: =IFERROR(E5/$B$5*100,"") | L5: =IFERROR(F5/$B$5*100,"")
A6: Vareforbrug | B6: ='res_raw'!$B$4 | C6: ='res_raw'!$C$4 | D6: ='res_raw'!$D$4 | E6: ='res_raw'!$E$4 | F6: ='res_raw'!$F$4 | H6: =IFERROR(B6/$B$6*100,"") | I6: =IFERROR(C6/$B$6*100,"") | J6: =IFERROR(D6/$B$6*100,"") | K6: =IFERROR(E6/$B$6*100,"") | L6: =IFERROR(F6/$B$6*100,"")
A7: Andre eksterne omkostninger | B7: ='res_raw'!$B$5 | C7: ='res_raw'!$C$5 | D7: ='res_raw'!$D$5 | E7: ='res_raw'!$E$5 | F7: ='res_raw'!$F$5 | H7: =IFERROR(B7/$B$7*100,"") | I7: =IFERROR(C7/$B$7*100,"") | J7: =IFERROR(D7/$B$7*100,"") | K7: =IFERROR(E7/$B$7*100,"") | L7: =IFERROR(F7/$B$7*100,"")
A8: Bruttoresultat | B8: ='res_raw'!$B$6 | C8: ='res_raw'!$C$6 | D8: ='res_raw'!$D$6 | E8: ='res_raw'!$E$6 | F8: ='res_raw'!$F$6 | H8: =IFERROR(B8/$B$8*100,"") | I8: =IFERROR(C8/$B$8*100,"") | J8: =IFERROR(D8/$B$8*100,"") | K8: =IFERROR(E8/$B$8*100,"") | L8: =IFERROR(F8/$B$8*100,"")
A9: Personaleomkostninger | B9: ='res_raw'!$B$7 | C9: ='res_raw'!$C$7 | D9: ='res_raw'!$D$7 | E9: ='res_raw'!$E$7 | F9: ='res_raw'!$F$7 | H9: =IFERROR(B9/$B$9*100,"") | I9: =IFERROR(C9/$B$9*100,"") | J9: =IFERROR(D9/$B$9*100,"") | K9: =IFERROR(E9/$B$9*100,"") | L9: =IFERROR(F9/$B$9*100,"")
A10: Resultat før afskrivninger | B10: =IFERROR($B$8-ABS($B$9),"") | C10: =IFERROR($C$8-ABS($C$9),"") | D10: =IFERROR($D$8-ABS($D$9),"") | E10: =IFERROR($E$8-ABS($E$9),"") | F10: =IFERROR($F$8-ABS($F$9),"") | H10: =IFERROR(B10/$B$10*100,"") | I10: =IFERROR(C10/$B$10*100,"") | J10: =IFERROR(D10/$B$10*100,"") | K10: =IFERROR(E10/$B$10*100,"") | L10: =IFERROR(F10/$B$10*100,"")
A11: Af- og nedskrivninger | B11: ='res_raw'!$B$9 | C11: ='res_raw'!$C$9 | D11: ='res_raw'!$D$9 | E11: ='res_raw'!$E$9 | F11: ='res_raw'!$F$9 | H11: =IFERROR(B11/$B$11*100,"") | I11: =IFERROR(C11/$B$11*100,"") | J11: =IFERROR(D11/$B$11*100,"") | K11: =IFERROR(E11/$B$11*100,"") | L11: =IFERROR(F11/$B$11*100,"")
A12: Andre driftsomkostninger | B12: ='res_raw'!$B$10 | C12: ='res_raw'!$C$10 | D12: ='res_raw'!$D$10 | E12: ='res_raw'!$E$10 | F12: ='res_raw'!$F$10 | H12: =IFERROR(B12/$B$12*100,"") | I12: =IFERROR(C12/$B$12*100,"") | J12: =IFERROR(D12/$B$12*100,"") | K12: =IFERROR(E12/$B$12*100,"") | L12: =IFERROR(F12/$B$12*100,"")
A13: Resultat af primær drift | B13: ='res_raw'!$B$11 | C13: ='res_raw'!$C$11 | D13: ='res_raw'!$D$11 | E13: ='res_raw'!$E$11 | F13: ='res_raw'!$F$11 | H13: =IFERROR(B13/$B$13*100,"") | I13: =IFERROR(C13/$B$13*100,"") | J13: =IFERROR(D13/$B$13*100,"") | K13: =IFERROR(E13/$B$13*100,"") | L13: =IFERROR(F13/$B$13*100,"")
A14: Indtægter af kapitalandele, dattervirksomheder | B14: ='res_raw'!$B$12 | C14: ='res_raw'!$C$12 | D14: ='res_raw'!$D$12 | E14: ='res_raw'!$E$12 | F14: ='res_raw'!$F$12 | H14: =IFERROR(B14/$B$14*100,"") | I14: =IFERROR(C14/$B$14*100,"") | J14: =IFERROR(D14/$B$14*100,"") | K14: =IFERROR(E14/$B$14*100,"") | L14: =IFERROR(F14/$B$14*100,"")
A15: Finansielle indtægter | B15: ='res_raw'!$B$13 | C15: ='res_raw'!$C$13 | D15: ='res_raw'!$D$13 | E15: ='res_raw'!$E$13 | F15: ='res_raw'!$F$13 | H15: =IFERROR(B15/$B$15*100,"") | I15: =IFERROR(C15/$B$15*100,"") | J15: =IFERROR(D15/$B$15*100,"") | K15: =IFERROR(E15/$B$15*100,"") | L15: =IFERROR(F15/$B$15*100,"")
A16: Finansielle omkostninger | B16: ='res_raw'!$B$14 | C16: ='res_raw'!$C$14 | D16: ='res_raw'!$D$14 | E16: ='res_raw'!$E$14 | F16: ='res_raw'!$F$14 | H16: =IFERROR(B16/$B$16*100,"") | I16: =IFERROR(C16/$B$16*100,"") | J16: =IFERROR(D16/$B$16*100,"") | K16: =IFERROR(E16/$B$16*100,"") | L16: =IFERROR(F16/$B$16*100,"")
A17: Finansielle poster, netto | B17: ='res_raw'!$B$15 | C17: ='res_raw'!$C$15 | D17: ='res_raw'!$D$15 | E17: ='res_raw'!$E$15 | F17: ='res_raw'!$F$15 | H17: =IFERROR(B17/$B$17*100,"") | I17: =IFERROR(C17/$B$17*100,"") | J17: =IFERROR(D17/$B$17*100,"") | K17: =IFERROR(E17/$B$17*100,"") | L17: =IFERROR(F17/$B$17*100,"")
A18: Resultat før skat | B18: ='res_raw'!$B$16 | C18: ='res_raw'!$C$16 | D18: ='res_raw'!$D$16 | E18: ='res_raw'!$E$16 | F18: ='res_raw'!$F$16 | H18: =IFERROR(B18/$B$18*100,"") | I18: =IFERROR(C18/$B$18*100,"") | J18: =IFERROR(D18/$B$18*100,"") | K18: =IFERROR(E18/$B$18*100,"") | L18: =IFERROR(F18/$B$18*100,"")
A19: Skat af årets resultat | B19: ='res_raw'!$B$17 | C19: ='res_raw'!$C$17 | D19: ='res_raw'!$D$17 | E19: ='res_raw'!$E$17 | F19: ='res_raw'!$F$17 | H19: =IFERROR(B19/$B$19*100,"") | I19: =IFERROR(C19/$B$19*100,"") | J19: =IFERROR(D19/$B$19*100,"") | K19: =IFERROR(E19/$B$19*100,"") | L19: =IFERROR(F19/$B$19*100,"")
A20: Årets resultat | B20: ='res_raw'!$B$18 | C20: ='res_raw'!$C$18 | D20: ='res_raw'!$D$18 | E20: ='res_raw'!$E$18 | F20: ='res_raw'!$F$18 | H20: =IFERROR(B20/$B$20*100,"") | I20: =IFERROR(C20/$B$20*100,"") | J20: =IFERROR(D20/$B$20*100,"") | K20: =IFERROR(E20/$B$20*100,"") | L20: =IFERROR(F20/$B$20*100,"")
A22: AKTIVER t.kr. | B22: 2021 | C22: 2022 | D22: 2023 | E22: 2024 | F22: 2025 | H22: 2021 | I22: 2022 | J22: 2023 | K22: 2024 | L22: 2025
A23: Immaterielle anlægsaktiver | B23: ='balance_raw'!$B$2 | C23: ='balance_raw'!$C$2 | D23: ='balance_raw'!$D$2 | E23: ='balance_raw'!$E$2 | F23: ='balance_raw'!$F$2 | H23: =IFERROR(B23/$B$23*100,"") | I23: =IFERROR(C23/$B$23*100,"") | J23: =IFERROR(D23/$B$23*100,"") | K23: =IFERROR(E23/$B$23*100,"") | L23: =IFERROR(F23/$B$23*100,"")
A24: Materielle anlægsaktiver | B24: ='balance_raw'!$B$3 | C24: ='balance_raw'!$C$3 | D24: ='balance_raw'!$D$3 | E24: ='balance_raw'!$E$3 | F24: ='balance_raw'!$F$3 | H24: =IFERROR(B24/$B$24*100,"") | I24: =IFERROR(C24/$B$24*100,"") | J24: =IFERROR(D24/$B$24*100,"") | K24: =IFERROR(E24/$B$24*100,"") | L24: =IFERROR(F24/$B$24*100,"")
A25: Kapitalandele, dattervirksomheder | B25: ='balance_raw'!$B$4 | C25: ='balance_raw'!$C$4 | D25: ='balance_raw'!$D$4 | E25: ='balance_raw'!$E$4 | F25: ='balance_raw'!$F$4 | H25: =IFERROR(B25/$B$25*100,"") | I25: =IFERROR(C25/$B$25*100,"") | J25: =IFERROR(D25/$B$25*100,"") | K25: =IFERROR(E25/$B$25*100,"") | L25: =IFERROR(F25/$B$25*100,"")
A26: Deposita | B26: ='balance_raw'!$B$5 | C26: ='balance_raw'!$C$5 | D26: ='balance_raw'!$D$5 | E26: ='balance_raw'!$E$5 | F26: ='balance_raw'!$F$5 | H26: =IFERROR(B26/$B$26*100,"") | I26: =IFERROR(C26/$B$26*100,"") | J26: =IFERROR(D26/$B$26*100,"") | K26: =IFERROR(E26/$B$26*100,"") | L26: =IFERROR(F26/$B$26*100,"")
A27: Finansielle anlægsaktiver | B27: ='balance_raw'!$B$6 | C27: ='balance_raw'!$C$6 | D27: ='balance_raw'!$D$6 | E27: ='balance_raw'!$E$6 | F27: ='balance_raw'!$F$6 | H27: =IFERROR(B27/$B$27*100,"") | I27: =IFERROR(C27/$B$27*100,"") | J27: =IFERROR(D27/$B$27*100,"") | K27: =IFERROR(E27/$B$27*100,"") | L27: =IFERROR(F27/$B$27*100,"")
A28: Anlægsaktiver | B28: ='balance_raw'!$B$7 | C28: ='balance_raw'!$C$7 | D28: ='balance_raw'!$D$7 | E28: ='balance_raw'!$E$7 | F28: ='balance_raw'!$F$7 | H28: =IFERROR(B28/$B$28*100,"") | I28: =IFERROR(C28/$B$28*100,"") | J28: =IFERROR(D28/$B$28*100,"") | K28: =IFERROR(E28/$B$28*100,"") | L28: =IFERROR(F28/$B$28*100,"")
A29: Råvarer og hjælpematerialer | B29: ='balance_raw'!$B$8 | C29: ='balance_raw'!$C$8 | D29: ='balance_raw'!$D$8 | E29: ='balance_raw'!$E$8 | F29: ='balance_raw'!$F$8 | H29: =IFERROR(B29/$B$29*100,"") | I29: =IFERROR(C29/$B$29*100,"") | J29: =IFERROR(D29/$B$29*100,"") | K29: =IFERROR(E29/$B$29*100,"") | L29: =IFERROR(F29/$B$29*100,"")
A30: Varer under fremstilling | B30: ='balance_raw'!$B$9 | C30: ='balance_raw'!$C$9 | D30: ='balance_raw'!$D$9 | E30: ='balance_raw'!$E$9 | F30: ='balance_raw'!$F$9 | H30: =IFERROR(B30/$B$30*100,"") | I30: =IFERROR(C30/$B$30*100,"") | J30: =IFERROR(D30/$B$30*100,"") | K30: =IFERROR(E30/$B$30*100,"") | L30: =IFERROR(F30/$B$30*100,"")
A31: Færdigvarer og handelsvarer | B31: ='balance_raw'!$B$10 | C31: ='balance_raw'!$C$10 | D31: ='balance_raw'!$D$10 | E31: ='balance_raw'!$E$10 | F31: ='balance_raw'!$F$10 | H31: =IFERROR(B31/$B$31*100,"") | I31: =IFERROR(C31/$B$31*100,"") | J31: =IFERROR(D31/$B$31*100,"") | K31: =IFERROR(E31/$B$31*100,"") | L31: =IFERROR(F31/$B$31*100,"")
A32: Varebeholdninger | B32: ='balance_raw'!$B$11 | C32: ='balance_raw'!$C$11 | D32: ='balance_raw'!$D$11 | E32: ='balance_raw'!$E$11 | F32: ='balance_raw'!$F$11 | H32: =IFERROR(B32/$B$32*100,"") | I32: =IFERROR(C32/$B$32*100,"") | J32: =IFERROR(D32/$B$32*100,"") | K32: =IFERROR(E32/$B$32*100,"") | L32: =IFERROR(F32/$B$32*100,"")
A33: Tilgodehavender fra salg og tjenesteydelser | B33: ='balance_raw'!$B$12 | C33: ='balance_raw'!$C$12 | D33: ='balance_raw'!$D$12 | E33: ='balance_raw'!$E$12 | F33: ='balance_raw'!$F$12 | H33: =IFERROR(B33/$B$33*100,"") | I33: =IFERROR(C33/$B$33*100,"") | J33: =IFERROR(D33/$B$33*100,"") | K33: =IFERROR(E33/$B$33*100,"") | L33: =IFERROR(F33/$B$33*100,"")
A34: Tilgodehavender hos tilknyttede virksomheder | B34: ='balance_raw'!$B$13 | C34: ='balance_raw'!$C$13 | D34: ='balance_raw'!$D$13 | E34: ='balance_raw'!$E$13 | F34: ='balance_raw'!$F$13 | H34: =IFERROR(B34/$B$34*100,"") | I34: =IFERROR(C34/$B$34*100,"") | J34: =IFERROR(D34/$B$34*100,"") | K34: =IFERROR(E34/$B$34*100,"") | L34: =IFERROR(F34/$B$34*100,"")
A35: Andre tilgodehavender | B35: ='balance_raw'!$B$14 | C35: ='balance_raw'!$C$14 | D35: ='balance_raw'!$D$14 | E35: ='balance_raw'!$E$14 | F35: ='balance_raw'!$F$14 | H35: =IFERROR(B35/$B$35*100,"") | I35: =IFERROR(C35/$B$35*100,"") | J35: =IFERROR(D35/$B$35*100,"") | K35: =IFERROR(E35/$B$35*100,"") | L35: =IFERROR(F35/$B$35*100,"")
A36: Periodeafgrænsningsposter (aktiver) | B36: ='balance_raw'!$B$15 | C36: ='balance_raw'!$C$15 | D36: ='balance_raw'!$D$15 | E36: ='balance_raw'!$E$15 | F36: ='balance_raw'!$F$15 | H36: =IFERROR(B36/$B$36*100,"") | I36: =IFERROR(C36/$B$36*100,"") | J36: =IFERROR(D36/$B$36*100,"") | K36: =IFERROR(E36/$B$36*100,"") | L36: =IFERROR(F36/$B$36*100,"")
A37: Udskudt skatteaktiv | B37: ='balance_raw'!$B$16 | C37: ='balance_raw'!$C$16 | D37: ='balance_raw'!$D$16 | E37: ='balance_raw'!$E$16 | F37: ='balance_raw'!$F$16 | H37: =IFERROR(B37/$B$37*100,"") | I37: =IFERROR(C37/$B$37*100,"") | J37: =IFERROR(D37/$B$37*100,"") | K37: =IFERROR(E37/$B$37*100,"") | L37: =IFERROR(F37/$B$37*100,"")
A38: Tilgodehavende skat hos tilknyttede virksomheder | B38: ='balance_raw'!$B$17 | C38: ='balance_raw'!$C$17 | D38: ='balance_raw'!$D$17 | E38: ='balance_raw'!$E$17 | F38: ='balance_raw'!$F$17 | H38: =IFERROR(B38/$B$38*100,"") | I38: =IFERROR(C38/$B$38*100,"") | J38: =IFERROR(D38/$B$38*100,"") | K38: =IFERROR(E38/$B$38*100,"") | L38: =IFERROR(F38/$B$38*100,"")
A39: Kortfristede skattetilgodehavender | B39: ='balance_raw'!$B$18 | C39: ='balance_raw'!$C$18 | D39: ='balance_raw'!$D$18 | E39: ='balance_raw'!$E$18 | F39: ='balance_raw'!$F$18 | H39: =IFERROR(B39/$B$39*100,"") | I39: =IFERROR(C39/$B$39*100,"") | J39: =IFERROR(D39/$B$39*100,"") | K39: =IFERROR(E39/$B$39*100,"") | L39: =IFERROR(F39/$B$39*100,"")
A40: Tilgodehavender | B40: ='balance_raw'!$B$19 | C40: ='balance_raw'!$C$19 | D40: ='balance_raw'!$D$19 | E40: ='balance_raw'!$E$19 | F40: ='balance_raw'!$F$19 | H40: =IFERROR(B40/$B$40*100,"") | I40: =IFERROR(C40/$B$40*100,"") | J40: =IFERROR(D40/$B$40*100,"") | K40: =IFERROR(E40/$B$40*100,"") | L40: =IFERROR(F40/$B$40*100,"")
A41: Værdipapirer | B41: ='balance_raw'!$B$20 | C41: ='balance_raw'!$C$20 | D41: ='balance_raw'!$D$20 | E41: ='balance_raw'!$E$20 | F41: ='balance_raw'!$F$20 | H41: =IFERROR(B41/$B$41*100,"") | I41: =IFERROR(C41/$B$41*100,"") | J41: =IFERROR(D41/$B$41*100,"") | K41: =IFERROR(E41/$B$41*100,"") | L41: =IFERROR(F41/$B$41*100,"")
...

Sheet res_raw
A1: iss (CVR None) — Resultatopgørelse & nøgleoplysninger (t.kr.) | B1: 2021 | C1: 2022 | D1: 2023 | E1: 2024 | F1: 2025
A2: Nettoomsætning | B2: 71363000 | C2: 76538000 | D2: 78681000 | E2: 83761000 | F2: 84684000
A3: Andre driftsindtægter
A4: Vareforbrug
A5: Andre eksterne omkostninger
A6: Bruttoresultat
A7: Personaleomkostninger | B7: 46369000 | C7: 48329000 | D7: 49607000 | E7: 52822000 | F7: 53888000
A8: Resultat før afskrivninger
A9: Af- og nedskrivninger | B9: 1760000 | C9: 1517000 | D9: 1464000 | E9: 1469000 | F9: 1555000
A10: Andre driftsomkostninger
A11: Resultat af primær drift | B11: 1701000 | C11: 2835000 | D11: 3138000 | E11: 3889000 | F11: 3950000
A12: Indtægter af kapitalandele, dattervirksomheder
A13: Finansielle indtægter | B13: 41000 | C13: 207000 | D13: 185000 | E13: 314000 | F13: 258000
A14: Finansielle omkostninger | B14: 697000 | C14: 596000 | D14: 792000 | E14: 904000 | F14: 919000
A15: Finansielle poster, netto
A16: Resultat før skat | B16: 1045000 | C16: 2446000 | D16: 2531000 | E16: 3299000 | F16: 3289000
A17: Skat af årets resultat | B17: 509000 | C17: 441000 | D17: 554000 | E17: 658000 | F17: 676000
A18: Årets resultat | B18: 536000 | C18: 2005000 | D18: 1977000 | E18: 2641000 | F18: 2613000
A19: Gns. antal medarbejdere
A20: Investering i materielle anlægsaktiver

Sheet balance_raw
A1: iss (CVR None) — Balance (t.kr.) | B1: 2021 | C1: 2022 | D1: 2023 | E1: 2024 | F1: 2025
A2: Immaterielle anlægsaktiver | B2: 22739000 | C2: 23920000 | D2: 23272000 | E2: 24359000 | F2: 24208000
A3: Materielle anlægsaktiver | B3: 2445000 | C3: 2403000 | D3: 2200000 | E3: 2424000 | F3: 2229000
A4: Kapitalandele, dattervirksomheder
A5: Deposita | B5: 457000 | C5: 512000 | D5: 195000 | E5: 605000
A6: Finansielle anlægsaktiver
A7: Anlægsaktiver | B7: 27362000 | C7: 28664000 | D7: 27555000 | E7: 29271000 | F7: 29017000
A8: Råvarer og hjælpematerialer | B8: 5020000 | C8: 6598000 | D8: 7323000 | E8: 7519000 | F8: 7170000
A9: Varer under fremstilling
A10: Færdigvarer og handelsvarer
A11: Varebeholdninger | B11: 177000 | C11: 231000 | D11: 239000 | E11: 251000 | F11: 245000
A12: Tilgodehavender fra salg og tjenesteydelser | B12: 10406000 | C12: 10996000 | D12: 11354000 | E12: 12449000 | F12: 12872000
A13: Tilgodehavender hos tilknyttede virksomheder
A14: Andre tilgodehavender
A15: Periodeafgrænsningsposter (aktiver)
A16: Udskudt skatteaktiv | B16: 790000 | C16: 912000 | D16: 962000 | E16: 885000 | F16: 822000
A17: Tilgodehavende skat hos tilknyttede virksomheder
A18: Kortfristede skattetilgodehavender | B18: 185000 | C18: 173000 | D18: 126000 | E18: 120000 | F18: 115000
A19: Tilgodehavender | B19: 1582000 | C19: 1695000 | D19: 1628000 | E19: 1721000 | F19: 1623000
A20: Værdipapirer
A21: Likvide beholdninger | B21: 3428000 | C21: 5214000 | D21: 6093000 | E21: 6829000 | F21: 1729000
A22: Omsætningsaktiver | B22: 16293000 | C22: 18341000 | D22: 20138000 | E22: 21370000 | F22: 16584000
A23: Aktiver | B23: 43655000 | C23: 47005000 | D23: 47693000 | E23: 50641000 | F23: 45601000
A24: Egenkapital i alt | B24: 7583000 | C24: 10156000 | D24: 9893000 | E24: 11143000 | F24: 9776000
A25: Hensættelse til udskudt skat | B25: 976000 | C25: 1178000 | D25: 1320000 | E25: 1156000 | F25: 1143000
A26: Hensatte forpligtelser | B26: 1351000 | C26: 1185000 | D26: 1135000 | E26: 1316000 | F26: 1104000
A27: Langfristede gældsforpligtelser | B27: 16094000 | C27: 15945000 | D27: 13427000 | E27: 13584000 | F27: 9762000
A28: Ansvarlig lånekapital (kortfristet)
A29: Kortfristet del af langfristede gældsforpligtelser
A30: Kreditinstitutter | B30: 888000 | C30: 963000 | D30: 3292000 | E30: 4757000 | F30: 5315000
A31: Leasingforpligtelser (kortfristet)
A32: Leverandører af varer og tjenesteydelser | B32: 5657000 | C32: 6952000 | D32: 7259000 | E32: 7387000 | F32: 6955000
A33: Gæld til tilknyttede virksomheder
A34: Gæld til selskabsdeltagere og ledelse
A35: Selskabsskat
A36: Gæld til tilknyttede virksomheder vedr. selskabsskat
A37: Anden gæld (kortfristet) | B37: 8730000 | C37: 8714000 | D37: 8482000 | E37: 9505000 | F37: 9735000
A38: Periodeafgrænsningsposter (passiver)
A39: Kortfristede gældsforpligtelser | B39: 16690000 | C39: 17417000 | D39: 20902000 | E39: 22300000 | F39: 22741000
A40: Gældsforpligtelser | B40: 35866000 | C40: 36190000 | D40: 37171000 | E40: 38728000 | F40: 35061000
...

Sheet pengestrom_raw
A1: iss (CVR None) — Pengestrømsopgørelse (t.kr.) | B1: 2021 | C1: 2022 | D1: 2023 | E1: 2024 | F1: 2025
A2: Pengestrømme fra driftsaktivitet | B2: 3221000 | C2: 3333000 | D2: 3392000 | E2: 3727000 | F2: 3989000
A3: Pengestrømme fra investeringsaktivitet | B3: 73000 | C3: -546000 | D3: -1042000 | E3: -1536000 | F3: -1184000
A4: Pengestrømme fra finansieringsaktivitet | B4: -2832000 | C4: -930000 | D4: -1334000 | E4: -1405000 | F4: -7638000
A5: Årets pengestrøm

Sheet Simpel_arts
A1: iss (CVR None) — Regnskabs- og nøgletal — artsopdelt
A3: Beløb i 1.000 kr. | B3: 2025 | C3: 2024 | D3: 2023 | F3: Note / XBRL-felt
A4: Uddrag af resultatopgørelse
A5: Nettoomsætning | B5: ='res_raw'!$F$2 | C5: ='res_raw'!$E$2 | D5: ='res_raw'!$D$2 | F5: fsa:Revenue
A6: Andre driftsindtægter | B6: ='res_raw'!$F$3 | C6: ='res_raw'!$E$3 | D6: ='res_raw'!$D$3 | F6: fsa:OtherOperatingIncome. Indtægter fra sekundære aktiviteter (huslejeindtægter, avance ved salg af anlæg mv.).
A7: Vareforbrug | B7: =-'res_raw'!$F$4 | C7: =-'res_raw'!$E$4 | D7: =-'res_raw'!$D$4 | F7: fsa:CostOfSales (vises negativt for korrekt SUM-formel).
A8: Andre eksterne omk. mv. | B8: =-'res_raw'!$F$5 | C8: =-'res_raw'!$E$5 | D8: =-'res_raw'!$D$5 | F8: fsa:OtherExternalExpenses (vises negativt). Husleje, energi, kontorhold mv.
A9: Bruttofortjeneste | B9: =SUM(B5:B8) | C9: =SUM(C5:C8) | D9: =SUM(D5:D8) | F9: Beregnet: Nettoomsætning + Andre driftsindt. − Vareforbrug − Andre ext. omk.
A10: Personaleomkostninger | B10: =-'res_raw'!$F$7 | C10: =-'res_raw'!$E$7 | D10: =-'res_raw'!$D$7 | F10: fsa:EmployeeBenefitsExpense (vises negativt). Lønninger, pension, sociale ydelser.
A11: Af- og nedskrivninger | B11: =-'res_raw'!$F$9 | C11: =-'res_raw'!$E$9 | D11: =-'res_raw'!$D$9 | F11: fsa:Depreciation (vises negativt). Af- og nedskrivninger på materielle og immaterielle anlægsaktiver.
A12: Andre driftsomkostninger | B12: =-'res_raw'!$F$10 | C12: =-'res_raw'!$E$10 | D12: =-'res_raw'!$D$10 | F12: fsa:OtherOperatingExpenses (vises negativt). Typisk 0 eller meget lille post.
A13: Resultat af primær drift | B13: =SUM(B9:B12) | C13: =SUM(C9:C12) | D13: =SUM(D9:D12) | F13: Beregnet: Bruttofortjeneste − Personaleomk. − Af- og nedskrivninger − Andre driftsomk. EBIT.
A14: Finansielle indtægter mv. | B14: =N('res_raw'!$F$12)+N('res_raw'!$F$13) | C14: =N('res_raw'!$E$12)+N('res_raw'!$E$13) | D14: =N('res_raw'!$D$12)+N('res_raw'!$D$13) | F14: fsa:IncomeFromSubsidiaries + fsa:OtherFinanceIncome.
A15: Finansielle omkostninger mv. | B15: =-'res_raw'!$F$14 | C15: =-'res_raw'!$E$14 | D15: =-'res_raw'!$D$14 | F15: fsa:OtherFinanceExpenses (vises negativt). Renteomkostninger, kurstab mv.
A16: Resultat før skat | B16: =SUM(B13:B15) | C16: =SUM(C13:C15) | D16: =SUM(D13:D15) | F16: Beregnet: EBIT + Fin. indtægter + Fin. omk. EBT.
A18: Uddrag af balance
A19: Anlægsaktiver | B19: ='balance_raw'!$F$7 | C19: ='balance_raw'!$E$7 | D19: ='balance_raw'!$D$7 | F19: fsa:NoncurrentAssets. Materielle, immaterielle og finansielle anlægsaktiver.
A20: Omsætningsaktiver | B20: ='balance_raw'!$F$22 | C20: ='balance_raw'!$E$22 | D20: ='balance_raw'!$D$22 | F20: fsa:CurrentAssets. Varebeholdninger, tilgodehavender, likvider.
A21: Aktiver i alt | B21: =SUM(B19:B20) | C21: =SUM(C19:C20) | D21: =SUM(D19:D20) | F21: Beregnet: Anlægsaktiver + Omsætningsaktiver. Bør matche fsa:Assets.
A23: Egenkapital | B23: ='balance_raw'!$F$24 | C23: ='balance_raw'!$E$24 | D23: ='balance_raw'!$D$24 | F23: fsa:Equity. Selskabskapital, overført resultat, reserver.
A24: Forpligtelser | B24: ='balance_raw'!$F$41-'balance_raw'!$F$24 | C24: ='balance_raw'!$E$41-'balance_raw'!$E$24 | D24: ='balance_raw'!$D$41-'balance_raw'!$D$24 | F24: Beregnet: Passiver (fsa:LiabilitiesAndEquity) − Egenkapital. Hensættelser + kort- og langfristet gæld.
A25: Passiver i alt | B25: =SUM(B23:B24) | C25: =SUM(C23:C24) | D25: =SUM(D23:D24) | F25: Beregnet: Egenkapital + Forpligtelser. Bør matche Aktiver i alt.
A27: Udvalgte balanceposter
A28: Varebeholdninger | B28: ='balance_raw'!$F$11 | C28: ='balance_raw'!$E$11 | D28: ='balance_raw'!$D$11 | F28: fsa:Inventories (eller fsa:ManufacturedGoodsAndGoodsForResale hvis total mangler).
A29: Tilgodehavender fra salg | B29: ='balance_raw'!$F$12 | C29: ='balance_raw'!$E$12 | D29: ='balance_raw'!$D$12 | F29: fsa:ShorttermTradeReceivables. Kortfristede tilgodehavender fra kunder.
A30: Kortfristede gældsforpligtelser | B30: ='balance_raw'!$F$39 | C30: ='balance_raw'!$E$39 | D30: ='balance_raw'!$D$39 | F30: fsa:ShorttermLiabilitiesOtherThanProvisions. Gæld der forfalder inden for 1 år.
A32: Rentabilitet
A33: Afkastningsgrad, % | B33: =IFERROR((B13+B14)/B21*100,"") | C33: =IFERROR((C13+C14)/C21*100,"") | D33: =IFERROR((D13+D14)/D21*100,"")
A34: Overskudsgrad, % | B34: =IFERROR((B13+B14)/B5*100,"") | C34: =IFERROR((C13+C14)/C5*100,"") | D34: =IFERROR((D13+D14)/D5*100,"")
A35: Aktivernes omsætningshastighed, gange | B35: =IFERROR(B5/B21,"") | C35: =IFERROR(C5/C21,"") | D35: =IFERROR(D5/D21,"")
A36: Gældsrente, % | B36: =IFERROR(-B15*100/B24,"") | C36: =IFERROR(-C15*100/C24,"") | D36: =IFERROR(-D15*100/D24,"")
A37: Egenkapitalens forrentning, % | B37: =IFERROR(B16/B23*100,"") | C37: =IFERROR(C16/C23*100,"") | D37: =IFERROR(D16/D23*100,"")
A38: Gearing, gange | B38: =IFERROR(B24/B23,"") | C38: =IFERROR(C24/C23,"") | D38: =IFERROR(D24/D23,"")
A40: Indekstal for indtjeningsevne (2023=100)
A41: Nettoomsætning | B41: =IFERROR(B5/$D5*100,"") | C41: =IFERROR(C5/$D5*100,"") | D41: =IFERROR(D5/$D5*100,"")
A42: Vareforbrug | B42: =IFERROR(B7/$D7*100,"") | C42: =IFERROR(C7/$D7*100,"") | D42: =IFERROR(D7/$D7*100,"")
A43: Andre eksterne omk. | B43: =IFERROR(B8/$D8*100,"") | C43: =IFERROR(C8/$D8*100,"") | D43: =IFERROR(D8/$D8*100,"")
A44: Personaleomkostninger | B44: =IFERROR(B10/$D10*100,"") | C44: =IFERROR(C10/$D10*100,"") | D44: =IFERROR(D10/$D10*100,"")
A45: Af- og nedskrivninger | B45: =IFERROR(B11/$D11*100,"") | C45: =IFERROR(C11/$D11*100,"") | D45: =IFERROR(D11/$D11*100,"")
A47: Indekstal for kapitaltilpasningsevne (2023=100)
...

Sheet Noter_info
A1: iss (CVR None) — Ukendte XBRL-felter — disse er noter og ikke en del af hoved-regnskabet
A2: Kategori | B2: Dansk navn | C2: XBRL feltnavn | D2: 2021 t.kr. | E2: 2022 t.kr. | F2: 2023 t.kr. | G2: 2024 t.kr. | H2: 2025 t.kr. | I2: Forklaring
A3: Øvrige (ukendt) | B3: ifrs-full:AdjustmentsForSharebasedPayments | C3: ifrs-full:AdjustmentsForSharebasedPayments | D3: 62000 | E3: 80000 | F3: 72000 | G3: 93000 | H3: 93000 | I3: Ingen forklaring tilgængelig.
A4: Øvrige (ukendt) | B4: ifrs-full:CashAdvancesAndLoansMadeToOtherPartiesClassifiedAsInvestingActivities | C4: ifrs-full:CashAdvancesAndLoansMadeToOtherPartiesClassifiedAsInvestingActivities | H4: 187000 | I4: Ingen forklaring tilgængelig.
A5: Øvrige (ukendt) | B5: ifrs-full:GainLossOnChangesInEffectOfLimitingNetDefinedBenefitAssetToAssetCeiling | C5: ifrs-full:GainLossOnChangesInEffectOfLimitingNetDefinedBenefitAssetToAssetCeiling | D5: 1080000 | E5: 43000 | F5: -299000 | G5: 28000 | H5: 341000 | I5: Ingen forklaring tilgængelig.
A6: Øvrige (ukendt) | B6: ifrs-full:GainsLossesOnHedgesOfNetInvestmentsInForeignOperationsBeforeTax | C6: ifrs-full:GainsLossesOnHedgesOfNetInvestmentsInForeignOperationsBeforeTax | D6: -191000 | E6: -43000 | F6: -84000 | G6: 0 | I6: Ingen forklaring tilgængelig.
A7: Øvrige (ukendt) | B7: ifrs-full:ImpairmentLossRecognisedInProfitOrLossGoodwill | C7: ifrs-full:ImpairmentLossRecognisedInProfitOrLossGoodwill | D7: 450000 | E7: 0 | I7: Ingen forklaring tilgængelig.
A8: Øvrige (ukendt) | B8: ifrs-full:NoncurrentLoansAndReceivables | C8: ifrs-full:NoncurrentLoansAndReceivables | H8: 187000 | I8: Ingen forklaring tilgængelig.
A9: Øvrige (ukendt) | B9: ifrs-full:OtherInflowsOutflowsOfCashClassifiedAsFinancingActivities | C9: ifrs-full:OtherInflowsOutflowsOfCashClassifiedAsFinancingActivities | D9: -472000 | E9: -58000 | F9: -147000 | G9: -259000 | H9: -72000 | I9: Ingen forklaring tilgængelig.
A10: Øvrige (ukendt) | B10: ifrs-full:OtherInflowsOutflowsOfCashClassifiedAsOperatingActivities | C10: ifrs-full:OtherInflowsOutflowsOfCashClassifiedAsOperatingActivities | D10: -74000 | E10: -31000 | F10: -42000 | G10: -59000 | H10: -46000 | I10: Ingen forklaring tilgængelig.
A11: Øvrige (ukendt) | B11: ifrs-full:ProceedsFromIssueOfBondsNotesAndDebentures | C11: ifrs-full:ProceedsFromIssueOfBondsNotesAndDebentures | F11: 0 | G11: 3696000 | H11: 0 | I11: Ingen forklaring tilgængelig.
A12: Øvrige (ukendt) | B12: ifrs-full:ReclassificationAdjustmentsOnExchangeDifferencesOnTranslationBeforeTax | C12: ifrs-full:ReclassificationAdjustmentsOnExchangeDifferencesOnTranslationBeforeTax | D12: 7000 | E12: 33000 | F12: 18000 | G12: 0 | I12: Ingen forklaring tilgængelig.
A13: Øvrige (ukendt) | B13: ifrs-full:RepaymentsOfBondsNotesAndDebentures | C13: ifrs-full:RepaymentsOfBondsNotesAndDebentures | D13: 1577000 | E13: 0 | F13: 0 | G13: 2237000 | H13: 3732000 | I13: Ingen forklaring tilgængelig.
