Workbook

Sheet Overblik
A1: harboe (CVR None) — Regnskabsanalyse – Resultatopgørelse & Balance (t.kr.)
H2: Indekstal (2021=100)
A3: Resultatopgørelse t.kr. | B3: 2021 | C3: 2022 | D3: 2023 | E3: 2024 | F3: 2025 | H3: 2021 | I3: 2022 | J3: 2023 | K3: 2024 | L3: 2025
A4: Nettoomsætning | B4: ='res_raw'!$B$2 | C4: ='res_raw'!$C$2 | D4: ='res_raw'!$D$2 | E4: ='res_raw'!$E$2 | F4: ='res_raw'!$F$2 | H4: =IFERROR(B4/$B$4*100,"") | I4: =IFERROR(C4/$B$4*100,"") | J4: =IFERROR(D4/$B$4*100,"") | K4: =IFERROR(E4/$B$4*100,"") | L4: =IFERROR(F4/$B$4*100,"")
A5: Produktionsomkostninger | B5: ='res_raw'!$B$3 | C5: ='res_raw'!$C$3 | D5: ='res_raw'!$D$3 | E5: ='res_raw'!$E$3 | F5: ='res_raw'!$F$3 | H5: =IFERROR(B5/$B$5*100,"") | I5: =IFERROR(C5/$B$5*100,"") | J5: =IFERROR(D5/$B$5*100,"") | K5: =IFERROR(E5/$B$5*100,"") | L5: =IFERROR(F5/$B$5*100,"")
A6: Bruttoresultat | B6: ='res_raw'!$B$4 | C6: ='res_raw'!$C$4 | D6: ='res_raw'!$D$4 | E6: ='res_raw'!$E$4 | F6: ='res_raw'!$F$4 | H6: =IFERROR(B6/$B$6*100,"") | I6: =IFERROR(C6/$B$6*100,"") | J6: =IFERROR(D6/$B$6*100,"") | K6: =IFERROR(E6/$B$6*100,"") | L6: =IFERROR(F6/$B$6*100,"")
A7: Salgs- og distributionsomkostninger | B7: ='res_raw'!$B$5 | C7: ='res_raw'!$C$5 | D7: ='res_raw'!$D$5 | E7: ='res_raw'!$E$5 | F7: ='res_raw'!$F$5 | H7: =IFERROR(B7/$B$7*100,"") | I7: =IFERROR(C7/$B$7*100,"") | J7: =IFERROR(D7/$B$7*100,"") | K7: =IFERROR(E7/$B$7*100,"") | L7: =IFERROR(F7/$B$7*100,"")
A8: Administrationsomkostninger | B8: ='res_raw'!$B$6 | C8: ='res_raw'!$C$6 | D8: ='res_raw'!$D$6 | E8: ='res_raw'!$E$6 | F8: ='res_raw'!$F$6 | H8: =IFERROR(B8/$B$8*100,"") | I8: =IFERROR(C8/$B$8*100,"") | J8: =IFERROR(D8/$B$8*100,"") | K8: =IFERROR(E8/$B$8*100,"") | L8: =IFERROR(F8/$B$8*100,"")
A9: Andre driftsindtægter | B9: ='res_raw'!$B$7 | C9: ='res_raw'!$C$7 | D9: ='res_raw'!$D$7 | E9: ='res_raw'!$E$7 | F9: ='res_raw'!$F$7 | H9: =IFERROR(B9/$B$9*100,"") | I9: =IFERROR(C9/$B$9*100,"") | J9: =IFERROR(D9/$B$9*100,"") | K9: =IFERROR(E9/$B$9*100,"") | L9: =IFERROR(F9/$B$9*100,"")
A10: Andre driftsomkostninger | B10: ='res_raw'!$B$8 | C10: ='res_raw'!$C$8 | D10: ='res_raw'!$D$8 | E10: ='res_raw'!$E$8 | F10: ='res_raw'!$F$8 | H10: =IFERROR(B10/$B$10*100,"") | I10: =IFERROR(C10/$B$10*100,"") | J10: =IFERROR(D10/$B$10*100,"") | K10: =IFERROR(E10/$B$10*100,"") | L10: =IFERROR(F10/$B$10*100,"")
A11: Resultat af primær drift | B11: ='res_raw'!$B$9 | C11: ='res_raw'!$C$9 | D11: ='res_raw'!$D$9 | E11: ='res_raw'!$E$9 | F11: ='res_raw'!$F$9 | H11: =IFERROR(B11/$B$11*100,"") | I11: =IFERROR(C11/$B$11*100,"") | J11: =IFERROR(D11/$B$11*100,"") | K11: =IFERROR(E11/$B$11*100,"") | L11: =IFERROR(F11/$B$11*100,"")
A12: Indtægter af kapitalandele, dattervirksomheder | B12: ='res_raw'!$B$10 | C12: ='res_raw'!$C$10 | D12: ='res_raw'!$D$10 | E12: ='res_raw'!$E$10 | F12: ='res_raw'!$F$10 | H12: =IFERROR(B12/$B$12*100,"") | I12: =IFERROR(C12/$B$12*100,"") | J12: =IFERROR(D12/$B$12*100,"") | K12: =IFERROR(E12/$B$12*100,"") | L12: =IFERROR(F12/$B$12*100,"")
A13: Finansielle indtægter | B13: ='res_raw'!$B$11 | C13: ='res_raw'!$C$11 | D13: ='res_raw'!$D$11 | E13: ='res_raw'!$E$11 | F13: ='res_raw'!$F$11 | H13: =IFERROR(B13/$B$13*100,"") | I13: =IFERROR(C13/$B$13*100,"") | J13: =IFERROR(D13/$B$13*100,"") | K13: =IFERROR(E13/$B$13*100,"") | L13: =IFERROR(F13/$B$13*100,"")
A14: Finansielle omkostninger | B14: ='res_raw'!$B$12 | C14: ='res_raw'!$C$12 | D14: ='res_raw'!$D$12 | E14: ='res_raw'!$E$12 | F14: ='res_raw'!$F$12 | H14: =IFERROR(B14/$B$14*100,"") | I14: =IFERROR(C14/$B$14*100,"") | J14: =IFERROR(D14/$B$14*100,"") | K14: =IFERROR(E14/$B$14*100,"") | L14: =IFERROR(F14/$B$14*100,"")
A15: Finansielle poster, netto | B15: ='res_raw'!$B$13 | C15: ='res_raw'!$C$13 | D15: ='res_raw'!$D$13 | E15: ='res_raw'!$E$13 | F15: ='res_raw'!$F$13 | H15: =IFERROR(B15/$B$15*100,"") | I15: =IFERROR(C15/$B$15*100,"") | J15: =IFERROR(D15/$B$15*100,"") | K15: =IFERROR(E15/$B$15*100,"") | L15: =IFERROR(F15/$B$15*100,"")
A16: Resultat før skat | B16: ='res_raw'!$B$14 | C16: ='res_raw'!$C$14 | D16: ='res_raw'!$D$14 | E16: ='res_raw'!$E$14 | F16: ='res_raw'!$F$14 | H16: =IFERROR(B16/$B$16*100,"") | I16: =IFERROR(C16/$B$16*100,"") | J16: =IFERROR(D16/$B$16*100,"") | K16: =IFERROR(E16/$B$16*100,"") | L16: =IFERROR(F16/$B$16*100,"")
A17: Skat af årets resultat | B17: ='res_raw'!$B$15 | C17: ='res_raw'!$C$15 | D17: ='res_raw'!$D$15 | E17: ='res_raw'!$E$15 | F17: ='res_raw'!$F$15 | H17: =IFERROR(B17/$B$17*100,"") | I17: =IFERROR(C17/$B$17*100,"") | J17: =IFERROR(D17/$B$17*100,"") | K17: =IFERROR(E17/$B$17*100,"") | L17: =IFERROR(F17/$B$17*100,"")
A18: Årets resultat | B18: ='res_raw'!$B$16 | C18: ='res_raw'!$C$16 | D18: ='res_raw'!$D$16 | E18: ='res_raw'!$E$16 | F18: ='res_raw'!$F$16 | H18: =IFERROR(B18/$B$18*100,"") | I18: =IFERROR(C18/$B$18*100,"") | J18: =IFERROR(D18/$B$18*100,"") | K18: =IFERROR(E18/$B$18*100,"") | L18: =IFERROR(F18/$B$18*100,"")
A20: AKTIVER t.kr. | B20: 2021 | C20: 2022 | D20: 2023 | E20: 2024 | F20: 2025 | H20: 2021 | I20: 2022 | J20: 2023 | K20: 2024 | L20: 2025
A21: Immaterielle anlægsaktiver | B21: ='balance_raw'!$B$2 | C21: ='balance_raw'!$C$2 | D21: ='balance_raw'!$D$2 | E21: ='balance_raw'!$E$2 | F21: ='balance_raw'!$F$2 | H21: =IFERROR(B21/$B$21*100,"") | I21: =IFERROR(C21/$B$21*100,"") | J21: =IFERROR(D21/$B$21*100,"") | K21: =IFERROR(E21/$B$21*100,"") | L21: =IFERROR(F21/$B$21*100,"")
A22: Materielle anlægsaktiver | B22: ='balance_raw'!$B$3 | C22: ='balance_raw'!$C$3 | D22: ='balance_raw'!$D$3 | E22: ='balance_raw'!$E$3 | F22: ='balance_raw'!$F$3 | H22: =IFERROR(B22/$B$22*100,"") | I22: =IFERROR(C22/$B$22*100,"") | J22: =IFERROR(D22/$B$22*100,"") | K22: =IFERROR(E22/$B$22*100,"") | L22: =IFERROR(F22/$B$22*100,"")
A23: Kapitalandele, dattervirksomheder | B23: ='balance_raw'!$B$4 | C23: ='balance_raw'!$C$4 | D23: ='balance_raw'!$D$4 | E23: ='balance_raw'!$E$4 | F23: ='balance_raw'!$F$4 | H23: =IFERROR(B23/$B$23*100,"") | I23: =IFERROR(C23/$B$23*100,"") | J23: =IFERROR(D23/$B$23*100,"") | K23: =IFERROR(E23/$B$23*100,"") | L23: =IFERROR(F23/$B$23*100,"")
A24: Deposita | B24: ='balance_raw'!$B$5 | C24: ='balance_raw'!$C$5 | D24: ='balance_raw'!$D$5 | E24: ='balance_raw'!$E$5 | F24: ='balance_raw'!$F$5 | H24: =IFERROR(B24/$B$24*100,"") | I24: =IFERROR(C24/$B$24*100,"") | J24: =IFERROR(D24/$B$24*100,"") | K24: =IFERROR(E24/$B$24*100,"") | L24: =IFERROR(F24/$B$24*100,"")
A25: Finansielle anlægsaktiver | B25: ='balance_raw'!$B$6 | C25: ='balance_raw'!$C$6 | D25: ='balance_raw'!$D$6 | E25: ='balance_raw'!$E$6 | F25: ='balance_raw'!$F$6 | H25: =IFERROR(B25/$B$25*100,"") | I25: =IFERROR(C25/$B$25*100,"") | J25: =IFERROR(D25/$B$25*100,"") | K25: =IFERROR(E25/$B$25*100,"") | L25: =IFERROR(F25/$B$25*100,"")
A26: Anlægsaktiver | B26: ='balance_raw'!$B$7 | C26: ='balance_raw'!$C$7 | D26: ='balance_raw'!$D$7 | E26: ='balance_raw'!$E$7 | F26: ='balance_raw'!$F$7 | H26: =IFERROR(B26/$B$26*100,"") | I26: =IFERROR(C26/$B$26*100,"") | J26: =IFERROR(D26/$B$26*100,"") | K26: =IFERROR(E26/$B$26*100,"") | L26: =IFERROR(F26/$B$26*100,"")
A27: Varebeholdninger | B27: ='balance_raw'!$B$8 | C27: ='balance_raw'!$C$8 | D27: ='balance_raw'!$D$8 | E27: ='balance_raw'!$E$8 | F27: ='balance_raw'!$F$8 | H27: =IFERROR(B27/$B$27*100,"") | I27: =IFERROR(C27/$B$27*100,"") | J27: =IFERROR(D27/$B$27*100,"") | K27: =IFERROR(E27/$B$27*100,"") | L27: =IFERROR(F27/$B$27*100,"")
A28: Tilgodehavender fra salg og tjenesteydelser | B28: ='balance_raw'!$B$9 | C28: ='balance_raw'!$C$9 | D28: ='balance_raw'!$D$9 | E28: ='balance_raw'!$E$9 | F28: ='balance_raw'!$F$9 | H28: =IFERROR(B28/$B$28*100,"") | I28: =IFERROR(C28/$B$28*100,"") | J28: =IFERROR(D28/$B$28*100,"") | K28: =IFERROR(E28/$B$28*100,"") | L28: =IFERROR(F28/$B$28*100,"")
A29: Tilgodehavender hos tilknyttede virksomheder | B29: ='balance_raw'!$B$10 | C29: ='balance_raw'!$C$10 | D29: ='balance_raw'!$D$10 | E29: ='balance_raw'!$E$10 | F29: ='balance_raw'!$F$10 | H29: =IFERROR(B29/$B$29*100,"") | I29: =IFERROR(C29/$B$29*100,"") | J29: =IFERROR(D29/$B$29*100,"") | K29: =IFERROR(E29/$B$29*100,"") | L29: =IFERROR(F29/$B$29*100,"")
A30: Andre tilgodehavender | B30: ='balance_raw'!$B$11 | C30: ='balance_raw'!$C$11 | D30: ='balance_raw'!$D$11 | E30: ='balance_raw'!$E$11 | F30: ='balance_raw'!$F$11 | H30: =IFERROR(B30/$B$30*100,"") | I30: =IFERROR(C30/$B$30*100,"") | J30: =IFERROR(D30/$B$30*100,"") | K30: =IFERROR(E30/$B$30*100,"") | L30: =IFERROR(F30/$B$30*100,"")
A31: Periodeafgrænsningsposter (aktiver) | B31: ='balance_raw'!$B$12 | C31: ='balance_raw'!$C$12 | D31: ='balance_raw'!$D$12 | E31: ='balance_raw'!$E$12 | F31: ='balance_raw'!$F$12 | H31: =IFERROR(B31/$B$31*100,"") | I31: =IFERROR(C31/$B$31*100,"") | J31: =IFERROR(D31/$B$31*100,"") | K31: =IFERROR(E31/$B$31*100,"") | L31: =IFERROR(F31/$B$31*100,"")
A32: Udskudt skatteaktiv | B32: ='balance_raw'!$B$13 | C32: ='balance_raw'!$C$13 | D32: ='balance_raw'!$D$13 | E32: ='balance_raw'!$E$13 | F32: ='balance_raw'!$F$13 | H32: =IFERROR(B32/$B$32*100,"") | I32: =IFERROR(C32/$B$32*100,"") | J32: =IFERROR(D32/$B$32*100,"") | K32: =IFERROR(E32/$B$32*100,"") | L32: =IFERROR(F32/$B$32*100,"")
A33: Tilgodehavende skat hos tilknyttede virksomheder | B33: ='balance_raw'!$B$14 | C33: ='balance_raw'!$C$14 | D33: ='balance_raw'!$D$14 | E33: ='balance_raw'!$E$14 | F33: ='balance_raw'!$F$14 | H33: =IFERROR(B33/$B$33*100,"") | I33: =IFERROR(C33/$B$33*100,"") | J33: =IFERROR(D33/$B$33*100,"") | K33: =IFERROR(E33/$B$33*100,"") | L33: =IFERROR(F33/$B$33*100,"")
A34: Kortfristede skattetilgodehavender | B34: ='balance_raw'!$B$15 | C34: ='balance_raw'!$C$15 | D34: ='balance_raw'!$D$15 | E34: ='balance_raw'!$E$15 | F34: ='balance_raw'!$F$15 | H34: =IFERROR(B34/$B$34*100,"") | I34: =IFERROR(C34/$B$34*100,"") | J34: =IFERROR(D34/$B$34*100,"") | K34: =IFERROR(E34/$B$34*100,"") | L34: =IFERROR(F34/$B$34*100,"")
A35: Tilgodehavender | B35: ='balance_raw'!$B$16 | C35: ='balance_raw'!$C$16 | D35: ='balance_raw'!$D$16 | E35: ='balance_raw'!$E$16 | F35: ='balance_raw'!$F$16 | H35: =IFERROR(B35/$B$35*100,"") | I35: =IFERROR(C35/$B$35*100,"") | J35: =IFERROR(D35/$B$35*100,"") | K35: =IFERROR(E35/$B$35*100,"") | L35: =IFERROR(F35/$B$35*100,"")
A36: Værdipapirer | B36: ='balance_raw'!$B$17 | C36: ='balance_raw'!$C$17 | D36: ='balance_raw'!$D$17 | E36: ='balance_raw'!$E$17 | F36: ='balance_raw'!$F$17 | H36: =IFERROR(B36/$B$36*100,"") | I36: =IFERROR(C36/$B$36*100,"") | J36: =IFERROR(D36/$B$36*100,"") | K36: =IFERROR(E36/$B$36*100,"") | L36: =IFERROR(F36/$B$36*100,"")
A37: Likvide beholdninger | B37: ='balance_raw'!$B$18 | C37: ='balance_raw'!$C$18 | D37: ='balance_raw'!$D$18 | E37: ='balance_raw'!$E$18 | F37: ='balance_raw'!$F$18 | H37: =IFERROR(B37/$B$37*100,"") | I37: =IFERROR(C37/$B$37*100,"") | J37: =IFERROR(D37/$B$37*100,"") | K37: =IFERROR(E37/$B$37*100,"") | L37: =IFERROR(F37/$B$37*100,"")
A38: Omsætningsaktiver | B38: ='balance_raw'!$B$19 | C38: ='balance_raw'!$C$19 | D38: ='balance_raw'!$D$19 | E38: ='balance_raw'!$E$19 | F38: ='balance_raw'!$F$19 | H38: =IFERROR(B38/$B$38*100,"") | I38: =IFERROR(C38/$B$38*100,"") | J38: =IFERROR(D38/$B$38*100,"") | K38: =IFERROR(E38/$B$38*100,"") | L38: =IFERROR(F38/$B$38*100,"")
A39: Aktiver | B39: ='balance_raw'!$B$20 | C39: ='balance_raw'!$C$20 | D39: ='balance_raw'!$D$20 | E39: ='balance_raw'!$E$20 | F39: ='balance_raw'!$F$20 | H39: =IFERROR(B39/$B$39*100,"") | I39: =IFERROR(C39/$B$39*100,"") | J39: =IFERROR(D39/$B$39*100,"") | K39: =IFERROR(E39/$B$39*100,"") | L39: =IFERROR(F39/$B$39*100,"")
A41: PASSIVER t.kr. | B41: 2021 | C41: 2022 | D41: 2023 | E41: 2024 | F41: 2025 | H41: 2021 | I41: 2022 | J41: 2023 | K41: 2024 | L41: 2025
A42: Selskabskapital | B42: ='balance_raw'!$B$21 | C42: ='balance_raw'!$C$21 | D42: ='balance_raw'!$D$21 | E42: ='balance_raw'!$E$21 | F42: ='balance_raw'!$F$21 | H42: =IFERROR(B42/$B$42*100,"") | I42: =IFERROR(C42/$B$42*100,"") | J42: =IFERROR(D42/$B$42*100,"") | K42: =IFERROR(E42/$B$42*100,"") | L42: =IFERROR(F42/$B$42*100,"")
...

Sheet res_raw
A1: harboe (CVR None) — Resultatopgørelse & nøgleoplysninger (t.kr.) | B1: 2021 | C1: 2022 | D1: 2023 | E1: 2024 | F1: 2025
A2: Nettoomsætning | B2: 1328184 | C2: 1419353 | D2: 1621066 | E2: 1817069 | F2: 1822588
A3: Produktionsomkostninger | B3: 1105266 | C3: 1161534 | D3: 1349830 | E3: 1464255 | F3: 1466556
A4: Bruttoresultat | B4: 222918 | C4: 257819 | D4: 271236 | E4: 352814 | F4: 356032
A5: Salgs- og distributionsomkostninger | B5: 165277 | C5: 202934 | D5: 212175 | E5: 197982 | F5: 211238
A6: Administrationsomkostninger | B6: 57658 | C6: 60161 | D6: 65099 | E6: 81369 | F6: 90693
A7: Andre driftsindtægter | B7: 13323 | C7: 10802 | D7: 10811 | E7: 9805 | F7: 15851
A8: Andre driftsomkostninger | B8: 3280 | C8: 6322 | D8: 7736 | E8: 6165 | F8: 6184
A9: Resultat af primær drift | B9: 10026 | C9: -796 | D9: -2963 | E9: 77103 | F9: 63768
A10: Indtægter af kapitalandele, dattervirksomheder
A11: Finansielle indtægter | B11: 138 | C11: 206 | D11: 1957 | E11: 806 | F11: 1875
A12: Finansielle omkostninger | B12: 6921 | C12: 6367 | D12: 8015 | E12: 10037 | F12: 9497
A13: Finansielle poster, netto
A14: Resultat før skat | B14: 3243 | C14: -6957 | D14: -9021 | E14: 67872 | F14: 56146
A15: Skat af årets resultat | B15: 1584 | C15: -2730 | D15: -4683 | E15: 13111 | F15: 11350
A16: Årets resultat | B16: 1659 | C16: -4227 | D16: -4338 | E16: 54761 | F16: 44796
A17: Gns. antal medarbejdere
A18: Investering i materielle anlægsaktiver | B18: 45400 | C18: 49452 | D18: 61517 | E18: 129245 | F18: 115705

Sheet balance_raw
A1: harboe (CVR None) — Balance (t.kr.) | B1: 2021 | C1: 2022 | D1: 2023 | E1: 2024 | F1: 2025
A2: Immaterielle anlægsaktiver | B2: 13421 | C2: 6218 | D2: 4202 | E2: 3982 | F2: 3783
A3: Materielle anlægsaktiver | B3: 667947 | C3: 613578 | D3: 589011 | E3: 636873 | F3: 739302
A4: Kapitalandele, dattervirksomheder
A5: Deposita | B5: 5885 | C5: 2363 | D5: 1538 | E5: 1538 | F5: 1538
A6: Finansielle anlægsaktiver
A7: Anlægsaktiver | B7: 706954 | C7: 653619 | D7: 622801 | E7: 667650 | F7: 766712
A8: Varebeholdninger | B8: 144726 | C8: 164926 | D8: 205368 | E8: 194416 | F8: 199459
A9: Tilgodehavender fra salg og tjenesteydelser | B9: 264396 | C9: 271883 | D9: 355541 | E9: 418227 | F9: 419674
A10: Tilgodehavender hos tilknyttede virksomheder
A11: Andre tilgodehavender
A12: Periodeafgrænsningsposter (aktiver) | C12: 6504 | D12: 6572 | E12: 4573 | F12: 4757
A13: Udskudt skatteaktiv
A14: Tilgodehavende skat hos tilknyttede virksomheder
A15: Kortfristede skattetilgodehavender
A16: Tilgodehavender
A17: Værdipapirer
A18: Likvide beholdninger | B18: 16642 | C18: 46090 | D18: 9365 | E18: 33132 | F18: 30441
A19: Omsætningsaktiver | B19: 434115 | C19: 489403 | D19: 576846 | E19: 652776 | F19: 654331
A20: Aktiver | B20: 1141069 | C20: 1143022 | D20: 1199647 | E20: 1320426 | F20: 1421043
A21: Selskabskapital | B21: 60000 | C21: 60000 | D21: 60000 | E21: 60000 | F21: 60000
A22: Reserve for nettoopskrivning (indre værdis metode)
A23: Reserve for udviklingsomkostninger
A24: Reserve for sikringstransaktioner
A25: Andre reserver | B25: -1275 | C25: -225 | D25: -180 | E25: -9 | F25: 224
A26: Overført resultat | B26: 621067 | C26: 621128 | D26: 616814 | E26: 659575 | F26: 695926
A27: Egenkapital i alt | B27: 679792 | C27: 680903 | D27: 676634 | E27: 731566 | F27: 768150
A28: Hensættelse til udskudt skat | B28: 44629 | C28: 46453 | D28: 43380 | E28: 42656 | F28: 47729
A29: Hensatte forpligtelser | B29: 44629 | C29: 46453 | D29: 43380 | E29: 42656 | F29: 47729
A30: Ansvarlig lånekapital (langfristet)
A31: Langfristede lån
A32: Leasingforpligtelser (langfristet) | B32: 39907 | C32: 33029 | D32: 35342 | E32: 33435 | F32: 31999
A33: Anden gæld (langfristet) | B33: 86301 | C33: 70318 | D33: 54175 | E33: 36441 | F33: 67153
A34: Langfristede gældsforpligtelser | B34: 191687 | C34: 167172 | D34: 0 | E34: 54757 | F34: 178075
A35: Ansvarlig lånekapital (kortfristet)
A36: Kortfristet del af langfristede gældsforpligtelser
A37: Kreditinstitutter | B37: 16199 | C37: 0 | D37: 91427 | E37: 23316 | F37: 73933
A38: Leasingforpligtelser (kortfristet) | B38: 9996 | C38: 9683 | D38: 10813 | E38: 10886 | F38: 12135
A39: Leverandører af varer og tjenesteydelser | B39: 117908 | C39: 158597 | D39: 145121 | E39: 244505 | F39: 254769
A40: Gæld til tilknyttede virksomheder
...

Sheet pengestrom_raw
A1: harboe (CVR None) — Pengestrømsopgørelse (t.kr.) | B1: 2021 | C1: 2022 | D1: 2023 | E1: 2024 | F1: 2025
A2: Pengestrømme fra driftsaktivitet | B2: 21402 | C2: 100134 | D2: -58785 | E2: 182011 | F2: 86120
A3: Pengestrømme fra investeringsaktivitet | B3: -36256 | C3: -47119 | D3: -57066 | E3: -127041 | F3: -99591
A4: Pengestrømme fra finansieringsaktivitet | B4: -14180 | C4: -23384 | D4: 78838 | E4: -31257 | F4: 10725
A5: Årets pengestrøm

Sheet Simpel_funktion
A1: harboe (CVR None) — Regnskabs- og nøgletal — funktionsopdelt
A3: Beløb i 1.000 kr. | B3: 2025 | C3: 2024 | D3: 2023 | F3: Note / XBRL-felt
A4: Uddrag af resultatopgørelse
A5: Nettoomsætning | B5: ='res_raw'!$F$2 | C5: ='res_raw'!$E$2 | D5: ='res_raw'!$D$2 | F5: fsa:Revenue
A6: Produktionsomkostninger | B6: =-'res_raw'!$F$3 | C6: =-'res_raw'!$E$3 | D6: =-'res_raw'!$D$3 | F6: fsa:CostOfProduction (vises negativt). Materialer, lønninger, produktionsoverhead.
A7: Bruttoresultat | B7: =SUM(B5:B6) | C7: =SUM(C5:C6) | D7: =SUM(D5:D6) | F7: Beregnet: Nettoomsætning − Produktionsomkostninger. Matcher fsa:GrossResult.
A8: Salgs- og distributionsomk. | B8: =-'res_raw'!$F$5 | C8: =-'res_raw'!$E$5 | D8: =-'res_raw'!$D$5 | F8: fsa:DistributionCosts (vises negativt). Marketing, salg, distribution.
A9: Administrationsomkostninger mv. | B9: =-'res_raw'!$F$6 | C9: =-'res_raw'!$E$6 | D9: =-'res_raw'!$D$6 | F9: fsa:AdministrativeExpenses (vises negativt). Generel administration.
A10: Andre driftsindtægter | B10: ='res_raw'!$F$7 | C10: ='res_raw'!$E$7 | D10: ='res_raw'!$D$7 | F10: fsa:OtherOperatingIncome. Sekundære driftsindtægter (huslejeindtægter, off. tilskud, avancer mv.).
A11: Andre driftsomkostninger | B11: =-'res_raw'!$F$8 | C11: =-'res_raw'!$E$8 | D11: =-'res_raw'!$D$8 | F11: fsa:OtherOperatingExpenses (vises negativt). Sekundære driftsomkostninger.
A12: Resultat af primær drift | B12: =SUM(B7:B11) | C12: =SUM(C7:C11) | D12: =SUM(D7:D11) | F12: Beregnet: Bruttoresultat − Salgs/dist. − Administration + Andre driftsindt. − Andre driftsomk. EBIT.
A13: Finansielle indtægter mv. | B13: =N('res_raw'!$F$10)+N('res_raw'!$F$11) | C13: =N('res_raw'!$E$10)+N('res_raw'!$E$11) | D13: =N('res_raw'!$D$10)+N('res_raw'!$D$11) | F13: fsa:IncomeFromSubsidiaries + fsa:OtherFinanceIncome.
A14: Finansielle omkostninger mv. | B14: =-'res_raw'!$F$12 | C14: =-'res_raw'!$E$12 | D14: =-'res_raw'!$D$12 | F14: fsa:OtherFinanceExpenses (vises negativt). Renteomkostninger, kurstab.
A15: Resultat før skat | B15: =SUM(B12:B14) | C15: =SUM(C12:C14) | D15: =SUM(D12:D14) | F15: Beregnet: EBIT + Fin. indtægter + Fin. omk. EBT.
A17: Uddrag af balance
A18: Anlægsaktiver | B18: ='balance_raw'!$F$7 | C18: ='balance_raw'!$E$7 | D18: ='balance_raw'!$D$7 | F18: fsa:NoncurrentAssets. Materielle, immaterielle og finansielle anlægsaktiver.
A19: Omsætningsaktiver | B19: ='balance_raw'!$F$19 | C19: ='balance_raw'!$E$19 | D19: ='balance_raw'!$D$19 | F19: fsa:CurrentAssets. Varebeholdninger, tilgodehavender, likvider.
A20: Aktiver i alt | B20: =SUM(B18:B19) | C20: =SUM(C18:C19) | D20: =SUM(D18:D19) | F20: Beregnet: Anlægsaktiver + Omsætningsaktiver. Bør matche fsa:Assets.
A22: Egenkapital | B22: ='balance_raw'!$F$27 | C22: ='balance_raw'!$E$27 | D22: ='balance_raw'!$D$27 | F22: fsa:Equity. Selskabskapital, overført resultat, reserver.
A23: Forpligtelser | B23: ='balance_raw'!$F$48-'balance_raw'!$F$27 | C23: ='balance_raw'!$E$48-'balance_raw'!$E$27 | D23: ='balance_raw'!$D$48-'balance_raw'!$D$27 | F23: Beregnet: Passiver (fsa:LiabilitiesAndEquity) − Egenkapital. Hensættelser + kort- og langfristet gæld.
A24: Passiver i alt | B24: =SUM(B22:B23) | C24: =SUM(C22:C23) | D24: =SUM(D22:D23) | F24: Beregnet: Egenkapital + Forpligtelser. Bør matche Aktiver i alt.
A26: Udvalgte balanceposter
A27: Varebeholdninger | B27: ='balance_raw'!$F$8 | C27: ='balance_raw'!$E$8 | D27: ='balance_raw'!$D$8 | F27: fsa:Inventories (eller fsa:ManufacturedGoodsAndGoodsForResale hvis total mangler).
A28: Tilgodehavender fra salg | B28: ='balance_raw'!$F$9 | C28: ='balance_raw'!$E$9 | D28: ='balance_raw'!$D$9 | F28: fsa:ShorttermTradeReceivables. Kortfristede tilgodehavender fra kunder.
A29: Kortfristede gældsforpligtelser | B29: ='balance_raw'!$F$46 | C29: ='balance_raw'!$E$46 | D29: ='balance_raw'!$D$46 | F29: fsa:ShorttermLiabilitiesOtherThanProvisions. Gæld der forfalder inden for 1 år.
A31: Rentabilitet
A32: Afkastningsgrad, % | B32: =IFERROR((B12+B13)/B20*100,"") | C32: =IFERROR((C12+C13)/C20*100,"") | D32: =IFERROR((D12+D13)/D20*100,"")
A33: Overskudsgrad, % | B33: =IFERROR((B12+B13)/B5*100,"") | C33: =IFERROR((C12+C13)/C5*100,"") | D33: =IFERROR((D12+D13)/D5*100,"")
A34: Aktivernes omsætningshastighed, gange | B34: =IFERROR(B5/B20,"") | C34: =IFERROR(C5/C20,"") | D34: =IFERROR(D5/D20,"")
A35: Gældsrente, % | B35: =IFERROR(-B14*100/B23,"") | C35: =IFERROR(-C14*100/C23,"") | D35: =IFERROR(-D14*100/D23,"")
A36: Egenkapitalens forrentning, % | B36: =IFERROR(B15/B22*100,"") | C36: =IFERROR(C15/C22*100,"") | D36: =IFERROR(D15/D22*100,"")
A37: Gearing, gange | B37: =IFERROR(B23/B22,"") | C37: =IFERROR(C23/C22,"") | D37: =IFERROR(D23/D22,"")
A39: Indekstal for indtjeningsevne (2023=100)
A40: Nettoomsætning | B40: =IFERROR(B5/$D5*100,"") | C40: =IFERROR(C5/$D5*100,"") | D40: =IFERROR(D5/$D5*100,"")
A41: Produktionsomkostninger | B41: =IFERROR(B6/$D6*100,"") | C41: =IFERROR(C6/$D6*100,"") | D41: =IFERROR(D6/$D6*100,"")
A42: Salgs- og distributionsomk. | B42: =IFERROR(B8/$D8*100,"") | C42: =IFERROR(C8/$D8*100,"") | D42: =IFERROR(D8/$D8*100,"")
A43: Administrationsomk. | B43: =IFERROR(B9/$D9*100,"") | C43: =IFERROR(C9/$D9*100,"") | D43: =IFERROR(D9/$D9*100,"")
A44: Andre driftsomkostninger | B44: =IFERROR(B11/$D11*100,"") | C44: =IFERROR(C11/$D11*100,"") | D44: =IFERROR(D11/$D11*100,"")
A46: Indekstal for kapitaltilpasningsevne (2023=100)
A47: Nettoomsætning | B47: =IFERROR(B5*100/$D5,"") | C47: =IFERROR(C5*100/$D5,"") | D47: =IFERROR(D5*100/$D5,"")
...
