Workbook

Sheet Overblik_56759328
A1: Toms Gruppen A/S (CVR 56759328) — Regnskabsanalyse – Resultatopgørelse & Balance (t.kr.) · Klasse C-stor · Revision
H2: Indekstal (2021=100)
A3: Resultatopgørelse t.kr. | B3: 2021 | C3: 2022 | D3: 2023 | E3: 2024 | F3: 2025 | H3: 2021 | I3: 2022 | J3: 2023 | K3: 2024 | L3: 2025
A4: Nettoomsætning | B4: ='res_raw_56759328'!$B$2 | C4: ='res_raw_56759328'!$C$2 | D4: ='res_raw_56759328'!$D$2 | E4: ='res_raw_56759328'!$E$2 | F4: ='res_raw_56759328'!$F$2 | H4: =IFERROR(B4/$B$4*100,"") | I4: =IFERROR(C4/$B$4*100,"") | J4: =IFERROR(D4/$B$4*100,"") | K4: =IFERROR(E4/$B$4*100,"") | L4: =IFERROR(F4/$B$4*100,"")
A5: Produktionsomkostninger | B5: ='res_raw_56759328'!$B$3 | C5: ='res_raw_56759328'!$C$3 | D5: ='res_raw_56759328'!$D$3 | E5: ='res_raw_56759328'!$E$3 | F5: ='res_raw_56759328'!$F$3 | H5: =IFERROR(B5/$B$5*100,"") | I5: =IFERROR(C5/$B$5*100,"") | J5: =IFERROR(D5/$B$5*100,"") | K5: =IFERROR(E5/$B$5*100,"") | L5: =IFERROR(F5/$B$5*100,"")
A6: Bruttoresultat | B6: ='res_raw_56759328'!$B$4 | C6: ='res_raw_56759328'!$C$4 | D6: ='res_raw_56759328'!$D$4 | E6: ='res_raw_56759328'!$E$4 | F6: ='res_raw_56759328'!$F$4 | H6: =IFERROR(B6/$B$6*100,"") | I6: =IFERROR(C6/$B$6*100,"") | J6: =IFERROR(D6/$B$6*100,"") | K6: =IFERROR(E6/$B$6*100,"") | L6: =IFERROR(F6/$B$6*100,"")
A7: Salgs- og distributionsomkostninger | B7: ='res_raw_56759328'!$B$5 | C7: ='res_raw_56759328'!$C$5 | D7: ='res_raw_56759328'!$D$5 | E7: ='res_raw_56759328'!$E$5 | F7: ='res_raw_56759328'!$F$5 | H7: =IFERROR(B7/$B$7*100,"") | I7: =IFERROR(C7/$B$7*100,"") | J7: =IFERROR(D7/$B$7*100,"") | K7: =IFERROR(E7/$B$7*100,"") | L7: =IFERROR(F7/$B$7*100,"")
A8: Administrationsomkostninger | B8: ='res_raw_56759328'!$B$6 | C8: ='res_raw_56759328'!$C$6 | D8: ='res_raw_56759328'!$D$6 | E8: ='res_raw_56759328'!$E$6 | F8: ='res_raw_56759328'!$F$6 | H8: =IFERROR(B8/$B$8*100,"") | I8: =IFERROR(C8/$B$8*100,"") | J8: =IFERROR(D8/$B$8*100,"") | K8: =IFERROR(E8/$B$8*100,"") | L8: =IFERROR(F8/$B$8*100,"")
A9: Andre driftsindtægter | B9: ='res_raw_56759328'!$B$7 | C9: ='res_raw_56759328'!$C$7 | D9: ='res_raw_56759328'!$D$7 | E9: ='res_raw_56759328'!$E$7 | F9: ='res_raw_56759328'!$F$7 | H9: =IFERROR(B9/$B$9*100,"") | I9: =IFERROR(C9/$B$9*100,"") | J9: =IFERROR(D9/$B$9*100,"") | K9: =IFERROR(E9/$B$9*100,"") | L9: =IFERROR(F9/$B$9*100,"")
A10: Andre driftsomkostninger | B10: ='res_raw_56759328'!$B$8 | C10: ='res_raw_56759328'!$C$8 | D10: ='res_raw_56759328'!$D$8 | E10: ='res_raw_56759328'!$E$8 | F10: ='res_raw_56759328'!$F$8 | H10: =IFERROR(B10/$B$10*100,"") | I10: =IFERROR(C10/$B$10*100,"") | J10: =IFERROR(D10/$B$10*100,"") | K10: =IFERROR(E10/$B$10*100,"") | L10: =IFERROR(F10/$B$10*100,"")
A11: Resultat af primær drift | B11: ='res_raw_56759328'!$B$9 | C11: ='res_raw_56759328'!$C$9 | D11: ='res_raw_56759328'!$D$9 | E11: ='res_raw_56759328'!$E$9 | F11: ='res_raw_56759328'!$F$9 | H11: =IFERROR(B11/$B$11*100,"") | I11: =IFERROR(C11/$B$11*100,"") | J11: =IFERROR(D11/$B$11*100,"") | K11: =IFERROR(E11/$B$11*100,"") | L11: =IFERROR(F11/$B$11*100,"")
A12: Indtægter af kapitalandele, dattervirksomheder | B12: ='res_raw_56759328'!$B$10 | C12: ='res_raw_56759328'!$C$10 | D12: ='res_raw_56759328'!$D$10 | E12: ='res_raw_56759328'!$E$10 | F12: ='res_raw_56759328'!$F$10 | H12: =IFERROR(B12/$B$12*100,"") | I12: =IFERROR(C12/$B$12*100,"") | J12: =IFERROR(D12/$B$12*100,"") | K12: =IFERROR(E12/$B$12*100,"") | L12: =IFERROR(F12/$B$12*100,"")
A13: Finansielle indtægter | B13: ='res_raw_56759328'!$B$11 | C13: ='res_raw_56759328'!$C$11 | D13: ='res_raw_56759328'!$D$11 | E13: ='res_raw_56759328'!$E$11 | F13: ='res_raw_56759328'!$F$11 | H13: =IFERROR(B13/$B$13*100,"") | I13: =IFERROR(C13/$B$13*100,"") | J13: =IFERROR(D13/$B$13*100,"") | K13: =IFERROR(E13/$B$13*100,"") | L13: =IFERROR(F13/$B$13*100,"")
A14: Finansielle omkostninger | B14: ='res_raw_56759328'!$B$12 | C14: ='res_raw_56759328'!$C$12 | D14: ='res_raw_56759328'!$D$12 | E14: ='res_raw_56759328'!$E$12 | F14: ='res_raw_56759328'!$F$12 | H14: =IFERROR(B14/$B$14*100,"") | I14: =IFERROR(C14/$B$14*100,"") | J14: =IFERROR(D14/$B$14*100,"") | K14: =IFERROR(E14/$B$14*100,"") | L14: =IFERROR(F14/$B$14*100,"")
A15: Finansielle poster, netto | B15: ='res_raw_56759328'!$B$13 | C15: ='res_raw_56759328'!$C$13 | D15: ='res_raw_56759328'!$D$13 | E15: ='res_raw_56759328'!$E$13 | F15: ='res_raw_56759328'!$F$13 | H15: =IFERROR(B15/$B$15*100,"") | I15: =IFERROR(C15/$B$15*100,"") | J15: =IFERROR(D15/$B$15*100,"") | K15: =IFERROR(E15/$B$15*100,"") | L15: =IFERROR(F15/$B$15*100,"")
A16: Resultat før skat | B16: ='res_raw_56759328'!$B$14 | C16: ='res_raw_56759328'!$C$14 | D16: ='res_raw_56759328'!$D$14 | E16: ='res_raw_56759328'!$E$14 | F16: ='res_raw_56759328'!$F$14 | H16: =IFERROR(B16/$B$16*100,"") | I16: =IFERROR(C16/$B$16*100,"") | J16: =IFERROR(D16/$B$16*100,"") | K16: =IFERROR(E16/$B$16*100,"") | L16: =IFERROR(F16/$B$16*100,"")
A17: Skat af årets resultat | B17: ='res_raw_56759328'!$B$15 | C17: ='res_raw_56759328'!$C$15 | D17: ='res_raw_56759328'!$D$15 | E17: ='res_raw_56759328'!$E$15 | F17: ='res_raw_56759328'!$F$15 | H17: =IFERROR(B17/$B$17*100,"") | I17: =IFERROR(C17/$B$17*100,"") | J17: =IFERROR(D17/$B$17*100,"") | K17: =IFERROR(E17/$B$17*100,"") | L17: =IFERROR(F17/$B$17*100,"")
A18: Årets resultat | B18: ='res_raw_56759328'!$B$16 | C18: ='res_raw_56759328'!$C$16 | D18: ='res_raw_56759328'!$D$16 | E18: ='res_raw_56759328'!$E$16 | F18: ='res_raw_56759328'!$F$16 | H18: =IFERROR(B18/$B$18*100,"") | I18: =IFERROR(C18/$B$18*100,"") | J18: =IFERROR(D18/$B$18*100,"") | K18: =IFERROR(E18/$B$18*100,"") | L18: =IFERROR(F18/$B$18*100,"")
A20: AKTIVER t.kr. | B20: 2021 | C20: 2022 | D20: 2023 | E20: 2024 | F20: 2025 | H20: 2021 | I20: 2022 | J20: 2023 | K20: 2024 | L20: 2025
A21: Udviklingsprojekter | B21: ='balance_raw_56759328'!$B$2 | C21: ='balance_raw_56759328'!$C$2 | D21: ='balance_raw_56759328'!$D$2 | E21: ='balance_raw_56759328'!$E$2 | F21: ='balance_raw_56759328'!$F$2 | H21: =IFERROR(B21/$B$21*100,"") | I21: =IFERROR(C21/$B$21*100,"") | J21: =IFERROR(D21/$B$21*100,"") | K21: =IFERROR(E21/$B$21*100,"") | L21: =IFERROR(F21/$B$21*100,"")
A22: Patenter, varemærker mv. | B22: ='balance_raw_56759328'!$B$3 | C22: ='balance_raw_56759328'!$C$3 | D22: ='balance_raw_56759328'!$D$3 | E22: ='balance_raw_56759328'!$E$3 | F22: ='balance_raw_56759328'!$F$3 | H22: =IFERROR(B22/$B$22*100,"") | I22: =IFERROR(C22/$B$22*100,"") | J22: =IFERROR(D22/$B$22*100,"") | K22: =IFERROR(E22/$B$22*100,"") | L22: =IFERROR(F22/$B$22*100,"")
A23: Goodwill | B23: ='balance_raw_56759328'!$B$4 | C23: ='balance_raw_56759328'!$C$4 | D23: ='balance_raw_56759328'!$D$4 | E23: ='balance_raw_56759328'!$E$4 | F23: ='balance_raw_56759328'!$F$4 | H23: =IFERROR(B23/$B$23*100,"") | I23: =IFERROR(C23/$B$23*100,"") | J23: =IFERROR(D23/$B$23*100,"") | K23: =IFERROR(E23/$B$23*100,"") | L23: =IFERROR(F23/$B$23*100,"")
A24: Immaterielle anlægsaktiver | B24: ='balance_raw_56759328'!$B$5 | C24: ='balance_raw_56759328'!$C$5 | D24: ='balance_raw_56759328'!$D$5 | E24: ='balance_raw_56759328'!$E$5 | F24: ='balance_raw_56759328'!$F$5 | H24: =IFERROR(B24/$B$24*100,"") | I24: =IFERROR(C24/$B$24*100,"") | J24: =IFERROR(D24/$B$24*100,"") | K24: =IFERROR(E24/$B$24*100,"") | L24: =IFERROR(F24/$B$24*100,"")
A25: Grunde og bygninger | B25: ='balance_raw_56759328'!$B$6 | C25: ='balance_raw_56759328'!$C$6 | D25: ='balance_raw_56759328'!$D$6 | E25: ='balance_raw_56759328'!$E$6 | F25: ='balance_raw_56759328'!$F$6 | H25: =IFERROR(B25/$B$25*100,"") | I25: =IFERROR(C25/$B$25*100,"") | J25: =IFERROR(D25/$B$25*100,"") | K25: =IFERROR(E25/$B$25*100,"") | L25: =IFERROR(F25/$B$25*100,"")
A26: Produktionsanlæg og maskiner | B26: ='balance_raw_56759328'!$B$7 | C26: ='balance_raw_56759328'!$C$7 | D26: ='balance_raw_56759328'!$D$7 | E26: ='balance_raw_56759328'!$E$7 | F26: ='balance_raw_56759328'!$F$7 | H26: =IFERROR(B26/$B$26*100,"") | I26: =IFERROR(C26/$B$26*100,"") | J26: =IFERROR(D26/$B$26*100,"") | K26: =IFERROR(E26/$B$26*100,"") | L26: =IFERROR(F26/$B$26*100,"")
A27: Driftsmateriel og inventar | B27: ='balance_raw_56759328'!$B$8 | C27: ='balance_raw_56759328'!$C$8 | D27: ='balance_raw_56759328'!$D$8 | E27: ='balance_raw_56759328'!$E$8 | F27: ='balance_raw_56759328'!$F$8 | H27: =IFERROR(B27/$B$27*100,"") | I27: =IFERROR(C27/$B$27*100,"") | J27: =IFERROR(D27/$B$27*100,"") | K27: =IFERROR(E27/$B$27*100,"") | L27: =IFERROR(F27/$B$27*100,"")
A28: Indretning af lejede lokaler | B28: ='balance_raw_56759328'!$B$9 | C28: ='balance_raw_56759328'!$C$9 | D28: ='balance_raw_56759328'!$D$9 | E28: ='balance_raw_56759328'!$E$9 | F28: ='balance_raw_56759328'!$F$9 | H28: =IFERROR(B28/$B$28*100,"") | I28: =IFERROR(C28/$B$28*100,"") | J28: =IFERROR(D28/$B$28*100,"") | K28: =IFERROR(E28/$B$28*100,"") | L28: =IFERROR(F28/$B$28*100,"")
A29: Forudbetaling og anlægsaktiver under opførelse | B29: ='balance_raw_56759328'!$B$10 | C29: ='balance_raw_56759328'!$C$10 | D29: ='balance_raw_56759328'!$D$10 | E29: ='balance_raw_56759328'!$E$10 | F29: ='balance_raw_56759328'!$F$10 | H29: =IFERROR(B29/$B$29*100,"") | I29: =IFERROR(C29/$B$29*100,"") | J29: =IFERROR(D29/$B$29*100,"") | K29: =IFERROR(E29/$B$29*100,"") | L29: =IFERROR(F29/$B$29*100,"")
A30: Materielle anlægsaktiver | B30: ='balance_raw_56759328'!$B$11 | C30: ='balance_raw_56759328'!$C$11 | D30: ='balance_raw_56759328'!$D$11 | E30: ='balance_raw_56759328'!$E$11 | F30: ='balance_raw_56759328'!$F$11 | H30: =IFERROR(B30/$B$30*100,"") | I30: =IFERROR(C30/$B$30*100,"") | J30: =IFERROR(D30/$B$30*100,"") | K30: =IFERROR(E30/$B$30*100,"") | L30: =IFERROR(F30/$B$30*100,"")
A31: Finansielle anlægsaktiver | B31: ='balance_raw_56759328'!$B$12 | C31: ='balance_raw_56759328'!$C$12 | D31: ='balance_raw_56759328'!$D$12 | E31: ='balance_raw_56759328'!$E$12 | F31: ='balance_raw_56759328'!$F$12 | H31: =IFERROR(B31/$B$31*100,"") | I31: =IFERROR(C31/$B$31*100,"") | J31: =IFERROR(D31/$B$31*100,"") | K31: =IFERROR(E31/$B$31*100,"") | L31: =IFERROR(F31/$B$31*100,"")
A32: Anlægsaktiver | B32: ='balance_raw_56759328'!$B$13 | C32: ='balance_raw_56759328'!$C$13 | D32: ='balance_raw_56759328'!$D$13 | E32: ='balance_raw_56759328'!$E$13 | F32: ='balance_raw_56759328'!$F$13 | H32: =IFERROR(B32/$B$32*100,"") | I32: =IFERROR(C32/$B$32*100,"") | J32: =IFERROR(D32/$B$32*100,"") | K32: =IFERROR(E32/$B$32*100,"") | L32: =IFERROR(F32/$B$32*100,"")
A33: Varebeholdninger | B33: ='balance_raw_56759328'!$B$14 | C33: ='balance_raw_56759328'!$C$14 | D33: ='balance_raw_56759328'!$D$14 | E33: ='balance_raw_56759328'!$E$14 | F33: ='balance_raw_56759328'!$F$14 | H33: =IFERROR(B33/$B$33*100,"") | I33: =IFERROR(C33/$B$33*100,"") | J33: =IFERROR(D33/$B$33*100,"") | K33: =IFERROR(E33/$B$33*100,"") | L33: =IFERROR(F33/$B$33*100,"")
A34: Tilgodehavender fra salg og tjenesteydelser | B34: ='balance_raw_56759328'!$B$15 | C34: ='balance_raw_56759328'!$C$15 | D34: ='balance_raw_56759328'!$D$15 | E34: ='balance_raw_56759328'!$E$15 | F34: ='balance_raw_56759328'!$F$15 | H34: =IFERROR(B34/$B$34*100,"") | I34: =IFERROR(C34/$B$34*100,"") | J34: =IFERROR(D34/$B$34*100,"") | K34: =IFERROR(E34/$B$34*100,"") | L34: =IFERROR(F34/$B$34*100,"")
A35: Tilgodehavender hos tilknyttede virksomheder | B35: ='balance_raw_56759328'!$B$16 | C35: ='balance_raw_56759328'!$C$16 | D35: ='balance_raw_56759328'!$D$16 | E35: ='balance_raw_56759328'!$E$16 | F35: ='balance_raw_56759328'!$F$16 | H35: =IFERROR(B35/$B$35*100,"") | I35: =IFERROR(C35/$B$35*100,"") | J35: =IFERROR(D35/$B$35*100,"") | K35: =IFERROR(E35/$B$35*100,"") | L35: =IFERROR(F35/$B$35*100,"")
A36: Andre tilgodehavender | B36: ='balance_raw_56759328'!$B$17 | C36: ='balance_raw_56759328'!$C$17 | D36: ='balance_raw_56759328'!$D$17 | E36: ='balance_raw_56759328'!$E$17 | F36: ='balance_raw_56759328'!$F$17 | H36: =IFERROR(B36/$B$36*100,"") | I36: =IFERROR(C36/$B$36*100,"") | J36: =IFERROR(D36/$B$36*100,"") | K36: =IFERROR(E36/$B$36*100,"") | L36: =IFERROR(F36/$B$36*100,"")
A37: Periodeafgrænsningsposter (aktiver) | B37: ='balance_raw_56759328'!$B$18 | C37: ='balance_raw_56759328'!$C$18 | D37: ='balance_raw_56759328'!$D$18 | E37: ='balance_raw_56759328'!$E$18 | F37: ='balance_raw_56759328'!$F$18 | H37: =IFERROR(B37/$B$37*100,"") | I37: =IFERROR(C37/$B$37*100,"") | J37: =IFERROR(D37/$B$37*100,"") | K37: =IFERROR(E37/$B$37*100,"") | L37: =IFERROR(F37/$B$37*100,"")
A38: Udskudt skatteaktiv | B38: ='balance_raw_56759328'!$B$19 | C38: ='balance_raw_56759328'!$C$19 | D38: ='balance_raw_56759328'!$D$19 | E38: ='balance_raw_56759328'!$E$19 | F38: ='balance_raw_56759328'!$F$19 | H38: =IFERROR(B38/$B$38*100,"") | I38: =IFERROR(C38/$B$38*100,"") | J38: =IFERROR(D38/$B$38*100,"") | K38: =IFERROR(E38/$B$38*100,"") | L38: =IFERROR(F38/$B$38*100,"")
A39: Tilgodehavende skat hos tilknyttede virksomheder | B39: ='balance_raw_56759328'!$B$20 | C39: ='balance_raw_56759328'!$C$20 | D39: ='balance_raw_56759328'!$D$20 | E39: ='balance_raw_56759328'!$E$20 | F39: ='balance_raw_56759328'!$F$20 | H39: =IFERROR(B39/$B$39*100,"") | I39: =IFERROR(C39/$B$39*100,"") | J39: =IFERROR(D39/$B$39*100,"") | K39: =IFERROR(E39/$B$39*100,"") | L39: =IFERROR(F39/$B$39*100,"")
A40: Kortfristede skattetilgodehavender | B40: ='balance_raw_56759328'!$B$21 | C40: ='balance_raw_56759328'!$C$21 | D40: ='balance_raw_56759328'!$D$21 | E40: ='balance_raw_56759328'!$E$21 | F40: ='balance_raw_56759328'!$F$21 | H40: =IFERROR(B40/$B$40*100,"") | I40: =IFERROR(C40/$B$40*100,"") | J40: =IFERROR(D40/$B$40*100,"") | K40: =IFERROR(E40/$B$40*100,"") | L40: =IFERROR(F40/$B$40*100,"")
A41: Tilgodehavender | B41: ='balance_raw_56759328'!$B$22 | C41: ='balance_raw_56759328'!$C$22 | D41: ='balance_raw_56759328'!$D$22 | E41: ='balance_raw_56759328'!$E$22 | F41: ='balance_raw_56759328'!$F$22 | H41: =IFERROR(B41/$B$41*100,"") | I41: =IFERROR(C41/$B$41*100,"") | J41: =IFERROR(D41/$B$41*100,"") | K41: =IFERROR(E41/$B$41*100,"") | L41: =IFERROR(F41/$B$41*100,"")
...

Sheet res_raw_56759328
A1: Toms Gruppen A/S (CVR 56759328) — Resultatopgørelse & nøgleoplysninger (t.kr.) | B1: 2021 | C1: 2022 | D1: 2023 | E1: 2024 | F1: 2025
A2: Nettoomsætning | B2: 1602273 | C2: 1777718 | D2: 1660868 | E2: 1683500 | F2: 1802100
A3: Produktionsomkostninger | B3: 1031522 | C3: 1142482 | D3: 1203505 | E3: 1239900 | F3: 1393200
A4: Bruttoresultat | B4: 570751 | C4: 635236 | D4: 457363 | E4: 443600 | F4: 408900
A5: Salgs- og distributionsomkostninger | B5: 407105 | C5: 449398 | D5: 310453 | E5: 251600 | F5: 254200
A6: Administrationsomkostninger | B6: 88547 | C6: 90481 | D6: 97044 | E6: 109500 | F6: 102200
A7: Andre driftsindtægter | E7: 90600 | F7: 1100
A8: Andre driftsomkostninger | F8: 2200
A9: Resultat af primær drift | B9: 75099 | C9: 95357 | D9: 49866 | E9: 82500 | F9: 52500
A10: Indtægter af kapitalandele, dattervirksomheder | B10: 0 | C10: 0 | D10: 0 | E10: 0 | F10: 0
A11: Finansielle indtægter | B11: 0 | C11: 2223 | D11: 33643 | E11: 5500 | F11: 27000
A12: Finansielle omkostninger | B12: 22418 | C12: 10540 | D12: 12436 | E12: 11500 | F12: 30100
A13: Finansielle poster, netto | B13: -22400 | C13: -8300 | D13: 21200 | E13: -6000 | F13: -3100
A14: Resultat før skat | B14: 52681 | C14: 87040 | D14: 71073 | E14: 167100 | F14: 48300
A15: Skat af årets resultat | B15: -3399 | C15: 15071 | D15: 16734 | E15: 43800 | F15: 7100
A16: Årets resultat | B16: 56080 | C16: 71969 | D16: 54339 | E16: 123300 | F16: 41200
A17: Gns. antal medarbejdere | B17: 928 | C17: 919 | D17: 902 | E17: 841 | F17: 900
A18: Investering i materielle anlægsaktiver

Sheet balance_raw_56759328
A1: Toms Gruppen A/S (CVR 56759328) — Balance (t.kr.) | B1: 2021 | C1: 2022 | D1: 2023 | E1: 2024 | F1: 2025
A2: Udviklingsprojekter | D2: 10670 | E2: 0
A3: Patenter, varemærker mv. | B3: 4596 | C3: 4195 | D3: 939 | E3: 13100
A4: Goodwill | B4: 962 | C4: 0 | D4: 0
A5: Immaterielle anlægsaktiver | B5: 5558 | C5: 4195 | D5: 11609 | E5: 13100 | F5: 10900
A6: Grunde og bygninger | B6: 311875 | C6: 300760 | D6: 325425 | E6: 316900
A7: Produktionsanlæg og maskiner | B7: 442635 | C7: 417381 | D7: 396952 | E7: 367200
A8: Driftsmateriel og inventar | B8: 17833 | C8: 9191 | D8: 7819 | E8: 12400
A9: Indretning af lejede lokaler
A10: Forudbetaling og anlægsaktiver under opførelse | B10: 3682 | C10: 4324 | D10: 7026 | E10: 9900
A11: Materielle anlægsaktiver | B11: 776025 | C11: 731656 | D11: 737222 | E11: 706400 | F11: 761100
A12: Finansielle anlægsaktiver | B12: 36556 | C12: 40095 | D12: 41561 | E12: 16800
A13: Anlægsaktiver | B13: 818139 | C13: 775946 | D13: 790392 | E13: 736300 | F13: 788600
A14: Varebeholdninger | B14: 235224 | C14: 277756 | D14: 318694 | E14: 285700 | F14: 346300
A15: Tilgodehavender fra salg og tjenesteydelser | B15: 203244 | C15: 267076 | D15: 289411 | E15: 290000 | F15: 314700
A16: Tilgodehavender hos tilknyttede virksomheder | B16: 0 | C16: 3 | D16: 81 | E16: 18300 | F16: 0
A17: Andre tilgodehavender | B17: 24761 | C17: 33229 | D17: 11712 | E17: 34400 | F17: 39300
A18: Periodeafgrænsningsposter (aktiver)
A19: Udskudt skatteaktiv | B19: 36556 | C19: 40095 | D19: 41561 | E19: 16800 | F19: 16600
A20: Tilgodehavende skat hos tilknyttede virksomheder
A21: Kortfristede skattetilgodehavender | B21: 3583 | C21: 2261 | D21: 12276 | E21: 500 | F21: 5500
A22: Tilgodehavender | B22: 231588 | C22: 306025 | D22: 313480
A23: Værdipapirer | B23: 725 | C23: 774 | D23: 846
A24: Likvide beholdninger | B24: 97053 | C24: 31638 | D24: 61553 | E24: 183900 | F24: 111500
A25: Omsætningsaktiver | B25: 564590 | C25: 616193 | D25: 694573 | E25: 812800 | F25: 817300
A26: Aktiver | B26: 1382729 | C26: 1392139 | D26: 1484965 | E26: 1549100 | F26: 1605900
A27: Selskabskapital | B27: 3500 | C27: 3500 | D27: 3500 | E27: 3500 | F27: 3500
A28: Reserve for nettoopskrivning (indre værdis metode)
A29: Reserve for udviklingsomkostninger
A30: Reserve for sikringstransaktioner
A31: Andre reserver | F31: 11800
A32: Overført resultat | B32: 760033 | C32: 833686 | D32: 904692 | E32: 1033400 | F32: 1083100
A33: Egenkapital i alt | B33: 763533 | C33: 837186 | D33: 908192 | E33: 1036900 | F33: 1098400
A34: Hensættelse til udskudt skat | B34: 24445 | F34: 37800
A35: Hensatte forpligtelser | B35: 21447 | C35: 31 | D35: 60338 | E35: 28700 | F35: 61700
A36: Ansvarlig lånekapital (langfristet)
A37: Langfristede lån | B37: 163985 | C37: 155497 | D37: 146860 | E37: 138200 | F37: 129100
A38: Leasingforpligtelser (langfristet)
A39: Anden gæld (langfristet) | B39: 14691 | C39: 14781
A40: Langfristede gældsforpligtelser | B40: 224568 | C40: 219131 | D40: 224361 | E40: 210900 | F40: 195000
...

Sheet pengestrom_raw_56759328
A1: Toms Gruppen A/S (CVR 56759328) — Pengestrømsopgørelse (t.kr.) | B1: 2021 | C1: 2022 | D1: 2023 | E1: 2024 | F1: 2025
A2: Pengestrømme fra driftsaktivitet | B2: 204566 | C2: 8925 | D2: 90420 | E2: 95100 | F2: 62900
A3: Pengestrømme fra investeringsaktivitet | B3: -49693 | C3: -48413 | D3: -44375 | E3: 53400 | F3: -130700
A4: Pengestrømme fra finansieringsaktivitet | B4: -63842 | C4: -16828 | D4: -17185 | E4: -20100 | F4: -11300
A5: Årets pengestrøm

Sheet Simpel_funktion
A1: Toms Gruppen A/S (CVR 56759328) — Regnskabs- og nøgletal (CVR: 56759328) — funktionsopdelt
A3: Beløb i 1.000 kr. | B3: 2025 | C3: 2024 | D3: 2023 | F3: Note / XBRL-felt
A4: Uddrag af resultatopgørelse
A5: Nettoomsætning | B5: ='res_raw_56759328'!$F$2 | C5: ='res_raw_56759328'!$E$2 | D5: ='res_raw_56759328'!$D$2 | F5: fsa:Revenue
A6: Produktionsomkostninger | B6: =-'res_raw_56759328'!$F$3 | C6: =-'res_raw_56759328'!$E$3 | D6: =-'res_raw_56759328'!$D$3 | F6: fsa:CostOfProduction (vises negativt). Materialer, lønninger, produktionsoverhead.
A7: Bruttoresultat | B7: =SUM(B5:B6) | C7: =SUM(C5:C6) | D7: =SUM(D5:D6) | F7: Beregnet: Nettoomsætning − Produktionsomkostninger. Matcher fsa:GrossResult.
A8: Salgs- og distributionsomk. | B8: =-'res_raw_56759328'!$F$5 | C8: =-'res_raw_56759328'!$E$5 | D8: =-'res_raw_56759328'!$D$5 | F8: fsa:DistributionCosts (vises negativt). Marketing, salg, distribution.
A9: Administrationsomkostninger mv. | B9: =-'res_raw_56759328'!$F$6 | C9: =-'res_raw_56759328'!$E$6 | D9: =-'res_raw_56759328'!$D$6 | F9: fsa:AdministrativeExpenses (vises negativt). Generel administration.
A10: Andre driftsindtægter | B10: ='res_raw_56759328'!$F$7 | C10: ='res_raw_56759328'!$E$7 | D10: ='res_raw_56759328'!$D$7 | F10: fsa:OtherOperatingIncome. Sekundære driftsindtægter (huslejeindtægter, off. tilskud, avancer mv.).
A11: Andre driftsomkostninger | B11: =-'res_raw_56759328'!$F$8 | C11: =-'res_raw_56759328'!$E$8 | D11: =-'res_raw_56759328'!$D$8 | F11: fsa:OtherOperatingExpenses (vises negativt). Sekundære driftsomkostninger.
A12: Resultat af primær drift | B12: =SUM(B7:B11) | C12: =SUM(C7:C11) | D12: =SUM(D7:D11) | F12: Beregnet: Bruttoresultat − Salgs/dist. − Administration + Andre driftsindt. − Andre driftsomk. EBIT.
A13: Finansielle indtægter mv. | B13: =N('res_raw_56759328'!$F$10)+N('res_raw_56759328'!$F$11) | C13: =N('res_raw_56759328'!$E$10)+N('res_raw_56759328'!$E$11) | D13: =N('res_raw_56759328'!$D$10)+N('res_raw_56759328'!$D$11) | F13: fsa:IncomeFromSubsidiaries + fsa:OtherFinanceIncome.
A14: Finansielle omkostninger mv. | B14: =-'res_raw_56759328'!$F$12 | C14: =-'res_raw_56759328'!$E$12 | D14: =-'res_raw_56759328'!$D$12 | F14: fsa:OtherFinanceExpenses (vises negativt). Renteomkostninger, kurstab.
A15: Resultat før skat | B15: =SUM(B12:B14) | C15: =SUM(C12:C14) | D15: =SUM(D12:D14) | F15: Beregnet: EBIT + Fin. indtægter + Fin. omk. EBT.
A17: Uddrag af balance
A18: Anlægsaktiver | B18: ='balance_raw_56759328'!$F$13 | C18: ='balance_raw_56759328'!$E$13 | D18: ='balance_raw_56759328'!$D$13 | F18: fsa:NoncurrentAssets. Materielle, immaterielle og finansielle anlægsaktiver.
A19: Omsætningsaktiver | B19: ='balance_raw_56759328'!$F$25 | C19: ='balance_raw_56759328'!$E$25 | D19: ='balance_raw_56759328'!$D$25 | F19: fsa:CurrentAssets. Varebeholdninger, tilgodehavender, likvider.
A20: Aktiver i alt | B20: =SUM(B18:B19) | C20: =SUM(C18:C19) | D20: =SUM(D18:D19) | F20: Beregnet: Anlægsaktiver + Omsætningsaktiver. Bør matche fsa:Assets.
A22: Egenkapital | B22: ='balance_raw_56759328'!$F$33 | C22: ='balance_raw_56759328'!$E$33 | D22: ='balance_raw_56759328'!$D$33 | F22: fsa:Equity. Selskabskapital, overført resultat, reserver.
A23: Forpligtelser | B23: ='balance_raw_56759328'!$F$54-'balance_raw_56759328'!$F$33 | C23: ='balance_raw_56759328'!$E$54-'balance_raw_56759328'!$E$33 | D23: ='balance_raw_56759328'!$D$54-'balance_raw_56759328'!$D$33 | F23: Beregnet: Passiver (fsa:LiabilitiesAndEquity) − Egenkapital. Hensættelser + kort- og langfristet gæld.
A24: Passiver i alt | B24: =SUM(B22:B23) | C24: =SUM(C22:C23) | D24: =SUM(D22:D23) | F24: Beregnet: Egenkapital + Forpligtelser. Bør matche Aktiver i alt.
A26: Udvalgte balanceposter
A27: Varebeholdninger | B27: ='balance_raw_56759328'!$F$14 | C27: ='balance_raw_56759328'!$E$14 | D27: ='balance_raw_56759328'!$D$14 | F27: fsa:Inventories (eller fsa:ManufacturedGoodsAndGoodsForResale hvis total mangler).
A28: Tilgodehavender fra salg | B28: ='balance_raw_56759328'!$F$15 | C28: ='balance_raw_56759328'!$E$15 | D28: ='balance_raw_56759328'!$D$15 | F28: fsa:ShorttermTradeReceivables. Kortfristede tilgodehavender fra kunder.
A29: Kortfristede gældsforpligtelser | B29: ='balance_raw_56759328'!$F$52 | C29: ='balance_raw_56759328'!$E$52 | D29: ='balance_raw_56759328'!$D$52 | F29: fsa:ShorttermLiabilitiesOtherThanProvisions. Gæld der forfalder inden for 1 år.
A31: Rentabilitet
A32: Afkastningsgrad, % | B32: =IFERROR((B12+B13)/B20*100,"") | C32: =IFERROR((C12+C13)/C20*100,"") | D32: =IFERROR((D12+D13)/D20*100,"")
A33: Overskudsgrad, % | B33: =IFERROR((B12+B13)/B5*100,"") | C33: =IFERROR((C12+C13)/C5*100,"") | D33: =IFERROR((D12+D13)/D5*100,"")
A34: Aktivernes omsætningshastighed, gange | B34: =IFERROR(B5/B20,"") | C34: =IFERROR(C5/C20,"") | D34: =IFERROR(D5/D20,"")
A35: Gældsrente, % | B35: =IFERROR(-B14*100/B23,"") | C35: =IFERROR(-C14*100/C23,"") | D35: =IFERROR(-D14*100/D23,"")
A36: Egenkapitalens forrentning, % | B36: =IFERROR(B15/B22*100,"") | C36: =IFERROR(C15/C22*100,"") | D36: =IFERROR(D15/D22*100,"")
A37: Gearing, gange | B37: =IFERROR(B23/B22,"") | C37: =IFERROR(C23/C22,"") | D37: =IFERROR(D23/D22,"")
A39: Indekstal for indtjeningsevne (2023=100)
A40: Nettoomsætning | B40: =IFERROR(B5/$D5*100,"") | C40: =IFERROR(C5/$D5*100,"") | D40: =IFERROR(D5/$D5*100,"")
A41: Produktionsomkostninger | B41: =IFERROR(B6/$D6*100,"") | C41: =IFERROR(C6/$D6*100,"") | D41: =IFERROR(D6/$D6*100,"")
A42: Salgs- og distributionsomk. | B42: =IFERROR(B8/$D8*100,"") | C42: =IFERROR(C8/$D8*100,"") | D42: =IFERROR(D8/$D8*100,"")
A43: Administrationsomk. | B43: =IFERROR(B9/$D9*100,"") | C43: =IFERROR(C9/$D9*100,"") | D43: =IFERROR(D9/$D9*100,"")
A44: Andre driftsomkostninger | B44: =IFERROR(B11/$D11*100,"") | C44: =IFERROR(C11/$D11*100,"") | D44: =IFERROR(D11/$D11*100,"")
A46: Indekstal for kapitaltilpasningsevne (2023=100)
A47: Nettoomsætning | B47: =IFERROR(B5*100/$D5,"") | C47: =IFERROR(C5*100/$D5,"") | D47: =IFERROR(D5*100/$D5,"")
...

Sheet Noter_info
A1: Toms Gruppen A/S (CVR 56759328) — Ukendte XBRL-felter — disse er noter og ikke en del af hoved-regnskabet
A2: Kategori | B2: Dansk navn | C2: XBRL feltnavn | D2: 2021 t.kr. | E2: 2022 t.kr. | F2: 2023 t.kr. | G2: 2024 t.kr. | H2: 2025 t.kr. | I2: Forklaring
A3: Øvrige (ukendt) | B3: fsa:AdjustmentsOfCollateralsBySaleOfInvestments | C3: fsa:AdjustmentsOfCollateralsBySaleOfInvestments | D3: 256 | I3: Ingen forklaring tilgængelig.
A4: Øvrige (ukendt) | B4: fsa:CashFlowsStatement | C4: fsa:CashFlowsStatement | D4: 2 | I4: Ingen forklaring tilgængelig.
A5: Øvrige (ukendt) | B5: fsa:DepreciationOfEquity | C5: fsa:DepreciationOfEquity | H5: 0 | I5: Ingen forklaring tilgængelig.
A6: Øvrige (ukendt) | B6: fsa:Dividend | C6: fsa:Dividend | E6: -71969 | I6: Ingen forklaring tilgængelig.
A7: Øvrige (ukendt) | B7: fsa:ImpairmentLossesAndDepreciationOfActuarialGainsLossesStatementOfChangesInEquity | C7: fsa:ImpairmentLossesAndDepreciationOfActuarialGainsLossesStatementOfChangesInEquity | H7: 2000 | I7: Ingen forklaring tilgængelig.
A8: Øvrige (ukendt) | B8: fsa:LongtermDeferredIncome | C8: fsa:LongtermDeferredIncome | E8: 32182 | F8: 43431 | G8: 39100 | I8: Ingen forklaring tilgængelig.
A9: Øvrige (ukendt) | B9: fsa:ProvisionsForInvestmentsInGroupEnterprises | C9: fsa:ProvisionsForInvestmentsInGroupEnterprises | D9: 6911 | I9: Ingen forklaring tilgængelig.
